Workbook

Sheet 113年9月23日
A1: 項次
B3: 工程名稱 | C3: 預定完成日期 | F3: 實際完成日期 | G3: 113年9月23日當日動員機具 | L3: 承辦 工務所 | M3: =工程基本資料!D3 -> 任益芳 | N3: =M3 -> 任益芳 | O3: =L6 -> 南區工務所
B4: =工程基本資料!C3 -> H-113-03-113019 | C4: 項目 | D4: 日期 | G4: 項目 | H4: 數量 | J4: 今日施作內容 | K4: 明日預定施作內容 | N4: =N3 -> 任益芳 | O4: =O3 -> 南區工務所
A5: 1 | B5: =工程基本資料!B3 -> 113年度南區河濱公園路面暨災後復原預約維護工程 | C5: 機車便道 | D5: 年 月 日 | F5: 年 月 日 | G5: 人(含司機) | H5: 0 | I5: 人 | N5: =N4 -> 任益芳 | O5: =O4 -> 南區工務所
C6: 停車場 | D6: 年 月 日 | F6: 年 月 日 | G6: 怪手 | H6: 0 | I6: 輛 | L6: =工程基本資料!E3 -> 南區工務所 | M6: =工程基本資料!I3 -> 松瑩營造有限公司 | N6: =N5 -> 任益芳 | O6: =O5 -> 南區工務所
C7: 自行車道 | D7: 年 月 日 | F7: 年 月 日 | G7: 吊車 | H7: 0 | I7: 輛 | N7: =N6 -> 任益芳 | O7: =O6 -> 南區工務所
C8: 全面完成 | D8: 年 月 日 | F8: 年 月 日 | G8: 推土機 | H8: 0 | I8: 輛 | N8: =N7 -> 任益芳 | O8: =O7 -> 南區工務所
G9: 卡車 | H9: 0 | I9: 輛 | N9: =N8 -> 任益芳 | O9: =O8 -> 南區工務所
G10: 水車 | H10: 0 | I10: 輛 | N10: =N9 -> 任益芳 | O10: =O9 -> 南區工務所
G11: 夾子車 | H11: 0 | I11: 輛 | N11: =N10 -> 任益芳 | O11: =O10 -> 南區工務所
G12: 鏈鋸 | H12: 0 | I12: 台 | N12: =N11 -> 任益芳 | O12: =O11 -> 南區工務所
G13: 小山貓 | H13: 0 | I13: 輛 | N13: =N12 -> 任益芳 | O13: =O12 -> 南區工務所
B14: 工程名稱 | C14: 預定完成日期 | F14: 實際完成日期 | G14: =$G$3 -> 113年9月23日當日動員機具 | L14: 承辦 工務所 | M14: =工程基本資料!D4 -> 任益芳 | N14: =M14 -> 任益芳 | O14: =L17 -> 南區工務所
B15: =工程基本資料!C4 -> H-113-03-113022 | C15: 項目 | D15: 日期 | G15: 項目 | H15: 數量 | J15: 今日施作內容 | K15: 明日預定施作內容 | N15: =N14 -> 任益芳 | O15: =O14 -> 南區工務所
A16: 2 | B16: =工程基本資料!B4 -> 113年度南區水利建造物檢修改善及災後復原(新店溪永福橋至萬板大橋段)預約維護工程 | C16: 機車便道 | D16: 年 月 日 | F16: 年 月 日 | G16: 人(含司機) | H16: 0 | I16: 人 | N16: =N15 -> 任益芳 | O16: =O15 -> 南區工務所
C17: 停車場 | D17: 年 月 日 | F17: 年 月 日 | G17: 怪手 | H17: 0 | I17: 輛 | L17: =工程基本資料!E4 -> 南區工務所 | M17: =工程基本資料!I4 -> 鋐城營造有限公司 | N17: =N16 -> 任益芳 | O17: =O16 -> 南區工務所
C18: 自行車道 | D18: 年 月 日 | F18: 年 月 日 | G18: 吊車 | H18: 0 | I18: 輛 | N18: =N17 -> 任益芳 | O18: =O17 -> 南區工務所
C19: 全面完成 | D19: 年 月 日 | F19: 年 月 日 | G19: 推土機 | H19: 0 | I19: 輛 | N19: =N18 -> 任益芳 | O19: =O18 -> 南區工務所
G20: 卡車 | H20: 0 | I20: 輛 | N20: =N19 -> 任益芳 | O20: =O19 -> 南區工務所
G21: 水車 | H21: 0 | I21: 輛 | N21: =N20 -> 任益芳 | O21: =O20 -> 南區工務所
G22: 夾子車 | H22: 0 | I22: 輛 | N22: =N21 -> 任益芳 | O22: =O21 -> 南區工務所
G23: 鏈鋸 | H23: 0 | I23: 台 | N23: =N22 -> 任益芳 | O23: =O22 -> 南區工務所
G24: 小山貓 | H24: 0 | I24: 輛 | N24: =N22 -> 任益芳 | O24: =O23 -> 南區工務所
B25: 工程名稱 | C25: 預定完成日期 | F25: 實際完成日期 | G25: =$G$3 -> 113年9月23日當日動員機具 | L25: 承辦 工務所 | M25: =工程基本資料!D5 -> 王伯豪 | N25: =M25 -> 王伯豪 | O25: =L28 -> 南區工務所
B26: =工程基本資料!C5 -> H-113-03-113047 | C26: 項目 | D26: 日期 | G26: 項目 | H26: 數量 | J26: 今日施作內容 | K26: 明日預定施作內容 | N26: =N25 -> 王伯豪 | O26: =O25 -> 南區工務所
A27: 3 | B27: =工程基本資料!B5 -> 113年度南區河濱公園土木（含颱風豪雨設施撤離）暨災後復原預約維護工程 | C27: 機車便道 | D27: 年 月 日 | F27: 年 月 日 | G27: 人(含司機) | H27: 12 | I27: 人 | J27: 景美溪(北新橋至道南橋)自行車道清理 | K27: 景美溪(北新橋至道南橋)自行車道清理 | N27: =N26 -> 王伯豪 | O27: =O26 -> 南區工務所
C28: 停車場 | D28: 年 月 日 | F28: 年 月 日 | G28: 怪手 | H28: 1 | I28: 輛 | L28: =工程基本資料!E5 -> 南區工務所 | M28: =工程基本資料!I5 -> 泇溢營造有限公司 | N28: =N27 -> 王伯豪 | O28: =O27 -> 南區工務所
C29: 自行車道 | D29: 113年 9月 24日 | F29: 年 月 日 | G29: 吊車 | H29: 0 | I29: 輛 | N29: =N28 -> 王伯豪 | O29: =O28 -> 南區工務所
C30: 全面完成 | D30: 年 月 日 | F30: 年 月 日 | G30: 推土機 | H30: 1 | I30: 輛 | N30: =N29 -> 王伯豪 | O30: =O29 -> 南區工務所
G31: 卡車 | H31: 3 | I31: 輛 | N31: =N30 -> 王伯豪 | O31: =O30 -> 南區工務所
G32: 水車 | H32: 1 | I32: 輛 | N32: =N31 -> 王伯豪 | O32: =O31 -> 南區工務所
G33: 夾子車 | H33: 0 | I33: 輛 | N33: =N32 -> 王伯豪 | O33: =O32 -> 南區工務所
G34: 鏈鋸 | H34: 0 | I34: 台 | N34: =N33 -> 王伯豪 | O34: =O33 -> 南區工務所
G35: 小山貓 | H35: 1 | I35: 輛 | N35: =N34 -> 王伯豪 | O35: =O34 -> 南區工務所
B36: 工程名稱 | C36: 預定完成日期 | F36: 實際完成日期 | G36: =$G$3 -> 113年9月23日當日動員機具 | L36: 承辦 工務所 | M36: =工程基本資料!D6 -> 詹智為、張思漢 | N36: =M36 -> 詹智為、張思漢 | O36: =L39 -> 北區工務所
B37: =工程基本資料!C6 -> H-113-03-113021 | C37: 項目 | D37: 日期 | G37: 項目 | H37: 數量 | J37: 今日施作內容 | K37: 明日預定施作內容 | N37: =N36 -> 詹智為、張思漢 | O37: =O36 -> 北區工務所
A38: 4 | B38: =工程基本資料!B6 -> 113年度西區水利建造物檢修改善及災後復原(基隆河左岸高速公路內湖橋至洲美大橋段)預約維護工程 | C38: 機車便道 | D38: 113年9月23日 | F38: 年 月 日 | G38: 人(含司機) | H38: 9 | I38: 人 | J38: 機車便道淤泥清理 | K38: 停車場淤泥清理 | N38: =N37 -> 詹智為、張思漢 | O38: =O37 -> 北區工務所
C39: 停車場 | D39: 113年9月25日 | F39: 年 月 日 | G39: 怪手 | H39: 0 | I39: 輛 | L39: =工程基本資料!E6 -> 北區工務所 | M39: =工程基本資料!I6 -> 逸峰營造有限公司 | N39: =N38 -> 詹智為、張思漢 | O39: =O38 -> 北區工務所
C40: 自行車道 | D40: 113年9月30日 | F40: 年 月 日 | G40: 吊車 | H40: 1 | I40: 輛 | N40: =N39 -> 詹智為、張思漢 | O40: =O39 -> 北區工務所
C41: 全面完成 | D41: 113年10月7日 | F41: 年 月 日 | G41: 推土機 | H41: 1 | I41: 輛 | N41: =N40 -> 詹智為、張思漢 | O41: =O40 -> 北區工務所
...

Sheet 113年9月24日
A1: 項次
B3: 工程名稱 | C3: 預定完成日期 | F3: 實際完成日期 | G3: 113年9月24日當日動員機具 | L3: 承辦 工務所 | M3: =工程基本資料!D3 -> 任益芳 | N3: =M3 -> 任益芳 | O3: =L6 -> 南區工務所
B4: =工程基本資料!C3 -> H-113-03-113019 | C4: 項目 | D4: 日期 | G4: 項目 | H4: 數量 | J4: 今日施作內容 | K4: 明日預定施作內容 | N4: =N3 -> 任益芳 | O4: =O3 -> 南區工務所
A5: 1 | B5: =工程基本資料!B3 -> 113年度南區河濱公園路面暨災後復原預約維護工程 | C5: 機車便道 | D5: 年 月 日 | F5: 年 月 日 | G5: 人(含司機) | H5: 0 | I5: 人 | N5: =N4 -> 任益芳 | O5: =O4 -> 南區工務所
C6: 停車場 | D6: 年 月 日 | F6: 年 月 日 | G6: 怪手 | H6: 0 | I6: 輛 | L6: =工程基本資料!E3 -> 南區工務所 | M6: =工程基本資料!I3 -> 松瑩營造有限公司 | N6: =N5 -> 任益芳 | O6: =O5 -> 南區工務所
C7: 自行車道 | D7: 年 月 日 | F7: 年 月 日 | G7: 吊車 | H7: 0 | I7: 輛 | N7: =N6 -> 任益芳 | O7: =O6 -> 南區工務所
C8: 全面完成 | D8: 年 月 日 | F8: 年 月 日 | G8: 推土機 | H8: 0 | I8: 輛 | N8: =N7 -> 任益芳 | O8: =O7 -> 南區工務所
G9: 卡車 | H9: 0 | I9: 輛 | N9: =N8 -> 任益芳 | O9: =O8 -> 南區工務所
G10: 水車 | H10: 0 | I10: 輛 | N10: =N9 -> 任益芳 | O10: =O9 -> 南區工務所
G11: 夾子車 | H11: 0 | I11: 輛 | N11: =N10 -> 任益芳 | O11: =O10 -> 南區工務所
G12: 鏈鋸 | H12: 0 | I12: 台 | N12: =N11 -> 任益芳 | O12: =O11 -> 南區工務所
G13: 小山貓 | H13: 0 | I13: 輛 | N13: =N12 -> 任益芳 | O13: =O12 -> 南區工務所
B14: 工程名稱 | C14: 預定完成日期 | F14: 實際完成日期 | G14: =$G$3 -> 113年9月24日當日動員機具 | L14: 承辦 工務所 | M14: =工程基本資料!D4 -> 任益芳 | N14: =M14 -> 任益芳 | O14: =L17 -> 南區工務所
B15: =工程基本資料!C4 -> H-113-03-113022 | C15: 項目 | D15: 日期 | G15: 項目 | H15: 數量 | J15: 今日施作內容 | K15: 明日預定施作內容 | N15: =N14 -> 任益芳 | O15: =O14 -> 南區工務所
A16: 2 | B16: =工程基本資料!B4 -> 113年度南區水利建造物檢修改善及災後復原(新店溪永福橋至萬板大橋段)預約維護工程 | C16: 機車便道 | D16: 年 月 日 | F16: 年 月 日 | G16: 人(含司機) | H16: 0 | I16: 人 | N16: =N15 -> 任益芳 | O16: =O15 -> 南區工務所
C17: 停車場 | D17: 年 月 日 | F17: 年 月 日 | G17: 怪手 | H17: 0 | I17: 輛 | L17: =工程基本資料!E4 -> 南區工務所 | M17: =工程基本資料!I4 -> 鋐城營造有限公司 | N17: =N16 -> 任益芳 | O17: =O16 -> 南區工務所
C18: 自行車道 | D18: 年 月 日 | F18: 年 月 日 | G18: 吊車 | H18: 0 | I18: 輛 | N18: =N17 -> 任益芳 | O18: =O17 -> 南區工務所
C19: 全面完成 | D19: 年 月 日 | F19: 年 月 日 | G19: 推土機 | H19: 0 | I19: 輛 | N19: =N18 -> 任益芳 | O19: =O18 -> 南區工務所
G20: 卡車 | H20: 0 | I20: 輛 | N20: =N19 -> 任益芳 | O20: =O19 -> 南區工務所
G21: 水車 | H21: 0 | I21: 輛 | N21: =N20 -> 任益芳 | O21: =O20 -> 南區工務所
G22: 夾子車 | H22: 0 | I22: 輛 | N22: =N21 -> 任益芳 | O22: =O21 -> 南區工務所
G23: 鏈鋸 | H23: 0 | I23: 台 | N23: =N22 -> 任益芳 | O23: =O22 -> 南區工務所
G24: 小山貓 | H24: 0 | I24: 輛 | N24: =N22 -> 任益芳 | O24: =O23 -> 南區工務所
B25: 工程名稱 | C25: 預定完成日期 | F25: 實際完成日期 | G25: =$G$3 -> 113年9月24日當日動員機具 | L25: 承辦 工務所 | M25: =工程基本資料!D5 -> 王伯豪 | N25: =M25 -> 王伯豪 | O25: =L28 -> 南區工務所
B26: =工程基本資料!C5 -> H-113-03-113047 | C26: 項目 | D26: 日期 | G26: 項目 | H26: 數量 | J26: 今日施作內容 | K26: 明日預定施作內容 | N26: =N25 -> 王伯豪 | O26: =O25 -> 南區工務所
A27: 3 | B27: =工程基本資料!B5 -> 113年度南區河濱公園土木（含颱風豪雨設施撤離）暨災後復原預約維護工程 | C27: 機車便道 | D27: 年 月 日 | F27: 年 月 日 | G27: 人(含司機) | H27: 8 | I27: 人 | J27: 景美溪（一壽橋至恆光橋自行車道清理） | K27: 景美溪沿岸石墩、路燈、欄杆等設施物上雜草清除 | N27: =N26 -> 王伯豪 | O27: =O26 -> 南區工務所
C28: 停車場 | D28: 年 月 日 | F28: 年 月 日 | G28: 怪手 | H28: 1 | I28: 輛 | L28: =工程基本資料!E5 -> 南區工務所 | M28: =工程基本資料!I5 -> 泇溢營造有限公司 | N28: =N27 -> 王伯豪 | O28: =O27 -> 南區工務所
C29: 自行車道 | D29: 113年 9月 24日 | F29: 113年9月 24日 | G29: 吊車 | H29: 1 | I29: 輛 | N29: =N28 -> 王伯豪 | O29: =O28 -> 南區工務所
C30: 全面完成 | D30: 113年 9月 29日 | F30: 年 月 日 | G30: 推土機 | H30: 1 | I30: 輛 | N30: =N29 -> 王伯豪 | O30: =O29 -> 南區工務所
G31: 卡車 | H31: 3 | I31: 輛 | N31: =N30 -> 王伯豪 | O31: =O30 -> 南區工務所
G32: 水車 | H32: 1 | I32: 輛 | N32: =N31 -> 王伯豪 | O32: =O31 -> 南區工務所
G33: 夾子車 | H33: 0 | I33: 輛 | N33: =N32 -> 王伯豪 | O33: =O32 -> 南區工務所
G34: 鏈鋸 | H34: 0 | I34: 台 | N34: =N33 -> 王伯豪 | O34: =O33 -> 南區工務所
G35: 小山貓 | H35: 1 | I35: 輛 | N35: =N34 -> 王伯豪 | O35: =O34 -> 南區工務所
B36: 工程名稱 | C36: 預定完成日期 | F36: 實際完成日期 | G36: =$G$3 -> 113年9月24日當日動員機具 | L36: 承辦 工務所 | M36: =工程基本資料!D6 -> 詹智為、張思漢 | N36: =M36 -> 詹智為、張思漢 | O36: =L39 -> 北區工務所
B37: =工程基本資料!C6 -> H-113-03-113021 | C37: 項目 | D37: 日期 | G37: 項目 | H37: 數量 | J37: 今日施作內容 | K37: 明日預定施作內容 | N37: =N36 -> 詹智為、張思漢 | O37: =O36 -> 北區工務所
A38: 4 | B38: =工程基本資料!B6 -> 113年度西區水利建造物檢修改善及災後復原(基隆河左岸高速公路內湖橋至洲美大橋段)預約維護工程 | C38: 機車便道 | D38: 113年9月23日 | F38: 113年9月23日 | G38: 人(含司機) | H38: 9 | I38: 人 | J38: 大直橋下低水護岸步道沖洗社子橋下籃球場沖洗 | K38: 大直橋下低水護岸步道沖洗 | N38: =N37 -> 詹智為、張思漢 | O38: =O37 -> 北區工務所
C39: 停車場 | D39: 113年9月25日 | F39: 113年9月23日 | G39: 怪手 | H39: 0 | I39: 輛 | L39: =工程基本資料!E6 -> 北區工務所 | M39: =工程基本資料!I6 -> 逸峰營造有限公司 | N39: =N38 -> 詹智為、張思漢 | O39: =O38 -> 北區工務所
C40: 自行車道 | D40: 113年9月30日 | F40: 年 月 日 | G40: 吊車 | H40: 0 | I40: 輛 | N40: =N39 -> 詹智為、張思漢 | O40: =O39 -> 北區工務所
C41: 全面完成 | D41: 113年10月7日 | F41: 年 月 日 | G41: 推土機 | H41: 2 | I41: 輛 | N41: =N40 -> 詹智為、張思漢 | O41: =O40 -> 北區工務所
...

Sheet 113年9月25日
A1: 項次
B3: 工程名稱 | C3: 預定完成日期 | F3: 實際完成日期 | G3: 113年9月25日當日動員機具 | N3: 承辦 工務所 | O3: =工程基本資料!D3 -> 任益芳 | P3: =O3 -> 任益芳 | Q3: =N6 -> 南區工務所
B4: =工程基本資料!C3 -> H-113-03-113019 | C4: 項目 | D4: 日期 | G4: 項目 | H4: 數量 | J4: 已完成項目 | K4: 未完成項目 | L4: 今日施作內容 | M4: 明日預定施作內容 | P4: =P3 -> 任益芳 | Q4: =Q3 -> 南區工務所
A5: 1 | B5: =工程基本資料!B3 -> 113年度南區河濱公園路面暨災後復原預約維護工程 | C5: 機車便道 | D5: 年 月 日 | F5: 年 月 日 | G5: 人(含司機) | H5: 0 | I5: 人 | P5: =P4 -> 任益芳 | Q5: =Q4 -> 南區工務所
C6: 停車場 | D6: 年 月 日 | F6: 年 月 日 | G6: 怪手 | H6: 0 | I6: 輛 | N6: =工程基本資料!E3 -> 南區工務所 | O6: =工程基本資料!I3 -> 松瑩營造有限公司 | P6: =P5 -> 任益芳 | Q6: =Q5 -> 南區工務所
C7: 自行車道 | D7: 年 月 日 | F7: 年 月 日 | G7: 吊車 | H7: 0 | I7: 輛 | P7: =P6 -> 任益芳 | Q7: =Q6 -> 南區工務所
C8: 全面完成 | D8: 年 月 日 | F8: 年 月 日 | G8: 推土機 | H8: 0 | I8: 輛 | P8: =P7 -> 任益芳 | Q8: =Q7 -> 南區工務所
G9: 卡車 | H9: 0 | I9: 輛 | P9: =P8 -> 任益芳 | Q9: =Q8 -> 南區工務所
G10: 水車 | H10: 0 | I10: 輛 | P10: =P9 -> 任益芳 | Q10: =Q9 -> 南區工務所
G11: 夾子車 | H11: 0 | I11: 輛 | P11: =P10 -> 任益芳 | Q11: =Q10 -> 南區工務所
G12: 鏈鋸 | H12: 0 | I12: 台 | P12: =P11 -> 任益芳 | Q12: =Q11 -> 南區工務所
G13: 小山貓 | H13: 0 | I13: 輛 | P13: =P12 -> 任益芳 | Q13: =Q12 -> 南區工務所
B14: 工程名稱 | C14: 預定完成日期 | F14: 實際完成日期 | G14: =$G$3 -> 113年9月25日當日動員機具 | N14: 承辦 工務所 | O14: =工程基本資料!D4 -> 任益芳 | P14: =O14 -> 任益芳 | Q14: =N17 -> 南區工務所
B15: =工程基本資料!C4 -> H-113-03-113022 | C15: 項目 | D15: 日期 | G15: 項目 | H15: 數量 | J15: 已完成項目 | K15: 未完成項目 | L15: 今日施作內容 | M15: 明日預定施作內容 | P15: =P14 -> 任益芳 | Q15: =Q14 -> 南區工務所
A16: 2 | B16: =工程基本資料!B4 -> 113年度南區水利建造物檢修改善及災後復原(新店溪永福橋至萬板大橋段)預約維護工程 | C16: 機車便道 | D16: 年 月 日 | F16: 年 月 日 | G16: 人(含司機) | H16: 0 | I16: 人 | P16: =P15 -> 任益芳 | Q16: =Q15 -> 南區工務所
C17: 停車場 | D17: 年 月 日 | F17: 年 月 日 | G17: 怪手 | H17: 0 | I17: 輛 | N17: =工程基本資料!E4 -> 南區工務所 | O17: =工程基本資料!I4 -> 鋐城營造有限公司 | P17: =P16 -> 任益芳 | Q17: =Q16 -> 南區工務所
C18: 自行車道 | D18: 年 月 日 | F18: 年 月 日 | G18: 吊車 | H18: 0 | I18: 輛 | P18: =P17 -> 任益芳 | Q18: =Q17 -> 南區工務所
C19: 全面完成 | D19: 年 月 日 | F19: 年 月 日 | G19: 推土機 | H19: 0 | I19: 輛 | P19: =P18 -> 任益芳 | Q19: =Q18 -> 南區工務所
G20: 卡車 | H20: 0 | I20: 輛 | P20: =P19 -> 任益芳 | Q20: =Q19 -> 南區工務所
G21: 水車 | H21: 0 | I21: 輛 | P21: =P20 -> 任益芳 | Q21: =Q20 -> 南區工務所
G22: 夾子車 | H22: 0 | I22: 輛 | P22: =P21 -> 任益芳 | Q22: =Q21 -> 南區工務所
G23: 鏈鋸 | H23: 0 | I23: 台 | P23: =P22 -> 任益芳 | Q23: =Q22 -> 南區工務所
G24: 小山貓 | H24: 0 | I24: 輛 | P24: =P22 -> 任益芳 | Q24: =Q23 -> 南區工務所
B25: 工程名稱 | C25: 預定完成日期 | F25: 實際完成日期 | G25: =$G$3 -> 113年9月25日當日動員機具 | N25: 承辦 工務所 | O25: =工程基本資料!D5 -> 王伯豪 | P25: =O25 -> 王伯豪 | Q25: =N28 -> 南區工務所
B26: =工程基本資料!C5 -> H-113-03-113047 | C26: 項目 | D26: 日期 | G26: 項目 | H26: 數量 | J26: 已完成項目 | K26: 未完成項目 | L26: 今日施作內容 | M26: 明日預定施作內容 | P26: =P25 -> 王伯豪 | Q26: =Q25 -> 南區工務所
A27: 3 | B27: =工程基本資料!B5 -> 113年度南區河濱公園土木（含颱風豪雨設施撤離）暨災後復原預約維護工程 | C27: 機車便道 | D27: 年 月 日 | F27: 年 月 日 | G27: 人(含司機) | H27: 10 | I27: 人 | L27: 景美溪沿岸石墩、路燈、欄杆等設施物上雜草清除 | M27: 景美溪沿岸石墩、路燈、欄杆等設施物上雜草清除 | P27: =P26 -> 王伯豪 | Q27: =Q26 -> 南區工務所
C28: 停車場 | D28: 年 月 日 | F28: 年 月 日 | G28: 怪手 | H28: 1 | I28: 輛 | N28: =工程基本資料!E5 -> 南區工務所 | O28: =工程基本資料!I5 -> 泇溢營造有限公司 | P28: =P27 -> 王伯豪 | Q28: =Q27 -> 南區工務所
C29: 自行車道 | D29: 113年 9月 24日 | F29: 113年9月 24日 | G29: 吊車 | H29: 1 | I29: 輛 | P29: =P28 -> 王伯豪 | Q29: =Q28 -> 南區工務所
C30: 全面完成 | D30: 113年 9月 29日 | F30: 年 月 日 | G30: 推土機 | H30: 1 | I30: 輛 | P30: =P29 -> 王伯豪 | Q30: =Q29 -> 南區工務所
G31: 卡車 | H31: 3 | I31: 輛 | P31: =P30 -> 王伯豪 | Q31: =Q30 -> 南區工務所
G32: 水車 | H32: 1 | I32: 輛 | P32: =P31 -> 王伯豪 | Q32: =Q31 -> 南區工務所
G33: 夾子車 | H33: 0 | I33: 輛 | P33: =P32 -> 王伯豪 | Q33: =Q32 -> 南區工務所
G34: 鏈鋸 | H34: 0 | I34: 台 | P34: =P33 -> 王伯豪 | Q34: =Q33 -> 南區工務所
G35: 小山貓 | H35: 0 | I35: 輛 | P35: =P34 -> 王伯豪 | Q35: =Q34 -> 南區工務所
B36: 工程名稱 | C36: 預定完成日期 | F36: 實際完成日期 | G36: =$G$3 -> 113年9月25日當日動員機具 | N36: 承辦 工務所 | O36: =工程基本資料!D6 -> 詹智為、張思漢 | P36: =O36 -> 詹智為、張思漢 | Q36: =N39 -> 北區工務所
B37: =工程基本資料!C6 -> H-113-03-113021 | C37: 項目 | D37: 日期 | G37: 項目 | H37: 數量 | J37: 已完成項目 | K37: 未完成項目 | L37: 今日施作內容 | M37: 明日預定施作內容 | P37: =P36 -> 詹智為、張思漢 | Q37: =Q36 -> 北區工務所
A38: 4 | B38: =工程基本資料!B6 -> 113年度西區水利建造物檢修改善及災後復原(基隆河左岸高速公路內湖橋至洲美大橋段)預約維護工程 | C38: 機車便道 | D38: 113年9月23日 | F38: 113年9月23日 | G38: 人(含司機) | H38: 7 | I38: 人 | L38: 大直橋下低水護岸步道沖洗 | M38: 大直橋下低水護岸步道沖洗 | P38: =P37 -> 詹智為、張思漢 | Q38: =Q37 -> 北區工務所
C39: 停車場 | D39: 113年9月25日 | F39: 113年9月23日 | G39: 怪手 | H39: 0 | I39: 輛 | N39: =工程基本資料!E6 -> 北區工務所 | O39: =工程基本資料!I6 -> 逸峰營造有限公司 | P39: =P38 -> 詹智為、張思漢 | Q39: =Q38 -> 北區工務所
C40: 自行車道 | D40: 113年9月30日 | F40: 113年9月24日 | G40: 吊車 | H40: 0 | I40: 輛 | P40: =P39 -> 詹智為、張思漢 | Q40: =Q39 -> 北區工務所
C41: 全面完成 | D41: 113年10月7日 | F41: 年 月 日 | G41: 推土機 | H41: 0 | I41: 輛 | P41: =P40 -> 詹智為、張思漢 | Q41: =Q40 -> 北區工務所
...

Sheet 113年9月26日
A1: 項次
B3: 工程名稱 | C3: 預定完成日期 | F3: 實際完成日期 | G3: 113年9月26日當日動員機具 | N3: 承辦 工務所 | O3: =工程基本資料!D3 -> 任益芳 | P3: =O3 -> 任益芳 | Q3: =N6 -> 南區工務所
B4: =工程基本資料!C3 -> H-113-03-113019 | C4: 項目 | D4: 日期 | G4: 項目 | H4: 數量 | J4: 已完成項目 | K4: 未完成項目 | L4: 今日施作內容 | M4: 明日預定施作內容 | P4: =P3 -> 任益芳 | Q4: =Q3 -> 南區工務所
A5: 1 | B5: =工程基本資料!B3 -> 113年度南區河濱公園路面暨災後復原預約維護工程 | C5: 機車便道 | D5: 年 月 日 | F5: 年 月 日 | G5: 人(含司機) | H5: 0 | I5: 人 | P5: =P4 -> 任益芳 | Q5: =Q4 -> 南區工務所
C6: 停車場 | D6: 年 月 日 | F6: 年 月 日 | G6: 怪手 | H6: 0 | I6: 輛 | N6: =工程基本資料!E3 -> 南區工務所 | O6: =工程基本資料!I3 -> 松瑩營造有限公司 | P6: =P5 -> 任益芳 | Q6: =Q5 -> 南區工務所
C7: 自行車道 | D7: 年 月 日 | F7: 年 月 日 | G7: 吊車 | H7: 0 | I7: 輛 | P7: =P6 -> 任益芳 | Q7: =Q6 -> 南區工務所
C8: 全面完成 | D8: 年 月 日 | F8: 年 月 日 | G8: 推土機 | H8: 0 | I8: 輛 | P8: =P7 -> 任益芳 | Q8: =Q7 -> 南區工務所
G9: 卡車 | H9: 0 | I9: 輛 | P9: =P8 -> 任益芳 | Q9: =Q8 -> 南區工務所
G10: 水車 | H10: 0 | I10: 輛 | P10: =P9 -> 任益芳 | Q10: =Q9 -> 南區工務所
G11: 夾子車 | H11: 0 | I11: 輛 | P11: =P10 -> 任益芳 | Q11: =Q10 -> 南區工務所
G12: 鏈鋸 | H12: 0 | I12: 台 | P12: =P11 -> 任益芳 | Q12: =Q11 -> 南區工務所
G13: 小山貓 | H13: 0 | I13: 輛 | P13: =P12 -> 任益芳 | Q13: =Q12 -> 南區工務所
B14: 工程名稱 | C14: 預定完成日期 | F14: 實際完成日期 | G14: =$G$3 -> 113年9月26日當日動員機具 | N14: 承辦 工務所 | O14: =工程基本資料!D4 -> 任益芳 | P14: =O14 -> 任益芳 | Q14: =N17 -> 南區工務所
B15: =工程基本資料!C4 -> H-113-03-113022 | C15: 項目 | D15: 日期 | G15: 項目 | H15: 數量 | J15: 已完成項目 | K15: 未完成項目 | L15: 今日施作內容 | M15: 明日預定施作內容 | P15: =P14 -> 任益芳 | Q15: =Q14 -> 南區工務所
A16: 2 | B16: =工程基本資料!B4 -> 113年度南區水利建造物檢修改善及災後復原(新店溪永福橋至萬板大橋段)預約維護工程 | C16: 機車便道 | D16: 年 月 日 | F16: 年 月 日 | G16: 人(含司機) | H16: 0 | I16: 人 | P16: =P15 -> 任益芳 | Q16: =Q15 -> 南區工務所
C17: 停車場 | D17: 年 月 日 | F17: 年 月 日 | G17: 怪手 | H17: 0 | I17: 輛 | N17: =工程基本資料!E4 -> 南區工務所 | O17: =工程基本資料!I4 -> 鋐城營造有限公司 | P17: =P16 -> 任益芳 | Q17: =Q16 -> 南區工務所
C18: 自行車道 | D18: 年 月 日 | F18: 年 月 日 | G18: 吊車 | H18: 0 | I18: 輛 | P18: =P17 -> 任益芳 | Q18: =Q17 -> 南區工務所
C19: 全面完成 | D19: 年 月 日 | F19: 年 月 日 | G19: 推土機 | H19: 0 | I19: 輛 | P19: =P18 -> 任益芳 | Q19: =Q18 -> 南區工務所
G20: 卡車 | H20: 0 | I20: 輛 | P20: =P19 -> 任益芳 | Q20: =Q19 -> 南區工務所
G21: 水車 | H21: 0 | I21: 輛 | P21: =P20 -> 任益芳 | Q21: =Q20 -> 南區工務所
G22: 夾子車 | H22: 0 | I22: 輛 | P22: =P21 -> 任益芳 | Q22: =Q21 -> 南區工務所
G23: 鏈鋸 | H23: 0 | I23: 台 | P23: =P22 -> 任益芳 | Q23: =Q22 -> 南區工務所
G24: 小山貓 | H24: 0 | I24: 輛 | P24: =P22 -> 任益芳 | Q24: =Q23 -> 南區工務所
B25: 工程名稱 | C25: 預定完成日期 | F25: 實際完成日期 | G25: =$G$3 -> 113年9月26日當日動員機具 | N25: 承辦 工務所 | O25: =工程基本資料!D5 -> 王伯豪 | P25: =O25 -> 王伯豪 | Q25: =N28 -> 南區工務所
B26: =工程基本資料!C5 -> H-113-03-113047 | C26: 項目 | D26: 日期 | G26: 項目 | H26: 數量 | J26: 已完成項目 | K26: 未完成項目 | L26: 今日施作內容 | M26: 明日預定施作內容 | P26: =P25 -> 王伯豪 | Q26: =Q25 -> 南區工務所
A27: 3 | B27: =工程基本資料!B5 -> 113年度南區河濱公園土木（含颱風豪雨設施撤離）暨災後復原預約維護工程 | C27: 機車便道 | D27: 年 月 日 | F27: 年 月 日 | G27: 人(含司機) | I27: 人 | P27: =P26 -> 王伯豪 | Q27: =Q26 -> 南區工務所
C28: 停車場 | D28: 年 月 日 | F28: 年 月 日 | G28: 怪手 | I28: 輛 | N28: =工程基本資料!E5 -> 南區工務所 | O28: =工程基本資料!I5 -> 泇溢營造有限公司 | P28: =P27 -> 王伯豪 | Q28: =Q27 -> 南區工務所
C29: 自行車道 | D29: 113年 9月 24日 | F29: 113年9月 24日 | G29: 吊車 | I29: 輛 | P29: =P28 -> 王伯豪 | Q29: =Q28 -> 南區工務所
C30: 全面完成 | D30: 113年 9月 29日 | F30: 年 月 日 | G30: 推土機 | I30: 輛 | P30: =P29 -> 王伯豪 | Q30: =Q29 -> 南區工務所
G31: 卡車 | I31: 輛 | P31: =P30 -> 王伯豪 | Q31: =Q30 -> 南區工務所
G32: 水車 | I32: 輛 | P32: =P31 -> 王伯豪 | Q32: =Q31 -> 南區工務所
G33: 夾子車 | I33: 輛 | P33: =P32 -> 王伯豪 | Q33: =Q32 -> 南區工務所
G34: 鏈鋸 | I34: 台 | P34: =P33 -> 王伯豪 | Q34: =Q33 -> 南區工務所
G35: 小山貓 | I35: 輛 | P35: =P34 -> 王伯豪 | Q35: =Q34 -> 南區工務所
B36: 工程名稱 | C36: 預定完成日期 | F36: 實際完成日期 | G36: =$G$3 -> 113年9月26日當日動員機具 | N36: 承辦 工務所 | O36: =工程基本資料!D6 -> 詹智為、張思漢 | P36: =O36 -> 詹智為、張思漢 | Q36: =N39 -> 北區工務所
B37: =工程基本資料!C6 -> H-113-03-113021 | C37: 項目 | D37: 日期 | G37: 項目 | H37: 數量 | J37: 已完成項目 | K37: 未完成項目 | L37: 今日施作內容 | M37: 明日預定施作內容 | P37: =P36 -> 詹智為、張思漢 | Q37: =Q36 -> 北區工務所
A38: 4 | B38: =工程基本資料!B6 -> 113年度西區水利建造物檢修改善及災後復原(基隆河左岸高速公路內湖橋至洲美大橋段)預約維護工程 | C38: 機車便道 | D38: 113年9月23日 | F38: 113年9月23日 | G38: 人(含司機) | I38: 人 | P38: =P37 -> 詹智為、張思漢 | Q38: =Q37 -> 北區工務所
C39: 停車場 | D39: 113年9月25日 | F39: 113年9月23日 | G39: 怪手 | I39: 輛 | N39: =工程基本資料!E6 -> 北區工務所 | O39: =工程基本資料!I6 -> 逸峰營造有限公司 | P39: =P38 -> 詹智為、張思漢 | Q39: =Q38 -> 北區工務所
C40: 自行車道 | D40: 113年9月30日 | F40: 113年9月24日 | G40: 吊車 | I40: 輛 | P40: =P39 -> 詹智為、張思漢 | Q40: =Q39 -> 北區工務所
C41: 全面完成 | D41: 113年10月7日 | F41: 年 月 日 | G41: 推土機 | I41: 輛 | P41: =P40 -> 詹智為、張思漢 | Q41: =Q40 -> 北區工務所
...

Sheet 工程基本資料
B1: 工程名稱 | C1: 契約編號 | D1: 監造人員 | E1: 工務所 | F1: 主要 行政區別 | G1: 規劃設計 單位 | H1: 原契約上限金額 | I1: 廠商名稱 | J1: 廠商地址 | K1: 廠商負責人 | N1: 卡車 | P1: 項次 | Q1: 自有救災能量 | R1: 民間廠商支 | S1: 總計
R2: 援救災能量
A3: 1 | B3: 113年度南區河濱公園路面暨災後復原預約維護工程 | C3: H-113-03-113019 | D3: 任益芳 | E3: 南區工務所 | I3: 松瑩營造有限公司 | P3: 動員救災人力(人) | Q3: 19(新工處) +121(公園處) +9(大地處) | R3: 197(水利處)+4(建管處) | S3: 350 | U3: =6+6+5+15+10 -> 42
A4: 2 | B4: 113年度南區水利建造物檢修改善及災後復原(新店溪永福橋至萬板大橋段)預約維護工程 | C4: H-113-03-113022 | D4: 任益芳 | E4: 南區工務所 | I4: 鋐城營造有限公司 | P4: 大型工程車(輛) | Q4: 1(新工處) | R4: 22(水利處)+2(建管處) | S4: 25 | U4: =2+2+1+4+1 -> 10
A5: 3 | B5: 113年度南區河濱公園土木（含颱風豪雨設施撤離）暨災後復原預約維護工程 | C5: H-113-03-113047 | D5: 王伯豪 | E5: 南區工務所 | I5: 泇溢營造有限公司 | P5: 小型工程車(輛) | Q5: 5(新工處) +26(公園處) +4(大地處) | R5: 19(水利處)+2(建管處) | S5: 56 | U5: =2+2+1+2+1+2 -> 10
A6: 4 | B6: 113年度西區水利建造物檢修改善及災後復原(基隆河左岸高速公路內湖橋至洲美大橋段)預約維護工程 | C6: H-113-03-113021 | D6: 詹智為、張思漢 | E6: 北區工務所 | I6: 逸峰營造有限公司 | P6: 發電機(臺) | Q6: - | R6: 13(水利處) | S6: 13
A7: 5 | B7: 113年度北區河濱公園土木暨災後復原預約維護工程 | C7: H-113-03-113025 | D7: 周根杉 | E7: 北區工務所 | I7: 冠錏營造有限公司 | P7: 抽水機(臺) | Q7: - | R7: 143(水利處) | S7: 143
A8: 6 | B8: 113年度東區水利建造物檢修改善及災後復原(基隆河左岸高速公路內湖橋上游段，含四分溪及大坑溪)預約維護工程 | C8: H-113-03-113020 | D8: 陳政誠 | E8: 南內工務所 | I8: 淞源營造有限公司 | P8: 其他機具(臺) | Q8: 3(新工處) +52(公園處) +1(大地處) | R8: 43(水利處) | S8: 99
A9: 7 | B9: 113年度東區河濱公園路面暨災後復原預約維護工程 | C9: H-113-03-113018 | D9: 陳政誠 | E9: 南內工務所 | I9: 松瑩營造有限公司 | P9: 太空包(包) | Q9: - | R9: - | S9: -
A10: 8 | B10: 113年度東區河濱公園土木暨災後復原預約維護工程 | C10: H-113-03-113045 | D10: 江志偉 | E10: 南內工務所 | I10: 和遠營造有限公司 | P10: 砂包(包) | Q10: - | R10: - | S10: -
A11: 9 | B11: 113年度北區水利建造物檢修改善及災後復原(雙溪右岸至關渡水岸公園段)預約維護工程 | C11: H-113-03-113023 | D11: 沈明勳 | E11: 北投工務所 | I11: 久勝營造有限公司 | P11: 鏈鋸(臺) | Q11: - | R11: - | S11: - | U11: 2
A12: 10 | B12: 113年度北區河濱公園路面暨災後復原預約維護工程 | C12: H-113-03-113017 | D12: 余成偉 | E12: 北投工務所 | I12: 冠錏營造有限公司
A13: 11
A14: 12
A15: 13
A16: 14
A17: 15 | L17: 無
A18: 16 | L18: 無
