Workbook

Sheet 5-3.鋼筋
A1: 臺北市政府工務局水利工程處
A2: 材料設備檢（試）驗管制總表
A3: ="工程名稱:"&'1.計畫'!A1:I1 -> 工程名稱:磺港溪再造C段護岸及步道整建工程（延壽橋至三合橋） | H3: 契約編號：H-111-03-112080
A4: 監造單位：任泰技術顧問有限公司 | H4: 施工廠商：上溢營造份有限公司
A5: 項次 | B5: 契約詳細表項次 | C5: 契約 數量 | D5: 進場 日期 | E5: 進場 數量 | F5: 抽樣 日期 | G5: 規定抽（取）樣頻率 | H5: 累積進場數量 | I5: 抽試驗結果 | J5: 抽驗及會同人員 | K5: 備註
B6: 材料(設備)名稱 | D6: 進場 數量 | F6: 抽樣 數量 | H6: 累積抽樣數量 | K6: (歸檔編號)
A7: 3-1 | B7: 1.2.3、1.3.5、1.3.20、1.3.6、1.4.7、1.4.8、1.5.8、1.5.9、1.6.11 | C7: 694822.61 KG | D7: 45275 | E7: 49,000 KG | F7: 45282 | G7: 以同一爐號及相同標稱直徑之鋼筋為1組，每組取1支試樣，但同一爐號質量超過50t至100t以下者，每組取2支，同一爐號質量超過100t者，每增加50t(不足50t，以50t計)，每組另加取1支。 | H7: 49,000 KG | I7: 合格 | J7: 水利處：李晏然 任 泰：游文圃 上 溢：郭冠廷 | K7: 113年1月22日 112任泰顧字 第0122010010號 D19*2、D25*2
B8: 鋼筋 | D8: 49,000 KG | F8: 49,000 KG (4組) | H8: 49,000 KG (4組)
A9: 3-2 | B9: 1.2.3、1.3.5、1.3.20、1.3.6、1.4.7、1.4.8、1.5.8、1.5.9、1.6.11 | C9: 694822.61 KG | D9: 45282 | E9: 73,000 KG | F9: 45287 | H9: 122,000 KG | I9: 合格 | J9: 水利處：李晏然 任 泰：游文圃 上 溢：郭冠廷 | K9: 113年1月22日 112任泰顧字 第0122010010號 D10*1、D13*1、 D16*2
B10: 鋼筋 | D10: 73,000 KG | F10: 73,000 KG (4組) | H10: 122,000 KG (8組)
A11: 3-3 | B11: 1.2.3、1.3.5、1.3.20、1.3.6、1.4.7、1.4.8、1.5.8、1.5.9、1.6.11 | C11: 694822.61 KG | D11: 45317 | E11: 146,000 KG | F11: 45321 | H11: 268,000 KG | I11: 合格 | J11: 水利處：李晏然 任 泰：白博文 上 溢：郭冠廷 | K11: 113年2月27日 113任泰顧字 第0227010010號 D13*2、D16*2、D19*1、D22*1、D25*2、D32*2
B12: 鋼筋 | D12: 146,000 KG | F12: 146,000 KG (10組) | H12: 268,000 KG (18組)
A13: 3-4 | B13: 1.2.3、1.3.5、1.3.20、1.3.6、1.4.7、1.4.8、1.5.8、1.5.9、1.6.11 | C13: 694822.61 KG | D13: 45376 | E13: 51,000 KG | F13: 45383 | H13: 319,000 KG | I13: 合格 | J13: 水利處：李晏然 任 泰：白博文 上 溢：郭冠廷 | K13: 113年5月14日 113任泰顧字 第0514010012號 D25*3
B14: 鋼筋 | D14: 51,000 KG | F14: 51,000 KG (3組) | H14: 319,000 KG (21組)
A15: 3-5 | B15: 1.2.3、1.3.5、1.3.20、1.3.6、1.4.7、1.4.8、1.5.8、1.5.9、1.6.11 | C15: 694822.61 KG | D15: 45317 | E15: 146,000 KG | F15: 45418 | H15: 319,000 KG | I15: 合格 | J15: 水利處：李晏然 任 泰：白博文 上 溢：郭冠廷 | K15: 113年5月22日113任泰顧字第0522010011號D10*1 (113.5.6府查核)
B16: 鋼筋 | D16: 0KG | F16: 府查核取樣 (1組) | H16: 319,000 KG (22組)
A17: 編制： | D17: 工地主任： | H17: 附註：
A18: 1.本表於施工期間監造單位依契約約定之「材料、設備送審文件、樣品一覽表」分類登錄，俾利控管材料檢驗使用情形。 2.監造單位應依監造計畫之材料設備抽驗程序及標準辦理材料設備抽驗，如有單項材料設備廠商自主檢查頻率未達 3次時，廠商在辦理自主檢查取樣前，應通知監造單位轉知考工單位會同廠商辦理抽驗（即前2次均由本處派員抽驗）。 3.本表規定檢驗頻率請依據工程契約或施工規範約定填寫。
A19: 3-6 | B19: 1.2.3、1.3.5、1.3.20、1.3.6、1.4.7、1.4.8、1.5.8、1.5.9、1.6.11 | C19: 694822.61 KG | D19: 45435 | E19: 178,000 KG | F19: 45440 | G19: 以同一爐號及相同標稱直徑之鋼筋為1組，每組取1支試樣，但同一爐號質量超過50t至100t以下者，每組取2支，同一爐號質量超過100t者，每增加50t(不足50t，以50t計)，每組另加取1支。 | H19: 497,000 KG | I19: 合格 | J19: 水利處：李晏然 任 泰：白博文 上 溢：郭冠廷 | K19: 113年5月22日 113任泰顧字 第0523010001號 D10*2、D13*2、D16*1、D19*1、D22*2、D25*2、D32*1
B20: 鋼筋 | D20: 178,000 KG | F20: 178,000 KG (11組) | H20: 497,000 KG (33組)
A21: 3-7 | B21: 1.2.3、1.3.5、1.3.20、1.3.6、1.4.7、1.4.8、1.5.8、1.5.9、1.6.11 | C21: 694822.61 KG | D21: 45463 | E21: 97,000 KG | F21: 45467 | H21: 594,000 KG | I21: 合格 | J21: 水利處：李晏然 任 泰：白博文 上 溢：郭冠廷 | K21: 113年7月18日 113任泰顧字 第1130718105號 D13*3、D16*1、D25*2、D29*1
B22: 鋼筋 | D22: 97,000 KG | F22: 97,000 KG (7組) | H22: 594,000 KG (40組)
A23: 3-8 | B23: 1.2.3、1.3.5、1.3.20、1.3.6、1.4.7、1.4.8、1.5.8、1.5.9、1.6.11 | C23: 694822.61 KG | D23: 45518 | E23: 156,000 KG | F23: 45526 | H23: 750,000 KG | I23: 合格 | J23: 水利處：李晏然 任 泰：王淑慧 上 溢：葉展志 | K23: 113年9月26日 113任泰顧字 第1130926621號 D13*2、D16*5、D22*2、D29*1
B24: 鋼筋 | D24: 156,000 KG | F24: 156,000 KG (10組) | H24: 750,000 KG (50組)
A25: 3-9 | B25: 1.2.3、1.3.5、1.3.20、1.3.6、1.4.7、1.4.8、1.5.8、1.5.9、1.6.11 | C25: 694822.61 KG | D25: 45548 | E25: 156,000 KG | F25: 45554 | H25: 957,400 KG | I25: 合格 | J25: 任 泰：王淑慧 上 溢：胡舜豪 | K25: 113年11月6日 113任泰顧字 第1131106622號 D13*3、D19*1、D22*4、D25*1
B26: 鋼筋 | D26: 207,400 KG | F26: 207,400 KG (9組) | H26: 957,400 KG (59組)
A27: 3-10 | B27: 1.2.3、1.3.5、1.3.20、1.3.6、1.4.7、1.4.8、1.5.8、1.5.9、1.6.11 | C27: 694822.61 KG | D27: 45705 | E27: 156,000 KG | F27: 45714 | H27: 1,000,400 KG | I27: 合格 | J27: 任 泰：王淑慧 上 溢：康祐銓 | K27: 114年4月17日 任泰顧字 第1140417622號 D13*2、D16*1 | M27: =957400+43000 -> 1000400
B28: 鋼筋 | D28: 43,000 KG | F28: 43,000 KG (3組) | H28: 1,000,400 KG (62組)
A29: 編制： | D29: 工地主任： | H29: 附註：
A30: 1.本表於施工期間監造單位依契約約定之「材料、設備送審文件、樣品一覽表」分類登錄，俾利控管材料檢驗使用情形。 2.監造單位應依監造計畫之材料設備抽驗程序及標準辦理材料設備抽驗，如有單項材料設備廠商自主檢查頻率未達 3次時，廠商在辦理自主檢查取樣前，應通知監造單位轉知考工單位會同廠商辦理抽驗（即前2次均由本處派員抽驗）。 3.本表規定檢驗頻率請依據工程契約或施工規範約定填寫。

Sheet 1.計畫
A1: 磺港溪再造C段護岸及步道整建工程（延壽橋至三合橋）
A2: 計畫書送審管制總表(含工程保險) | H2: ="施工廠商："&$L$2 -> 施工廠商：上溢營造股份有限公司 | L2: 上溢營造股份有限公司
H3: ="監造單位："&$L$3 -> 監造單位：任泰技術顧問有限公司 | L3: 任泰技術顧問有限公司
A4: 得標日期： | B4: 44749 | C4: 訂約日期： | D4: 45128 | E4: 開工日期： | F4: 45192 | G4: 預定完工日期： | H4: =F4+730-1+10+132 -> 46063
A5: 項次 | B5: 送審項目 | C5: 應提送時程 | D5: 限定提送日期 | E5: 第一次送審日期 | F5: 第二次送審日期 | G5: 監造審查日期 | H5: 機關核定日期 | I5: 備註
A6: ☆ | B6: 監造計畫 | C6: 勞務契約決標(110/00/00) 後20日內 | F6: 44414 | G6: - | H6: 110/8/10 北市工水工字 第1106005424號 | I6: 110/00/00 辦理審查會議
A8: ☆ | B8: 監造用人計畫 | C8: 勞務契約決標(110/00/00) 後7日內 | F8: - | G8: - | H8: 110/8/10 北市工水工字 第1106005424號 | I8: -
A9: =ROW()-8 -> 1 | B9: 職業安全衛生管理計畫 | C9: 訂約後15日內 | D9: =$D$4+15 -> 45143 | E9: 112年8月4日 溢磺字 第1120804001號 | F9: 112年8月16日 溢磺字 第1120816021號 | G9: 112年8月21日 112任泰顧字 第0821010003號 | H9: 112年8月29日 北市工水工字 第1126047456號
A10: =ROW()-8 -> 2 | B10: 整體施工計畫 | C10: 工程開工前 | D10: =F4 -> 45192 | E10: 112年8月28日 溢磺字 第1120828001號 | F10: 112年9月5日 溢磺字 第1120904022號 | G10: 112年9月8日 112任泰顧字 第0908010002號 | H10: 112年9月14日 北市工水工字 第1126050960號
A11: =ROW()-8 -> 3 | B11: 整體品質計畫 | C11: 訂約後30日內 | D11: =$D$4+30 -> 45158 | E11: 112年8月17日 溢磺字 第1120817021號 | F11: 112年8月29日 溢磺字 第1120829021號 | G11: 112年9月7日 112任泰顧字 第0907010001號 | H11: 112年9月14日 北市工水工字 第1126050728號
A12: =ROW()-8 -> 4 | B12: 人員報核(開工前資料) | C12: 工程開工前 | D12: =F4 -> 45192 | E12: 112年9月19日 溢磺字 第1120919021號 | F12: - | G12: 112年9月20日 112任泰顧字 第0920010001號 | H12: 112年10月11日 北市工水工字 第1126056074號
A13: =ROW()-8 -> 5 | B13: 營造綜合保險 | C13: 第1次估驗計價前，最遲不得逾開工後1個月。 | D13: =F4+30 -> 45222 | E13: 112年9月21日 溢磺字 第1120921021號 | F13: - | G13: 112年9月22日 112任泰顧字 第0922010002號 | H13: 112年9月23日 北市工水工字 第1126053488號
A14: =ROW()-8 -> 6 | B14: 職業安全衛生管理計畫 (修正1版) | C14: - | D14: 113年6月6日 | E14: 113年5月27日 溢磺字 第1130527023號 | F14: - | G14: 113年5月27日 113任泰顧字 第1130527103號 | H14: 113年5月30日 北市工水工字 第1136033052號 | I14: 113年5月6日 臺北市政府 工程施工查核小組 查核紀錄辦理
A15: =ROW()-8 -> 7 | B15: 整體施工計畫 (修正1版) | C15: - | D15: 113年6月6日 | E15: 113年5月27日 溢磺字 第1130527022號 | F15: - | G15: 113年5月27日 113任泰顧字 第1130527102號 | H15: 113年5月30日 北市工水工字 第1136033049號 | I15: 113年5月6日 臺北市政府 工程施工查核小組 查核紀錄辦理
A16: =ROW()-8 -> 8 | B16: 整體品質計畫 (修正1版) | C16: - | D16: 113年6月6日 | E16: 113年5月27日 溢磺字 第1130527021號 | F16: - | G16: 113年5月27日 113任泰顧字 第1130527101號 | H16: 113年5月30日 北市工水工字 第1136033051號 | I16: 113年5月6日 臺北市政府 工程施工查核小組 查核紀錄辦理
A17: =ROW()-8 -> 9 | B17: 營造綜合保險 | C17: 應於接獲 變更設計修正契約總 價表或工期展延經核 准通知後[20]日內辦 妥。 | D17: 45541 | E17: 113年8月30日 溢磺字 第1130830021號 | F17: - | G17: 113年8月30日 113任泰顧字 第1130830621號 | H17: 113年9月2日 北市工水工字 第1136050653號 | I17: 第二次變更設計
A18: =ROW()-8 -> 10 | B18: 整體施工計畫 (修正2版) | C18: - | D18: 114年1月6日 | E18: 114年1月6日 溢磺字 第1140106021號 | F18: 114年1月15日 溢磺字 第1140115021號 | G18: 114年1月16日 任泰顧字 第1140116621號 | H18: 114年1月20日 北市工水工字 第1146011039號 | I18: 第二次變更設計
A19: =ROW()-8 -> 11 | B19: 整體品質計畫 (修正2版) | C19: - | D19: 114年1月6日 | E19: 114年1月6日 溢磺字 第1140106021號 | F19: 114年1月15日 溢磺字 第1140115021號 | G19: 114年1月16日 任泰顧字 第1140116621號 | H19: 114年1月20日 北市工水工字 第1146011039號 | I19: 第二次變更設計
A20: =ROW()-8 -> 12 | B20: 營造綜合保險 | C20: 應於接獲 變更設計修正契約總 價表或工期展延經核 准通知後[20]日內辦 妥。 | D20: 45672 | E20: 114年1月13日 溢磺字 第1140113021號 | F20: - | G20: 114年1月14日 任泰顧字 第1140114621號 | H20: 114年1月16日 北市工水工字 第1146010473號 | I20: 第三次變更設計 | K20: 45286 | L20: =K20+20 -> 45306
A21: =ROW()-8 -> 13 | B21: 整體施工計畫 (修正3版) | C21: - | D21: 114年4月30日 | E21: 114年4月23日 溢磺字 第1140423023號 | F21: 114年4月24日 溢磺字 第1140424024號 | G21: 114年4月24日 任泰顧字 第1140424623號 | H21: 114年4月28日 北市工水工字 第146027963號 | I21: 第三次變更設計
A22: =ROW()-8 -> 14 | B22: 整體品質計畫 (修正3版) | C22: - | D22: 114年4月30日 | E22: 114年4月23日 溢磺字 第1140423022號 | F22: 114年4月24日 溢磺字 第1140424024號 | G22: 114年4月24日 任泰顧字 第1140424623號 | H22: 114年4月28日 北市工水工字 第146027963號 | I22: 第三次變更設計
A23: =ROW()-8 -> 15 | B23: 營造綜合保險 | C23: 應於接獲 變更設計修正契約總 價表或工期展延經核 准通知後[20]日內辦 妥。 | D23: 45796 | E23: 114年5月15日 溢磺字 第1140515023號 | F23: - | G23: 114年5月15日 任泰顧字 第1140515623號 | H23: 114年5月20日 北市工水工字 第1146032182號 | I23: 第四次變更設計 | K23: 45286 | L23: =K23+20 -> 45306
A24: =ROW()-8 -> 16 | B24: 營造綜合保險 | C24: 應於接獲 變更設計修正契約總 價表或工期展延經核 准通知後[20]日內辦 妥。 | D24: 46049 | E24: 115年1月15日 溢磺字 第1150115021號 | F24: - | G24: 115年1月15日 任泰顧字 第1150115621號 | H24: 115年1月19日 北市工水工字 第1156010450號 | I24: 第五次變更設計 | K24: 45286 | L24: =K24+20 -> 45306
A25: =ROW()-8 -> 17 | B25: 營造綜合保險 | C25: 應於接獲 變更設計修正契約總 價表或工期展延經核 准通知後[20]日內辦 妥。 | D25: 46057 | E25: 115年2月4日 溢磺字 第1150204023號 | F25: 115年2月11日 溢磺字 第1150211021號 | G25: 115年2月11日 任泰顧字 第1150211621號 | H25: 115年2月24日 北市工水工字 第1156015809號 | I25: 第二次工期檢討 | K25: 45286 | L25: =K25+20 -> 45306

Sheet 2.分項計畫
A1: ='1.計畫'!A1:I1 -> 磺港溪再造C段護岸及步道整建工程（延壽橋至三合橋）
A2: 分項計畫送審管制總表 | H2: ="施工廠商："&$K$2 -> 施工廠商：上溢營造股份有限公司 | K2: ='1.計畫'!L2 -> 上溢營造股份有限公司
H3: ="監造單位："&$K$3 -> 監造單位：任泰技術顧問有限公司 | K3: ='1.計畫'!L3 -> 任泰技術顧問有限公司
A4: 得標日期： | B4: ='1.計畫'!B4 -> 44749 | C4: 訂約日期： | D4: ='1.計畫'!D4 -> 45128 | E4: 開工日期： | F4: ='1.計畫'!F4 -> 45192 | G4: 預定完工日期： | H4: ='1.計畫'!H4:I4 -> 46063
A5: 項次 | B5: 送審項目 | C5: 應提送時程 | D5: 限定提送日期 | E5: 第一次送審日期 | F5: 第二次送審日期 | G5: 監造審查日期 | H5: 機關核定日期 | I5: 備註
A6: ☆ | B6: 監造計畫 | C6: 勞務契約決標(110/00/00) 後20日內 | F6: 44414 | G6: - | H6: 110/8/10 北市工水工字 第1106005424號 | I6: 110/00/00 辦理審查會議
A7: ☆ | B7: 監造用人計畫 | C7: 勞務契約決標(110/00/00) 後7日內 | F7: - | G7: - | H7: 110/8/10 北市工水工字 第1106005424號 | I7: -
A8: =ROW()-7 -> 1 | B8: 安全視訊監控系統(CCTV)分項施工計畫 | C8: 預定施作 前15日 | D8: 45177 | E8: 112年8月24日 溢磺字 第1120824021號 | F8: - | G8: 112年9月1日 112任泰顧字 第0901010004號 | H8: 112年9月7日 北市工水工字 第1126049835號
A9: =ROW()-7 -> 2 | B9: 拆除工程分項計畫 | C9: 預定施作 前15日 | D9: 45177 | E9: 112年8月22日 溢磺字 第1120822022號 | F9: 112年9月4日 溢磺字 第1120904021號 | G9: 112年9月1日 112任泰顧字 第0901010003號 | H9: 112年9月7日 北市工水工字 第1126049830號
A10: =ROW()-7 -> 3 | B10: 生態檢核計畫 | C10: 開工前 | D10: 45192 | E10: 112年9月21日 溢磺字 第1120921022號 | F10: - | G10: 112年9月22日 112任泰顧字 第0922010001號 | H10: 112年10月5日 北市工水工字 第1126055392號
A11: =ROW()-7 -> 4 | B11: 剩餘土石方 資源處理計畫 (B5、B6) | C11: 預定產出餘土 前20日 | D11: 45204 | E11: 112年10月4日 溢磺字 第1121004022號 | F11: - | G11: 112年10月6日 112任泰顧字 第1006010003號 | H11: 112年10月13日 北市工水工字 第1126056302號
A12: =ROW()-7 -> 5 | B12: 剩餘土石方 資源處理計畫 (台北港) | C12: 預定產出餘土 前20日 | D12: 45219 | E12: 112年10月18日 溢磺字 第1121018021號 | F12: - | G12: 112年10月24日 112任泰顧字 第1024010001號 | H12: 112年10月26日 北市工水工字 第1126058896號
A13: =ROW()-7 -> 6 | B13: 河防建造物開挖暨復建計畫 | C13: 預定施作 前15日 | D13: 45177 | E13: 112年8月7日 溢磺字 第1120807002號 | F13: 112年8月16日 溢磺字 第1120816022號 | G13: 112年8月21日 112任泰顧字 第0821010002號 | H13: 112年10月23日 北市工水工字 第1126058439號
A14: =ROW()-7 -> 7 | B14: 全套管基樁計畫 | C14: 預定施作 前15日 | D14: 45292 | E14: 112年10月31日 溢磺字 第1121031021號 | F14: - | G14: 112年11月2日 112任泰顧字 第1102010001號 | H14: 112年11月8日 北市工水工字 第1126060812號
A15: =ROW()-7 -> 8 | B15: 鋼便橋分項施工計畫 | C15: 預定施作 前15日 | D15: 45275 | E15: 112年11月13日 溢磺字 第1121113022號 | F15: 112年12月11日 溢磺字 第1121211021號 | G15: 112年12月14日 112任泰顧字 第1214010001號 | H15: 113年1月19日 北市工水工字 第1136010164號
A16: =ROW()-7 -> 9 | B16: 橋梁工程計畫 | C16: 預定施作 前15日 | D16: 45443 | E16: 113年5月15日 溢磺字 第1121113022號 | F16: - | G16: 113年5月16日 113任泰顧字 第0516010001號 | H16: 113年5月24日 北市工水工字 第1136031101號
A17: =ROW()-7 -> 10 | B17: 鋪磚分項施工暨品質計畫 | C17: 預定施作 前15日 | D17: 45736 | E17: 114年2月24日 溢磺字 第1140224022號 | F17: - | G17: 114年2月25日 任泰顧字 第1140225621號 | H17: 114年3月3日 北市工水工字 第1146001130號
A18: =ROW()-7 -> 11 | B18: 剩餘土石方 資源處理計畫 (B4、B5) | C18: 預定產出餘土 前20日 | D18: 45306 | E18: 113年1月11日 溢磺字 第1130111021號 | F18: - | G18: 113年1月12日 112任泰顧字 第0112010001號 | H18: 113年1月15日 北市工水工字 第1136009266號
A19: =ROW()-7 -> 12 | B19: 護岸及護坡工程 分項施工暨品質計畫 | C19: 預定施作 前15日 | D19: 45397 | E19: 113年4月2日 溢磺字 第1130402021號 | F19: - | G19: 113年4月8日 113任泰顧字 第048010001號 | H19: 113年4月11日 北市工水工字 第1136023177號
... A23: =ROW()-7 -> 16 | B23: 警示面板分項施工計畫 | C23: 預定施作 前15日 | D23: 45992 | E23: 114年11月13日 溢磺字 第1141113022號 | F23: - | G23: 114年11月13日 任泰顧字 第1141113622號 | H23: 114年11月18日 北市工水工字 第1146006564號

Sheet 3.施工圖送審
A1: ='1.計畫'!A1:I1 -> 磺港溪再造C段護岸及步道整建工程（延壽橋至三合橋）
A2: 施工圖送審管制總表 | H2: ="施工廠商："&$K$2 -> 施工廠商：上溢營造股份有限公司 | K2: ='1.計畫'!L2 -> 上溢營造股份有限公司
H3: ="監造單位："&$K$3 -> 監造單位：任泰技術顧問有限公司 | K3: ='1.計畫'!L3 -> 任泰技術顧問有限公司
A4: 得標日期： | B4: ='1.計畫'!B4 -> 44749 | C4: 訂約日期： | D4: ='1.計畫'!D4 -> 45128 | E4: 開工日期： | F4: ='1.計畫'!F4 -> 45192 | G4: 預定完工日期： | H4: ='1.計畫'!H4:I4 -> 46063
A5: 項次 | B5: 送審項目 | C5: 應提送時程 | D5: 限定提送日期 | E5: 第一次送審日期 | F5: 第二次送審日期 | G5: 監造審查日期 | H5: 機關核定日期 | I5: 備註
A6: ☆ | B6: 監造計畫 | C6: 勞務契約決標(110/00/00) 後20日內 | F6: 44414 | G6: - | H6: 110/8/10 北市工水工字 第1106005424號 | I6: 110/00/00 辦理審查會議
A7: ☆ | B7: 監造用人計畫 | C7: 勞務契約決標(110/00/00) 後7日內 | F7: - | G7: - | H7: 110/8/10 北市工水工字 第1106005424號 | I7: -
A8: =ROW()-7 -> 1 | B8: 共月橋基樁 鋼筋施工圖 | C8: 預定施作 前15日 | D8: 112年12月07日 | E8: 112年12月07日 溢磺字 第1121207022號 | G8: 112年12月7日 112任泰顧字 第1207010001號 | H8: 113年1月18日 北市工水工字 第1136010182號
A9: =ROW()-7 -> 2 | B9: 三合橋污水人孔接續管道施工圖 | C9: 預定施作 前15日 | D9: 113年4月11日 | E9: 113年4月11日 溢磺字 第1130411025號 | G9: 113年4月16日 113任泰顧字 第0416010001號 | H9: 113年4月30日 北市工水工字 第1136027531號
A10: =ROW()-7 -> 3 | B10: 三合橋鋼構施工圖 | C10: 預定施作 前15日 | D10: 113年5月9日 | E10: 113年5月9日 溢磺字 第1130509021號 | G10: 113年5月9日 113任泰顧字 第0513010001號 | H10: 113年5月16日 北市工水工字 第1136030215號
A11: =ROW()-7 -> 4 | B11: 雙孔箱涵鋼筋施工圖 | C11: 預定施作 前15日 | D11: 113年5月15日 | E11: 113年5月15日 溢磺字 第1130515023號 | G11: 113年5月21日 113任泰顧字 第0521010001號 | H11: 113年5月24日 北市工水工字 第1136031824號
A12: =ROW()-7 -> 5 | B12: 單孔箱涵鋼筋施工圖 | C12: 預定施作 前15日 | D12: 113年6月12日 | E12: 113年5月31日 溢磺字 第1130531021號 | G12: 113年6月6日 113任泰顧字 第1130606101號 | H12: 113年6月12日 北市工水工字 第1136035062號
A13: =ROW()-7 -> 6 | B13: 共月橋鋼構施工圖 | C13: 預定施作 前15日 | D13: 113年10月31日 | E13: 113年10月9日 溢磺字 第1131009023號 | G13: 113年10月9日 113任泰顧字 第1131009624號 | H13: 113年10月18日 北市工水工字 第1136006290號
A14: =ROW()-7 -> 7 | B14: 道路側溝施工圖 | C14: 預定施作 前15日 | D14: 114年2月3日 | E14: 114年1月18日 溢磺字 第1140118021號 | G14: 114年1月18日 任泰顧字 第1140118621號 | H14: 114年2月6日 北市工水工字 第1146000625號
A15: =ROW()-7 -> 8 | B15: 號誌施工圖 | C15: 預定施作 前15日 | D15: 45731 | E15: 114年3月10日 溢磺字 第1140310023號 | G15: 114年3月11日 任泰顧字 第1140311623號 | H15: 114年3月25日 北市工水工字 第1146001368號
A16: =ROW()-7 -> 9 | B16: 警示設備配線施 工大樣圖 | C16: 預定施作 前15日 | D16: 45777 | E16: 114年4月16日 溢磺字 第1140416021號 | G16: 114年4月16日 任泰顧字 第1140416622號 | H16: 114年4月24日 北市工水工字 第1146002276號
A17: =ROW()-7 -> 10
A18: =ROW()-7 -> 11
A19: =ROW()-7 -> 12
A20: =ROW()-7 -> 13

Sheet 4.送審(廠商)
A1: 臺北市政府工務局水利工程處
A2: 材料設備送審管制總表
A3: 工程名稱:磺港溪再造C段護岸及步道整建工程（延壽橋至三合橋） | J3: 契約編號：H-111-03-112080
A4: 監造單位：任泰技術顧問有限公司 | J4: 施工廠商：上溢營造股份有限公司
A5: 項次 | B5: 契約詳細表項次 | C5: 契約數量 | D5: 是否取樣試驗 （是ˇ、否X） | E5: 預定送審 日期 | F5: 是否驗廠 | G5: 預定試驗單位 | H5: 送審資料（ˇ） | M5: 審查日期 | N5: 備註 (歸檔編號)
H6: 協力廠商資料 | I6: 型錄 | J6: 相關試驗報告 | K6: 樣品 | L6: 其他 | M6: 審查結果
B7: 材料(設備)名稱 | E7: 實際送審 日期 | F7: 驗廠日期
A8: 1-1 | B8: 1.2.4、1.2.5、 1.3.2、1.3.3、 1.3.4、1.3.20、 1.4.1、1.4.2、 1.4.3、1.4.9、 1.5.1、1.5.2、 1.5.3、1.6.6、 1.6.7 | C8: 140 397.84 M3 210 4,360.87 M3 280 709.04 M3 280W 883.62 M3 | D8: ˇ | E8: 112/11/1 | F8: X | G8: 桂田技術顧問有限公司 | H8: V | J8: V | M8: 112年8月22日 112任泰顧字 第0822010001號 (大象) 112年8月31日 112任泰顧字 第0831010001號 (龍形) 112年9月6日 112任泰顧字 第0906010002號 (正誠) | N8: 112年8月24日 北市工水工字 第1126047747號 同意備查 (大象) 112年9月6日 北市工水工字 第1126049551號 同意備查 (龍形) 112年9月7日 北市工水工字 第1126050509號 同意備查 (正誠)
B9: 預拌混凝土 | E9: 112/8/22 | F9: - | M9: 合格
A10: 1-2 | B10: 1.4.23 | C10: 1,526.83 M3 | D10: ˇ | E10: 113/2/2 | F10: X | G10: 桂田技術顧問有限公司 | H10: V | J10: V | M10: 113年2月1日 113任泰顧字 第0201010001號 (龍形) 113年2月19日 113任泰顧字第0219010004號 (正誠) | N10: 113年2月6日 北市工水工字 第1136012469號 同意備查 (龍形) 113年2月21日 北市工水工字 第1136014452號 同意備查 (正誠)
B11: 預拌混凝土，二型 | E11: 113/1/30 | F11: - | M11: 合格
A12: 1-3 | B12: 1.5.3 | C12: 1187 M3 | D12: ˇ | E12: 112/10/5 | F12: X | G12: 裕全顧問有限公司 | H12: V | I12: V | J12: V | K12: V | L12: V | M12: 112年10月5日 112任泰顧字第 1005010001號 (達踴) | N12: 112年10月11日 北市工水工字 第1126055994號 同意備查 (達踴)
B13: 控制性低強度回填材料(CLSM) | E13: 112/10/3 | F13: - | M13: 合格
A14: 1-4 | B14: - | C14: 0M3 | D14: ˇ | E14: 113/11/5 | F14: X | G14: 桂田技術顧問有限公司 | H14: V | J14: V | M14: 113年11月6日 任泰顧字 第1131106625號 (龍形企業) | N14: 113年11月11日 北市工水工字 第1136006842號 同意備查 (龍形企業)
B15: 無收縮混凝土 | E15: 113/11/5 | F15: - | M15: 合格
A16: 編制： | F16: 工地主任： | L16: 附註：
A17: 註：1.施工廠商應依契約之「材料、設備檢（試）驗一覽表」將資料填入，以預為準備材料設備送審事宜，並作為監造單位管制
B18: 各項材料設備送審期程，且需納入結算書陳核。
B19: 2.施工廠商應將本表於開工報核時檢附提供予監造單位，監造單位報核開工時應檢附本表。
B20: 3.施工廠商應於開工後適時更新本表，並提送監造單位審核，以確認各項材料設備送審期程是否符合時程。
A21: 2 | B21: 1.2.24、1.2.25、1.2.26 | C21: 界石收邊 360.35 M 緣石收邊 691.14 M 道路緣石收邊 890.62 M | D21: ˇ | E21: 114/4/1 | F21: X | G21: 桂田技術顧問有限公司 | I21: V | J21: V | M21: 113年10月9日 113任泰顧字 第1131009622號 (尚美) | N21: 113年10月18日 北市工水工字 第1136006288號 同意備查 (尚美)
B22: 預鑄路緣石 | E22: 113/10/9 | F22: - | M22: 合格
A23: 3 | B23: 1.2.3、1.3.5、1.3.6、1.3.20、1.4.7、1.4.8、1.5.8、1.5.9、1.6.11 | C23: SD280W 294353.68 KG SD420W 584649.02 KG | D23: ˇ | E23: 112/11/1 | F23: X | G23: 桂田技術顧問有限公司 | H23: V | J23: V | M23: 112年9月6日 112任泰顧字 第0906010003號 (友德) | N23: 112年9月7日 北市工水工字 第1126050536號 同意備查 (友德)
B24: 鋼筋 | E24: 112/9/4 | F24: - | M24: 合格
A25: 4 | B25: 1.6.1、1.6.2 | C25: 9.5MM 360.68 M3 19MM 917.25 M3 | D25: ˇ | E25: 114/1/15 | F25: X | G25: 臺北市政府工務局 | H25: V | I25: V | J25: V | K25: V | M25: 113年2月2日 113任泰顧字 第0202010001號 (合豐) 113年10月28日 任泰顧字 第1131028622號 (合豐) 114年2月24日 任泰顧字 第1140224621號 (大友) 114年7月7日 任泰顧字 第1140707252號 (大友) | N25: 113年2月6日 北市工水工字 第1136012746號 同意備查 (合豐) 113年11月1日 北市工水工字 第1136006651號 同意備查 (合豐) 114年2月27日 北市工水工字 第1146001058號 同意備查 (大友) 114年7月10日 北市工水工字 第1146041898號 同意備查 (大友)
B26: 瀝青混凝土 | E26: 113/2/2 | F26: - | M26: 合格
A27: 5 | B27: 1.2.84、1.2.85、1.2.86、1.2.87、1.2.94 | C27: 985.97M2 | D27: ˇ | E27: 114/1/1 | F27: X | G27: 日鼎檢測事業股份有限公司 | H27: V | J27: V | M27: 113年5月9日 113任泰顧字 第0509010003號 (築綠生態) | N27: 113年5月10日 北市工水工字 第1136029497號 同意備查 (築綠生態)
B28: 地工織物 | E28: 113/5/7 | F28: - | M28: 合格
A29: 編制： | F29: 工地主任： | L29: 附註：
A30: 註：1.施工廠商應依契約之「材料、設備檢（試）驗一覽表」將資料填入，以預為準備材料設備送審事宜，並作為監造單位管制
B31: 各項材料設備送審期程，且需納入結算書陳核。
B32: 2.施工廠商應將本表於開工報核時檢附提供予監造單位，監造單位報核開工時應檢附本表。
B33: 3.施工廠商應於開工後適時更新本表，並提送監造單位審核，以確認各項材料設備送審期程是否符合時程。
A34: =A27+1 -> 6 | B34: 1.2.52、1.2.53、1.2.54、1.2.55、1.2.56、1.3.24 | C34: 405.31 M | D34: ˇ | E34: 114/1/1 | F34: X | G34: 鄭兆鴻結構土木技師事務所 | H34: V | J34: V | K34: V | M34: 113年5月9日 113任泰顧字 第0509010001號 (振華興) | N34: 113年5月10日 北市工水工字 第1136029496號 同意備查 (振華興)
B35: 欄杆 | E35: 113/5/9 | F35: - | M35: 合格
A36: =A34+1 -> 7 | B36: 1.2.10、1.3.15 | C36: 159,208.45 KG | D36: ˇ | E36: 114/1/1 | F36: X | G36: 鄭兆鴻結構土木技師事務所 | H36: V | J36: V | M36: 113年5月9日 113任泰顧字 第0509010001號 (振華興) | N36: 113年5月10日 北市工水工字 第1136029496號 同意備查 (振華興)
B37: 結構用鋼材 | E37: 113/5/9 | F37: - | M37: 合格
A38: =A36+1 -> 8 | B38: 1.2.73 | C38: 773.78 M2 | D38: ˇ | E38: 114/1/15 | F38: X | G38: 信威檢驗科技有限公司 | J38: V | M38: 113年2月19日 113任泰顧字 第0219010001號 (勇順號誌) | N38: 113年2月20日 北市工水工字 第1136014400號 同意備查 (勇順號誌)
B39: 熱處理聚酯標線 | E39: 113/2/17 | F39: - | M39: 合格
A40: =A38+1 -> 9 | B40: 1.2.11~1.2.15、1.2.20、1.2.30、1.3.21~1.3.23、1.3.29、1.3.30、1.3.35 | C40: 5,940.47 M2 | D40: ˇ | E40: 114/4/1 | F40: X | G40: 三杰科技顧問股份有限公司 | H40: . | J40: V | M40: 113年2月19日 113任泰顧字 第0219010003號 (大中鋼鐵) | N40: 113年2月20日 北市工水工字 第1136014401號 同意備查 (大中鋼鐵)
...

Sheet 5-1.試驗140
A1: 臺北市政府工務局水利工程處
A2: 材料設備檢（試）驗管制總表
A3: ="工程名稱:"&'1.計畫'!A1:I1 -> 工程名稱:磺港溪再造C段護岸及步道整建工程（延壽橋至三合橋） | H3: 契約編號：H-111-03-112080
A4: 監造單位：任泰技術顧問有限公司 | H4: 施工廠商：上溢營造份有限公司
A5: 項次 | B5: 契約詳細表項次 | C5: 契約 數量 | D5: 進場 日期 | E5: 進場 數量 | F5: 抽樣 日期 | G5: 規定抽（取）樣頻率 | H5: 累積進場數量 | I5: 抽試驗結果 | J5: 抽驗及會同人員 | K5: 備註
B6: 材料(設備)名稱 | D6: 進場 數量 | F6: 抽樣 數量 | H6: 累積抽樣數量 | K6: (歸檔編號) | M6: 數量 | N6: 累計數量 | O6: 組數 | P6: 累計組數 | Q6: 水利處 | R6: 監造 | S6: 廠商
A7: ="1-140 -"&L7 -> 1-140 -1 | B7: 1.2.4、1.3.2、1.4.1、1.5.1、1.6.6 | C7: 397.84 M3 | D7: =VLOOKUP(L7,'210'!A:T,2,0) -> 45181 | E7: =M7&M8 -> 0 M3 | F7: =D7 -> 45181 | G7: 1.每批次數量未達20 m3時，免檢驗。 2.每批次數量達20～100 m3檢驗1組。 3.每批次數量超過100 m3時，每100 m3加驗1組，餘數未達100m³亦加驗1組。 | H7: =N7&M8 -> 0 M3 | I7: 合格 | J7: =IF(R7=0,"上 溢："&S7,IF(Q7=0,"任 泰："&R7&" "&"上 溢："&S7, "水利處："&Q7&" "&"任 泰："&R7&" "&"上 溢："&S7)) -> 水利處：李晏然 任 泰：游文圃 上 溢：康祐銓 | K7: 112年11月10日 112任泰顧字 第1110010001號 | L7: 1 | M7: =VLOOKUP(L7,'140'!A:T,5,0) -> 0 | N7: =M7 -> 0 | O7: =VLOOKUP(L7,'140'!A:T,6,0) -> 1 | P7: =O7 -> 1 | Q7: =VLOOKUP(L7,'140'!A:T,18,0) -> 李晏然 | R7: =VLOOKUP(L7,'140'!A:T,19,0) -> 游文圃 | S7: =VLOOKUP(L7,'140'!A:T,20,0) -> 康祐銓
B8: 結構用混凝土，預拌，140kgf/cm2 | D8: =M7&M8 -> 0 M3 | F8: =E7&CHAR(10)&"("&O7&O8&")" -> 0 M3 (1組) | H8: =H7&CHAR(10)&"("&P7&O8&")" -> 0 M3 (1組) | M8: M3 | O8: 組
A9: ="1-140 -"&L9 -> 1-140 -2 | B9: 1.2.4、1.3.2、1.4.1、1.5.1、1.6.6 | C9: 397.84 M3 | D9: =VLOOKUP(L9,'210'!A:T,2,0) -> 45484 | E9: =M9&M10 -> 8 M3 | F9: =D9 -> 45484 | H9: =N9&M10 -> 8 M3 | I9: 合格 | J9: =IF(R9=0,"上 溢："&S9,IF(Q9=0,"任 泰："&R9&" "&"上 溢："&S9, "水利處："&Q9&" "&"任 泰："&R9&" "&"上 溢："&S9)) -> 任 泰：白博文 上 溢：郭冠廷 | K9: 113年4月11日 113任泰顧字 第0411010013號 | L9: =L7+1 -> 2 | M9: =VLOOKUP(L9,'140'!A:T,5,0) -> 8 | N9: =N7+M9 -> 8 | O9: =VLOOKUP(L9,'140'!A:T,6,0) -> 1 | P9: =P7+O9 -> 2 | Q9: =VLOOKUP(L9,'140'!A:T,18,0) -> 0 | R9: =VLOOKUP(L9,'140'!A:T,19,0) -> 白博文 | S9: =VLOOKUP(L9,'140'!A:T,20,0) -> 郭冠廷
B10: 結構用混凝土，預拌，140kgf/cm2 | D10: =M9&M10 -> 8 M3 | F10: =E9&CHAR(10)&"("&O9&O10&")" -> 8 M3 (1組) | H10: =H9&CHAR(10)&"("&P9&O10&")" -> 8 M3 (2組) | M10: M3 | O10: 組
A11: ="1-140 -"&L11 -> 1-140 -3 | B11: 1.2.4、1.3.2、1.4.1、1.5.1、1.6.6 | C11: 397.84 M3 | D11: =VLOOKUP(L11,'210'!A:T,2,0) -> 45488 | E11: =M11&M12 -> 18 M3 | F11: =D11 -> 45488 | H11: =N11&M12 -> 26 M3 | I11: - | J11: 上 溢：郭冠廷 | K11: 本次澆置數量 未達20M3 免取樣 | L11: =L9+1 -> 3 | M11: =VLOOKUP(L11,'140'!A:T,5,0) -> 18 | N11: =N9+M11 -> 26 | O11: =VLOOKUP(L11,'140'!A:T,6,0) -> 0 | P11: =P9+O11 -> 2 | Q11: =VLOOKUP(L11,'140'!A:T,18,0) -> 0 | R11: =VLOOKUP(L11,'140'!A:T,19,0) -> 白博文 | S11: =VLOOKUP(L11,'140'!A:T,20,0) -> 郭冠廷
B12: 結構用混凝土，預拌，140kgf/cm2 | D12: =M11&M12 -> 18 M3 | F12: =E11&CHAR(10)&"("&O11&O12&")" -> 18 M3 (0組) | H12: =H11&CHAR(10)&"("&P11&O12&")" -> 26 M3 (2組) | K12: EF-1130305 混凝土 自主檢查表 | M12: M3 | O12: 組
A13: ="1-140 -"&L13 -> 1-140 -4 | B13: 1.2.4、1.3.2、1.4.1、1.5.1、1.6.6 | C13: 397.84 M3 | D13: =VLOOKUP(L13,'210'!A:T,2,0) -> 45492 | E13: =M13&M14 -> 20 M3 | F13: =D13 -> 45492 | H13: =N13&M14 -> 46 M3 | I13: 合格 | J13: =IF(R13=0,"上 溢："&S13,IF(Q13=0,"任 泰："&R13&" "&"上 溢："&S13, "水利處："&Q13&" "&"任 泰："&R13&" "&"上 溢："&S13)) -> 水利處：李晏然 任 泰：白博文 上 溢：郭冠廷 | K13: 113年5月10日 113任泰顧字 第0510010017號 | L13: =L11+1 -> 4 | M13: =VLOOKUP(L13,'140'!A:T,5,0) -> 20 | N13: =N11+M13 -> 46 | O13: =VLOOKUP(L13,'140'!A:T,6,0) -> 1 | P13: =P11+O13 -> 3 | Q13: =VLOOKUP(L13,'140'!A:T,18,0) -> 李晏然 | R13: =VLOOKUP(L13,'140'!A:T,19,0) -> 白博文 | S13: =VLOOKUP(L13,'140'!A:T,20,0) -> 郭冠廷
B14: 結構用混凝土，預拌，140kgf/cm2 | D14: =M13&M14 -> 20 M3 | F14: =E13&CHAR(10)&"("&O13&O14&")" -> 20 M3 (1組) | H14: =H13&CHAR(10)&"("&P13&O14&")" -> 46 M3 (3組) | M14: M3 | O14: 組
A15: ="1-140 -"&L15 -> 1-140 -5 | B15: 1.2.4、1.3.2、1.4.1、1.5.1、1.6.6 | C15: 397.84 M3 | D15: =VLOOKUP(L15,'210'!A:T,2,0) -> 45496 | E15: =M15&M16 -> 10 M3 | F15: =D15 -> 45496 | H15: =N15&M16 -> 56 M3 | I15: 合格 | J15: =IF(R15=0,"上 溢："&S15,IF(Q15=0,"任 泰："&R15&" "&"上 溢："&S15, "水利處："&Q15&" "&"任 泰："&R15&" "&"上 溢："&S15)) -> 水利處：李晏然 任 泰：白博文 上 溢：郭冠廷 | K15: 113年5月17日 113任泰顧字 第0517010015號 | L15: =L13+1 -> 5 | M15: =VLOOKUP(L15,'140'!A:T,5,0) -> 10 | N15: =N13+M15 -> 56 | O15: =VLOOKUP(L15,'140'!A:T,6,0) -> 1 | P15: =P13+O15 -> 4 | Q15: =VLOOKUP(L15,'140'!A:T,18,0) -> 李晏然 | R15: =VLOOKUP(L15,'140'!A:T,19,0) -> 白博文 | S15: =VLOOKUP(L15,'140'!A:T,20,0) -> 郭冠廷
B16: 結構用混凝土，預拌，140kgf/cm2 | D16: =M15&M16 -> 10 M3 | F16: =E15&CHAR(10)&"("&O15&O16&")" -> 10 M3 (1組) | H16: =H15&CHAR(10)&"("&P15&O16&")" -> 56 M3 (4組) | M16: M3 | O16: 組
A17: 編制： | D17: 工地主任： | H17: 附註：
A18: 1.本表於施工期間監造單位依契約約定之「材料、設備送審文件、樣品一覽表」分類登錄，俾利控管材料檢驗使用情形。 2.監造單位應依監造計畫之材料設備抽驗程序及標準辦理材料設備抽驗，如有單項材料設備廠商自主檢查頻率未達 3次時，廠商在辦理自主檢查取樣前，應通知監造單位轉知考工單位會同廠商辦理抽驗（即前2次均由本處派員抽驗）。 3.本表規定檢驗頻率請依據工程契約或施工規範約定填寫。
A19: ="1-140 -"&L19 -> 1-140 -6 | B19: 1.2.4、1.3.2、1.4.1、1.5.1、1.6.6 | C19: 397.84 M3 | D19: =VLOOKUP(L19,'140'!A:T,2,0) -> 45436 | E19: =M19&M20 -> 30 M3 | F19: =D19 -> 45436 | G19: 1.每批次數量未達20 m3時，免檢驗。 2.每批次數量達20～100 m3檢驗1組。 3.每批次數量超過100 m3時，每100 m3加驗1組，餘數未達100m³亦加驗1組。 | H19: =N19&M20 -> 86 M3 | I19: 合格 | J19: =IF(R19=0,"上 溢："&S19,IF(Q19=0,"任 泰："&R19&" "&"上 溢："&S19, "水利處："&Q19&" "&"任 泰："&R19&" "&"上 溢："&S19)) -> 任 泰：白博文 上 溢：郭冠廷 | K19: 113年7月2日 任泰顧字 第1130702107號 | L19: =L15+1 -> 6 | M19: =VLOOKUP(L19,'140'!A:T,5,0) -> 30 | N19: =N15+M19 -> 86 | O19: =VLOOKUP(L19,'140'!A:T,6,0) -> 1 | P19: =P15+O19 -> 5 | Q19: =VLOOKUP(L19,'140'!A:T,18,0) -> 0 | R19: =VLOOKUP(L19,'140'!A:T,19,0) -> 白博文 | S19: =VLOOKUP(L19,'140'!A:T,20,0) -> 郭冠廷
B20: 結構用混凝土，預拌，140kgf/cm2 | D20: =M19&M20 -> 30 M3 | F20: =E19&CHAR(10)&"("&O19&O20&")" -> 30 M3 (1組) | H20: =H19&CHAR(10)&"("&P19&O20&")" -> 86 M3 (5組) | M20: M3 | O20: 組
A21: ="1-140 -"&L21 -> 1-140 -7 | B21: 1.2.4、1.3.2、1.4.1、1.5.1、1.6.6 | C21: 397.84 M3 | D21: =VLOOKUP(L21,'140'!A:T,2,0) -> 45544 | E21: =M21&M22 -> 10 M3 | F21: =D21 -> 45544 | H21: =N21&M22 -> 96 M3 | I21: - | J21: =IF(R21=0,"上 溢："&S21,IF(Q21=0,"任 泰："&R21&" "&"上 溢："&S21, "水利處："&Q21&" "&"任 泰："&R21&" "&"上 溢："&S21)) -> 上 溢：葉展志 | K21: 本次澆置數量 未達20M3 免取樣 | L21: =L19+1 -> 7 | M21: =VLOOKUP(L21,'140'!A:T,5,0) -> 10 | N21: =N19+M21 -> 96 | O21: =VLOOKUP(L21,'140'!A:T,6,0) -> 0 | P21: =P19+O21 -> 5 | Q21: =VLOOKUP(L21,'140'!A:T,18,0) -> 0 | R21: =VLOOKUP(L21,'140'!A:T,19,0) -> 0 | S21: =VLOOKUP(L21,'140'!A:T,20,0) -> 葉展志
B22: 結構用混凝土，預拌，140kgf/cm2 | D22: =M21&M22 -> 10 M3 | F22: =E21&CHAR(10)&"("&O21&O22&")" -> 10 M3 (0組) | H22: =H21&CHAR(10)&"("&P21&O22&")" -> 96 M3 (5組) | K22: EF-1130909 混凝土 自主檢查表 | M22: M3 | O22: 組
A23: ="1-140 -"&L23 -> 1-140 -8 | B23: 1.2.4、1.3.2、1.4.1、1.5.1、1.6.6 | C23: 397.84 M3 | D23: =VLOOKUP(L23,'140'!A:T,2,0) -> 45666 | E23: =M23&M24 -> 5 M3 | F23: =D23 -> 45666 | H23: =N23&M24 -> 101 M3 | I23: - | J23: =IF(R23=0,"上 溢："&S23,IF(Q23=0,"任 泰："&R23&" "&"上 溢："&S23, "水利處："&Q23&" "&"任 泰："&R23&" "&"上 溢："&S23)) -> 上 溢：周昱辰 | K23: 本次澆置數量 未達20M3 免取樣 | L23: =L21+1 -> 8 | M23: =VLOOKUP(L23,'140'!A:T,5,0) -> 5 | N23: =N21+M23 -> 101 | O23: =VLOOKUP(L23,'140'!A:T,6,0) -> 0 | P23: =P21+O23 -> 5 | Q23: =VLOOKUP(L23,'140'!A:T,18,0) -> 0 | R23: =VLOOKUP(L23,'140'!A:T,19,0) -> 0 | S23: =VLOOKUP(L23,'140'!A:T,20,0) -> 周昱辰
B24: 結構用混凝土，預拌，140kgf/cm2 | D24: =M23&M24 -> 5 M3 | F24: =E23&CHAR(10)&"("&O23&O24&")" -> 5 M3 (0組) | H24: =H23&CHAR(10)&"("&P23&O24&")" -> 101 M3 (5組) | K24: EF-1140109 混凝土 自主檢查表 | M24: M3 | O24: 組
A25: ="1-140 -"&L25 -> 1-140 -9 | B25: 1.2.4、1.3.2、1.4.1、1.5.1、1.6.6 | C25: 397.84 M3 | D25: =VLOOKUP(L25,'140'!A:T,2,0) -> 45671 | E25: =M25&M26 -> 5 M3 | F25: =D25 -> 45671 | H25: =N25&M26 -> 106 M3 | I25: - | J25: =IF(R25=0,"上 溢："&S25,IF(Q25=0,"任 泰："&R25&" "&"上 溢："&S25, "水利處："&Q25&" "&"任 泰："&R25&" "&"上 溢："&S25)) -> 上 溢：周昱辰 | K25: 本次澆置數量 未達20M3 免取樣 | L25: =L23+1 -> 9 | M25: =VLOOKUP(L25,'140'!A:T,5,0) -> 5 | N25: =N23+M25 -> 106 | O25: =VLOOKUP(L25,'140'!A:T,6,0) -> 0 | P25: =P23+O25 -> 5 | Q25: =VLOOKUP(L25,'140'!A:T,18,0) -> 0 | R25: =VLOOKUP(L25,'140'!A:T,19,0) -> 0 | S25: =VLOOKUP(L25,'140'!A:T,20,0) -> 周昱辰
B26: 結構用混凝土，預拌，140kgf/cm2 | D26: =M25&M26 -> 5 M3 | F26: =E25&CHAR(10)&"("&O25&O26&")" -> 5 M3 (0組) | H26: =H25&CHAR(10)&"("&P25&O26&")" -> 106 M3 (5組) | K26: EF-1140114 混凝土 自主檢查表 | M26: M3 | O26: 組
A27: ="1-140 -"&L27 -> 1-140 -10 | B27: 1.2.4、1.3.2、1.4.1、1.5.1、1.6.6 | C27: 397.84 M3 | D27: =VLOOKUP(L27,'140'!A:T,2,0) -> 45674 | E27: =M27&M28 -> 5 M3 | F27: =D27 -> 45674 | H27: =N27&M28 -> 111 M3 | I27: - | J27: =IF(R27=0,"上 溢："&S27,IF(Q27=0,"任 泰："&R27&" "&"上 溢："&S27, "水利處："&Q27&" "&"任 泰："&R27&" "&"上 溢："&S27)) -> 上 溢：康祐銓 | K27: 本次澆置數量 未達20M3 免取樣 | L27: =L25+1 -> 10 | M27: =VLOOKUP(L27,'140'!A:T,5,0) -> 5 | N27: =N25+M27 -> 111 | O27: =VLOOKUP(L27,'140'!A:T,6,0) -> 0 | P27: =P25+O27 -> 5 | Q27: =VLOOKUP(L27,'140'!A:T,18,0) -> 0 | R27: =VLOOKUP(L27,'140'!A:T,19,0) -> 0 | S27: =VLOOKUP(L27,'140'!A:T,20,0) -> 康祐銓
B28: 結構用混凝土，預拌，140kgf/cm2 | D28: =M27&M28 -> 5 M3 | F28: =E27&CHAR(10)&"("&O27&O28&")" -> 5 M3 (0組) | H28: =H27&CHAR(10)&"("&P27&O28&")" -> 111 M3 (5組) | K28: EF-1140117 混凝土 自主檢查表 | M28: M3 | O28: 組
A29: 編制： | D29: 工地主任： | H29: 附註：
A30: 1.本表於施工期間監造單位依契約約定之「材料、設備送審文件、樣品一覽表」分類登錄，俾利控管材料檢驗使用情形。 2.監造單位應依監造計畫之材料設備抽驗程序及標準辦理材料設備抽驗，如有單項材料設備廠商自主檢查頻率未達 3次時，廠商在辦理自主檢查取樣前，應通知監造單位轉知考工單位會同廠商辦理抽驗（即前2次均由本處派員抽驗）。 3.本表規定檢驗頻率請依據工程契約或施工規範約定填寫。
A31: ="1-140 -"&L31 -> 1-140 -11 | B31: 1.2.4、1.3.2、1.4.1、1.5.1、1.6.6 | C31: 397.84 M3 | D31: =VLOOKUP(L31,'140'!A:T,2,0) -> 45678 | E31: =M31&M32 -> 4 M3 | F31: =D31 -> 45678 | G31: 1.每批次數量未達20 m3時，免檢驗。 2.每批次數量達20～100 m3檢驗1組。 3.每批次數量超過100 m3時，每100 m3加驗1組，餘數未達100m³亦加驗1組。 | H31: =N31&M32 -> 115 M3 | I31: - | J31: =IF(R31=0,"上 溢："&S31,IF(Q31=0,"任 泰："&R31&" "&"上 溢："&S31, "水利處："&Q31&" "&"任 泰："&R31&" "&"上 溢："&S31)) -> 上 溢：康祐銓 | K31: 本次澆置數量 未達20M3 免取樣 | L31: =L27+1 -> 11 | M31: =VLOOKUP(L31,'140'!A:T,5,0) -> 4 | N31: =N27+M31 -> 115 | O31: =VLOOKUP(L31,'140'!A:T,6,0) -> 0 | P31: =P27+O31 -> 5 | Q31: =VLOOKUP(L31,'140'!A:T,18,0) -> 0 | R31: =VLOOKUP(L31,'140'!A:T,19,0) -> 0 | S31: =VLOOKUP(L31,'140'!A:T,20,0) -> 康祐銓
B32: 結構用混凝土，預拌，140kgf/cm2 | D32: =M31&M32 -> 4 M3 | F32: =E31&CHAR(10)&"("&O31&O32&")" -> 4 M3 (0組) | H32: =H31&CHAR(10)&"("&P31&O32&")" -> 115 M3 (5組) | K32: EF-1140121 混凝土 自主檢查表 | M32: M3 | O32: 組
A33: ="1-140 -"&L33 -> 1-140 -12 | B33: 1.2.4、1.3.2、1.4.1、1.5.1、1.6.6 | C33: 397.84 M3 | D33: =VLOOKUP(L33,'140'!A:T,2,0) -> 45680 | E33: =M33&M34 -> 4.5 M3 | F33: =D33 -> 45680 | H33: =N33&M34 -> 119.5 M3 | I33: - | J33: =IF(R33=0,"上 溢："&S33,IF(Q33=0,"任 泰："&R33&" "&"上 溢："&S33, "水利處："&Q33&" "&"任 泰："&R33&" "&"上 溢："&S33)) -> 上 溢：康祐銓 | K33: 本次澆置數量 未達20M3 免取樣 | L33: =L31+1 -> 12 | M33: =VLOOKUP(L33,'140'!A:T,5,0) -> 4.5 | N33: =N31+M33 -> 119.5 | O33: =VLOOKUP(L33,'140'!A:T,6,0) -> 0 | P33: =P31+O33 -> 5 | Q33: =VLOOKUP(L33,'140'!A:T,18,0) -> 0 | R33: =VLOOKUP(L33,'140'!A:T,19,0) -> 0 | S33: =VLOOKUP(L33,'140'!A:T,20,0) -> 康祐銓
B34: 結構用混凝土，預拌，140kgf/cm2 | D34: =M33&M34 -> 4.5 M3 | F34: =E33&CHAR(10)&"("&O33&O34&")" -> 4.5 M3 (0組) | H34: =H33&CHAR(10)&"("&P33&O34&")" -> 119.5 M3 (5組) | K34: EF-1140123 混凝土 自主檢查表 | M34: M3 | O34: 組
A35: ="1-140 -"&L35 -> 1-140 -13 | B35: 1.2.4、1.3.2、1.4.1、1.5.1、1.6.6 | C35: 397.84 M3 | D35: =VLOOKUP(L35,'140'!A:T,2,0) -> 45692 | E35: =M35&M36 -> 6 M3 | F35: =D35 -> 45692 | H35: =N35&M36 -> 125.5 M3 | I35: - | J35: =IF(R35=0,"上 溢："&S35,IF(Q35=0,"任 泰："&R35&" "&"上 溢："&S35, "水利處："&Q35&" "&"任 泰："&R35&" "&"上 溢："&S35)) -> 上 溢：康祐銓 | K35: 本次澆置數量 未達20M3 免取樣 | L35: =L33+1 -> 13 | M35: =VLOOKUP(L35,'140'!A:T,5,0) -> 6 | N35: =N33+M35 -> 125.5 | O35: =VLOOKUP(L35,'140'!A:T,6,0) -> 0 | P35: =P33+O35 -> 5 | Q35: =VLOOKUP(L35,'140'!A:T,18,0) -> 0 | R35: =VLOOKUP(L35,'140'!A:T,19,0) -> 0 | S35: =VLOOKUP(L35,'140'!A:T,20,0) -> 康祐銓
B36: 結構用混凝土，預拌，140kgf/cm2 | D36: =M35&M36 -> 6 M3 | F36: =E35&CHAR(10)&"("&O35&O36&")" -> 6 M3 (0組) | H36: =H35&CHAR(10)&"("&P35&O36&")" -> 125.5 M3 (5組) | K36: EF-1140204 混凝土 自主檢查表 | M36: M3 | O36: 組
A37: ="1-140 -"&L37 -> 1-140 -14 | B37: 1.2.4、1.3.2、1.4.1、1.5.1、1.6.6 | C37: 397.84 M3 | D37: =VLOOKUP(L37,'140'!A:T,2,0) -> 45695 | E37: =M37&M38 -> 20 M3 | F37: =D37 -> 45695 | H37: =N37&M38 -> 145.5 M3 | I37: 合格 | J37: =IF(R37=0,"上 溢："&S37,IF(Q37=0,"任 泰："&R37&" "&"上 溢："&S37, "水利處："&Q37&" "&"任 泰："&R37&" "&"上 溢："&S37)) -> 上 溢：李建豪 | K37: 114年3月26日 任泰顧字 第1140326625號 | L37: =L35+1 -> 14 | M37: =VLOOKUP(L37,'140'!A:T,5,0) -> 20 | N37: =N35+M37 -> 145.5 | O37: =VLOOKUP(L37,'140'!A:T,6,0) -> 1 | P37: =P35+O37 -> 6 | Q37: =VLOOKUP(L37,'140'!A:T,18,0) -> 0 | R37: =VLOOKUP(L37,'140'!A:T,19,0) -> 0 | S37: =VLOOKUP(L37,'140'!A:T,20,0) -> 李建豪
B38: 結構用混凝土，預拌，140kgf/cm2 | D38: =M37&M38 -> 20 M3 | F38: =E37&CHAR(10)&"("&O37&O38&")" -> 20 M3 (1組) | H38: =H37&CHAR(10)&"("&P37&O38&")" -> 145.5 M3 (6組) | M38: M3 | O38: 組
A39: ="1-140 -"&L39 -> 1-140 -15 | B39: 1.2.4、1.3.2、1.4.1、1.5.1、1.6.6 | C39: 397.84 M3 | D39: =VLOOKUP(L39,'140'!A:T,2,0) -> 45698 | E39: =M39&M40 -> 10 M3 | F39: =D39 -> 45698 | H39: =N39&M40 -> 155.5 M3 | I39: - | J39: =IF(R39=0,"上 溢："&S39,IF(Q39=0,"任 泰："&R39&" "&"上 溢："&S39, "水利處："&Q39&" "&"任 泰："&R39&" "&"上 溢："&S39)) -> 上 溢：康祐銓 | K39: 本次澆置數量 未達20M3 免取樣 | L39: =L37+1 -> 15 | M39: =VLOOKUP(L39,'140'!A:T,5,0) -> 10 | N39: =N37+M39 -> 155.5 | O39: =VLOOKUP(L39,'140'!A:T,6,0) -> 0 | P39: =P37+O39 -> 6 | Q39: =VLOOKUP(L39,'140'!A:T,18,0) -> 0 | R39: =VLOOKUP(L39,'140'!A:T,19,0) -> 0 | S39: =VLOOKUP(L39,'140'!A:T,20,0) -> 康祐銓
B40: 結構用混凝土，預拌，140kgf/cm2 | D40: =M39&M40 -> 10 M3 | F40: =E39&CHAR(10)&"("&O39&O40&")" -> 10 M3 (0組) | H40: =H39&CHAR(10)&"("&P39&O40&")" -> 155.5 M3 (6組) | K40: EF-1140210 混凝土 自主檢查表 | M40: M3 | O40: 組
...

Sheet 5-1.試驗210
A1: 臺北市政府工務局水利工程處
A2: 材料設備檢（試）驗管制總表
A3: ="工程名稱:"&'1.計畫'!A1:I1 -> 工程名稱:磺港溪再造C段護岸及步道整建工程（延壽橋至三合橋） | H3: 契約編號：H-111-03-112080
A4: 監造單位：任泰技術顧問有限公司 | H4: 施工廠商：上溢營造份有限公司
A5: 項次 | B5: 契約詳細表項次 | C5: 契約 數量 | D5: 進場 日期 | E5: 進場 數量 | F5: 抽樣 日期 | G5: 規定抽（取）樣頻率 | H5: 累積進場數量 | I5: 抽試驗結果 | J5: 抽驗及會同人員 | K5: 備註
B6: 材料(設備)名稱 | D6: 進場 數量 | F6: 抽樣 數量 | H6: 累積抽樣數量 | K6: (歸檔編號) | M6: 數量 | N6: 累計數量 | O6: 組數 | P6: 累計組數 | Q6: 水利處 | R6: 監造 | S6: 廠商
A7: ="1-210 -"&L7 -> 1-210 -1 | B7: 1.2.5、1.3.3、1.4.2、1.5.2、1.6.7 | C7: 4,360.87 M3 | D7: =VLOOKUP(L7,'210'!A:T,2,0) -> 45181 | E7: =M7&M8 -> 0 M3 | F7: =D7 -> 45181 | G7: 1.每批次數量未達20 m3時，免檢驗。 2.每批次數量達20～100 m3檢驗1組。 3.每批次數量超過100 m3時，每100 m3加驗1組，餘數未達100m³亦加驗1組。 | H7: =N7&M8 -> 0 M3 | I7: 合格 | J7: =IF(R7=0,"上 溢："&S7,IF(Q7=0,"任 泰："&R7&" "&"上 溢："&S7, "水利處："&Q7&" "&"任 泰："&R7&" "&"上 溢："&S7)) -> 水利處：李晏然 任 泰：游文圃 上 溢：康祐銓 | K7: 112年11月10日 112任泰顧字 第1110010001號 | L7: 1 | M7: =VLOOKUP(L7,'210'!A:T,5,0) -> 0 | N7: =M7 -> 0 | O7: =VLOOKUP(L7,'210'!A:T,6,0) -> 1 | P7: =O7 -> 1 | Q7: =VLOOKUP(L7,'210'!A:T,18,0) -> 李晏然 | R7: =VLOOKUP(L7,'210'!A:T,19,0) -> 游文圃 | S7: =VLOOKUP(L7,'210'!A:T,20,0) -> 康祐銓
B8: 結構用混凝土，預拌，210kgf/cm2 | D8: =M7&M8 -> 0 M3 | F8: =E7&CHAR(10)&"("&O7&O8&")" -> 0 M3 (1組) | H8: =H7&CHAR(10)&"("&P7&O8&")" -> 0 M3 (1組) | M8: M3 | O8: 組
A9: ="1-210 -"&L9 -> 1-210 -2 | B9: 1.2.5、1.3.3、1.4.2、1.5.2、1.6.7 | C9: 4,360.87 M3 | D9: =VLOOKUP(L9,'210'!A:T,2,0) -> 45484 | E9: =M9&M10 -> 95 M3 | F9: =D9 -> 45484 | H9: =N9&M10 -> 95 M3 | I9: 合格 | J9: =IF(R9=0,"上 溢："&S9,IF(Q9=0,"任 泰："&R9&" "&"上 溢："&S9, "水利處："&Q9&" "&"任 泰："&R9&" "&"上 溢："&S9)) -> 任 泰：白博文 上 溢：葉展志 | K9: 113年8月15日 113任泰顧字 第1130815107號 | L9: =L7+1 -> 2 | M9: =VLOOKUP(L9,'210'!A:T,5,0) -> 95 | N9: =N7+M9 -> 95 | O9: =VLOOKUP(L9,'210'!A:T,6,0) -> 1 | P9: =P7+O9 -> 2 | Q9: =VLOOKUP(L9,'210'!A:T,18,0) -> 0 | R9: =VLOOKUP(L9,'210'!A:T,19,0) -> 白博文 | S9: =VLOOKUP(L9,'210'!A:T,20,0) -> 葉展志
B10: 結構用混凝土，預拌，210kgf/cm2 | D10: =M9&M10 -> 95 M3 | F10: =E9&CHAR(10)&"("&O9&O10&")" -> 95 M3 (1組) | H10: =H9&CHAR(10)&"("&P9&O10&")" -> 95 M3 (2組) | M10: M3 | O10: 組
A11: ="1-210 -"&L11 -> 1-210 -3 | B11: 1.2.5、1.3.3、1.4.2、1.5.2、1.6.7 | C11: 4,360.87 M3 | D11: =VLOOKUP(L11,'210'!A:T,2,0) -> 45488 | E11: =M11&M12 -> 198 M3 | F11: =D11 -> 45488 | H11: =N11&M12 -> 293 M3 | I11: 合格 | J11: =IF(R11=0,"上 溢："&S11,IF(Q11=0,"任 泰："&R11&" "&"上 溢："&S11, "水利處："&Q11&" "&"任 泰："&R11&" "&"上 溢："&S11)) -> 任 泰：白博文 上 溢：葉展志 | K11: 113年9月27日 113任泰顧字 第1130927621號 | L11: =L9+1 -> 3 | M11: =VLOOKUP(L11,'210'!A:T,5,0) -> 198 | N11: =N9+M11 -> 293 | O11: =VLOOKUP(L11,'210'!A:T,6,0) -> 2 | P11: =P9+O11 -> 4 | Q11: =VLOOKUP(L11,'210'!A:T,18,0) -> 0 | R11: =VLOOKUP(L11,'210'!A:T,19,0) -> 白博文 | S11: =VLOOKUP(L11,'210'!A:T,20,0) -> 葉展志
B12: 結構用混凝土，預拌，210kgf/cm2 | D12: =M11&M12 -> 198 M3 | F12: =E11&CHAR(10)&"("&O11&O12&")" -> 198 M3 (2組) | H12: =H11&CHAR(10)&"("&P11&O12&")" -> 293 M3 (4組) | M12: M3 | O12: 組
A13: ="1-210 -"&L13 -> 1-210 -4 | B13: 1.2.5、1.3.3、1.4.2、1.5.2、1.6.7 | C13: 4,360.87 M3 | D13: =VLOOKUP(L13,'210'!A:T,2,0) -> 45492 | E13: =M13&M14 -> 81 M3 | F13: =D13 -> 45492 | H13: =N13&M14 -> 374 M3 | I13: 合格 | J13: =IF(R13=0,"上 溢："&S13,IF(Q13=0,"任 泰："&R13&" "&"上 溢："&S13, "水利處："&Q13&" "&"任 泰："&R13&" "&"上 溢："&S13)) -> 任 泰：白博文 上 溢：葉展志 | K13: 113年9月27日 113任泰顧字 第1130927622號 | L13: =L11+1 -> 4 | M13: =VLOOKUP(L13,'210'!A:T,5,0) -> 81 | N13: =N11+M13 -> 374 | O13: =VLOOKUP(L13,'210'!A:T,6,0) -> 1 | P13: =P11+O13 -> 5 | Q13: =VLOOKUP(L13,'210'!A:T,18,0) -> 0 | R13: =VLOOKUP(L13,'210'!A:T,19,0) -> 白博文 | S13: =VLOOKUP(L13,'210'!A:T,20,0) -> 葉展志
B14: 結構用混凝土，預拌，210kgf/cm2 | D14: =M13&M14 -> 81 M3 | F14: =E13&CHAR(10)&"("&O13&O14&")" -> 81 M3 (1組) | H14: =H13&CHAR(10)&"("&P13&O14&")" -> 374 M3 (5組) | M14: M3 | O14: 組
A15: ="1-210 -"&L15 -> 1-210 -5 | B15: 1.2.5、1.3.3、1.4.2、1.5.2、1.6.7 | C15: 4,360.87 M3 | D15: =VLOOKUP(L15,'210'!A:T,2,0) -> 45496 | E15: =M15&M16 -> 188 M3 | F15: =D15 -> 45496 | H15: =N15&M16 -> 562 M3 | I15: 合格 | J15: =IF(R15=0,"上 溢："&S15,IF(Q15=0,"任 泰："&R15&" "&"上 溢："&S15, "水利處："&Q15&" "&"任 泰："&R15&" "&"上 溢："&S15)) -> 任 泰：白博文 上 溢：葉展志 | K15: 113年9月27日 113任泰顧字 第1130927623號 | L15: =L13+1 -> 5 | M15: =VLOOKUP(L15,'210'!A:T,5,0) -> 188 | N15: =N13+M15 -> 562 | O15: =VLOOKUP(L15,'210'!A:T,6,0) -> 2 | P15: =P13+O15 -> 7 | Q15: =VLOOKUP(L15,'210'!A:T,18,0) -> 0 | R15: =VLOOKUP(L15,'210'!A:T,19,0) -> 白博文 | S15: =VLOOKUP(L15,'210'!A:T,20,0) -> 葉展志
B16: 結構用混凝土，預拌，210kgf/cm2 | D16: =M15&M16 -> 188 M3 | F16: =E15&CHAR(10)&"("&O15&O16&")" -> 188 M3 (2組) | H16: =H15&CHAR(10)&"("&P15&O16&")" -> 562 M3 (7組) | M16: M3 | O16: 組
A17: ="1-210 -"&L17 -> 1-210 -6 | B17: 1.2.5、1.3.3、1.4.2、1.5.2、1.6.7 | C17: 4,360.87 M3 | D17: =VLOOKUP(L17,'210'!A:T,2,0) -> 45523 | E17: =M17&M18 -> 99 M3 | F17: =D17 -> 45523 | H17: =N17&M18 -> 661 M3 | I17: 合格 | J17: =IF(R17=0,"上 溢："&S17,IF(Q17=0,"任 泰："&R17&" "&"上 溢："&S17, "水利處："&Q17&" "&"任 泰："&R17&" "&"上 溢："&S17)) -> 任 泰：白博文 上 溢：葉展志 | K17: 113年9月27日 113任泰顧字 第1130927624號 | L17: =L15+1 -> 6 | M17: =VLOOKUP(L17,'210'!A:T,5,0) -> 99 | N17: =N15+M17 -> 661 | O17: =VLOOKUP(L17,'210'!A:T,6,0) -> 1 | P17: =P15+O17 -> 8 | Q17: =VLOOKUP(L17,'210'!A:T,18,0) -> 0 | R17: =VLOOKUP(L17,'210'!A:T,19,0) -> 白博文 | S17: =VLOOKUP(L17,'210'!A:T,20,0) -> 葉展志
B18: 結構用混凝土，預拌，210kgf/cm2 | D18: =M17&M18 -> 99 M3 | F18: =E17&CHAR(10)&"("&O17&O18&")" -> 99 M3 (1組) | H18: =H17&CHAR(10)&"("&P17&O18&")" -> 661 M3 (8組) | M18: M3 | O18: 組
A19: 編制： | D19: 工地主任： | H19: 附註：
A20: 1.本表於施工期間監造單位依契約約定之「材料、設備送審文件、樣品一覽表」分類登錄，俾利控管材料檢驗使用情形。 2.監造單位應依監造計畫之材料設備抽驗程序及標準辦理材料設備抽驗，如有單項材料設備廠商自主檢查頻率未達 3次時，廠商在辦理自主檢查取樣前，應通知監造單位轉知考工單位會同廠商辦理抽驗（即前2次均由本處派員抽驗）。 3.本表規定檢驗頻率請依據工程契約或施工規範約定填寫。
A21: ="1-210 -"&L21 -> 1-210 -7 | B21: 1.2.5、1.3.3、1.4.2、1.5.2、1.6.7 | C21: 4,360.87 M3 | D21: =VLOOKUP(L21,'210'!A:T,2,0) -> 45526 | E21: =M21&M22 -> 99 M3 | F21: =D21 -> 45526 | G21: 1.每批次數量未達20 m3時，免檢驗。 2.每批次數量達20～100 m3檢驗1組。 3.每批次數量超過100 m3時，每100 m3加驗1組，餘數未達100m³亦加驗1組。 | H21: =N21&M22 -> 760 M3 | I21: 合格 | J21: =IF(R21=0,"上 溢："&S21,IF(Q21=0,"任 泰："&R21&" "&"上 溢："&S21, "水利處："&Q21&" "&"任 泰："&R21&" "&"上 溢："&S21)) -> 上 溢：葉展志 | K21: 113年10月21日 113任泰顧字 第1131021621號 | L21: =L17+1 -> 7 | M21: =VLOOKUP(L21,'210'!A:T,5,0) -> 99 | N21: =N17+M21 -> 760 | O21: =VLOOKUP(L21,'210'!A:T,6,0) -> 1 | P21: =P17+O21 -> 9 | Q21: =VLOOKUP(L21,'210'!A:T,18,0) -> 0 | R21: =VLOOKUP(L21,'210'!A:T,19,0) -> 0 | S21: =VLOOKUP(L21,'210'!A:T,20,0) -> 葉展志
B22: 結構用混凝土，預拌，210kgf/cm2 | D22: =M21&M22 -> 99 M3 | F22: =E21&CHAR(10)&"("&O21&O22&")" -> 99 M3 (1組) | H22: =H21&CHAR(10)&"("&P21&O22&")" -> 760 M3 (9組) | M22: M3 | O22: 組
A23: ="1-210 -"&L23 -> 1-210 -8 | B23: 1.2.5、1.3.3、1.4.2、1.5.2、1.6.7 | C23: 4,360.87 M3 | D23: =VLOOKUP(L23,'210'!A:T,2,0) -> 45531 | E23: =M23&M24 -> 99 M3 | F23: =D23 -> 45531 | H23: =N23&M24 -> 859 M3 | I23: 合格 | J23: =IF(R23=0,"上 溢："&S23,IF(Q23=0,"任 泰："&R23&" "&"上 溢："&S23, "水利處："&Q23&" "&"任 泰："&R23&" "&"上 溢："&S23)) -> 上 溢：葉展志 | K23: 113年10月21日 113任泰顧字 第1131021622號 | L23: =L21+1 -> 8 | M23: =VLOOKUP(L23,'210'!A:T,5,0) -> 99 | N23: =N21+M23 -> 859 | O23: =VLOOKUP(L23,'210'!A:T,6,0) -> 1 | P23: =P21+O23 -> 10 | Q23: =VLOOKUP(L23,'210'!A:T,18,0) -> 0 | R23: =VLOOKUP(L23,'210'!A:T,19,0) -> 0 | S23: =VLOOKUP(L23,'210'!A:T,20,0) -> 葉展志
B24: 結構用混凝土，預拌，210kgf/cm2 | D24: =M23&M24 -> 99 M3 | F24: =E23&CHAR(10)&"("&O23&O24&")" -> 99 M3 (1組) | H24: =H23&CHAR(10)&"("&P23&O24&")" -> 859 M3 (10組) | M24: M3 | O24: 組
A25: ="1-210 -"&L25 -> 1-210 -9 | B25: 1.2.5、1.3.3、1.4.2、1.5.2、1.6.7 | C25: 4,360.87 M3 | D25: =VLOOKUP(L25,'210'!A:T,2,0) -> 45532 | E25: =M25&M26 -> 95 M3 | F25: =D25 -> 45532 | H25: =N25&M26 -> 954 M3 | I25: 合格 | J25: =IF(R25=0,"上 溢："&S25,IF(Q25=0,"任 泰："&R25&" "&"上 溢："&S25, "水利處："&Q25&" "&"任 泰："&R25&" "&"上 溢："&S25)) -> 任 泰：王淑慧 上 溢：康祐銓 | K25: 113年10月21日 113任泰顧字 第1131021623號 | L25: =L23+1 -> 9 | M25: =VLOOKUP(L25,'210'!A:T,5,0) -> 95 | N25: =N23+M25 -> 954 | O25: =VLOOKUP(L25,'210'!A:T,6,0) -> 1 | P25: =P23+O25 -> 11 | Q25: =VLOOKUP(L25,'210'!A:T,18,0) -> 0 | R25: =VLOOKUP(L25,'210'!A:T,19,0) -> 王淑慧 | S25: =VLOOKUP(L25,'210'!A:T,20,0) -> 康祐銓
B26: 結構用混凝土，預拌，210kgf/cm2 | D26: =M25&M26 -> 95 M3 | F26: =E25&CHAR(10)&"("&O25&O26&")" -> 95 M3 (1組) | H26: =H25&CHAR(10)&"("&P25&O26&")" -> 954 M3 (11組) | M26: M3 | O26: 組
A27: ="1-210 -"&L27 -> 1-210 -10 | B27: 1.2.5、1.3.3、1.4.2、1.5.2、1.6.7 | C27: 4,360.87 M3 | D27: =VLOOKUP(L27,'210'!A:T,2,0) -> 45534 | E27: =M27&M28 -> 99 M3 | F27: =D27 -> 45534 | H27: =N27&M28 -> 1053 M3 | I27: 合格 | J27: =IF(R27=0,"上 溢："&S27,IF(Q27=0,"任 泰："&R27&" "&"上 溢："&S27, "水利處："&Q27&" "&"任 泰："&R27&" "&"上 溢："&S27)) -> 上 溢：葉展志 | K27: 113年10月21日 113任泰顧字 第1131021624號 | L27: =L25+1 -> 10 | M27: =VLOOKUP(L27,'210'!A:T,5,0) -> 99 | N27: =N25+M27 -> 1053 | O27: =VLOOKUP(L27,'210'!A:T,6,0) -> 1 | P27: =P25+O27 -> 12 | Q27: =VLOOKUP(L27,'210'!A:T,18,0) -> 0 | R27: =VLOOKUP(L27,'210'!A:T,19,0) -> 0 | S27: =VLOOKUP(L27,'210'!A:T,20,0) -> 葉展志
B28: 結構用混凝土，預拌，210kgf/cm2 | D28: =M27&M28 -> 99 M3 | F28: =E27&CHAR(10)&"("&O27&O28&")" -> 99 M3 (1組) | H28: =H27&CHAR(10)&"("&P27&O28&")" -> 1053 M3 (12組) | M28: M3 | O28: 組
A29: ="1-210 -"&L29 -> 1-210 -11 | B29: 1.2.5、1.3.3、1.4.2、1.5.2、1.6.7 | C29: 4,360.87 M3 | D29: =VLOOKUP(L29,'210'!A:T,2,0) -> 45540 | E29: =M29&M30 -> 99 M3 | F29: =D29 -> 45540 | H29: =N29&M30 -> 1152 M3 | I29: 合格 | J29: =IF(R29=0,"上 溢："&S29,IF(Q29=0,"任 泰："&R29&" "&"上 溢："&S29, "水利處："&Q29&" "&"任 泰："&R29&" "&"上 溢："&S29)) -> 上 溢：葉展志 | K29: 113年11月6日 113任泰顧字 第1131106623號 | L29: =L27+1 -> 11 | M29: =VLOOKUP(L29,'210'!A:T,5,0) -> 99 | N29: =N27+M29 -> 1152 | O29: =VLOOKUP(L29,'210'!A:T,6,0) -> 1 | P29: =P27+O29 -> 13 | Q29: =VLOOKUP(L29,'210'!A:T,18,0) -> 0 | R29: =VLOOKUP(L29,'210'!A:T,19,0) -> 0 | S29: =VLOOKUP(L29,'210'!A:T,20,0) -> 葉展志
B30: 結構用混凝土，預拌，210kgf/cm2 | D30: =M29&M30 -> 99 M3 | F30: =E29&CHAR(10)&"("&O29&O30&")" -> 99 M3 (1組) | H30: =H29&CHAR(10)&"("&P29&O30&")" -> 1152 M3 (13組) | M30: M3 | O30: 組
A31: ="1-210 -"&L31 -> 1-210 -12 | B31: 1.2.5、1.3.3、1.4.2、1.5.2、1.6.7 | C31: 4,360.87 M3 | D31: =VLOOKUP(L31,'210'!A:T,2,0) -> 45544 | E31: =M31&M32 -> 99 M3 | F31: =D31 -> 45544 | H31: =N31&M32 -> 1251 M3 | I31: 合格 | J31: =IF(R31=0,"上 溢："&S31,IF(Q31=0,"任 泰："&R31&" "&"上 溢："&S31, "水利處："&Q31&" "&"任 泰："&R31&" "&"上 溢："&S31)) -> 上 溢：康祐銓 | K31: 113年11月6日 113任泰顧字 第1131106624號 | L31: =L29+1 -> 12 | M31: =VLOOKUP(L31,'210'!A:T,5,0) -> 99 | N31: =N29+M31 -> 1251 | O31: =VLOOKUP(L31,'210'!A:T,6,0) -> 1 | P31: =P29+O31 -> 14 | Q31: =VLOOKUP(L31,'210'!A:T,18,0) -> 0 | R31: =VLOOKUP(L31,'210'!A:T,19,0) -> 0 | S31: =VLOOKUP(L31,'210'!A:T,20,0) -> 康祐銓
B32: 結構用混凝土，預拌，210kgf/cm2 | D32: =M31&M32 -> 99 M3 | F32: =E31&CHAR(10)&"("&O31&O32&")" -> 99 M3 (1組) | H32: =H31&CHAR(10)&"("&P31&O32&")" -> 1251 M3 (14組) | M32: M3 | O32: 組
A33: 編制： | D33: 工地主任： | H33: 附註：
A34: 1.本表於施工期間監造單位依契約約定之「材料、設備送審文件、樣品一覽表」分類登錄，俾利控管材料檢驗使用情形。 2.監造單位應依監造計畫之材料設備抽驗程序及標準辦理材料設備抽驗，如有單項材料設備廠商自主檢查頻率未達 3次時，廠商在辦理自主檢查取樣前，應通知監造單位轉知考工單位會同廠商辦理抽驗（即前2次均由本處派員抽驗）。 3.本表規定檢驗頻率請依據工程契約或施工規範約定填寫。
A35: ="1-210 -"&L35 -> 1-210 -13 | B35: 1.2.5、1.3.3、1.4.2、1.5.2、1.6.7 | C35: 4,360.87 M3 | D35: =VLOOKUP(L35,'210'!A:T,2,0) -> 45545 | E35: =M35&M36 -> 95 M3 | F35: =D35 -> 45545 | G35: 1.每批次數量未達20 m3時，免檢驗。 2.每批次數量達20～100 m3檢驗1組。 3.每批次數量超過100 m3時，每100 m3加驗1組，餘數未達100m³亦加驗1組。 | H35: =N35&M36 -> 1346 M3 | I35: 合格 | J35: =IF(R35=0,"上 溢："&S35,IF(Q35=0,"任 泰："&R35&" "&"上 溢："&S35, "水利處："&Q35&" "&"任 泰："&R35&" "&"上 溢："&S35)) -> 上 溢：葉展志 | K35: 113年11月19日 113任泰顧字 第1131119621號 | L35: =L31+1 -> 13 | M35: =VLOOKUP(L35,'210'!A:T,5,0) -> 95 | N35: =N31+M35 -> 1346 | O35: =VLOOKUP(L35,'210'!A:T,6,0) -> 1 | P35: =P31+O35 -> 15 | Q35: =VLOOKUP(L35,'210'!A:T,18,0) -> 0 | R35: =VLOOKUP(L35,'210'!A:T,19,0) -> 0 | S35: =VLOOKUP(L35,'210'!A:T,20,0) -> 葉展志
B36: 結構用混凝土，預拌，210kgf/cm2 | D36: =M35&M36 -> 95 M3 | F36: =E35&CHAR(10)&"("&O35&O36&")" -> 95 M3 (1組) | H36: =H35&CHAR(10)&"("&P35&O36&")" -> 1346 M3 (15組) | M36: M3 | O36: 組
A37: ="1-210 -"&L37 -> 1-210 -14 | B37: 1.2.5、1.3.3、1.4.2、1.5.2、1.6.7 | C37: 4,360.87 M3 | D37: =VLOOKUP(L37,'210'!A:T,2,0) -> 45549 | E37: =M37&M38 -> 52 M3 | F37: =D37 -> 45549 | H37: =N37&M38 -> 1398 M3 | I37: 合格 | J37: =IF(R37=0,"上 溢："&S37,IF(Q37=0,"任 泰："&R37&" "&"上 溢："&S37, "水利處："&Q37&" "&"任 泰："&R37&" "&"上 溢："&S37)) -> 上 溢：葉展志 | K37: 113年11月19日 113任泰顧字 第1131119622號 | L37: =L35+1 -> 14 | M37: =VLOOKUP(L37,'210'!A:T,5,0) -> 52 | N37: =N35+M37 -> 1398 | O37: =VLOOKUP(L37,'210'!A:T,6,0) -> 1 | P37: =P35+O37 -> 16 | Q37: =VLOOKUP(L37,'210'!A:T,18,0) -> 0 | R37: =VLOOKUP(L37,'210'!A:T,19,0) -> 0 | S37: =VLOOKUP(L37,'210'!A:T,20,0) -> 葉展志
B38: 結構用混凝土，預拌，210kgf/cm2 | D38: =M37&M38 -> 52 M3 | F38: =E37&CHAR(10)&"("&O37&O38&")" -> 52 M3 (1組) | H38: =H37&CHAR(10)&"("&P37&O38&")" -> 1398 M3 (16組) | M38: M3 | O38: 組
A39: ="1-210 -"&L39 -> 1-210 -15 | B39: 1.2.5、1.3.3、1.4.2、1.5.2、1.6.7 | C39: 4,360.87 M3 | D39: =VLOOKUP(L39,'210'!A:T,2,0) -> 45553 | E39: =M39&M40 -> 95 M3 | F39: =D39 -> 45553 | H39: =N39&M40 -> 1493 M3 | I39: 合格 | J39: =IF(R39=0,"上 溢："&S39,IF(Q39=0,"任 泰："&R39&" "&"上 溢："&S39, "水利處："&Q39&" "&"任 泰："&R39&" "&"上 溢："&S39)) -> 上 溢：胡舜豪 | K39: 113年11月19日 113任泰顧字 第1131119623號 | L39: =L37+1 -> 15 | M39: =VLOOKUP(L39,'210'!A:T,5,0) -> 95 | N39: =N37+M39 -> 1493 | O39: =VLOOKUP(L39,'210'!A:T,6,0) -> 1 | P39: =P37+O39 -> 17 | Q39: =VLOOKUP(L39,'210'!A:T,18,0) -> 0 | R39: =VLOOKUP(L39,'210'!A:T,19,0) -> 0 | S39: =VLOOKUP(L39,'210'!A:T,20,0) -> 胡舜豪
B40: 結構用混凝土，預拌，210kgf/cm2 | D40: =M39&M40 -> 95 M3 | F40: =E39&CHAR(10)&"("&O39&O40&")" -> 95 M3 (1組) | H40: =H39&CHAR(10)&"("&P39&O40&")" -> 1493 M3 (17組) | M40: M3 | O40: 組
...

Sheet 5-1.試驗280
A1: 臺北市政府工務局水利工程處
A2: 材料設備檢（試）驗管制總表
A3: ="工程名稱:"&'1.計畫'!A1:I1 -> 工程名稱:磺港溪再造C段護岸及步道整建工程（延壽橋至三合橋） | H3: 契約編號：H-111-03-112080
A4: 監造單位：任泰技術顧問有限公司 | H4: 施工廠商：上溢營造份有限公司
A5: 項次 | B5: 契約詳細表項次 | C5: 契約 數量 | D5: 進場 日期 | E5: 進場 數量 | F5: 抽樣 日期 | G5: 規定抽（取）樣頻率 | H5: 累積進場數量 | I5: 抽試驗結果 | J5: 抽驗及會同人員 | K5: 備註
B6: 材料(設備)名稱 | D6: 進場 數量 | F6: 抽樣 數量 | H6: 累積抽樣數量 | K6: (歸檔編號) | M6: 數量 | N6: 累計數量 | O6: 組數 | P6: 累計組數 | Q6: 水利處 | R6: 監造 | S6: 廠商
A7: ="1-280 -"&L7 -> 1-280 -1 | B7: 1.4.3 | C7: 709.04 M3 | D7: =VLOOKUP(L7,'280'!A:T,2,0) -> 45181 | E7: =M7&M8 -> 0 M3 | F7: =D7 -> 45181 | G7: 1.每批次數量未達20 m3時，免檢驗。 2.每批次數量達20～100 m3檢驗1組。 3.每批次數量超過100 m3時，每100 m3加驗1組，餘數未達100m³亦加驗1組。 | H7: =N7&M8 -> 0 M3 | I7: 合格 | J7: =IF(R7=0,"上 溢："&S7,IF(Q7=0,"任 泰："&R7&" "&"上 溢："&S7, "水利處："&Q7&" "&"任 泰："&R7&" "&"上 溢："&S7)) -> 水利處：李晏然 任 泰：游文圃 上 溢：康祐銓 | K7: 112年11月10日 112任泰顧字 第1110010001號 | L7: 1 | M7: =VLOOKUP(L7,'280'!A:T,5,0) -> 0 | N7: =M7 -> 0 | O7: =VLOOKUP(L7,'280'!A:T,6,0) -> 1 | P7: =O7 -> 1 | Q7: =VLOOKUP(L7,'280'!A:T,18,0) -> 李晏然 | R7: =VLOOKUP(L7,'280'!A:T,19,0) -> 游文圃 | S7: =VLOOKUP(L7,'280'!A:T,20,0) -> 康祐銓
B8: 結構用混凝土，預拌，280kgf/cm2 | D8: =M7&M8 -> 0 M3 | F8: =E7&CHAR(10)&"("&O7&O8&")" -> 0 M3 (1組) | H8: =H7&CHAR(10)&"("&P7&O8&")" -> 0 M3 (1組) | M8: M3 | O8: 組
A9: ="1-280 -"&L9 -> 1-280 -2 | B9: 1.4.3 | C9: 709.04 M3 | D9: =VLOOKUP(L9,'280'!A:T,2,0) -> 45563 | E9: =M9&M10 -> 72 M3 | F9: =D9 -> 45563 | H9: =N9&M10 -> 72 M3 | I9: 合格 | J9: =IF(R9=0,"上 溢："&S9,IF(Q9=0,"任 泰："&R9&" "&"上 溢："&S9, "水利處："&Q9&" "&"任 泰："&R9&" "&"上 溢："&S9)) -> 任 泰：陳勇智 上 溢：李建豪 | K9: 113年12月17日 113任泰顧字 第1131217624號 | L9: =L7+1 -> 2 | M9: =VLOOKUP(L9,'280'!A:T,5,0) -> 72 | N9: =N7+M9 -> 72 | O9: =VLOOKUP(L9,'280'!A:T,6,0) -> 1 | P9: =P7+O9 -> 2 | Q9: =VLOOKUP(L9,'280'!A:T,18,0) -> 0 | R9: =VLOOKUP(L9,'280'!A:T,19,0) -> 陳勇智 | S9: =VLOOKUP(L9,'280'!A:T,20,0) -> 李建豪
B10: 結構用混凝土，預拌，280kgf/cm2 | D10: =M9&M10 -> 72 M3 | F10: =E9&CHAR(10)&"("&O9&O10&")" -> 72 M3 (1組) | H10: =H9&CHAR(10)&"("&P9&O10&")" -> 72 M3 (2組) | M10: M3 | O10: 組
A11: ="1-280 -"&L11 -> 1-280 -3 | B11: 1.4.3 | C11: 709.04 M3 | D11: =VLOOKUP(L11,'280'!A:T,2,0) -> 45584 | E11: =M11&M12 -> 35 M3 | F11: =D11 -> 45584 | H11: =N11&M12 -> 107 M3 | I11: 合格 | J11: =IF(R11=0,"上 溢："&S11,IF(Q11=0,"任 泰："&R11&" "&"上 溢："&S11, "水利處："&Q11&" "&"任 泰："&R11&" "&"上 溢："&S11)) -> 任 泰：陳勇智 上 溢：李建豪 | K11: 113年12月18日 113任泰顧字 第1131218625號 | L11: =L9+1 -> 3 | M11: =VLOOKUP(L11,'280'!A:T,5,0) -> 35 | N11: =N9+M11 -> 107 | O11: =VLOOKUP(L11,'280'!A:T,6,0) -> 1 | P11: =P9+O11 -> 3 | Q11: =VLOOKUP(L11,'280'!A:T,18,0) -> 0 | R11: =VLOOKUP(L11,'280'!A:T,19,0) -> 陳勇智 | S11: =VLOOKUP(L11,'280'!A:T,20,0) -> 李建豪
B12: 結構用混凝土，預拌，280kgf/cm2 | D12: =M11&M12 -> 35 M3 | F12: =E11&CHAR(10)&"("&O11&O12&")" -> 35 M3 (1組) | H12: =H11&CHAR(10)&"("&P11&O12&")" -> 107 M3 (3組) | M12: M3 | O12: 組
A13: ="1-280 -"&L13 -> 1-280 -4 | B13: 1.4.3 | C13: 709.04 M3 | D13: =VLOOKUP(L13,'280'!A:T,2,0) -> 45649 | E13: =M13&M14 -> 8 M3 | F13: =D13 -> 45649 | H13: =N13&M14 -> 115 M3 | I13: - | J13: =IF(R13=0,"上 溢："&S13,IF(Q13=0,"任 泰："&R13&" "&"上 溢："&S13, "水利處："&Q13&" "&"任 泰："&R13&" "&"上 溢："&S13)) -> 上 溢：周昱辰 | K13: 本次澆置數量 未達20M3 免取樣 | L13: =L11+1 -> 4 | M13: =VLOOKUP(L13,'280'!A:T,5,0) -> 8 | N13: =N11+M13 -> 115 | O13: =VLOOKUP(L13,'280'!A:T,6,0) -> 0 | P13: =P11+O13 -> 3 | Q13: =VLOOKUP(L13,'280'!A:T,18,0) -> 0 | R13: =VLOOKUP(L13,'280'!A:T,19,0) -> 0 | S13: =VLOOKUP(L13,'280'!A:T,20,0) -> 周昱辰
B14: 結構用混凝土，預拌，280kgf/cm2 | D14: =M13&M14 -> 8 M3 | F14: =E13&CHAR(10)&"("&O13&O14&")" -> 8 M3 (0組) | H14: =H13&CHAR(10)&"("&P13&O14&")" -> 115 M3 (3組) | K14: EF-1131226 混凝土 自主檢查表 | M14: M3 | O14: 組
L16: =L13+1 -> 5 | M16: =VLOOKUP(L16,'280'!A:T,5,0) -> #N/A | N16: =#REF!+M16 -> #REF! | O16: =VLOOKUP(L16,'280'!A:T,6,0) -> #N/A | P16: =#REF!+O16 -> #REF! | Q16: =VLOOKUP(L16,'280'!A:T,18,0) -> #N/A | R16: =VLOOKUP(L16,'280'!A:T,19,0) -> #N/A | S16: =VLOOKUP(L16,'280'!A:T,20,0) -> #N/A
A17: 編制： | D17: 工地主任： | H17: 附註：
A18: 1.本表於施工期間監造單位依契約約定之「材料、設備送審文件、樣品一覽表」分類登錄，俾利控管材料檢驗使用情形。 2.監造單位應依監造計畫之材料設備抽驗程序及標準辦理材料設備抽驗，如有單項材料設備廠商自主檢查頻率未達 3次時，廠商在辦理自主檢查取樣前，應通知監造單位轉知考工單位會同廠商辦理抽驗（即前2次均由本處派員抽驗）。 3.本表規定檢驗頻率請依據工程契約或施工規範約定填寫。
A26: 註：1.本表單於開工後應由廠商檢討提出預定進場日期，並由監造單位會同廠商定期檢討辦理情形。 2.材料或設備之現場抽樣檢驗項目(例如：外觀、尺度、型號、運轉功能等)，及抽樣送實驗室試驗項目(例如：混凝土高壓磚 抗壓強度、鋼筋抗拉強度及化學性質等)均應納入本表管制。 3.本表單格式僅提供參考，使用單位可依個別需要調整。

Sheet 5-1.420
A1: 臺北市政府工務局水利工程處
A2: 材料設備檢（試）驗管制總表
A3: ="工程名稱:"&'1.計畫'!A1:I1 -> 工程名稱:磺港溪再造C段護岸及步道整建工程（延壽橋至三合橋） | H3: 契約編號：H-111-03-112080
A4: 監造單位：任泰技術顧問有限公司 | H4: 施工廠商：上溢營造份有限公司
A5: 項次 | B5: 契約詳細表項次 | C5: 契約 數量 | D5: 進場 日期 | E5: 進場 數量 | F5: 抽樣 日期 | G5: 規定抽（取）樣頻率 | H5: 累積進場數量 | I5: 抽試驗結果 | J5: 抽驗及會同人員 | K5: 備註
B6: 材料(設備)名稱 | D6: 進場 數量 | F6: 抽樣 數量 | H6: 累積抽樣數量 | K6: (歸檔編號) | M6: 數量 | N6: 累計數量 | O6: 組數 | P6: 累計組數 | Q6: 水利處 | R6: 監造 | S6: 廠商
A7: ="1-420-"&L7 -> 1-420-1 | B7: - | C7: 0 M3 | D7: =VLOOKUP(L7,'420'!A:T,2,0) -> 45609 | E7: =M7&M8 -> 2 M3 | F7: =D7 -> 45609 | G7: 每日澆置量在1m3以下時取樣1次，每增加1m3增加取樣1次，每次必須取3個試體。 | H7: =N7&M8 -> 2 M3 | I7: 合格 | J7: =IF(R7=0,"上 溢："&S7,IF(Q7=0,"任 泰："&R7&" "&"上 溢："&S7, "水利處："&Q7&" "&"任 泰："&R7&" "&"上 溢："&S7)) -> 水利處：李晏然 任 泰：王淑慧 上 溢：張志禕 | K7: 114年2月19日 任泰顧字 第1140219627號 | L7: 1 | M7: =VLOOKUP(L7,'420'!A:T,5,0) -> 2 | N7: =M7 -> 2 | O7: =VLOOKUP(L7,'420'!A:T,6,0) -> 2 | P7: =O7 -> 2 | Q7: =VLOOKUP(L7,'420'!A:T,18,0) -> 李晏然 | R7: =VLOOKUP(L7,'420'!A:T,19,0) -> 王淑慧 | S7: =VLOOKUP(L7,'420'!A:T,20,0) -> 張志禕
B8: 無收縮混凝土，抗壓強度420 kgf/cm2 | D8: =M7&M8 -> 2 M3 | F8: =E7&CHAR(10)&"("&O7&O8&")" -> 2 M3 (2組) | H8: =H7&CHAR(10)&"("&P7&O8&")" -> 2 M3 (2組) | M8: M3 | O8: 組
A9: ="1-420-"&L9 -> 1-420-2 | B9: - | C9: 0 M3 | D9: =VLOOKUP(L9,'420'!A:T,2,0) -> 45609 | E9: =M9&M10 -> 11 M3 | F9: =D9 -> 45609 | H9: =N9&M10 -> 13 M3 | I9: 合格 | J9: =IF(R9=0,"上 溢："&S9,IF(Q9=0,"任 泰："&R9&" "&"上 溢："&S9, "水利處："&Q9&" "&"任 泰："&R9&" "&"上 溢："&S9)) -> 任 泰：王淑慧 上 溢：張志禕 | K9: 114年2月19日 任泰顧字 第1140219626號 | L9: =L7+1 -> 2 | M9: =VLOOKUP(L9,'420'!A:T,5,0) -> 11 | N9: =N7+M9 -> 13 | O9: =VLOOKUP(L9,'420'!A:T,6,0) -> 11 | P9: =P7+O9 -> 13 | Q9: =VLOOKUP(L9,'420'!A:T,18,0) -> 0 | R9: =VLOOKUP(L9,'420'!A:T,19,0) -> 王淑慧 | S9: =VLOOKUP(L9,'420'!A:T,20,0) -> 張志禕
B10: 無收縮混凝土，抗壓強度420 kgf/cm2 | D10: =M9&M10 -> 11 M3 | F10: =E9&CHAR(10)&"("&O9&O10&")" -> 11 M3 (11組) | H10: =H9&CHAR(10)&"("&P9&O10&")" -> 13 M3 (13組) | M10: M3 | O10: 組
A11: 編制： | D11: 工地主任： | H11: 附註：
A12: 1.本表於施工期間監造單位依契約約定之「材料、設備送審文件、樣品一覽表」分類登錄，俾利控管材料檢驗使用情形。 2.監造單位應依監造計畫之材料設備抽驗程序及標準辦理材料設備抽驗，如有單項材料設備廠商自主檢查頻率未達 3次時，廠商在辦理自主檢查取樣前，應通知監造單位轉知考工單位會同廠商辦理抽驗（即前2次均由本處派員抽驗）。 3.本表規定檢驗頻率請依據工程契約或施工規範約定填寫。
A30: 註：1.本表單於開工後應由廠商檢討提出預定進場日期，並由監造單位會同廠商定期檢討辦理情形。 2.材料或設備之現場抽樣檢驗項目(例如：外觀、尺度、型號、運轉功能等)，及抽樣送實驗室試驗項目(例如：混凝土高壓磚 抗壓強度、鋼筋抗拉強度及化學性質等)均應納入本表管制。 3.本表單格式僅提供參考，使用單位可依個別需要調整。

Sheet 5-1.試驗280W
A1: 臺北市政府工務局水利工程處
A2: 材料設備檢（試）驗管制總表
A3: ="工程名稱:"&'1.計畫'!A1:I1 -> 工程名稱:磺港溪再造C段護岸及步道整建工程（延壽橋至三合橋） | H3: 契約編號：H-111-03-112080
A4: 監造單位：任泰技術顧問有限公司 | H4: 施工廠商：上溢營造份有限公司
A5: 項次 | B5: 契約詳細表項次 | C5: 契約 數量 | D5: 進場 日期 | E5: 進場 數量 | F5: 抽樣 日期 | G5: 規定抽（取）樣頻率 | H5: 累積進場數量 | I5: 抽試驗結果 | J5: 抽驗及會同人員 | K5: 備註
B6: 材料(設備)名稱 | D6: 進場 數量 | F6: 抽樣 數量 | H6: 累積抽樣數量 | K6: (歸檔編號) | M6: 數量 | N6: 累計數量 | O6: 組數 | P6: 累計組數 | Q6: 水利處 | R6: 監造 | S6: 廠商
A7: ="1-280W-"&L7 -> 1-280W-1 | B7: 1.3.20 | C7: 883.62 M3 | D7: =VLOOKUP(L7,'280W'!A:T,2,0) -> 45181 | E7: =M7&M8 -> 0 M3 | F7: =D7 -> 45181 | G7: 1.每批次數量未達20 m3時，免檢驗。 2.每批次數量達20～100 m3檢驗1組。 3.每批次數量超過100 m3時，每100 m3加驗1組，餘數未達100m³亦加驗1組。 | H7: =N7&M8 -> 0 M3 | I7: 合格 | J7: =IF(R7=0,"上 溢："&S7,IF(Q7=0,"任 泰："&R7&" "&"上 溢："&S7, "水利處："&Q7&" "&"任 泰："&R7&" "&"上 溢："&S7)) -> 水利處：李晏然 任 泰：游文圃 上 溢：康祐銓 | K7: 112年11月10日 112任泰顧字 第1110010001號 | L7: 1 | M7: =VLOOKUP(L7,'280W'!A:T,5,0) -> 0 | N7: =M7 -> 0 | O7: =VLOOKUP(L7,'280W'!A:T,6,0) -> 1 | P7: =O7 -> 1 | Q7: =VLOOKUP(L7,'280W'!A:T,18,0) -> 李晏然 | R7: =VLOOKUP(L7,'280W'!A:T,19,0) -> 游文圃 | S7: =VLOOKUP(L7,'280W'!A:T,20,0) -> 康祐銓
B8: 結構用混凝土，(預拌，水中)，280kgf/cm2 | D8: =M7&M8 -> 0 M3 | F8: =E7&CHAR(10)&"("&O7&O8&")" -> 0 M3 (1組) | H8: =H7&CHAR(10)&"("&P7&O8&")" -> 0 M3 (1組) | M8: M3 | O8: 組
A9: ="1-280W-"&L9 -> 1-280W-2 | B9: 1.3.20 | C9: 883.62 M3 | D9: =VLOOKUP(L9,'280W'!A:T,2,0) -> 45289 | E9: =M9&M10 -> 58 M3 | F9: =D9 -> 45289 | H9: =N9&M10 -> 58 M3 | I9: 合格 | J9: =IF(R9=0,"上 溢："&S9,IF(Q9=0,"任 泰："&R9&" "&"上 溢："&S9, "水利處："&Q9&" "&"任 泰："&R9&" "&"上 溢："&S9)) -> 任 泰：游文圃 上 溢：康祐銓 | K9: 113年3月4日 113任泰顧字 第0304010010號 | L9: =L7+1 -> 2 | M9: =VLOOKUP(L9,'280W'!A:T,5,0) -> 58 | N9: =N7+M9 -> 58 | O9: =VLOOKUP(L9,'280W'!A:T,6,0) -> 1 | P9: =P7+O9 -> 2 | Q9: =VLOOKUP(L9,'280W'!A:T,18,0) -> 0 | R9: =VLOOKUP(L9,'280W'!A:T,19,0) -> 游文圃 | S9: =VLOOKUP(L9,'280W'!A:T,20,0) -> 康祐銓
B10: 結構用混凝土，(預拌，水中)，280kgf/cm2 | D10: =M9&M10 -> 58 M3 | F10: =E9&CHAR(10)&"("&O9&O10&")" -> 58 M3 (1組) | H10: =H9&CHAR(10)&"("&P9&O10&")" -> 58 M3 (2組) | M10: M3 | O10: 組
A11: ="1-280W-"&L11 -> 1-280W-3 | B11: 1.3.20 | C11: 883.62 M3 | D11: =VLOOKUP(L11,'280W'!A:T,2,0) -> 45296 | E11: =M11&M12 -> 58 M3 | F11: =D11 -> 45296 | H11: =N11&M12 -> 116 M3 | I11: 合格 | J11: =IF(R11=0,"上 溢："&S11,IF(Q11=0,"任 泰："&R11&" "&"上 溢："&S11, "水利處："&Q11&" "&"任 泰："&R11&" "&"上 溢："&S11)) -> 任 泰：游文圃 上 溢：康祐銓 | K11: 113年3月6日 113任泰顧字 第0306010010號 | L11: =L9+1 -> 3 | M11: =VLOOKUP(L11,'280W'!A:T,5,0) -> 58 | N11: =N9+M11 -> 116 | O11: =VLOOKUP(L11,'280W'!A:T,6,0) -> 1 | P11: =P9+O11 -> 3 | Q11: =VLOOKUP(L11,'280W'!A:T,18,0) -> 0 | R11: =VLOOKUP(L11,'280W'!A:T,19,0) -> 游文圃 | S11: =VLOOKUP(L11,'280W'!A:T,20,0) -> 康祐銓
B12: 結構用混凝土，(預拌，水中)，280kgf/cm2 | D12: =M11&M12 -> 58 M3 | F12: =E11&CHAR(10)&"("&O11&O12&")" -> 58 M3 (1組) | H12: =H11&CHAR(10)&"("&P11&O12&")" -> 116 M3 (3組) | M12: M3 | O12: 組
A13: ="1-280W-"&L13 -> 1-280W-4 | B13: 1.3.20 | C13: 883.62 M3 | D13: =VLOOKUP(L13,'280W'!A:T,2,0) -> 45300 | E13: =M13&M14 -> 58 M3 | F13: =D13 -> 45300 | H13: =N13&M14 -> 174 M3 | I13: 合格 | J13: =IF(R13=0,"上 溢："&S13,IF(Q13=0,"任 泰："&R13&" "&"上 溢："&S13, "水利處："&Q13&" "&"任 泰："&R13&" "&"上 溢："&S13)) -> 任 泰：游文圃 上 溢：郭冠廷 | K13: 113年3月7日 113任泰顧字 第0307010010號 | L13: =L11+1 -> 4 | M13: =VLOOKUP(L13,'280W'!A:T,5,0) -> 58 | N13: =N11+M13 -> 174 | O13: =VLOOKUP(L13,'280W'!A:T,6,0) -> 1 | P13: =P11+O13 -> 4 | Q13: =VLOOKUP(L13,'280W'!A:T,18,0) -> 0 | R13: =VLOOKUP(L13,'280W'!A:T,19,0) -> 游文圃 | S13: =VLOOKUP(L13,'280W'!A:T,20,0) -> 郭冠廷
B14: 結構用混凝土，(預拌，水中)，280kgf/cm2 | D14: =M13&M14 -> 58 M3 | F14: =E13&CHAR(10)&"("&O13&O14&")" -> 58 M3 (1組) | H14: =H13&CHAR(10)&"("&P13&O14&")" -> 174 M3 (4組) | M14: M3 | O14: 組
A15: ="1-280W-"&L15 -> 1-280W-5 | B15: 1.3.20 | C15: 883.62 M3 | D15: =VLOOKUP(L15,'280W'!A:T,2,0) -> 45303 | E15: =M15&M16 -> 58 M3 | F15: =D15 -> 45303 | H15: =N15&M16 -> 232 M3 | I15: 合格 | J15: =IF(R15=0,"上 溢："&S15,IF(Q15=0,"任 泰："&R15&" "&"上 溢："&S15, "水利處："&Q15&" "&"任 泰："&R15&" "&"上 溢："&S15)) -> 水利處：李晏然 任 泰：游文圃 上 溢：郭冠廷 | K15: 113年3月7日 113任泰顧字 第0308010010號 | L15: =L13+1 -> 5 | M15: =VLOOKUP(L15,'280W'!A:T,5,0) -> 58 | N15: =N13+M15 -> 232 | O15: =VLOOKUP(L15,'280W'!A:T,6,0) -> 1 | P15: =P13+O15 -> 5 | Q15: =VLOOKUP(L15,'280W'!A:T,18,0) -> 李晏然 | R15: =VLOOKUP(L15,'280W'!A:T,19,0) -> 游文圃 | S15: =VLOOKUP(L15,'280W'!A:T,20,0) -> 郭冠廷
B16: 結構用混凝土，(預拌，水中)，280kgf/cm2 | D16: =M15&M16 -> 58 M3 | F16: =E15&CHAR(10)&"("&O15&O16&")" -> 58 M3 (1組) | H16: =H15&CHAR(10)&"("&P15&O16&")" -> 232 M3 (5組) | M16: M3 | O16: 組
A17: 編制： | D17: 工地主任： | H17: 附註：
A18: 1.本表於施工期間監造單位依契約約定之「材料、設備送審文件、樣品一覽表」分類登錄，俾利控管材料檢驗使用情形。 2.監造單位應依監造計畫之材料設備抽驗程序及標準辦理材料設備抽驗，如有單項材料設備廠商自主檢查頻率未達 3次時，廠商在辦理自主檢查取樣前，應通知監造單位轉知考工單位會同廠商辦理抽驗（即前2次均由本處派員抽驗）。 3.本表規定檢驗頻率請依據工程契約或施工規範約定填寫。
A19: ="1-280W-"&L19 -> 1-280W-6 | B19: 1.3.20 | C19: 883.62 M3 | D19: =VLOOKUP(L19,'280W'!A:T,2,0) -> 45309 | E19: =M19&M20 -> 58 M3 | F19: =D19 -> 45309 | G19: 1.每批次數量未達20 m3時，免檢驗。 2.每批次數量達20～100 m3檢驗1組。 3.每批次數量超過100 m3時，每100 m3加驗1組，餘數未達100m³亦加驗1組。 | H19: =N19&M20 -> 290 M3 | I19: 合格 | J19: =IF(R19=0,"上 溢："&S19,IF(Q19=0,"任 泰："&R19&" "&"上 溢："&S19, "水利處："&Q19&" "&"任 泰："&R19&" "&"上 溢："&S19)) -> 任 泰：游文圃 上 溢：郭冠廷 | K19: 113年3月7日 113任泰顧字 第0311010010號 | L19: =L15+1 -> 6 | M19: =VLOOKUP(L19,'280W'!A:T,5,0) -> 58 | N19: =N15+M19 -> 290 | O19: =VLOOKUP(L19,'280W'!A:T,6,0) -> 1 | P19: =P15+O19 -> 6 | Q19: =VLOOKUP(L19,'280W'!A:T,18,0) -> 0 | R19: =VLOOKUP(L19,'280W'!A:T,19,0) -> 游文圃 | S19: =VLOOKUP(L19,'280W'!A:T,20,0) -> 郭冠廷
B20: 結構用混凝土，(預拌，水中)，280kgf/cm2 | D20: =M19&M20 -> 58 M3 | F20: =E19&CHAR(10)&"("&O19&O20&")" -> 58 M3 (1組) | H20: =H19&CHAR(10)&"("&P19&O20&")" -> 290 M3 (6組) | M20: M3 | O20: 組
A21: ="1-280W-"&L21 -> 1-280W-7 | B21: 1.3.20 | C21: 883.62 M3 | D21: =VLOOKUP(L21,'280W'!A:T,2,0) -> 45311 | E21: =M21&M22 -> 58 M3 | F21: =D21 -> 45311 | H21: =N21&M22 -> 348 M3 | I21: 合格 | J21: =IF(R21=0,"上 溢："&S21,IF(Q21=0,"任 泰："&R21&" "&"上 溢："&S21, "水利處："&Q21&" "&"任 泰："&R21&" "&"上 溢："&S21)) -> 任 泰：白博文 上 溢：郭冠廷 | K21: 113年3月12日 113任泰顧字 第1130312021號 | L21: =L19+1 -> 7 | M21: =VLOOKUP(L21,'280W'!A:T,5,0) -> 58 | N21: =N19+M21 -> 348 | O21: =VLOOKUP(L21,'280W'!A:T,6,0) -> 1 | P21: =P19+O21 -> 7 | Q21: =VLOOKUP(L21,'280W'!A:T,18,0) -> 0 | R21: =VLOOKUP(L21,'280W'!A:T,19,0) -> 白博文 | S21: =VLOOKUP(L21,'280W'!A:T,20,0) -> 郭冠廷
B22: 結構用混凝土，(預拌，水中)，280kgf/cm2 | D22: =M21&M22 -> 58 M3 | F22: =E21&CHAR(10)&"("&O21&O22&")" -> 58 M3 (1組) | H22: =H21&CHAR(10)&"("&P21&O22&")" -> 348 M3 (7組) | M22: M3 | O22: 組
A23: ="1-280W-"&L23 -> 1-280W-8 | B23: 1.3.20 | C23: 883.62 M3 | D23: =VLOOKUP(L23,'280W'!A:T,2,0) -> 45314 | E23: =M23&M24 -> 58 M3 | F23: =D23 -> 45314 | H23: =N23&M24 -> 406 M3 | I23: 合格 | J23: =IF(R23=0,"上 溢："&S23,IF(Q23=0,"任 泰："&R23&" "&"上 溢："&S23, "水利處："&Q23&" "&"任 泰："&R23&" "&"上 溢："&S23)) -> 任 泰：白博文 上 溢：郭冠廷 | K23: 113年3月20日 113任泰顧字 第0320010010號 | L23: =L21+1 -> 8 | M23: =VLOOKUP(L23,'280W'!A:T,5,0) -> 58 | N23: =N21+M23 -> 406 | O23: =VLOOKUP(L23,'280W'!A:T,6,0) -> 1 | P23: =P21+O23 -> 8 | Q23: =VLOOKUP(L23,'280W'!A:T,18,0) -> 0 | R23: =VLOOKUP(L23,'280W'!A:T,19,0) -> 白博文 | S23: =VLOOKUP(L23,'280W'!A:T,20,0) -> 郭冠廷
B24: 結構用混凝土，(預拌，水中)，280kgf/cm2 | D24: =M23&M24 -> 58 M3 | F24: =E23&CHAR(10)&"("&O23&O24&")" -> 58 M3 (1組) | H24: =H23&CHAR(10)&"("&P23&O24&")" -> 406 M3 (8組) | M24: M3 | O24: 組
