Workbook

Sheet 統計表
B1: 測量放樣 | C1: 土方開挖 | D1: 土方回填(含級配) | E1: 鋼筋工程 | F1: 模板工程 | G1: 混凝土工程 | H1: 植筋工程 | I1: 預力混凝土基樁 | J1: 砌塊石護岸 | K1: 低水護岸 | L1: 固床工 | M1: 全套管基樁 | N1: 鋼筋混凝土管 | O1: 鋼版樁 | P1: 路床/路基高程 | Q1: 瀝青混凝土 | R1: 景觀鋪面(一) | S1: 景觀鋪面(二) | T1: 預鑄緣石 | U1: 鋼構工程吊裝 | V1: 鋼構工程塗裝 | W1: 排水設施(一) | X1: 排水設施(二) | Y1: 木構造 | Z1: 管路 | AA1: 植栽(移植) | AB1: 植栽(新植) | AC1: 照明 | AD1: 既有橋梁拆除
A2: 45192 | B2: =IF(IFERROR(VLOOKUP(A2,'1.測量放樣'!C:D,1,0),"")="","","✔") | C2: =IF(IFERROR(VLOOKUP(A2,'2.土方開挖'!C:D,1,0),"")="","","✔") | D2: =IF(IFERROR(VLOOKUP(A2,'3.土方回填'!C:D,1,0),"")="","","✔") | E2: =IF(IFERROR(VLOOKUP(A2,'4.鋼筋'!C:D,1,0),"")="","","✔") | F2: =IF(IFERROR(VLOOKUP(A2,'5.模板'!C:D,1,0),"")="","","✔") | G2: =IF(IFERROR(VLOOKUP(A2,'6.混凝土'!C:D,1,0),"")="","","✔") | H2: =IF(IFERROR(VLOOKUP(A2,'7.植筋'!C:D,1,0),"")="","","✔") | I2: =IF(IFERROR(VLOOKUP(A2,'8.預力混凝土基樁'!C:D,1,0),"")="","","✔") | J2: =IF(IFERROR(VLOOKUP(A2,'9.砌塊石護岸'!C:D,1,0),"")="","","✔") | K2: =IF(IFERROR(VLOOKUP(A2,'10.低水護岸'!C:D,1,0),"")="","","✔") | L2: =IF(IFERROR(VLOOKUP(A2,'11.固床工'!C:D,1,0),"")="","","✔") | M2: =IF(IFERROR(VLOOKUP(A2,'12.全套管基樁'!C:D,1,0),"")="","","✔") | N2: =IF(IFERROR(VLOOKUP(A2,'13.鋼筋混凝土管工程'!C:D,1,0),"")="","","✔") | O2: =IF(IFERROR(VLOOKUP(A2,'14.鋼版樁'!C:D,1,0),"")="","","✔") | P2: =IF(IFERROR(VLOOKUP(A2,'15.路床 路基高程'!C:D,1,0),"")="","","✔") | Q2: =IF(IFERROR(VLOOKUP(A2,'16.瀝青混凝土'!C:D,1,0),"")="","","✔") | R2: =IF(IFERROR(VLOOKUP(A2,'17.景觀鋪面(一)'!C:D,1,0),"")="","","✔") | S2: =IF(IFERROR(VLOOKUP(A2,'18.景觀鋪面(二)'!C:D,1,0),"")="","","✔") | T2: =IF(IFERROR(VLOOKUP(A2,'19.預鑄緣石'!C:D,1,0),"")="","","✔") | U2: =IF(IFERROR(VLOOKUP(A2,'20.鋼構工程吊裝'!C:D,1,0),"")="","","✔") | V2: =IF(IFERROR(VLOOKUP(A2,'21.鋼構工程塗裝'!C:D,1,0),"")="","","✔") | W2: =IF(IFERROR(VLOOKUP(A2,'22.排水設施(一)'!C:D,1,0),"")="","","✔") | X2: =IF(IFERROR(VLOOKUP(A2,'23.排水設施(二)'!C:D,1,0),"")="","","✔") | Y2: =IF(IFERROR(VLOOKUP(A2,'24.木構造'!C:D,1,0),"")="","","✔") | Z2: =IF(IFERROR(VLOOKUP(A2,'25.管路'!C:D,1,0),"")="","","✔") | AA2: =IF(IFERROR(VLOOKUP(A2,'26.植栽(移植)'!C:D,1,0),"")="","","✔") -> ✔ | AB2: =IF(IFERROR(VLOOKUP(A2,'27.植栽(新植)'!C:D,1,0),"")="","","✔") | AC2: =IF(IFERROR(VLOOKUP(A2,'28.照明'!C:D,1,0),"")="","","✔") | AD2: =IF(IFERROR(VLOOKUP(A2,'29.既有橋梁拆除'!C:D,1,0),"")="","","✔")
A3: 45193 | B3: =IF(IFERROR(VLOOKUP(A3,'1.測量放樣'!C:D,1,0),"")="","","✔") | C3: =IF(IFERROR(VLOOKUP(A3,'2.土方開挖'!C:D,1,0),"")="","","✔") | D3: =IF(IFERROR(VLOOKUP(A3,'3.土方回填'!C:D,1,0),"")="","","✔") | E3: =IF(IFERROR(VLOOKUP(A3,'4.鋼筋'!C:D,1,0),"")="","","✔") | F3: =IF(IFERROR(VLOOKUP(A3,'5.模板'!C:D,1,0),"")="","","✔") | G3: =IF(IFERROR(VLOOKUP(A3,'6.混凝土'!C:D,1,0),"")="","","✔") | H3: =IF(IFERROR(VLOOKUP(A3,'7.植筋'!C:D,1,0),"")="","","✔") | I3: =IF(IFERROR(VLOOKUP(A3,'8.預力混凝土基樁'!C:D,1,0),"")="","","✔") | J3: =IF(IFERROR(VLOOKUP(A3,'9.砌塊石護岸'!C:D,1,0),"")="","","✔") | K3: =IF(IFERROR(VLOOKUP(A3,'10.低水護岸'!C:D,1,0),"")="","","✔") | L3: =IF(IFERROR(VLOOKUP(A3,'11.固床工'!C:D,1,0),"")="","","✔") | M3: =IF(IFERROR(VLOOKUP(A3,'12.全套管基樁'!C:D,1,0),"")="","","✔") | N3: =IF(IFERROR(VLOOKUP(A3,'13.鋼筋混凝土管工程'!C:D,1,0),"")="","","✔") | O3: =IF(IFERROR(VLOOKUP(A3,'14.鋼版樁'!C:D,1,0),"")="","","✔") | P3: =IF(IFERROR(VLOOKUP(A3,'15.路床 路基高程'!C:D,1,0),"")="","","✔") | Q3: =IF(IFERROR(VLOOKUP(A3,'16.瀝青混凝土'!C:D,1,0),"")="","","✔") | R3: =IF(IFERROR(VLOOKUP(A3,'17.景觀鋪面(一)'!C:D,1,0),"")="","","✔") | S3: =IF(IFERROR(VLOOKUP(A3,'18.景觀鋪面(二)'!C:D,1,0),"")="","","✔") | T3: =IF(IFERROR(VLOOKUP(A3,'19.預鑄緣石'!C:D,1,0),"")="","","✔") | U3: =IF(IFERROR(VLOOKUP(A3,'20.鋼構工程吊裝'!C:D,1,0),"")="","","✔") | V3: =IF(IFERROR(VLOOKUP(A3,'21.鋼構工程塗裝'!C:D,1,0),"")="","","✔") | W3: =IF(IFERROR(VLOOKUP(A3,'22.排水設施(一)'!C:D,1,0),"")="","","✔") | X3: =IF(IFERROR(VLOOKUP(A3,'23.排水設施(二)'!C:D,1,0),"")="","","✔") | Y3: =IF(IFERROR(VLOOKUP(A3,'24.木構造'!C:D,1,0),"")="","","✔") | Z3: =IF(IFERROR(VLOOKUP(A3,'25.管路'!C:D,1,0),"")="","","✔") | AA3: =IF(IFERROR(VLOOKUP(A3,'26.植栽(移植)'!C:D,1,0),"")="","","✔") | AB3: =IF(IFERROR(VLOOKUP(A3,'27.植栽(新植)'!C:D,1,0),"")="","","✔") | AC3: =IF(IFERROR(VLOOKUP(A3,'28.照明'!C:D,1,0),"")="","","✔") | AD3: =IF(IFERROR(VLOOKUP(A3,'29.既有橋梁拆除'!C:D,1,0),"")="","","✔")
A4: 45194 | B4: =IF(IFERROR(VLOOKUP(A4,'1.測量放樣'!C:D,1,0),"")="","","✔") | C4: =IF(IFERROR(VLOOKUP(A4,'2.土方開挖'!C:D,1,0),"")="","","✔") | D4: =IF(IFERROR(VLOOKUP(A4,'3.土方回填'!C:D,1,0),"")="","","✔") | E4: =IF(IFERROR(VLOOKUP(A4,'4.鋼筋'!C:D,1,0),"")="","","✔") | F4: =IF(IFERROR(VLOOKUP(A4,'5.模板'!C:D,1,0),"")="","","✔") | G4: =IF(IFERROR(VLOOKUP(A4,'6.混凝土'!C:D,1,0),"")="","","✔") | H4: =IF(IFERROR(VLOOKUP(A4,'7.植筋'!C:D,1,0),"")="","","✔") | I4: =IF(IFERROR(VLOOKUP(A4,'8.預力混凝土基樁'!C:D,1,0),"")="","","✔") | J4: =IF(IFERROR(VLOOKUP(A4,'9.砌塊石護岸'!C:D,1,0),"")="","","✔") | K4: =IF(IFERROR(VLOOKUP(A4,'10.低水護岸'!C:D,1,0),"")="","","✔") | L4: =IF(IFERROR(VLOOKUP(A4,'11.固床工'!C:D,1,0),"")="","","✔") | M4: =IF(IFERROR(VLOOKUP(A4,'12.全套管基樁'!C:D,1,0),"")="","","✔") | N4: =IF(IFERROR(VLOOKUP(A4,'13.鋼筋混凝土管工程'!C:D,1,0),"")="","","✔") | O4: =IF(IFERROR(VLOOKUP(A4,'14.鋼版樁'!C:D,1,0),"")="","","✔") | P4: =IF(IFERROR(VLOOKUP(A4,'15.路床 路基高程'!C:D,1,0),"")="","","✔") | Q4: =IF(IFERROR(VLOOKUP(A4,'16.瀝青混凝土'!C:D,1,0),"")="","","✔") | R4: =IF(IFERROR(VLOOKUP(A4,'17.景觀鋪面(一)'!C:D,1,0),"")="","","✔") | S4: =IF(IFERROR(VLOOKUP(A4,'18.景觀鋪面(二)'!C:D,1,0),"")="","","✔") | T4: =IF(IFERROR(VLOOKUP(A4,'19.預鑄緣石'!C:D,1,0),"")="","","✔") | U4: =IF(IFERROR(VLOOKUP(A4,'20.鋼構工程吊裝'!C:D,1,0),"")="","","✔") | V4: =IF(IFERROR(VLOOKUP(A4,'21.鋼構工程塗裝'!C:D,1,0),"")="","","✔") | W4: =IF(IFERROR(VLOOKUP(A4,'22.排水設施(一)'!C:D,1,0),"")="","","✔") | X4: =IF(IFERROR(VLOOKUP(A4,'23.排水設施(二)'!C:D,1,0),"")="","","✔") | Y4: =IF(IFERROR(VLOOKUP(A4,'24.木構造'!C:D,1,0),"")="","","✔") | Z4: =IF(IFERROR(VLOOKUP(A4,'25.管路'!C:D,1,0),"")="","","✔") | AA4: =IF(IFERROR(VLOOKUP(A4,'26.植栽(移植)'!C:D,1,0),"")="","","✔") -> ✔ | AB4: =IF(IFERROR(VLOOKUP(A4,'27.植栽(新植)'!C:D,1,0),"")="","","✔") | AC4: =IF(IFERROR(VLOOKUP(A4,'28.照明'!C:D,1,0),"")="","","✔") | AD4: =IF(IFERROR(VLOOKUP(A4,'29.既有橋梁拆除'!C:D,1,0),"")="","","✔")
A5: 45195 | B5: =IF(IFERROR(VLOOKUP(A5,'1.測量放樣'!C:D,1,0),"")="","","✔") | C5: =IF(IFERROR(VLOOKUP(A5,'2.土方開挖'!C:D,1,0),"")="","","✔") | D5: =IF(IFERROR(VLOOKUP(A5,'3.土方回填'!C:D,1,0),"")="","","✔") | E5: =IF(IFERROR(VLOOKUP(A5,'4.鋼筋'!C:D,1,0),"")="","","✔") | F5: =IF(IFERROR(VLOOKUP(A5,'5.模板'!C:D,1,0),"")="","","✔") | G5: =IF(IFERROR(VLOOKUP(A5,'6.混凝土'!C:D,1,0),"")="","","✔") | H5: =IF(IFERROR(VLOOKUP(A5,'7.植筋'!C:D,1,0),"")="","","✔") | I5: =IF(IFERROR(VLOOKUP(A5,'8.預力混凝土基樁'!C:D,1,0),"")="","","✔") | J5: =IF(IFERROR(VLOOKUP(A5,'9.砌塊石護岸'!C:D,1,0),"")="","","✔") | K5: =IF(IFERROR(VLOOKUP(A5,'10.低水護岸'!C:D,1,0),"")="","","✔") | L5: =IF(IFERROR(VLOOKUP(A5,'11.固床工'!C:D,1,0),"")="","","✔") | M5: =IF(IFERROR(VLOOKUP(A5,'12.全套管基樁'!C:D,1,0),"")="","","✔") | N5: =IF(IFERROR(VLOOKUP(A5,'13.鋼筋混凝土管工程'!C:D,1,0),"")="","","✔") | O5: =IF(IFERROR(VLOOKUP(A5,'14.鋼版樁'!C:D,1,0),"")="","","✔") | P5: =IF(IFERROR(VLOOKUP(A5,'15.路床 路基高程'!C:D,1,0),"")="","","✔") | Q5: =IF(IFERROR(VLOOKUP(A5,'16.瀝青混凝土'!C:D,1,0),"")="","","✔") | R5: =IF(IFERROR(VLOOKUP(A5,'17.景觀鋪面(一)'!C:D,1,0),"")="","","✔") | S5: =IF(IFERROR(VLOOKUP(A5,'18.景觀鋪面(二)'!C:D,1,0),"")="","","✔") | T5: =IF(IFERROR(VLOOKUP(A5,'19.預鑄緣石'!C:D,1,0),"")="","","✔") | U5: =IF(IFERROR(VLOOKUP(A5,'20.鋼構工程吊裝'!C:D,1,0),"")="","","✔") | V5: =IF(IFERROR(VLOOKUP(A5,'21.鋼構工程塗裝'!C:D,1,0),"")="","","✔") | W5: =IF(IFERROR(VLOOKUP(A5,'22.排水設施(一)'!C:D,1,0),"")="","","✔") | X5: =IF(IFERROR(VLOOKUP(A5,'23.排水設施(二)'!C:D,1,0),"")="","","✔") | Y5: =IF(IFERROR(VLOOKUP(A5,'24.木構造'!C:D,1,0),"")="","","✔") | Z5: =IF(IFERROR(VLOOKUP(A5,'25.管路'!C:D,1,0),"")="","","✔") | AA5: =IF(IFERROR(VLOOKUP(A5,'26.植栽(移植)'!C:D,1,0),"")="","","✔") | AB5: =IF(IFERROR(VLOOKUP(A5,'27.植栽(新植)'!C:D,1,0),"")="","","✔") | AC5: =IF(IFERROR(VLOOKUP(A5,'28.照明'!C:D,1,0),"")="","","✔") | AD5: =IF(IFERROR(VLOOKUP(A5,'29.既有橋梁拆除'!C:D,1,0),"")="","","✔")
A6: 45196 | B6: =IF(IFERROR(VLOOKUP(A6,'1.測量放樣'!C:D,1,0),"")="","","✔") | C6: =IF(IFERROR(VLOOKUP(A6,'2.土方開挖'!C:D,1,0),"")="","","✔") | D6: =IF(IFERROR(VLOOKUP(A6,'3.土方回填'!C:D,1,0),"")="","","✔") | E6: =IF(IFERROR(VLOOKUP(A6,'4.鋼筋'!C:D,1,0),"")="","","✔") | F6: =IF(IFERROR(VLOOKUP(A6,'5.模板'!C:D,1,0),"")="","","✔") | G6: =IF(IFERROR(VLOOKUP(A6,'6.混凝土'!C:D,1,0),"")="","","✔") | H6: =IF(IFERROR(VLOOKUP(A6,'7.植筋'!C:D,1,0),"")="","","✔") | I6: =IF(IFERROR(VLOOKUP(A6,'8.預力混凝土基樁'!C:D,1,0),"")="","","✔") | J6: =IF(IFERROR(VLOOKUP(A6,'9.砌塊石護岸'!C:D,1,0),"")="","","✔") | K6: =IF(IFERROR(VLOOKUP(A6,'10.低水護岸'!C:D,1,0),"")="","","✔") | L6: =IF(IFERROR(VLOOKUP(A6,'11.固床工'!C:D,1,0),"")="","","✔") | M6: =IF(IFERROR(VLOOKUP(A6,'12.全套管基樁'!C:D,1,0),"")="","","✔") | N6: =IF(IFERROR(VLOOKUP(A6,'13.鋼筋混凝土管工程'!C:D,1,0),"")="","","✔") | O6: =IF(IFERROR(VLOOKUP(A6,'14.鋼版樁'!C:D,1,0),"")="","","✔") | P6: =IF(IFERROR(VLOOKUP(A6,'15.路床 路基高程'!C:D,1,0),"")="","","✔") | Q6: =IF(IFERROR(VLOOKUP(A6,'16.瀝青混凝土'!C:D,1,0),"")="","","✔") | R6: =IF(IFERROR(VLOOKUP(A6,'17.景觀鋪面(一)'!C:D,1,0),"")="","","✔") | S6: =IF(IFERROR(VLOOKUP(A6,'18.景觀鋪面(二)'!C:D,1,0),"")="","","✔") | T6: =IF(IFERROR(VLOOKUP(A6,'19.預鑄緣石'!C:D,1,0),"")="","","✔") | U6: =IF(IFERROR(VLOOKUP(A6,'20.鋼構工程吊裝'!C:D,1,0),"")="","","✔") | V6: =IF(IFERROR(VLOOKUP(A6,'21.鋼構工程塗裝'!C:D,1,0),"")="","","✔") | W6: =IF(IFERROR(VLOOKUP(A6,'22.排水設施(一)'!C:D,1,0),"")="","","✔") | X6: =IF(IFERROR(VLOOKUP(A6,'23.排水設施(二)'!C:D,1,0),"")="","","✔") | Y6: =IF(IFERROR(VLOOKUP(A6,'24.木構造'!C:D,1,0),"")="","","✔") | Z6: =IF(IFERROR(VLOOKUP(A6,'25.管路'!C:D,1,0),"")="","","✔") | AA6: =IF(IFERROR(VLOOKUP(A6,'26.植栽(移植)'!C:D,1,0),"")="","","✔") | AB6: =IF(IFERROR(VLOOKUP(A6,'27.植栽(新植)'!C:D,1,0),"")="","","✔") | AC6: =IF(IFERROR(VLOOKUP(A6,'28.照明'!C:D,1,0),"")="","","✔") | AD6: =IF(IFERROR(VLOOKUP(A6,'29.既有橋梁拆除'!C:D,1,0),"")="","","✔")
A7: 45197 | B7: =IF(IFERROR(VLOOKUP(A7,'1.測量放樣'!C:D,1,0),"")="","","✔") | C7: =IF(IFERROR(VLOOKUP(A7,'2.土方開挖'!C:D,1,0),"")="","","✔") | D7: =IF(IFERROR(VLOOKUP(A7,'3.土方回填'!C:D,1,0),"")="","","✔") | E7: =IF(IFERROR(VLOOKUP(A7,'4.鋼筋'!C:D,1,0),"")="","","✔") | F7: =IF(IFERROR(VLOOKUP(A7,'5.模板'!C:D,1,0),"")="","","✔") | G7: =IF(IFERROR(VLOOKUP(A7,'6.混凝土'!C:D,1,0),"")="","","✔") | H7: =IF(IFERROR(VLOOKUP(A7,'7.植筋'!C:D,1,0),"")="","","✔") | I7: =IF(IFERROR(VLOOKUP(A7,'8.預力混凝土基樁'!C:D,1,0),"")="","","✔") | J7: =IF(IFERROR(VLOOKUP(A7,'9.砌塊石護岸'!C:D,1,0),"")="","","✔") | K7: =IF(IFERROR(VLOOKUP(A7,'10.低水護岸'!C:D,1,0),"")="","","✔") | L7: =IF(IFERROR(VLOOKUP(A7,'11.固床工'!C:D,1,0),"")="","","✔") | M7: =IF(IFERROR(VLOOKUP(A7,'12.全套管基樁'!C:D,1,0),"")="","","✔") | N7: =IF(IFERROR(VLOOKUP(A7,'13.鋼筋混凝土管工程'!C:D,1,0),"")="","","✔") | O7: =IF(IFERROR(VLOOKUP(A7,'14.鋼版樁'!C:D,1,0),"")="","","✔") | P7: =IF(IFERROR(VLOOKUP(A7,'15.路床 路基高程'!C:D,1,0),"")="","","✔") | Q7: =IF(IFERROR(VLOOKUP(A7,'16.瀝青混凝土'!C:D,1,0),"")="","","✔") | R7: =IF(IFERROR(VLOOKUP(A7,'17.景觀鋪面(一)'!C:D,1,0),"")="","","✔") | S7: =IF(IFERROR(VLOOKUP(A7,'18.景觀鋪面(二)'!C:D,1,0),"")="","","✔") | T7: =IF(IFERROR(VLOOKUP(A7,'19.預鑄緣石'!C:D,1,0),"")="","","✔") | U7: =IF(IFERROR(VLOOKUP(A7,'20.鋼構工程吊裝'!C:D,1,0),"")="","","✔") | V7: =IF(IFERROR(VLOOKUP(A7,'21.鋼構工程塗裝'!C:D,1,0),"")="","","✔") | W7: =IF(IFERROR(VLOOKUP(A7,'22.排水設施(一)'!C:D,1,0),"")="","","✔") | X7: =IF(IFERROR(VLOOKUP(A7,'23.排水設施(二)'!C:D,1,0),"")="","","✔") | Y7: =IF(IFERROR(VLOOKUP(A7,'24.木構造'!C:D,1,0),"")="","","✔") | Z7: =IF(IFERROR(VLOOKUP(A7,'25.管路'!C:D,1,0),"")="","","✔") | AA7: =IF(IFERROR(VLOOKUP(A7,'26.植栽(移植)'!C:D,1,0),"")="","","✔") | AB7: =IF(IFERROR(VLOOKUP(A7,'27.植栽(新植)'!C:D,1,0),"")="","","✔") | AC7: =IF(IFERROR(VLOOKUP(A7,'28.照明'!C:D,1,0),"")="","","✔") | AD7: =IF(IFERROR(VLOOKUP(A7,'29.既有橋梁拆除'!C:D,1,0),"")="","","✔")
A8: 45198 | B8: =IF(IFERROR(VLOOKUP(A8,'1.測量放樣'!C:D,1,0),"")="","","✔") | C8: =IF(IFERROR(VLOOKUP(A8,'2.土方開挖'!C:D,1,0),"")="","","✔") | D8: =IF(IFERROR(VLOOKUP(A8,'3.土方回填'!C:D,1,0),"")="","","✔") | E8: =IF(IFERROR(VLOOKUP(A8,'4.鋼筋'!C:D,1,0),"")="","","✔") | F8: =IF(IFERROR(VLOOKUP(A8,'5.模板'!C:D,1,0),"")="","","✔") | G8: =IF(IFERROR(VLOOKUP(A8,'6.混凝土'!C:D,1,0),"")="","","✔") | H8: =IF(IFERROR(VLOOKUP(A8,'7.植筋'!C:D,1,0),"")="","","✔") | I8: =IF(IFERROR(VLOOKUP(A8,'8.預力混凝土基樁'!C:D,1,0),"")="","","✔") | J8: =IF(IFERROR(VLOOKUP(A8,'9.砌塊石護岸'!C:D,1,0),"")="","","✔") | K8: =IF(IFERROR(VLOOKUP(A8,'10.低水護岸'!C:D,1,0),"")="","","✔") | L8: =IF(IFERROR(VLOOKUP(A8,'11.固床工'!C:D,1,0),"")="","","✔") | M8: =IF(IFERROR(VLOOKUP(A8,'12.全套管基樁'!C:D,1,0),"")="","","✔") | N8: =IF(IFERROR(VLOOKUP(A8,'13.鋼筋混凝土管工程'!C:D,1,0),"")="","","✔") | O8: =IF(IFERROR(VLOOKUP(A8,'14.鋼版樁'!C:D,1,0),"")="","","✔") | P8: =IF(IFERROR(VLOOKUP(A8,'15.路床 路基高程'!C:D,1,0),"")="","","✔") | Q8: =IF(IFERROR(VLOOKUP(A8,'16.瀝青混凝土'!C:D,1,0),"")="","","✔") | R8: =IF(IFERROR(VLOOKUP(A8,'17.景觀鋪面(一)'!C:D,1,0),"")="","","✔") | S8: =IF(IFERROR(VLOOKUP(A8,'18.景觀鋪面(二)'!C:D,1,0),"")="","","✔") | T8: =IF(IFERROR(VLOOKUP(A8,'19.預鑄緣石'!C:D,1,0),"")="","","✔") | U8: =IF(IFERROR(VLOOKUP(A8,'20.鋼構工程吊裝'!C:D,1,0),"")="","","✔") | V8: =IF(IFERROR(VLOOKUP(A8,'21.鋼構工程塗裝'!C:D,1,0),"")="","","✔") | W8: =IF(IFERROR(VLOOKUP(A8,'22.排水設施(一)'!C:D,1,0),"")="","","✔") | X8: =IF(IFERROR(VLOOKUP(A8,'23.排水設施(二)'!C:D,1,0),"")="","","✔") | Y8: =IF(IFERROR(VLOOKUP(A8,'24.木構造'!C:D,1,0),"")="","","✔") | Z8: =IF(IFERROR(VLOOKUP(A8,'25.管路'!C:D,1,0),"")="","","✔") | AA8: =IF(IFERROR(VLOOKUP(A8,'26.植栽(移植)'!C:D,1,0),"")="","","✔") | AB8: =IF(IFERROR(VLOOKUP(A8,'27.植栽(新植)'!C:D,1,0),"")="","","✔") | AC8: =IF(IFERROR(VLOOKUP(A8,'28.照明'!C:D,1,0),"")="","","✔") | AD8: =IF(IFERROR(VLOOKUP(A8,'29.既有橋梁拆除'!C:D,1,0),"")="","","✔")
A9: 45199 | B9: =IF(IFERROR(VLOOKUP(A9,'1.測量放樣'!C:D,1,0),"")="","","✔") | C9: =IF(IFERROR(VLOOKUP(A9,'2.土方開挖'!C:D,1,0),"")="","","✔") | D9: =IF(IFERROR(VLOOKUP(A9,'3.土方回填'!C:D,1,0),"")="","","✔") | E9: =IF(IFERROR(VLOOKUP(A9,'4.鋼筋'!C:D,1,0),"")="","","✔") | F9: =IF(IFERROR(VLOOKUP(A9,'5.模板'!C:D,1,0),"")="","","✔") | G9: =IF(IFERROR(VLOOKUP(A9,'6.混凝土'!C:D,1,0),"")="","","✔") | H9: =IF(IFERROR(VLOOKUP(A9,'7.植筋'!C:D,1,0),"")="","","✔") | I9: =IF(IFERROR(VLOOKUP(A9,'8.預力混凝土基樁'!C:D,1,0),"")="","","✔") | J9: =IF(IFERROR(VLOOKUP(A9,'9.砌塊石護岸'!C:D,1,0),"")="","","✔") | K9: =IF(IFERROR(VLOOKUP(A9,'10.低水護岸'!C:D,1,0),"")="","","✔") | L9: =IF(IFERROR(VLOOKUP(A9,'11.固床工'!C:D,1,0),"")="","","✔") | M9: =IF(IFERROR(VLOOKUP(A9,'12.全套管基樁'!C:D,1,0),"")="","","✔") | N9: =IF(IFERROR(VLOOKUP(A9,'13.鋼筋混凝土管工程'!C:D,1,0),"")="","","✔") | O9: =IF(IFERROR(VLOOKUP(A9,'14.鋼版樁'!C:D,1,0),"")="","","✔") | P9: =IF(IFERROR(VLOOKUP(A9,'15.路床 路基高程'!C:D,1,0),"")="","","✔") | Q9: =IF(IFERROR(VLOOKUP(A9,'16.瀝青混凝土'!C:D,1,0),"")="","","✔") | R9: =IF(IFERROR(VLOOKUP(A9,'17.景觀鋪面(一)'!C:D,1,0),"")="","","✔") | S9: =IF(IFERROR(VLOOKUP(A9,'18.景觀鋪面(二)'!C:D,1,0),"")="","","✔") | T9: =IF(IFERROR(VLOOKUP(A9,'19.預鑄緣石'!C:D,1,0),"")="","","✔") | U9: =IF(IFERROR(VLOOKUP(A9,'20.鋼構工程吊裝'!C:D,1,0),"")="","","✔") | V9: =IF(IFERROR(VLOOKUP(A9,'21.鋼構工程塗裝'!C:D,1,0),"")="","","✔") | W9: =IF(IFERROR(VLOOKUP(A9,'22.排水設施(一)'!C:D,1,0),"")="","","✔") | X9: =IF(IFERROR(VLOOKUP(A9,'23.排水設施(二)'!C:D,1,0),"")="","","✔") | Y9: =IF(IFERROR(VLOOKUP(A9,'24.木構造'!C:D,1,0),"")="","","✔") | Z9: =IF(IFERROR(VLOOKUP(A9,'25.管路'!C:D,1,0),"")="","","✔") | AA9: =IF(IFERROR(VLOOKUP(A9,'26.植栽(移植)'!C:D,1,0),"")="","","✔") | AB9: =IF(IFERROR(VLOOKUP(A9,'27.植栽(新植)'!C:D,1,0),"")="","","✔") | AC9: =IF(IFERROR(VLOOKUP(A9,'28.照明'!C:D,1,0),"")="","","✔") | AD9: =IF(IFERROR(VLOOKUP(A9,'29.既有橋梁拆除'!C:D,1,0),"")="","","✔")
A10: 45200 | B10: =IF(IFERROR(VLOOKUP(A10,'1.測量放樣'!C:D,1,0),"")="","","✔") | C10: =IF(IFERROR(VLOOKUP(A10,'2.土方開挖'!C:D,1,0),"")="","","✔") | D10: =IF(IFERROR(VLOOKUP(A10,'3.土方回填'!C:D,1,0),"")="","","✔") | E10: =IF(IFERROR(VLOOKUP(A10,'4.鋼筋'!C:D,1,0),"")="","","✔") | F10: =IF(IFERROR(VLOOKUP(A10,'5.模板'!C:D,1,0),"")="","","✔") | G10: =IF(IFERROR(VLOOKUP(A10,'6.混凝土'!C:D,1,0),"")="","","✔") | H10: =IF(IFERROR(VLOOKUP(A10,'7.植筋'!C:D,1,0),"")="","","✔") | I10: =IF(IFERROR(VLOOKUP(A10,'8.預力混凝土基樁'!C:D,1,0),"")="","","✔") | J10: =IF(IFERROR(VLOOKUP(A10,'9.砌塊石護岸'!C:D,1,0),"")="","","✔") | K10: =IF(IFERROR(VLOOKUP(A10,'10.低水護岸'!C:D,1,0),"")="","","✔") | L10: =IF(IFERROR(VLOOKUP(A10,'11.固床工'!C:D,1,0),"")="","","✔") | M10: =IF(IFERROR(VLOOKUP(A10,'12.全套管基樁'!C:D,1,0),"")="","","✔") | N10: =IF(IFERROR(VLOOKUP(A10,'13.鋼筋混凝土管工程'!C:D,1,0),"")="","","✔") | O10: =IF(IFERROR(VLOOKUP(A10,'14.鋼版樁'!C:D,1,0),"")="","","✔") | P10: =IF(IFERROR(VLOOKUP(A10,'15.路床 路基高程'!C:D,1,0),"")="","","✔") | Q10: =IF(IFERROR(VLOOKUP(A10,'16.瀝青混凝土'!C:D,1,0),"")="","","✔") | R10: =IF(IFERROR(VLOOKUP(A10,'17.景觀鋪面(一)'!C:D,1,0),"")="","","✔") | S10: =IF(IFERROR(VLOOKUP(A10,'18.景觀鋪面(二)'!C:D,1,0),"")="","","✔") | T10: =IF(IFERROR(VLOOKUP(A10,'19.預鑄緣石'!C:D,1,0),"")="","","✔") | U10: =IF(IFERROR(VLOOKUP(A10,'20.鋼構工程吊裝'!C:D,1,0),"")="","","✔") | V10: =IF(IFERROR(VLOOKUP(A10,'21.鋼構工程塗裝'!C:D,1,0),"")="","","✔") | W10: =IF(IFERROR(VLOOKUP(A10,'22.排水設施(一)'!C:D,1,0),"")="","","✔") | X10: =IF(IFERROR(VLOOKUP(A10,'23.排水設施(二)'!C:D,1,0),"")="","","✔") | Y10: =IF(IFERROR(VLOOKUP(A10,'24.木構造'!C:D,1,0),"")="","","✔") | Z10: =IF(IFERROR(VLOOKUP(A10,'25.管路'!C:D,1,0),"")="","","✔") | AA10: =IF(IFERROR(VLOOKUP(A10,'26.植栽(移植)'!C:D,1,0),"")="","","✔") | AB10: =IF(IFERROR(VLOOKUP(A10,'27.植栽(新植)'!C:D,1,0),"")="","","✔") | AC10: =IF(IFERROR(VLOOKUP(A10,'28.照明'!C:D,1,0),"")="","","✔") | AD10: =IF(IFERROR(VLOOKUP(A10,'29.既有橋梁拆除'!C:D,1,0),"")="","","✔")
A11: 45201 | B11: =IF(IFERROR(VLOOKUP(A11,'1.測量放樣'!C:D,1,0),"")="","","✔") | C11: =IF(IFERROR(VLOOKUP(A11,'2.土方開挖'!C:D,1,0),"")="","","✔") | D11: =IF(IFERROR(VLOOKUP(A11,'3.土方回填'!C:D,1,0),"")="","","✔") | E11: =IF(IFERROR(VLOOKUP(A11,'4.鋼筋'!C:D,1,0),"")="","","✔") | F11: =IF(IFERROR(VLOOKUP(A11,'5.模板'!C:D,1,0),"")="","","✔") | G11: =IF(IFERROR(VLOOKUP(A11,'6.混凝土'!C:D,1,0),"")="","","✔") | H11: =IF(IFERROR(VLOOKUP(A11,'7.植筋'!C:D,1,0),"")="","","✔") | I11: =IF(IFERROR(VLOOKUP(A11,'8.預力混凝土基樁'!C:D,1,0),"")="","","✔") | J11: =IF(IFERROR(VLOOKUP(A11,'9.砌塊石護岸'!C:D,1,0),"")="","","✔") | K11: =IF(IFERROR(VLOOKUP(A11,'10.低水護岸'!C:D,1,0),"")="","","✔") | L11: =IF(IFERROR(VLOOKUP(A11,'11.固床工'!C:D,1,0),"")="","","✔") | M11: =IF(IFERROR(VLOOKUP(A11,'12.全套管基樁'!C:D,1,0),"")="","","✔") | N11: =IF(IFERROR(VLOOKUP(A11,'13.鋼筋混凝土管工程'!C:D,1,0),"")="","","✔") | O11: =IF(IFERROR(VLOOKUP(A11,'14.鋼版樁'!C:D,1,0),"")="","","✔") | P11: =IF(IFERROR(VLOOKUP(A11,'15.路床 路基高程'!C:D,1,0),"")="","","✔") | Q11: =IF(IFERROR(VLOOKUP(A11,'16.瀝青混凝土'!C:D,1,0),"")="","","✔") | R11: =IF(IFERROR(VLOOKUP(A11,'17.景觀鋪面(一)'!C:D,1,0),"")="","","✔") | S11: =IF(IFERROR(VLOOKUP(A11,'18.景觀鋪面(二)'!C:D,1,0),"")="","","✔") | T11: =IF(IFERROR(VLOOKUP(A11,'19.預鑄緣石'!C:D,1,0),"")="","","✔") | U11: =IF(IFERROR(VLOOKUP(A11,'20.鋼構工程吊裝'!C:D,1,0),"")="","","✔") | V11: =IF(IFERROR(VLOOKUP(A11,'21.鋼構工程塗裝'!C:D,1,0),"")="","","✔") | W11: =IF(IFERROR(VLOOKUP(A11,'22.排水設施(一)'!C:D,1,0),"")="","","✔") | X11: =IF(IFERROR(VLOOKUP(A11,'23.排水設施(二)'!C:D,1,0),"")="","","✔") | Y11: =IF(IFERROR(VLOOKUP(A11,'24.木構造'!C:D,1,0),"")="","","✔") | Z11: =IF(IFERROR(VLOOKUP(A11,'25.管路'!C:D,1,0),"")="","","✔") | AA11: =IF(IFERROR(VLOOKUP(A11,'26.植栽(移植)'!C:D,1,0),"")="","","✔") | AB11: =IF(IFERROR(VLOOKUP(A11,'27.植栽(新植)'!C:D,1,0),"")="","","✔") | AC11: =IF(IFERROR(VLOOKUP(A11,'28.照明'!C:D,1,0),"")="","","✔") | AD11: =IF(IFERROR(VLOOKUP(A11,'29.既有橋梁拆除'!C:D,1,0),"")="","","✔")
A12: 45202 | B12: =IF(IFERROR(VLOOKUP(A12,'1.測量放樣'!C:D,1,0),"")="","","✔") | C12: =IF(IFERROR(VLOOKUP(A12,'2.土方開挖'!C:D,1,0),"")="","","✔") | D12: =IF(IFERROR(VLOOKUP(A12,'3.土方回填'!C:D,1,0),"")="","","✔") | E12: =IF(IFERROR(VLOOKUP(A12,'4.鋼筋'!C:D,1,0),"")="","","✔") | F12: =IF(IFERROR(VLOOKUP(A12,'5.模板'!C:D,1,0),"")="","","✔") | G12: =IF(IFERROR(VLOOKUP(A12,'6.混凝土'!C:D,1,0),"")="","","✔") | H12: =IF(IFERROR(VLOOKUP(A12,'7.植筋'!C:D,1,0),"")="","","✔") | I12: =IF(IFERROR(VLOOKUP(A12,'8.預力混凝土基樁'!C:D,1,0),"")="","","✔") | J12: =IF(IFERROR(VLOOKUP(A12,'9.砌塊石護岸'!C:D,1,0),"")="","","✔") | K12: =IF(IFERROR(VLOOKUP(A12,'10.低水護岸'!C:D,1,0),"")="","","✔") | L12: =IF(IFERROR(VLOOKUP(A12,'11.固床工'!C:D,1,0),"")="","","✔") | M12: =IF(IFERROR(VLOOKUP(A12,'12.全套管基樁'!C:D,1,0),"")="","","✔") | N12: =IF(IFERROR(VLOOKUP(A12,'13.鋼筋混凝土管工程'!C:D,1,0),"")="","","✔") | O12: =IF(IFERROR(VLOOKUP(A12,'14.鋼版樁'!C:D,1,0),"")="","","✔") | P12: =IF(IFERROR(VLOOKUP(A12,'15.路床 路基高程'!C:D,1,0),"")="","","✔") | Q12: =IF(IFERROR(VLOOKUP(A12,'16.瀝青混凝土'!C:D,1,0),"")="","","✔") | R12: =IF(IFERROR(VLOOKUP(A12,'17.景觀鋪面(一)'!C:D,1,0),"")="","","✔") | S12: =IF(IFERROR(VLOOKUP(A12,'18.景觀鋪面(二)'!C:D,1,0),"")="","","✔") | T12: =IF(IFERROR(VLOOKUP(A12,'19.預鑄緣石'!C:D,1,0),"")="","","✔") | U12: =IF(IFERROR(VLOOKUP(A12,'20.鋼構工程吊裝'!C:D,1,0),"")="","","✔") | V12: =IF(IFERROR(VLOOKUP(A12,'21.鋼構工程塗裝'!C:D,1,0),"")="","","✔") | W12: =IF(IFERROR(VLOOKUP(A12,'22.排水設施(一)'!C:D,1,0),"")="","","✔") | X12: =IF(IFERROR(VLOOKUP(A12,'23.排水設施(二)'!C:D,1,0),"")="","","✔") | Y12: =IF(IFERROR(VLOOKUP(A12,'24.木構造'!C:D,1,0),"")="","","✔") | Z12: =IF(IFERROR(VLOOKUP(A12,'25.管路'!C:D,1,0),"")="","","✔") | AA12: =IF(IFERROR(VLOOKUP(A12,'26.植栽(移植)'!C:D,1,0),"")="","","✔") | AB12: =IF(IFERROR(VLOOKUP(A12,'27.植栽(新植)'!C:D,1,0),"")="","","✔") | AC12: =IF(IFERROR(VLOOKUP(A12,'28.照明'!C:D,1,0),"")="","","✔") | AD12: =IF(IFERROR(VLOOKUP(A12,'29.既有橋梁拆除'!C:D,1,0),"")="","","✔")
A13: 45203 | B13: =IF(IFERROR(VLOOKUP(A13,'1.測量放樣'!C:D,1,0),"")="","","✔") | C13: =IF(IFERROR(VLOOKUP(A13,'2.土方開挖'!C:D,1,0),"")="","","✔") | D13: =IF(IFERROR(VLOOKUP(A13,'3.土方回填'!C:D,1,0),"")="","","✔") | E13: =IF(IFERROR(VLOOKUP(A13,'4.鋼筋'!C:D,1,0),"")="","","✔") | F13: =IF(IFERROR(VLOOKUP(A13,'5.模板'!C:D,1,0),"")="","","✔") | G13: =IF(IFERROR(VLOOKUP(A13,'6.混凝土'!C:D,1,0),"")="","","✔") | H13: =IF(IFERROR(VLOOKUP(A13,'7.植筋'!C:D,1,0),"")="","","✔") | I13: =IF(IFERROR(VLOOKUP(A13,'8.預力混凝土基樁'!C:D,1,0),"")="","","✔") | J13: =IF(IFERROR(VLOOKUP(A13,'9.砌塊石護岸'!C:D,1,0),"")="","","✔") | K13: =IF(IFERROR(VLOOKUP(A13,'10.低水護岸'!C:D,1,0),"")="","","✔") | L13: =IF(IFERROR(VLOOKUP(A13,'11.固床工'!C:D,1,0),"")="","","✔") | M13: =IF(IFERROR(VLOOKUP(A13,'12.全套管基樁'!C:D,1,0),"")="","","✔") | N13: =IF(IFERROR(VLOOKUP(A13,'13.鋼筋混凝土管工程'!C:D,1,0),"")="","","✔") | O13: =IF(IFERROR(VLOOKUP(A13,'14.鋼版樁'!C:D,1,0),"")="","","✔") | P13: =IF(IFERROR(VLOOKUP(A13,'15.路床 路基高程'!C:D,1,0),"")="","","✔") | Q13: =IF(IFERROR(VLOOKUP(A13,'16.瀝青混凝土'!C:D,1,0),"")="","","✔") | R13: =IF(IFERROR(VLOOKUP(A13,'17.景觀鋪面(一)'!C:D,1,0),"")="","","✔") | S13: =IF(IFERROR(VLOOKUP(A13,'18.景觀鋪面(二)'!C:D,1,0),"")="","","✔") | T13: =IF(IFERROR(VLOOKUP(A13,'19.預鑄緣石'!C:D,1,0),"")="","","✔") | U13: =IF(IFERROR(VLOOKUP(A13,'20.鋼構工程吊裝'!C:D,1,0),"")="","","✔") | V13: =IF(IFERROR(VLOOKUP(A13,'21.鋼構工程塗裝'!C:D,1,0),"")="","","✔") | W13: =IF(IFERROR(VLOOKUP(A13,'22.排水設施(一)'!C:D,1,0),"")="","","✔") | X13: =IF(IFERROR(VLOOKUP(A13,'23.排水設施(二)'!C:D,1,0),"")="","","✔") | Y13: =IF(IFERROR(VLOOKUP(A13,'24.木構造'!C:D,1,0),"")="","","✔") | Z13: =IF(IFERROR(VLOOKUP(A13,'25.管路'!C:D,1,0),"")="","","✔") | AA13: =IF(IFERROR(VLOOKUP(A13,'26.植栽(移植)'!C:D,1,0),"")="","","✔") | AB13: =IF(IFERROR(VLOOKUP(A13,'27.植栽(新植)'!C:D,1,0),"")="","","✔") | AC13: =IF(IFERROR(VLOOKUP(A13,'28.照明'!C:D,1,0),"")="","","✔") | AD13: =IF(IFERROR(VLOOKUP(A13,'29.既有橋梁拆除'!C:D,1,0),"")="","","✔")
... A741: 45931 | B741: =IF(IFERROR(VLOOKUP(A741,'1.測量放樣'!C:D,1,0),"")="","","✔") | C741: =IF(IFERROR(VLOOKUP(A741,'2.土方開挖'!C:D,1,0),"")="","","✔") | D741: =IF(IFERROR(VLOOKUP(A741,'3.土方回填'!C:D,1,0),"")="","","✔") | E741: =IF(IFERROR(VLOOKUP(A741,'4.鋼筋'!C:D,1,0),"")="","","✔") | F741: =IF(IFERROR(VLOOKUP(A741,'5.模板'!C:D,1,0),"")="","","✔") | G741: =IF(IFERROR(VLOOKUP(A741,'6.混凝土'!C:D,1,0),"")="","","✔") | H741: =IF(IFERROR(VLOOKUP(A741,'7.植筋'!C:D,1,0),"")="","","✔") | I741: =IF(IFERROR(VLOOKUP(A741,'8.預力混凝土基樁'!C:D,1,0),"")="","","✔") | J741: =IF(IFERROR(VLOOKUP(A741,'9.砌塊石護岸'!C:D,1,0),"")="","","✔") | K741: =IF(IFERROR(VLOOKUP(A741,'10.低水護岸'!C:D,1,0),"")="","","✔") | L741: =IF(IFERROR(VLOOKUP(A741,'11.固床工'!C:D,1,0),"")="","","✔") | M741: =IF(IFERROR(VLOOKUP(A741,'12.全套管基樁'!C:D,1,0),"")="","","✔") | N741: =IF(IFERROR(VLOOKUP(A741,'13.鋼筋混凝土管工程'!C:D,1,0),"")="","","✔") | O741: =IF(IFERROR(VLOOKUP(A741,'14.鋼版樁'!C:D,1,0),"")="","","✔") | P741: =IF(IFERROR(VLOOKUP(A741,'15.路床 路基高程'!C:D,1,0),"")="","","✔") | Q741: =IF(IFERROR(VLOOKUP(A741,'16.瀝青混凝土'!C:D,1,0),"")="","","✔") | R741: =IF(IFERROR(VLOOKUP(A741,'17.景觀鋪面(一)'!C:D,1,0),"")="","","✔") | S741: =IF(IFERROR(VLOOKUP(A741,'18.景觀鋪面(二)'!C:D,1,0),"")="","","✔") | T741: =IF(IFERROR(VLOOKUP(A741,'19.預鑄緣石'!C:D,1,0),"")="","","✔") | U741: =IF(IFERROR(VLOOKUP(A741,'20.鋼構工程吊裝'!C:D,1,0),"")="","","✔") | V741: =IF(IFERROR(VLOOKUP(A741,'21.鋼構工程塗裝'!C:D,1,0),"")="","","✔") | W741: =IF(IFERROR(VLOOKUP(A741,'22.排水設施(一)'!C:D,1,0),"")="","","✔") | X741: =IF(IFERROR(VLOOKUP(A741,'23.排水設施(二)'!C:D,1,0),"")="","","✔") | Y741: =IF(IFERROR(VLOOKUP(A741,'24.木構造'!C:D,1,0),"")="","","✔") | Z741: =IF(IFERROR(VLOOKUP(A741,'25.管路'!C:D,1,0),"")="","","✔") | AA741: =IF(IFERROR(VLOOKUP(A741,'26.植栽(移植)'!C:D,1,0),"")="","","✔") | AB741: =IF(IFERROR(VLOOKUP(A741,'27.植栽(新植)'!C:D,1,0),"")="","","✔") | AC741: =IF(IFERROR(VLOOKUP(A741,'28.照明'!C:D,1,0),"")="","","✔") | AD741: =IF(IFERROR(VLOOKUP(A741,'29.既有橋梁拆除'!C:D,1,0),"")="","","✔")

Sheet 統計圖
A1: 自主檢查統計表
A2: 編號 | B2: 項目 | C2: 檢查次數 | I2: 項目 | J2: 監造 | L2: 業主
A3: =ROW()-2 -> 1 | B3: 測量放樣 | C3: =COUNTA('1.測量放樣'!A:A)-4 -> 8 | G3: A | H3: =A3&"."&B3 -> 1.測量放樣 | I3: =B3 -> 測量放樣 | J3: =COUNTIF('1.測量放樣'!E:E,"*監造*") -> 4 | K3: =IFERROR(J3/C3,"") -> 0.5 | L3: =COUNTIF('1.測量放樣'!E:E,"*業主*") -> 0 | M3: =IFERROR(L3/C3,"") -> 0
A4: =ROW()-2 -> 2 | B4: 土方開挖 | C4: =COUNTA('2.土方開挖'!A:A)-4 -> 21 | G4: B | H4: =A4&"."&B4 -> 2.土方開挖 | I4: =B4 -> 土方開挖 | J4: =COUNTIF('2.土方開挖'!E:E,"*監造*") -> 9 | K4: =IFERROR(J4/C4,"") -> 0.42857143 | L4: =COUNTIF('2.土方開挖'!E:E,"*業主*") -> 1 | M4: =IFERROR(L4/C4,"") -> 0.047619048
A5: =ROW()-2 -> 3 | B5: 土方回填(含級配) | C5: =COUNTA('3.土方回填'!A:A)-4 -> 0 | G5: C | H5: =A5&"."&B5 -> 3.土方回填(含級配) | I5: =B5 -> 土方回填(含級配) | J5: =COUNTIF('3.土方回填'!E:E,"*監造*") -> 0 | K5: =IFERROR(J5/C5,"") | L5: =COUNTIF('3.土方回填'!E:E,"*業主*") -> 0 | M5: =IFERROR(L5/C5,"")
A6: =ROW()-2 -> 4 | B6: 鋼筋工程 | C6: =COUNTA('4.鋼筋'!A:A)-4 -> 16 | G6: D | H6: =A6&"."&B6 -> 4.鋼筋工程 | I6: =B6 -> 鋼筋工程 | J6: =COUNTIF('4.鋼筋'!E:E,"*監造*") -> 16 | K6: =IFERROR(J6/C6,"") -> 1 | L6: =COUNTIF('4.鋼筋'!E:E,"*業主*") -> 1 | M6: =IFERROR(L6/C6,"") -> 0.0625
A7: =ROW()-2 -> 5 | B7: 模板工程 | C7: =COUNTA('5.模板'!A:A)-4 -> 4 | G7: E | H7: =A7&"."&B7 -> 5.模板工程 | I7: =B7 -> 模板工程 | J7: =COUNTIF('5.模板'!E:E,"*監造*") -> 2 | K7: =IFERROR(J7/C7,"") -> 0.5 | L7: =COUNTIF('5.模板'!E:E,"*業主*") -> 0 | M7: =IFERROR(L7/C7,"") -> 0
A8: =ROW()-2 -> 6 | B8: 混凝土工程 | C8: =COUNTA('6.混凝土'!A:A)-4 -> 17 | G8: F | H8: =A8&"."&B8 -> 6.混凝土工程 | I8: =B8 -> 混凝土工程 | J8: =COUNTIF('6.混凝土'!E:E,"*監造*") -> 16 | K8: =IFERROR(J8/C8,"") -> 0.94117647 | L8: =COUNTIF('6.混凝土'!E:E,"*業主*") -> 1 | M8: =IFERROR(L8/C8,"") -> 0.058823529
A9: =ROW()-2 -> 7 | B9: 植筋工程 | C9: =COUNTA('7.植筋'!A:A)-4 -> 0 | G9: G | H9: =A9&"."&B9 -> 7.植筋工程 | I9: =B9 -> 植筋工程 | J9: =COUNTIF('7.植筋'!E:E,"*監造*") -> 0 | K9: =IFERROR(J9/C9,"") | L9: =COUNTIF('7.植筋'!E:E,"*業主*") -> 0 | M9: =IFERROR(L9/C9,"")
A10: =ROW()-2 -> 8 | B10: 預力混凝土基樁 | C10: =COUNTA('8.預力混凝土基樁'!A:A)-4 -> 3 | G10: H | H10: =A10&"."&B10 -> 8.預力混凝土基樁 | I10: =B10 -> 預力混凝土基樁 | J10: =COUNTIF('8.預力混凝土基樁'!E:E,"*監造*") -> 2 | K10: =IFERROR(J10/C10,"") -> 0.66666667 | L10: =COUNTIF('8.預力混凝土基樁'!E:E,"*業主*") -> 2 | M10: =IFERROR(L10/C10,"") -> 0.66666667
A11: =ROW()-2 -> 9 | B11: 砌塊石護岸 | C11: =COUNTA('9.砌塊石護岸'!A:A)-4 -> 0 | G11: I | H11: =A11&"."&B11 -> 9.砌塊石護岸 | I11: =B11 -> 砌塊石護岸 | J11: =COUNTIF('9.砌塊石護岸'!E:E,"*監造*") -> 0 | K11: =IFERROR(J11/C11,"") | L11: =COUNTIF('9.砌塊石護岸'!E:E,"*業主*") -> 0 | M11: =IFERROR(L11/C11,"")
A12: =ROW()-2 -> 10 | B12: 低水護岸 | C12: =COUNTA('10.低水護岸'!A:A)-4 -> 0 | G12: J | H12: =A12&"."&B12 -> 10.低水護岸 | I12: =B12 -> 低水護岸 | J12: =COUNTIF('10.低水護岸'!E:E,"*監造*") -> 0 | K12: =IFERROR(J12/C12,"") | L12: =COUNTIF('10.低水護岸'!E:E,"*業主*") -> 0 | M12: =IFERROR(L12/C12,"")
A13: =ROW()-2 -> 11 | B13: 固床工 | C13: =COUNTA('11.固床工'!A:A)-4 -> 0 | G13: K | H13: =A13&"."&B13 -> 11.固床工 | I13: =B13 -> 固床工 | J13: =COUNTIF('11.固床工'!E:E,"*監造*") -> 0 | K13: =IFERROR(J13/C13,"") | L13: =COUNTIF('11.固床工'!E:E,"*業主*") -> 0 | M13: =IFERROR(L13/C13,"")
A14: =ROW()-2 -> 12 | B14: 全套管基樁 | C14: =COUNTA('12.全套管基樁'!A:A)-4 -> 14 | G14: L | H14: =A14&"."&B14 -> 12.全套管基樁 | I14: =B14 -> 全套管基樁 | J14: =COUNTIF('12.全套管基樁'!E:E,"*監造*") -> 11 | K14: =IFERROR(J14/C14,"") -> 0.78571429 | L14: =COUNTIF('12.全套管基樁'!E:E,"*業主*") -> 1 | M14: =IFERROR(L14/C14,"") -> 0.071428571
A15: =ROW()-2 -> 13 | B15: 鋼筋混凝土管 | C15: =COUNTA('13.鋼筋混凝土管工程'!A:A)-4 -> 0 | G15: M | H15: =A15&"."&B15 -> 13.鋼筋混凝土管 | I15: =B15 -> 鋼筋混凝土管 | J15: =COUNTIF('13.鋼筋混凝土管工程'!E:E,"*監造*") -> 0 | K15: =IFERROR(J15/C15,"") | L15: =COUNTIF('13.鋼筋混凝土管工程'!E:E,"*業主*") -> 0 | M15: =IFERROR(L15/C15,"")
A16: =ROW()-2 -> 14 | B16: 鋼版樁 | C16: =COUNTA('14.鋼版樁'!A:A)-4 -> 3 | G16: N | H16: =A16&"."&B16 -> 14.鋼版樁 | I16: =B16 -> 鋼版樁 | J16: =COUNTIF('14.鋼版樁'!E:E,"*監造*") -> 2 | K16: =IFERROR(J16/C16,"") -> 0.66666667 | L16: =COUNTIF('14.鋼版樁'!E:E,"*業主*") -> 0 | M16: =IFERROR(L16/C16,"") -> 0
A17: =ROW()-2 -> 15 | B17: 路床/路基高程 | C17: =COUNTA('15.路床 路基高程'!A:A)-4 -> 0 | G17: O | H17: =A17&"."&B17 -> 15.路床/路基高程 | I17: =B17 -> 路床/路基高程 | J17: =COUNTIF('15.路床 路基高程'!E:E,"*監造*") -> 0 | K17: =IFERROR(J17/C17,"") | L17: =COUNTIF('15.路床 路基高程'!E:E,"*業主*") -> 0 | M17: =IFERROR(L17/C17,"")
A18: =ROW()-2 -> 16 | B18: 瀝青混凝土 | C18: =COUNTA('16.瀝青混凝土'!A:A)-4 -> 0 | G18: P | H18: =A18&"."&B18 -> 16.瀝青混凝土 | I18: =B18 -> 瀝青混凝土 | J18: =COUNTIF('6.混凝土'!E:E,"*監造*") -> 16 | K18: =IFERROR(J18/C18,"") | L18: =COUNTIF('6.混凝土'!E:E,"*業主*") -> 1 | M18: =IFERROR(L18/C18,"")
A19: =ROW()-2 -> 17 | B19: 景觀鋪面(一) | C19: =COUNTA('17.景觀鋪面(一)'!A:A)-4 -> 0 | G19: Q | H19: =A19&"."&B19 -> 17.景觀鋪面(一) | I19: =B19 -> 景觀鋪面(一) | J19: =COUNTIF('17.景觀鋪面(一)'!E:E,"*監造*") -> 0 | K19: =IFERROR(J19/C19,"") | L19: =COUNTIF('17.景觀鋪面(一)'!E:E,"*業主*") -> 0 | M19: =IFERROR(L19/C19,"")
A20: =ROW()-2 -> 18 | B20: 景觀鋪面(二) | C20: =COUNTA('18.景觀鋪面(二)'!A:A)-4 -> 0 | G20: R | H20: =A20&"."&B20 -> 18.景觀鋪面(二) | I20: =B20 -> 景觀鋪面(二) | J20: =COUNTIF('18.景觀鋪面(二)'!E:E,"*監造*") -> 0 | K20: =IFERROR(J20/C20,"") | L20: =COUNTIF('18.景觀鋪面(二)'!E:E,"*業主*") -> 0 | M20: =IFERROR(L20/C20,"")
A21: =ROW()-2 -> 19 | B21: 預鑄緣石 | C21: =COUNTA('19.預鑄緣石'!A:A)-4 -> 0 | G21: S | H21: =A21&"."&B21 -> 19.預鑄緣石 | I21: =B21 -> 預鑄緣石 | J21: =COUNTIF('19.預鑄緣石'!E:E,"*監造*") -> 0 | K21: =IFERROR(J21/C21,"") | L21: =COUNTIF('19.預鑄緣石'!E:E,"*業主*") -> 0 | M21: =IFERROR(L21/C21,"")
A22: =ROW()-2 -> 20 | B22: 鋼構工程吊裝 | C22: =COUNTA('20.鋼構工程吊裝'!A:A)-4 -> 0 | G22: T | H22: =A22&"."&B22 -> 20.鋼構工程吊裝 | I22: =B22 -> 鋼構工程吊裝 | J22: =COUNTIF('20.鋼構工程吊裝'!E:E,"*監造*") -> 0 | K22: =IFERROR(J22/C22,"") | L22: =COUNTIF('20.鋼構工程吊裝'!E:E,"*業主*") -> 0 | M22: =IFERROR(L22/C22,"")
A23: =ROW()-2 -> 21 | B23: 鋼構工程塗裝 | C23: =COUNTA('21.鋼構工程塗裝'!A:A)-4 -> 0 | G23: U | H23: =A23&"."&B23 -> 21.鋼構工程塗裝 | I23: =B23 -> 鋼構工程塗裝 | J23: =COUNTIF('21.鋼構工程塗裝'!E:E,"*監造*") -> 0 | K23: =IFERROR(J23/C23,"") | L23: =COUNTIF('21.鋼構工程塗裝'!E:E,"*業主*") -> 0 | M23: =IFERROR(L23/C23,"")
A24: =ROW()-2 -> 22 | B24: 排水設施(一) | C24: =COUNTA('22.排水設施(一)'!A:A)-4 -> 0 | G24: V | H24: =A24&"."&B24 -> 22.排水設施(一) | I24: =B24 -> 排水設施(一) | J24: =COUNTIF('22.排水設施(一)'!E:E,"*監造*") -> 0 | K24: =IFERROR(J24/C24,"") | L24: =COUNTIF('22.排水設施(一)'!E:E,"*業主*") -> 0 | M24: =IFERROR(L24/C24,"")
A25: =ROW()-2 -> 23 | B25: 排水設施(二) | C25: =COUNTA('23.排水設施(二)'!A:A)-4 -> 0 | G25: W | H25: =A25&"."&B25 -> 23.排水設施(二) | I25: =B25 -> 排水設施(二) | J25: =COUNTIF('23.排水設施(二)'!E:E,"*監造*") -> 0 | K25: =IFERROR(J25/C25,"") | L25: =COUNTIF('23.排水設施(二)'!E:E,"*業主*") -> 0 | M25: =IFERROR(L25/C25,"")
A26: =ROW()-2 -> 24 | B26: 木構造 | C26: =COUNTA('24.木構造'!A:A)-4 -> 0 | G26: X | H26: =A26&"."&B26 -> 24.木構造 | I26: =B26 -> 木構造 | J26: =COUNTIF('24.木構造'!E:E,"*監造*") -> 0 | K26: =IFERROR(J26/C26,"") | L26: =COUNTIF('24.木構造'!E:E,"*業主*") -> 0 | M26: =IFERROR(L26/C26,"")
A27: =ROW()-2 -> 25 | B27: 管路 | C27: =COUNTA('25.管路'!A:A)-4 -> 0 | G27: Y | H27: =A27&"."&B27 -> 25.管路 | I27: =B27 -> 管路 | J27: =COUNTIF('25.管路'!E:E,"*監造*") -> 0 | K27: =IFERROR(J27/C27,"") | L27: =COUNTIF('25.管路'!E:E,"*業主*") -> 0 | M27: =IFERROR(L27/C27,"")
A28: =ROW()-2 -> 26 | B28: 植栽(移植) | C28: =COUNTA('26.植栽(移植)'!A:A)-4 -> 7 | G28: Z | H28: =A28&"."&B28 -> 26.植栽(移植) | I28: =B28 -> 植栽(移植) | J28: =COUNTIF('26.植栽(移植)'!E:E,"*監造*") -> 3 | K28: =IFERROR(J28/C28,"") -> 0.42857143 | L28: =COUNTIF('26.植栽(移植)'!E:E,"*業主*") -> 0 | M28: =IFERROR(L28/C28,"") -> 0
A29: =ROW()-2 -> 27 | B29: 植栽(新植) | C29: =COUNTA('27.植栽(新植)'!A:A)-4 -> 0 | G29: AA | H29: =A29&"."&B29 -> 27.植栽(新植) | I29: =B29 -> 植栽(新植) | J29: =COUNTIF('27.植栽(新植)'!E:E,"*監造*") -> 0 | K29: =IFERROR(J29/C29,"") | L29: =COUNTIF('27.植栽(新植)'!E:E,"*業主*") -> 0 | M29: =IFERROR(L29/C29,"")
A30: =ROW()-2 -> 28 | B30: 照明 | C30: =COUNTA('28.照明'!A:A)-4 -> 0 | H30: =A30&"."&B30 -> 28.照明 | I30: =B30 -> 照明 | J30: =COUNTIF('28.照明'!E:E,"*監造*") -> 0 | K30: =IFERROR(J30/C30,"") | L30: =COUNTIF('28.照明'!E:E,"*業主*") -> 0 | M30: =IFERROR(L30/C30,"")
A31: =ROW()-2 -> 29 | B31: 既有橋梁拆除 | C31: =COUNTA('29.既有橋梁拆除'!A:A)-4 -> 14 | G31: AB | H31: =A31&"."&B31 -> 29.既有橋梁拆除 | I31: =B31 -> 既有橋梁拆除 | J31: =COUNTIF('29.既有橋梁拆除'!E:E,"*監造*") -> 5 | K31: =IFERROR(J31/C31,"") -> 0.35714286 | L31: =COUNTIF('29.既有橋梁拆除'!E:E,"*業主*") -> 0 | M31: =IFERROR(L31/C31,"") -> 0
A32: 合計 | C32: =SUM(C3:C31) -> 107

Sheet 1.測量放樣
A1: 臺北市政府工務局水利工程處 | F1: =CELL("filename",A1) -> \\上溢北投\d\雲端\A.上溢\1.磺港溪再造C段護岸及步道整建工程（延壽橋至三合橋）\9.施工\4.自主檢查\自主檢查統計\[磺港溪C-A自主檢查統計1130401.xlsx]1.測量放樣
A2: 磺港溪再造C段護岸及步道整建工程（延壽橋至三合橋） | G2: =RIGHT(F1,LEN(F1)-FIND("]",F1)) -> 1.測量放樣
A3: =G13&"自主檢查表統計" -> 測量放樣自主檢查表統計 | F3: . | G3: =SUBSTITUTE(G2,F3,"") -> 1測量放樣
A4: 次數 | B4: 編號 | C4: 檢查日期 | D4: 檢查部位 | E4: 備註 | F4: 0 | G4: =SUBSTITUTE(G3,F4,"") -> 1測量放樣
A5: =ROW()-4 -> 1 | B5: EA-1121113 | C5: 45243 | D5: 新設河道(0K+300~0K+450) | E5: 監造 | F5: 1 | G5: =SUBSTITUTE(G4,F5,"") -> 測量放樣
A6: =ROW()-4 -> 2 | B6: EA-1121120 | C6: 45250 | D6: 新設河道(0K+450~0K+650) | E6: 監造 | F6: 2 | G6: =SUBSTITUTE(G5,F6,"") -> 測量放樣
A7: =ROW()-4 -> 3 | B7: EA-1121202 | C7: 45262 | D7: 新設河道(0K+300~0K+450) | E7: 監造 | F7: 3 | G7: =SUBSTITUTE(G6,F7,"") -> 測量放樣
A8: =ROW()-4 -> 4 | B8: EA-1121203 | C8: 45263 | D8: 新設河道(0K+450~0K+650) | F8: 4 | G8: =SUBSTITUTE(G7,F8,"") -> 測量放樣
A9: =ROW()-4 -> 5 | B9: EA-1130106 | C9: 45297 | D9: 新設河道(0K+500~0K+650) | E9: 監造 | F9: 5 | G9: =SUBSTITUTE(G8,F9,"") -> 測量放樣
A10: =ROW()-4 -> 6 | B10: EA-1130216 | C10: 45338 | D10: 地梁(0K+500~0K+625) | F10: 6 | G10: =SUBSTITUTE(G9,F10,"") -> 測量放樣
A11: =ROW()-4 -> 7 | B11: EA-1130304 | C11: 45355 | D11: 砌石(0K+500~0K+625) | F11: 7 | G11: =SUBSTITUTE(G10,F11,"") -> 測量放樣
A12: =ROW()-4 -> 8 | B12: EA-1130314 | C12: 45365 | D12: 地梁(0K+306~0K+500) | F12: 8 | G12: =SUBSTITUTE(G11,F12,"") -> 測量放樣
F13: 9 | G13: =SUBSTITUTE(G12,F13,"") -> 測量放樣

Sheet 2.土方開挖
A1: 臺北市政府工務局水利工程處 | F1: =CELL("filename",A1) -> \\上溢北投\d\雲端\A.上溢\1.磺港溪再造C段護岸及步道整建工程（延壽橋至三合橋）\9.施工\4.自主檢查\自主檢查統計\[磺港溪C-A自主檢查統計1130401.xlsx]2.土方開挖
A2: 磺港溪再造C段護岸及步道整建工程（延壽橋至三合橋） | G2: =RIGHT(F1,LEN(F1)-FIND("]",F1)) -> 2.土方開挖
A3: =G13&"自主檢查表統計" -> 土方開挖自主檢查表統計 | F3: . | G3: =SUBSTITUTE(G2,F3,"") -> 2土方開挖
A4: 次數 | B4: 編號 | C4: 檢查日期 | D4: 檢查部位 | E4: 備註 | F4: 0 | G4: =SUBSTITUTE(G3,F4,"") -> 2土方開挖
A5: =ROW()-4 -> 1 | B5: EB-1121108 | C5: 45238 | D5: 新設河道(0K+500~0K+550)第1層 | E5: 監造 | F5: 1 | G5: =SUBSTITUTE(G4,F5,"") -> 2土方開挖
A6: =ROW()-4 -> 2 | B6: EB-1121113 | C6: 45243 | D6: 新設河道(0K+500~0K+550)第1層 | E6: 監造 | F6: 2 | G6: =SUBSTITUTE(G5,F6,"") -> 土方開挖
A7: =ROW()-4 -> 3 | B7: EB-1121116 | C7: 45246 | D7: 新設河道(0K+500~0K+550)第1層 | F7: 3 | G7: =SUBSTITUTE(G6,F7,"") -> 土方開挖
A8: =ROW()-4 -> 4 | B8: EB-1121122 | C8: 45252 | D8: 新設河道(0K+550~0K+600)第1層 | E8: 監造 | F8: 4 | G8: =SUBSTITUTE(G7,F8,"") -> 土方開挖
A9: =ROW()-4 -> 5 | B9: EB-1121123 | C9: 45253 | D9: 新設河道(0K+550~0K+600)第1層 | F9: 5 | G9: =SUBSTITUTE(G8,F9,"") -> 土方開挖
A10: =ROW()-4 -> 6 | B10: EB-1121127 | C10: 45257 | D10: 新設河道(0K+550~0K+600)第1層 | F10: 6 | G10: =SUBSTITUTE(G9,F10,"") -> 土方開挖
A11: =ROW()-4 -> 7 | B11: EB-1121204 | C11: 45264 | D11: 新設河道(0K+500~0K+550)第2層 | E11: 監造 | F11: 7 | G11: =SUBSTITUTE(G10,F11,"") -> 土方開挖
A12: =ROW()-4 -> 8 | B12: EB-1121205 | C12: 45265 | D12: 新設河道(0K+500~0K+550)第2層 | F12: 8 | G12: =SUBSTITUTE(G11,F12,"") -> 土方開挖
A13: =ROW()-4 -> 9 | B13: EB-1121206 | C13: 45266 | D13: 新設河道(0K+550~0K+600)第2層 | E13: 監造 | F13: 9 | G13: =SUBSTITUTE(G12,F13,"") -> 土方開挖
A14: =ROW()-4 -> 10 | B14: EB-1121207 | C14: 45267 | D14: 新設河道(0K+550~0K+600)第2層
A15: =ROW()-4 -> 11 | B15: EB-1121209 | C15: 45269 | D15: 新設河道(0K+550~0K+600)第2層
A16: =ROW()-4 -> 12 | B16: EB-1121210 | C16: 45270 | D16: 新設河道(0K+550~0K+600)第2層 | E16: 監造
A17: =ROW()-4 -> 13 | B17: EB-1130102 | C17: 45293 | D17: 新設河道(0K+500~0K+550)第3層 | E17: 監造
A18: =ROW()-4 -> 14 | B18: EB-1130103 | C18: 45294 | D18: 新設河道(0K+550~0K+600)第3層
A19: =ROW()-4 -> 15 | B19: EB-1130104 | C19: 45295 | D19: 新設河道(0K+550~0K+600)第3層 | E19: 監造
A20: =ROW()-4 -> 16 | B20: EB-1130216 | C20: 45338 | D20: 地梁(0K+500~0K+625)
A21: =ROW()-4 -> 17 | B21: EB-1130304 | C21: 45355 | D21: 新設河道(0K+306~0K+500)第1層
A22: =ROW()-4 -> 18 | B22: EB-1130311 | C22: 45362 | D22: 新設河道(0K+306~0K+500)第2層
A23: =ROW()-4 -> 19 | B23: EB-1130312 | C23: 45363 | D23: 新設河道(0K+306~0K+500)第2層
A24: =ROW()-4 -> 20 | B24: EB-1130313 | C24: 45364 | D24: 新設河道(0K+306~0K+500)第3層
C25: 45364 | D25: 新設河道(0K+306~0K+400)第3層 | E25: 監造、業主
A26: =ROW()-5 -> 21 | B26: EB-1130314 | C26: 45365 | D26: 地梁(0K+306~0K+500)

Sheet 3.土方回填
A1: 臺北市政府工務局水利工程處 | F1: =CELL("filename",A1) -> \\上溢北投\d\雲端\A.上溢\1.磺港溪再造C段護岸及步道整建工程（延壽橋至三合橋）\9.施工\4.自主檢查\自主檢查統計\[磺港溪C-A自主檢查統計1130401.xlsx]3.土方回填
A2: 磺港溪再造C段護岸及步道整建工程（延壽橋至三合橋） | G2: =RIGHT(F1,LEN(F1)-FIND("]",F1)) -> 3.土方回填
A3: =G13&"自主檢查表統計" -> 土方回填自主檢查表統計 | F3: . | G3: =SUBSTITUTE(G2,F3,"") -> 3土方回填
A4: 次數 | B4: 編號 | C4: 檢查日期 | D4: 檢查部位 | E4: 備註 | F4: 0 | G4: =SUBSTITUTE(G3,F4,"") -> 3土方回填
B5: EC- | F5: 1 | G5: =SUBSTITUTE(G4,F5,"") -> 3土方回填
F6: 2 | G6: =SUBSTITUTE(G5,F6,"") -> 3土方回填
F7: 3 | G7: =SUBSTITUTE(G6,F7,"") -> 土方回填
F8: 4 | G8: =SUBSTITUTE(G7,F8,"") -> 土方回填
F9: 5 | G9: =SUBSTITUTE(G8,F9,"") -> 土方回填
F10: 6 | G10: =SUBSTITUTE(G9,F10,"") -> 土方回填
F11: 7 | G11: =SUBSTITUTE(G10,F11,"") -> 土方回填
F12: 8 | G12: =SUBSTITUTE(G11,F12,"") -> 土方回填
F13: 9 | G13: =SUBSTITUTE(G12,F13,"") -> 土方回填

Sheet 4.鋼筋
A1: 臺北市政府工務局水利工程處 | F1: =CELL("filename",A1) -> \\上溢北投\d\雲端\A.上溢\1.磺港溪再造C段護岸及步道整建工程（延壽橋至三合橋）\9.施工\4.自主檢查\自主檢查統計\[磺港溪C-A自主檢查統計1130401.xlsx]4.鋼筋
A2: 磺港溪再造C段護岸及步道整建工程（延壽橋至三合橋） | G2: =RIGHT(F1,LEN(F1)-FIND("]",F1)) -> 4.鋼筋
A3: =G13&"自主檢查表統計" -> 鋼筋自主檢查表統計 | F3: . | G3: =SUBSTITUTE(G2,F3,"") -> 4鋼筋
A4: 次數 | B4: 編號 | C4: 檢查日期 | D4: 檢查部位 | E4: 備註 | F4: 0 | G4: =SUBSTITUTE(G3,F4,"") -> 4鋼筋
A5: =ROW()-4 -> 1 | B5: ED-1121225 | C5: 45285 | D5: 共月橋全套管基樁1鋼筋籠 | F5: 1 | G5: =SUBSTITUTE(G4,F5,"") -> 4鋼筋
A6: =ROW()-4 -> 2 | B6: ED-1121226 | C6: 45286 | D6: 共月橋全套管基樁1鋼筋籠 | E6: 監造 | F6: 2 | G6: =SUBSTITUTE(G5,F6,"") -> 4鋼筋
A7: =ROW()-4 -> 3 | B7: ED-1121226-1 | C7: 45286 | D7: 共月橋全套管基樁2鋼筋籠 | E7: 監造 | F7: 3 | G7: =SUBSTITUTE(G6,F7,"") -> 4鋼筋
A8: =ROW()-4 -> 4 | B8: ED-1130108 | C8: 45299 | D8: 共月橋全套管基樁3鋼筋籠 | E8: 監造 | F8: 4 | G8: =SUBSTITUTE(G7,F8,"") -> 鋼筋
A9: =ROW()-4 -> 5 | B9: ED-1130109 | C9: 45300 | D9: 共月橋全套管基樁4鋼筋籠 | E9: 監造 | F9: 5 | G9: =SUBSTITUTE(G8,F9,"") -> 鋼筋
A10: =ROW()-4 -> 6 | B10: ED-1130116 | C10: 45307 | D10: 共月橋全套管基樁5鋼筋籠 | E10: 主辦、監造 | F10: 6 | G10: =SUBSTITUTE(G9,F10,"") -> 鋼筋
A11: =ROW()-4 -> 7 | B11: ED-1130119 | C11: 45310 | D11: 共月橋全套管基樁6鋼筋籠 | E11: 監造 | F11: 7 | G11: =SUBSTITUTE(G10,F11,"") -> 鋼筋
A12: =ROW()-4 -> 8 | B12: ED-1130119-1 | C12: 45310 | D12: 共月橋全套管基樁7鋼筋籠 | E12: 監造 | F12: 8 | G12: =SUBSTITUTE(G11,F12,"") -> 鋼筋
A13: =ROW()-4 -> 9 | B13: ED-1130119-2 | C13: 45310 | D13: 共月橋全套管基樁8鋼筋籠 | E13: 監造 | F13: 9 | G13: =SUBSTITUTE(G12,F13,"") -> 鋼筋
A14: =ROW()-4 -> 10 | B14: ED-1130130 | C14: 45321 | D14: 共月橋全套管基樁9鋼筋籠 | E14: 監造
A15: =ROW()-4 -> 11 | B15: ED-1130130-1 | C15: 45321 | D15: 共月橋全套管基樁10鋼筋籠 | E15: 監造
A16: =ROW()-4 -> 12 | B16: ED-1130130-2 | C16: 45321 | D16: 共月橋全套管基樁11鋼筋籠 | E16: 監造
A17: =ROW()-4 -> 13 | B17: ED-1130220 | C17: 45342 | D17: 地梁(0K+540~0K+625) | E17: 監造
A18: =ROW()-4 -> 14 | B18: ED-1130306 | C18: 45357 | D18: 共月橋P1、P2橋台基礎 | E18: 監造
A19: =ROW()-4 -> 15 | B19: ED-1130312 | C19: 45363 | D19: 共月橋P1、P2橋墩柱 | E19: 監造
A20: =ROW()-4 -> 16 | B20: ED-1130326 | C20: 45377 | D20: 地梁(0K+306~0K+540) | E20: 監造
C21: 45377 | D21: 地梁(0K+440~0K+480) | E21: 業主、監造

Sheet 5.模板
A1: 臺北市政府工務局水利工程處 | F1: =CELL("filename",A1) -> \\上溢北投\d\雲端\A.上溢\1.磺港溪再造C段護岸及步道整建工程（延壽橋至三合橋）\9.施工\4.自主檢查\自主檢查統計\[磺港溪C-A自主檢查統計1130401.xlsx]5.模板
A2: 磺港溪再造C段護岸及步道整建工程（延壽橋至三合橋） | G2: =RIGHT(F1,LEN(F1)-FIND("]",F1)) -> 5.模板
A3: =G13&"自主檢查表統計" -> 模板自主檢查表統計 | F3: . | G3: =SUBSTITUTE(G2,F3,"") -> 5模板
A4: 次數 | B4: 編號 | C4: 檢查日期 | D4: 檢查部位 | E4: 備註 | F4: 0 | G4: =SUBSTITUTE(G3,F4,"") -> 5模板
A5: =ROW()-4 -> 1 | B5: EE-1130221 | C5: 45343 | D5: 地梁(0K+540~0K+625) | E5: 監造 | F5: 1 | G5: =SUBSTITUTE(G4,F5,"") -> 5模板
A6: =ROW()-4 -> 2 | B6: EE-1130307 | C6: 45358 | D6: 共月橋P1、P2橋台基礎 | F6: 2 | G6: =SUBSTITUTE(G5,F6,"") -> 5模板
A7: =ROW()-4 -> 3 | B7: EE-1130313 | C7: 45364 | D7: 共月橋P1、P2橋墩柱 | E7: 監造 | F7: 3 | G7: =SUBSTITUTE(G6,F7,"") -> 5模板
A8: =ROW()-4 -> 4 | B8: EE-1130327 | C8: 45378 | D8: 地梁(0K+306~0K+540) | F8: 4 | G8: =SUBSTITUTE(G7,F8,"") -> 5模板
F9: 5 | G9: =SUBSTITUTE(G8,F9,"") -> 模板
F10: 6 | G10: =SUBSTITUTE(G9,F10,"") -> 模板
F11: 7 | G11: =SUBSTITUTE(G10,F11,"") -> 模板
F12: 8 | G12: =SUBSTITUTE(G11,F12,"") -> 模板
F13: 9 | G13: =SUBSTITUTE(G12,F13,"") -> 模板

Sheet 6.混凝土
A1: 臺北市政府工務局水利工程處 | F1: =CELL("filename",A1) -> \\上溢北投\d\雲端\A.上溢\1.磺港溪再造C段護岸及步道整建工程（延壽橋至三合橋）\9.施工\4.自主檢查\自主檢查統計\[磺港溪C-A自主檢查統計1130401.xlsx]6.混凝土
A2: 磺港溪再造C段護岸及步道整建工程（延壽橋至三合橋） | G2: =RIGHT(F1,LEN(F1)-FIND("]",F1)) -> 6.混凝土
A3: =G13&"自主檢查表統計" -> 混凝土自主檢查表統計 | F3: . | G3: =SUBSTITUTE(G2,F3,"") -> 6混凝土
A4: 次數 | B4: 編號 | C4: 檢查日期 | D4: 檢查部位 | E4: 備註 | F4: 0 | G4: =SUBSTITUTE(G3,F4,"") -> 6混凝土
A5: =ROW()-4 -> 1 | B5: EF-1121229 | C5: 45289 | D5: 共月橋全套管基樁1 | E5: 監造 | F5: 1 | G5: =SUBSTITUTE(G4,F5,"") -> 6混凝土
A6: =ROW()-4 -> 2 | B6: EF-1130105 | C6: 45296 | D6: 共月橋全套管基樁2 | E6: 監造 | F6: 2 | G6: =SUBSTITUTE(G5,F6,"") -> 6混凝土
A7: =ROW()-4 -> 3 | B7: EF-1130109 | C7: 45300 | D7: 共月橋全套管基樁4 | E7: 監造 | F7: 3 | G7: =SUBSTITUTE(G6,F7,"") -> 6混凝土
A8: =ROW()-4 -> 4 | B8: EF-1130112 | C8: 45303 | D8: 共月橋全套管基樁3 | E8: 監造、業主 | F8: 4 | G8: =SUBSTITUTE(G7,F8,"") -> 6混凝土
A9: =ROW()-4 -> 5 | B9: EF-1130118 | C9: 45309 | D9: 共月橋全套管基樁5 | E9: 監造 | F9: 5 | G9: =SUBSTITUTE(G8,F9,"") -> 6混凝土
A10: =ROW()-4 -> 6 | B10: EF-1130120 | C10: 45311 | D10: 共月橋全套管基樁6 | E10: 監造 | F10: 6 | G10: =SUBSTITUTE(G9,F10,"") -> 混凝土
A11: =ROW()-4 -> 7 | B11: EF-1130123 | C11: 45314 | D11: 共月橋全套管基樁7 | E11: 監造 | F11: 7 | G11: =SUBSTITUTE(G10,F11,"") -> 混凝土
A12: =ROW()-4 -> 8 | B12: EF-1130129 | C12: 45320 | D12: 共月橋全套管基樁8 | E12: 監造 | F12: 8 | G12: =SUBSTITUTE(G11,F12,"") -> 混凝土
A13: =ROW()-4 -> 9 | B13: EF-1130130 | C13: 45321 | D13: 共月橋全套管基樁9 | E13: 監造 | F13: 9 | G13: =SUBSTITUTE(G12,F13,"") -> 混凝土
A14: =ROW()-4 -> 10 | B14: EF-1130201 | C14: 45323 | D14: 共月橋全套管基樁10、11 | E14: 監造
A15: =ROW()-4 -> 11 | B15: EF-1130217 | C15: 45339 | D15: 地梁(0K+500~0K+625)底PC | E15: 監造
A16: =ROW()-4 -> 12 | B16: EF-1130222 | C16: 45344 | D16: 地梁(0K+540~0K+625) | E16: 監造
A17: =ROW()-4 -> 13 | B17: EF-1130305 | C17: 45356 | D17: 共月橋P1、P2橋台、砌石0K+540~0K+625底
A18: =ROW()-4 -> 14 | B18: EF-1130307 | C18: 45358 | D18: 共月橋P1、P2橋台基礎 | E18: 監造
A19: =ROW()-4 -> 15 | B19: EF-1130313 | C19: 45364 | D19: 共月橋P1、P2橋墩柱 | E19: 監造
A20: =ROW()-4 -> 16 | B20: EF-1130325 | C20: 45376 | D20: 地梁(0K+306~0K+500)底PC | E20: 監造
A21: =ROW()-4 -> 17 | B21: EF-1130327 | C21: 45378 | D21: 地梁(0K+306~0K+540) | E21: 監造

Sheet 7.植筋
A1: 臺北市政府工務局水利工程處 | F1: =CELL("filename",A1) -> \\上溢北投\d\雲端\A.上溢\1.磺港溪再造C段護岸及步道整建工程（延壽橋至三合橋）\9.施工\4.自主檢查\自主檢查統計\[磺港溪C-A自主檢查統計1130401.xlsx]7.植筋
A2: 磺港溪再造C段護岸及步道整建工程（延壽橋至三合橋） | G2: =RIGHT(F1,LEN(F1)-FIND("]",F1)) -> 7.植筋
A3: =G13&"自主檢查表統計" -> 植筋自主檢查表統計 | F3: . | G3: =SUBSTITUTE(G2,F3,"") -> 7植筋
A4: 次數 | B4: 編號 | C4: 檢查日期 | D4: 檢查部位 | E4: 備註 | F4: 0 | G4: =SUBSTITUTE(G3,F4,"") -> 7植筋
B5: EG- | F5: 1 | G5: =SUBSTITUTE(G4,F5,"") -> 7植筋
F6: 2 | G6: =SUBSTITUTE(G5,F6,"") -> 7植筋
F7: 3 | G7: =SUBSTITUTE(G6,F7,"") -> 7植筋
F8: 4 | G8: =SUBSTITUTE(G7,F8,"") -> 7植筋
F9: 5 | G9: =SUBSTITUTE(G8,F9,"") -> 7植筋
F10: 6 | G10: =SUBSTITUTE(G9,F10,"") -> 7植筋
F11: 7 | G11: =SUBSTITUTE(G10,F11,"") -> 植筋
F12: 8 | G12: =SUBSTITUTE(G11,F12,"") -> 植筋
F13: 9 | G13: =SUBSTITUTE(G12,F13,"") -> 植筋

Sheet 8.預力混凝土基樁
A1: 臺北市政府工務局水利工程處 | F1: =CELL("filename",A1) -> \\上溢北投\d\雲端\A.上溢\1.磺港溪再造C段護岸及步道整建工程（延壽橋至三合橋）\9.施工\4.自主檢查\自主檢查統計\[磺港溪C-A自主檢查統計1130401.xlsx]8.預力混凝土基樁
A2: 磺港溪再造C段護岸及步道整建工程（延壽橋至三合橋） | G2: =RIGHT(F1,LEN(F1)-FIND("]",F1)) -> 8.預力混凝土基樁
A3: =G13&"自主檢查表統計" -> 預力混凝土基樁自主檢查表統計 | F3: . | G3: =SUBSTITUTE(G2,F3,"") -> 8預力混凝土基樁
A4: 次數 | B4: 編號 | C4: 檢查日期 | D4: 檢查部位 | E4: 備註 | F4: 0 | G4: =SUBSTITUTE(G3,F4,"") -> 8預力混凝土基樁
A5: =ROW()-4 -> 1 | B5: EH-1121225 | C5: 45285 | D5: 擋土牆TYPE3(施工前) | E5: 業主、監造 | F5: 1 | G5: =SUBSTITUTE(G4,F5,"") -> 8預力混凝土基樁
A6: =ROW()-4 -> 2 | B6: EH-1121227 | C6: 45287 | D6: 擋土牆TYPE3 | E6: 業主、監造 | F6: 2 | G6: =SUBSTITUTE(G5,F6,"") -> 8預力混凝土基樁
A7: =ROW()-4 -> 3 | B7: EH-1121228 | C7: 45288 | D7: 擋土牆TYPE3 | F7: 3 | G7: =SUBSTITUTE(G6,F7,"") -> 8預力混凝土基樁
F8: 4 | G8: =SUBSTITUTE(G7,F8,"") -> 8預力混凝土基樁
F9: 5 | G9: =SUBSTITUTE(G8,F9,"") -> 8預力混凝土基樁
F10: 6 | G10: =SUBSTITUTE(G9,F10,"") -> 8預力混凝土基樁
F11: 7 | G11: =SUBSTITUTE(G10,F11,"") -> 8預力混凝土基樁
F12: 8 | G12: =SUBSTITUTE(G11,F12,"") -> 預力混凝土基樁
F13: 9 | G13: =SUBSTITUTE(G12,F13,"") -> 預力混凝土基樁

Sheet 9.砌塊石護岸
A1: 臺北市政府工務局水利工程處 | F1: =CELL("filename",A1) -> \\上溢北投\d\雲端\A.上溢\1.磺港溪再造C段護岸及步道整建工程（延壽橋至三合橋）\9.施工\4.自主檢查\自主檢查統計\[磺港溪C-A自主檢查統計1130401.xlsx]9.砌塊石護岸
A2: 磺港溪再造C段護岸及步道整建工程（延壽橋至三合橋） | G2: =RIGHT(F1,LEN(F1)-FIND("]",F1)) -> 9.砌塊石護岸
A3: =G13&"自主檢查表統計" -> 砌塊石護岸自主檢查表統計 | F3: . | G3: =SUBSTITUTE(G2,F3,"") -> 9砌塊石護岸
A4: 次數 | B4: 編號 | C4: 檢查日期 | D4: 檢查部位 | E4: 備註 | F4: 0 | G4: =SUBSTITUTE(G3,F4,"") -> 9砌塊石護岸
B5: EI- | F5: 1 | G5: =SUBSTITUTE(G4,F5,"") -> 9砌塊石護岸
F6: 2 | G6: =SUBSTITUTE(G5,F6,"") -> 9砌塊石護岸
F7: 3 | G7: =SUBSTITUTE(G6,F7,"") -> 9砌塊石護岸
F8: 4 | G8: =SUBSTITUTE(G7,F8,"") -> 9砌塊石護岸
F9: 5 | G9: =SUBSTITUTE(G8,F9,"") -> 9砌塊石護岸
F10: 6 | G10: =SUBSTITUTE(G9,F10,"") -> 9砌塊石護岸
F11: 7 | G11: =SUBSTITUTE(G10,F11,"") -> 9砌塊石護岸
F12: 8 | G12: =SUBSTITUTE(G11,F12,"") -> 9砌塊石護岸
F13: 9 | G13: =SUBSTITUTE(G12,F13,"") -> 砌塊石護岸

Sheet 10.低水護岸
A1: 臺北市政府工務局水利工程處 | F1: =CELL("filename",A1) -> \\上溢北投\d\雲端\A.上溢\1.磺港溪再造C段護岸及步道整建工程（延壽橋至三合橋）\9.施工\4.自主檢查\自主檢查統計\[磺港溪C-A自主檢查統計1130401.xlsx]10.低水護岸
A2: 磺港溪再造C段護岸及步道整建工程（延壽橋至三合橋） | G2: =RIGHT(F1,LEN(F1)-FIND("]",F1)) -> 10.低水護岸
A3: =G13&"自主檢查表統計" -> 低水護岸自主檢查表統計 | F3: . | G3: =SUBSTITUTE(G2,F3,"") -> 10低水護岸
A4: 次數 | B4: 編號 | C4: 檢查日期 | D4: 檢查部位 | E4: 備註 | F4: 0 | G4: =SUBSTITUTE(G3,F4,"") -> 1低水護岸
B5: EJ- | F5: 1 | G5: =SUBSTITUTE(G4,F5,"") -> 低水護岸
F6: 2 | G6: =SUBSTITUTE(G5,F6,"") -> 低水護岸
F7: 3 | G7: =SUBSTITUTE(G6,F7,"") -> 低水護岸
F8: 4 | G8: =SUBSTITUTE(G7,F8,"") -> 低水護岸
F9: 5 | G9: =SUBSTITUTE(G8,F9,"") -> 低水護岸
F10: 6 | G10: =SUBSTITUTE(G9,F10,"") -> 低水護岸
F11: 7 | G11: =SUBSTITUTE(G10,F11,"") -> 低水護岸
F12: 8 | G12: =SUBSTITUTE(G11,F12,"") -> 低水護岸
F13: 9 | G13: =SUBSTITUTE(G12,F13,"") -> 低水護岸

Sheet 11.固床工
A1: 臺北市政府工務局水利工程處 | F1: =CELL("filename",A1) -> \\上溢北投\d\雲端\A.上溢\1.磺港溪再造C段護岸及步道整建工程（延壽橋至三合橋）\9.施工\4.自主檢查\自主檢查統計\[磺港溪C-A自主檢查統計1130401.xlsx]11.固床工
A2: 磺港溪再造C段護岸及步道整建工程（延壽橋至三合橋） | G2: =RIGHT(F1,LEN(F1)-FIND("]",F1)) -> 11.固床工
A3: =G13&"自主檢查表統計" -> 固床工自主檢查表統計 | F3: . | G3: =SUBSTITUTE(G2,F3,"") -> 11固床工
A4: 次數 | B4: 編號 | C4: 檢查日期 | D4: 檢查部位 | E4: 備註 | F4: 0 | G4: =SUBSTITUTE(G3,F4,"") -> 11固床工
B5: EK- | F5: 1 | G5: =SUBSTITUTE(G4,F5,"") -> 固床工
F6: 2 | G6: =SUBSTITUTE(G5,F6,"") -> 固床工
F7: 3 | G7: =SUBSTITUTE(G6,F7,"") -> 固床工
F8: 4 | G8: =SUBSTITUTE(G7,F8,"") -> 固床工
F9: 5 | G9: =SUBSTITUTE(G8,F9,"") -> 固床工
F10: 6 | G10: =SUBSTITUTE(G9,F10,"") -> 固床工
F11: 7 | G11: =SUBSTITUTE(G10,F11,"") -> 固床工
F12: 8 | G12: =SUBSTITUTE(G11,F12,"") -> 固床工
F13: 9 | G13: =SUBSTITUTE(G12,F13,"") -> 固床工

Sheet 12.全套管基樁
A1: 臺北市政府工務局水利工程處 | F1: =CELL("filename",A1) -> \\上溢北投\d\雲端\A.上溢\1.磺港溪再造C段護岸及步道整建工程（延壽橋至三合橋）\9.施工\4.自主檢查\自主檢查統計\[磺港溪C-A自主檢查統計1130401.xlsx]12.全套管基樁
A2: 磺港溪再造C段護岸及步道整建工程（延壽橋至三合橋） | G2: =RIGHT(F1,LEN(F1)-FIND("]",F1)) -> 12.全套管基樁
A3: =G11&"自主檢查表統計" -> 全套管基樁自主檢查表統計 | F3: . | G3: =SUBSTITUTE(G2,F3,"") -> 12全套管基樁
A4: 次數 | B4: 編號 | C4: 檢查日期 | D4: 檢查部位 | E4: 備註 | F4: 0 | G4: =SUBSTITUTE(G3,F4,"") -> 12全套管基樁
A5: =ROW()-4 -> 1 | B5: EL-1121229 | C5: 45289 | D5: 共月橋全套管基樁1 | E5: 監造 | F5: 1 | G5: =SUBSTITUTE(G4,F5,"") -> 2全套管基樁
A6: =ROW()-4 -> 2 | B6: EL-1130105 | C6: 45296 | D6: 共月橋全套管基樁2 | E6: 監造 | F6: 2 | G6: =SUBSTITUTE(G5,F6,"") -> 全套管基樁
A7: =ROW()-4 -> 3 | B7: EL-1130109 | C7: 45300 | D7: 共月橋全套管基樁4 | E7: 監造 | F7: 3 | G7: =SUBSTITUTE(G6,F7,"") -> 全套管基樁
A8: =ROW()-4 -> 4 | B8: EL-1130111 | C8: 45302 | D8: 共月橋全套管基樁3 | E8: 監造 | F8: 4 | G8: =SUBSTITUTE(G7,F8,"") -> 全套管基樁
A9: =ROW()-4 -> 5 | B9: EL-1130112 | C9: 45303 | D9: 共月橋全套管基樁3澆置 | F9: 5 | G9: =SUBSTITUTE(G8,F9,"") -> 全套管基樁
A10: =ROW()-4 -> 6 | B10: EL-1130117 | C10: 45308 | D10: 共月橋全套管基樁5 | E10: 監造 | F10: 6 | G10: =SUBSTITUTE(G9,F10,"") -> 全套管基樁
A11: =ROW()-4 -> 7 | B11: EL-1130118 | C11: 45309 | D11: 共月橋全套管基樁5澆置 | F11: 7 | G11: =SUBSTITUTE(G10,F11,"") -> 全套管基樁
A12: =ROW()-4 -> 8 | B12: EL-1130120 | C12: 45311 | D12: 共月橋全套管基樁6 | E12: 監造 | F12: 8 | G12: =SUBSTITUTE(G11,F12,"") -> 全套管基樁
A13: =ROW()-4 -> 9 | B13: EL-1130123 | C13: 45314 | D13: 共月橋全套管基樁7 | E13: 監造 | F13: 9 | G13: =SUBSTITUTE(G12,F13,"") -> 全套管基樁
A14: =ROW()-4 -> 10 | B14: EL-1130129 | C14: 45320 | D14: 共月橋全套管基樁8 | E14: 監造
A15: =ROW()-4 -> 11 | B15: EL-1130130 | C15: 45321 | D15: 共月橋全套管基樁9 | E15: 監造
A16: =ROW()-4 -> 12 | B16: EL-1130131 | C16: 45322 | D16: 共月橋全套管基樁10 | E16: 監造
A17: =ROW()-4 -> 13 | B17: EL-1130201 | C17: 45323 | D17: 共月橋全套管基樁11 | E17: 業主、監造
A18: =ROW()-4 -> 14 | B18: EL-1130201-1 | C18: 45323 | D18: 共月橋全套管基樁10、11澆置

Sheet 13.鋼筋混凝土管工程
A1: 臺北市政府工務局水利工程處 | F1: =CELL("filename",A1) -> \\上溢北投\d\雲端\A.上溢\1.磺港溪再造C段護岸及步道整建工程（延壽橋至三合橋）\9.施工\4.自主檢查\自主檢查統計\[磺港溪C-A自主檢查統計1130401.xlsx]13.鋼筋混凝土管工程
A2: 磺港溪再造C段護岸及步道整建工程（延壽橋至三合橋） | G2: =RIGHT(F1,LEN(F1)-FIND("]",F1)) -> 13.鋼筋混凝土管工程
A3: =G13&"自主檢查表統計" -> 鋼筋混凝土管工程自主檢查表統計 | F3: . | G3: =SUBSTITUTE(G2,F3,"") -> 13鋼筋混凝土管工程
A4: 次數 | B4: 編號 | C4: 檢查日期 | D4: 檢查部位 | E4: 備註 | F4: 0 | G4: =SUBSTITUTE(G3,F4,"") -> 13鋼筋混凝土管工程
B5: EM- | F5: 1 | G5: =SUBSTITUTE(G4,F5,"") -> 3鋼筋混凝土管工程
F6: 2 | G6: =SUBSTITUTE(G5,F6,"") -> 3鋼筋混凝土管工程
F7: 3 | G7: =SUBSTITUTE(G6,F7,"") -> 鋼筋混凝土管工程
F8: 4 | G8: =SUBSTITUTE(G7,F8,"") -> 鋼筋混凝土管工程
F9: 5 | G9: =SUBSTITUTE(G8,F9,"") -> 鋼筋混凝土管工程
F10: 6 | G10: =SUBSTITUTE(G9,F10,"") -> 鋼筋混凝土管工程
F11: 7 | G11: =SUBSTITUTE(G10,F11,"") -> 鋼筋混凝土管工程
F12: 8 | G12: =SUBSTITUTE(G11,F12,"") -> 鋼筋混凝土管工程
F13: 9 | G13: =SUBSTITUTE(G12,F13,"") -> 鋼筋混凝土管工程

Sheet 14.鋼版樁
A1: 臺北市政府工務局水利工程處 | F1: =CELL("filename",A1) -> \\上溢北投\d\雲端\A.上溢\1.磺港溪再造C段護岸及步道整建工程（延壽橋至三合橋）\9.施工\4.自主檢查\自主檢查統計\[磺港溪C-A自主檢查統計1130401.xlsx]14.鋼版樁
A2: 磺港溪再造C段護岸及步道整建工程（延壽橋至三合橋） | G2: =RIGHT(F1,LEN(F1)-FIND("]",F1)) -> 14.鋼版樁
A3: =G13&"自主檢查表統計" -> 鋼版樁自主檢查表統計 | F3: . | G3: =SUBSTITUTE(G2,F3,"") -> 14鋼版樁
A4: 次數 | B4: 編號 | C4: 檢查日期 | D4: 檢查部位 | E4: 備註 | F4: 0 | G4: =SUBSTITUTE(G3,F4,"") -> 14鋼版樁
A5: =ROW()-4 -> 1 | B5: EN-1121207 | C5: 45267 | D5: 共月橋圍堰 | E5: 監造 | F5: 1 | G5: =SUBSTITUTE(G4,F5,"") -> 4鋼版樁
A6: =ROW()-4 -> 2 | B6: EN-1121219 | C6: 45279 | D6: 擋土牆TYPE3 | E6: 監造 | F6: 2 | G6: =SUBSTITUTE(G5,F6,"") -> 4鋼版樁
A7: =ROW()-4 -> 3 | B7: EN-1130313 | C7: 45364 | D7: 三合橋圍堰 | F7: 3 | G7: =SUBSTITUTE(G6,F7,"") -> 4鋼版樁
F8: 4 | G8: =SUBSTITUTE(G7,F8,"") -> 鋼版樁
F9: 5 | G9: =SUBSTITUTE(G8,F9,"") -> 鋼版樁
F10: 6 | G10: =SUBSTITUTE(G9,F10,"") -> 鋼版樁
F11: 7 | G11: =SUBSTITUTE(G10,F11,"") -> 鋼版樁
F12: 8 | G12: =SUBSTITUTE(G11,F12,"") -> 鋼版樁
F13: 9 | G13: =SUBSTITUTE(G12,F13,"") -> 鋼版樁

Sheet 15.路床 路基高程
A1: 臺北市政府工務局水利工程處 | F1: =CELL("filename",A1) -> \\上溢北投\d\雲端\A.上溢\1.磺港溪再造C段護岸及步道整建工程（延壽橋至三合橋）\9.施工\4.自主檢查\自主檢查統計\[磺港溪C-A自主檢查統計1130401.xlsx]15.路床 路基高程
A2: 磺港溪再造C段護岸及步道整建工程（延壽橋至三合橋） | G2: =RIGHT(F1,LEN(F1)-FIND("]",F1)) -> 15.路床 路基高程
A3: =G13&"自主檢查表統計" -> 路床 路基高程自主檢查表統計 | F3: . | G3: =SUBSTITUTE(G2,F3,"") -> 15路床 路基高程
A4: 次數 | B4: 編號 | C4: 檢查日期 | D4: 檢查部位 | E4: 備註 | F4: 0 | G4: =SUBSTITUTE(G3,F4,"") -> 15路床 路基高程
B5: EO- | F5: 1 | G5: =SUBSTITUTE(G4,F5,"") -> 5路床 路基高程
F6: 2 | G6: =SUBSTITUTE(G5,F6,"") -> 5路床 路基高程
F7: 3 | G7: =SUBSTITUTE(G6,F7,"") -> 5路床 路基高程
F8: 4 | G8: =SUBSTITUTE(G7,F8,"") -> 5路床 路基高程
F9: 5 | G9: =SUBSTITUTE(G8,F9,"") -> 路床 路基高程
F10: 6 | G10: =SUBSTITUTE(G9,F10,"") -> 路床 路基高程
F11: 7 | G11: =SUBSTITUTE(G10,F11,"") -> 路床 路基高程
F12: 8 | G12: =SUBSTITUTE(G11,F12,"") -> 路床 路基高程
F13: 9 | G13: =SUBSTITUTE(G12,F13,"") -> 路床 路基高程

Sheet 16.瀝青混凝土
A1: 臺北市政府工務局水利工程處 | F1: =CELL("filename",A1) -> \\上溢北投\d\雲端\A.上溢\1.磺港溪再造C段護岸及步道整建工程（延壽橋至三合橋）\9.施工\4.自主檢查\自主檢查統計\[磺港溪C-A自主檢查統計1130401.xlsx]16.瀝青混凝土
A2: 磺港溪再造C段護岸及步道整建工程（延壽橋至三合橋） | G2: =RIGHT(F1,LEN(F1)-FIND("]",F1)) -> 16.瀝青混凝土
A3: =G13&"自主檢查表統計" -> 瀝青混凝土自主檢查表統計 | F3: . | G3: =SUBSTITUTE(G2,F3,"") -> 16瀝青混凝土
A4: 次數 | B4: 編號 | C4: 檢查日期 | D4: 檢查部位 | E4: 備註 | F4: 0 | G4: =SUBSTITUTE(G3,F4,"") -> 16瀝青混凝土
B5: EP- | F5: 1 | G5: =SUBSTITUTE(G4,F5,"") -> 6瀝青混凝土
F6: 2 | G6: =SUBSTITUTE(G5,F6,"") -> 6瀝青混凝土
F7: 3 | G7: =SUBSTITUTE(G6,F7,"") -> 6瀝青混凝土
F8: 4 | G8: =SUBSTITUTE(G7,F8,"") -> 6瀝青混凝土
F9: 5 | G9: =SUBSTITUTE(G8,F9,"") -> 6瀝青混凝土
F10: 6 | G10: =SUBSTITUTE(G9,F10,"") -> 瀝青混凝土
F11: 7 | G11: =SUBSTITUTE(G10,F11,"") -> 瀝青混凝土
F12: 8 | G12: =SUBSTITUTE(G11,F12,"") -> 瀝青混凝土
F13: 9 | G13: =SUBSTITUTE(G12,F13,"") -> 瀝青混凝土

Sheet 17.景觀鋪面(一)
A1: 臺北市政府工務局水利工程處 | F1: =CELL("filename",A1) -> \\上溢北投\d\雲端\A.上溢\1.磺港溪再造C段護岸及步道整建工程（延壽橋至三合橋）\9.施工\4.自主檢查\自主檢查統計\[磺港溪C-A自主檢查統計1130401.xlsx]17.景觀鋪面(一)
A2: 磺港溪再造C段護岸及步道整建工程（延壽橋至三合橋） | G2: =RIGHT(F1,LEN(F1)-FIND("]",F1)) -> 17.景觀鋪面(一)
A3: =G13&"自主檢查表統計" -> 景觀鋪面(一)自主檢查表統計 | F3: . | G3: =SUBSTITUTE(G2,F3,"") -> 17景觀鋪面(一)
A4: 次數 | B4: 編號 | C4: 檢查日期 | D4: 檢查部位 | E4: 備註 | F4: 0 | G4: =SUBSTITUTE(G3,F4,"") -> 17景觀鋪面(一)
B5: EQ- | F5: 1 | G5: =SUBSTITUTE(G4,F5,"") -> 7景觀鋪面(一)
F6: 2 | G6: =SUBSTITUTE(G5,F6,"") -> 7景觀鋪面(一)
F7: 3 | G7: =SUBSTITUTE(G6,F7,"") -> 7景觀鋪面(一)
F8: 4 | G8: =SUBSTITUTE(G7,F8,"") -> 7景觀鋪面(一)
F9: 5 | G9: =SUBSTITUTE(G8,F9,"") -> 7景觀鋪面(一)
F10: 6 | G10: =SUBSTITUTE(G9,F10,"") -> 7景觀鋪面(一)
F11: 7 | G11: =SUBSTITUTE(G10,F11,"") -> 景觀鋪面(一)
F12: 8 | G12: =SUBSTITUTE(G11,F12,"") -> 景觀鋪面(一)
F13: 9 | G13: =SUBSTITUTE(G12,F13,"") -> 景觀鋪面(一)

Sheet 18.景觀鋪面(二)
A1: 臺北市政府工務局水利工程處 | F1: =CELL("filename",A1) -> \\上溢北投\d\雲端\A.上溢\1.磺港溪再造C段護岸及步道整建工程（延壽橋至三合橋）\9.施工\4.自主檢查\自主檢查統計\[磺港溪C-A自主檢查統計1130401.xlsx]18.景觀鋪面(二)
A2: 磺港溪再造C段護岸及步道整建工程（延壽橋至三合橋） | G2: =RIGHT(F1,LEN(F1)-FIND("]",F1)) -> 18.景觀鋪面(二)
A3: =G13&"自主檢查表統計" -> 景觀鋪面(二)自主檢查表統計 | F3: . | G3: =SUBSTITUTE(G2,F3,"") -> 18景觀鋪面(二)
A4: 次數 | B4: 編號 | C4: 檢查日期 | D4: 檢查部位 | E4: 備註 | F4: 0 | G4: =SUBSTITUTE(G3,F4,"") -> 18景觀鋪面(二)
B5: ER- | F5: 1 | G5: =SUBSTITUTE(G4,F5,"") -> 8景觀鋪面(二)
F6: 2 | G6: =SUBSTITUTE(G5,F6,"") -> 8景觀鋪面(二)
F7: 3 | G7: =SUBSTITUTE(G6,F7,"") -> 8景觀鋪面(二)
F8: 4 | G8: =SUBSTITUTE(G7,F8,"") -> 8景觀鋪面(二)
F9: 5 | G9: =SUBSTITUTE(G8,F9,"") -> 8景觀鋪面(二)
F10: 6 | G10: =SUBSTITUTE(G9,F10,"") -> 8景觀鋪面(二)
F11: 7 | G11: =SUBSTITUTE(G10,F11,"") -> 8景觀鋪面(二)
F12: 8 | G12: =SUBSTITUTE(G11,F12,"") -> 景觀鋪面(二)
F13: 9 | G13: =SUBSTITUTE(G12,F13,"") -> 景觀鋪面(二)

Sheet 19.預鑄緣石
A1: 臺北市政府工務局水利工程處 | F1: =CELL("filename",A1) -> \\上溢北投\d\雲端\A.上溢\1.磺港溪再造C段護岸及步道整建工程（延壽橋至三合橋）\9.施工\4.自主檢查\自主檢查統計\[磺港溪C-A自主檢查統計1130401.xlsx]19.預鑄緣石
A2: 磺港溪再造C段護岸及步道整建工程（延壽橋至三合橋） | G2: =RIGHT(F1,LEN(F1)-FIND("]",F1)) -> 19.預鑄緣石
A3: =G13&"自主檢查表統計" -> 預鑄緣石自主檢查表統計 | F3: . | G3: =SUBSTITUTE(G2,F3,"") -> 19預鑄緣石
A4: 次數 | B4: 編號 | C4: 檢查日期 | D4: 檢查部位 | E4: 備註 | F4: 0 | G4: =SUBSTITUTE(G3,F4,"") -> 19預鑄緣石
B5: ES- | F5: 1 | G5: =SUBSTITUTE(G4,F5,"") -> 9預鑄緣石
F6: 2 | G6: =SUBSTITUTE(G5,F6,"") -> 9預鑄緣石
F7: 3 | G7: =SUBSTITUTE(G6,F7,"") -> 9預鑄緣石
F8: 4 | G8: =SUBSTITUTE(G7,F8,"") -> 9預鑄緣石
F9: 5 | G9: =SUBSTITUTE(G8,F9,"") -> 9預鑄緣石
F10: 6 | G10: =SUBSTITUTE(G9,F10,"") -> 9預鑄緣石
F11: 7 | G11: =SUBSTITUTE(G10,F11,"") -> 9預鑄緣石
F12: 8 | G12: =SUBSTITUTE(G11,F12,"") -> 9預鑄緣石
F13: 9 | G13: =SUBSTITUTE(G12,F13,"") -> 預鑄緣石

Sheet 20.鋼構工程吊裝
A1: 臺北市政府工務局水利工程處 | F1: =CELL("filename",A1) -> \\上溢北投\d\雲端\A.上溢\1.磺港溪再造C段護岸及步道整建工程（延壽橋至三合橋）\9.施工\4.自主檢查\自主檢查統計\[磺港溪C-A自主檢查統計1130401.xlsx]20.鋼構工程吊裝
A2: 磺港溪再造C段護岸及步道整建工程（延壽橋至三合橋） | G2: =RIGHT(F1,LEN(F1)-FIND("]",F1)) -> 20.鋼構工程吊裝
A3: =G13&"自主檢查表統計" -> 鋼構工程吊裝自主檢查表統計 | F3: . | G3: =SUBSTITUTE(G2,F3,"") -> 20鋼構工程吊裝
A4: 次數 | B4: 編號 | C4: 檢查日期 | D4: 檢查部位 | E4: 備註 | F4: 0 | G4: =SUBSTITUTE(G3,F4,"") -> 2鋼構工程吊裝
B5: ET- | F5: 1 | G5: =SUBSTITUTE(G4,F5,"") -> 2鋼構工程吊裝
F6: 2 | G6: =SUBSTITUTE(G5,F6,"") -> 鋼構工程吊裝
F7: 3 | G7: =SUBSTITUTE(G6,F7,"") -> 鋼構工程吊裝
F8: 4 | G8: =SUBSTITUTE(G7,F8,"") -> 鋼構工程吊裝
F9: 5 | G9: =SUBSTITUTE(G8,F9,"") -> 鋼構工程吊裝
F10: 6 | G10: =SUBSTITUTE(G9,F10,"") -> 鋼構工程吊裝
F11: 7 | G11: =SUBSTITUTE(G10,F11,"") -> 鋼構工程吊裝
F12: 8 | G12: =SUBSTITUTE(G11,F12,"") -> 鋼構工程吊裝
F13: 9 | G13: =SUBSTITUTE(G12,F13,"") -> 鋼構工程吊裝

Sheet 21.鋼構工程塗裝
A1: 臺北市政府工務局水利工程處 | F1: =CELL("filename",A1) -> \\上溢北投\d\雲端\A.上溢\1.磺港溪再造C段護岸及步道整建工程（延壽橋至三合橋）\9.施工\4.自主檢查\自主檢查統計\[磺港溪C-A自主檢查統計1130401.xlsx]21.鋼構工程塗裝
A2: 磺港溪再造C段護岸及步道整建工程（延壽橋至三合橋） | G2: =RIGHT(F1,LEN(F1)-FIND("]",F1)) -> 21.鋼構工程塗裝
A3: =G13&"自主檢查表統計" -> 鋼構工程塗裝自主檢查表統計 | F3: . | G3: =SUBSTITUTE(G2,F3,"") -> 21鋼構工程塗裝
A4: 次數 | B4: 編號 | C4: 檢查日期 | D4: 檢查部位 | E4: 備註 | F4: 0 | G4: =SUBSTITUTE(G3,F4,"") -> 21鋼構工程塗裝
B5: EU- | F5: 1 | G5: =SUBSTITUTE(G4,F5,"") -> 2鋼構工程塗裝
F6: 2 | G6: =SUBSTITUTE(G5,F6,"") -> 鋼構工程塗裝
F7: 3 | G7: =SUBSTITUTE(G6,F7,"") -> 鋼構工程塗裝
F8: 4 | G8: =SUBSTITUTE(G7,F8,"") -> 鋼構工程塗裝
F9: 5 | G9: =SUBSTITUTE(G8,F9,"") -> 鋼構工程塗裝
F10: 6 | G10: =SUBSTITUTE(G9,F10,"") -> 鋼構工程塗裝
F11: 7 | G11: =SUBSTITUTE(G10,F11,"") -> 鋼構工程塗裝
F12: 8 | G12: =SUBSTITUTE(G11,F12,"") -> 鋼構工程塗裝
F13: 9 | G13: =SUBSTITUTE(G12,F13,"") -> 鋼構工程塗裝

Sheet 22.排水設施(一)
A1: 臺北市政府工務局水利工程處 | F1: =CELL("filename",A1) -> \\上溢北投\d\雲端\A.上溢\1.磺港溪再造C段護岸及步道整建工程（延壽橋至三合橋）\9.施工\4.自主檢查\自主檢查統計\[磺港溪C-A自主檢查統計1130401.xlsx]22.排水設施(一)
A2: 磺港溪再造C段護岸及步道整建工程（延壽橋至三合橋） | G2: =RIGHT(F1,LEN(F1)-FIND("]",F1)) -> 22.排水設施(一)
A3: =G13&"自主檢查表統計" -> 排水設施(一)自主檢查表統計 | F3: . | G3: =SUBSTITUTE(G2,F3,"") -> 22排水設施(一)
A4: 次數 | B4: 編號 | C4: 檢查日期 | D4: 檢查部位 | E4: 備註 | F4: 0 | G4: =SUBSTITUTE(G3,F4,"") -> 22排水設施(一)
B5: EV- | F5: 1 | G5: =SUBSTITUTE(G4,F5,"") -> 22排水設施(一)
F6: 2 | G6: =SUBSTITUTE(G5,F6,"") -> 排水設施(一)
F7: 3 | G7: =SUBSTITUTE(G6,F7,"") -> 排水設施(一)
F8: 4 | G8: =SUBSTITUTE(G7,F8,"") -> 排水設施(一)
F9: 5 | G9: =SUBSTITUTE(G8,F9,"") -> 排水設施(一)
F10: 6 | G10: =SUBSTITUTE(G9,F10,"") -> 排水設施(一)
F11: 7 | G11: =SUBSTITUTE(G10,F11,"") -> 排水設施(一)
F12: 8 | G12: =SUBSTITUTE(G11,F12,"") -> 排水設施(一)
F13: 9 | G13: =SUBSTITUTE(G12,F13,"") -> 排水設施(一)

Sheet 23.排水設施(二)
A1: 臺北市政府工務局水利工程處 | F1: =CELL("filename",A1) -> \\上溢北投\d\雲端\A.上溢\1.磺港溪再造C段護岸及步道整建工程（延壽橋至三合橋）\9.施工\4.自主檢查\自主檢查統計\[磺港溪C-A自主檢查統計1130401.xlsx]23.排水設施(二)
A2: 磺港溪再造C段護岸及步道整建工程（延壽橋至三合橋） | G2: =RIGHT(F1,LEN(F1)-FIND("]",F1)) -> 23.排水設施(二)
A3: =G13&"自主檢查表統計" -> 排水設施(二)自主檢查表統計 | F3: . | G3: =SUBSTITUTE(G2,F3,"") -> 23排水設施(二)
A4: 次數 | B4: 編號 | C4: 檢查日期 | D4: 檢查部位 | E4: 備註 | F4: 0 | G4: =SUBSTITUTE(G3,F4,"") -> 23排水設施(二)
B5: EW- | F5: 1 | G5: =SUBSTITUTE(G4,F5,"") -> 23排水設施(二)
F6: 2 | G6: =SUBSTITUTE(G5,F6,"") -> 3排水設施(二)
F7: 3 | G7: =SUBSTITUTE(G6,F7,"") -> 排水設施(二)
F8: 4 | G8: =SUBSTITUTE(G7,F8,"") -> 排水設施(二)
F9: 5 | G9: =SUBSTITUTE(G8,F9,"") -> 排水設施(二)
F10: 6 | G10: =SUBSTITUTE(G9,F10,"") -> 排水設施(二)
F11: 7 | G11: =SUBSTITUTE(G10,F11,"") -> 排水設施(二)
F12: 8 | G12: =SUBSTITUTE(G11,F12,"") -> 排水設施(二)
F13: 9 | G13: =SUBSTITUTE(G12,F13,"") -> 排水設施(二)

Sheet 24.木構造
A1: 臺北市政府工務局水利工程處 | F1: =CELL("filename",A1) -> \\上溢北投\d\雲端\A.上溢\1.磺港溪再造C段護岸及步道整建工程（延壽橋至三合橋）\9.施工\4.自主檢查\自主檢查統計\[磺港溪C-A自主檢查統計1130401.xlsx]24.木構造
A2: 磺港溪再造C段護岸及步道整建工程（延壽橋至三合橋） | G2: =RIGHT(F1,LEN(F1)-FIND("]",F1)) -> 24.木構造
A3: =G13&"自主檢查表統計" -> 木構造自主檢查表統計 | F3: . | G3: =SUBSTITUTE(G2,F3,"") -> 24木構造
A4: 次數 | B4: 編號 | C4: 檢查日期 | D4: 檢查部位 | E4: 備註 | F4: 0 | G4: =SUBSTITUTE(G3,F4,"") -> 24木構造
B5: EX- | F5: 1 | G5: =SUBSTITUTE(G4,F5,"") -> 24木構造
F6: 2 | G6: =SUBSTITUTE(G5,F6,"") -> 4木構造
F7: 3 | G7: =SUBSTITUTE(G6,F7,"") -> 4木構造
F8: 4 | G8: =SUBSTITUTE(G7,F8,"") -> 木構造
F9: 5 | G9: =SUBSTITUTE(G8,F9,"") -> 木構造
F10: 6 | G10: =SUBSTITUTE(G9,F10,"") -> 木構造
F11: 7 | G11: =SUBSTITUTE(G10,F11,"") -> 木構造
F12: 8 | G12: =SUBSTITUTE(G11,F12,"") -> 木構造
F13: 9 | G13: =SUBSTITUTE(G12,F13,"") -> 木構造

Sheet 25.管路
A1: 臺北市政府工務局水利工程處 | F1: =CELL("filename",A1) -> \\上溢北投\d\雲端\A.上溢\1.磺港溪再造C段護岸及步道整建工程（延壽橋至三合橋）\9.施工\4.自主檢查\自主檢查統計\[磺港溪C-A自主檢查統計1130401.xlsx]25.管路
