Workbook

Sheet 統計圖
A1: 自主檢查統計表
A2: 編號 | B2: 項目 | C2: 檢查次數 | I2: 項目 | J2: 監造 | L2: 業主
A3: =ROW()-2 -> 1 | B3: 測量放樣 | C3: =COUNTA('1.測量放樣'!A:A)-4 -> 7 | G3: A | H3: =A3&"."&B3 -> 1.測量放樣 | I3: =B3 -> 測量放樣 | J3: =COUNTIF('1.測量放樣'!E:E,"*監造*") -> 4 | K3: =IFERROR(J3/C3,"") -> 0.57142857 | L3: =COUNTIF('1.測量放樣'!E:E,"*業主*") -> 0 | M3: =IFERROR(L3/C3,"") -> 0
A4: =ROW()-2 -> 2 | B4: 土方開挖 | C4: =COUNTA('2.土方開挖'!A:A)-4 -> 16 | G4: B | H4: =A4&"."&B4 -> 2.土方開挖 | I4: =B4 -> 土方開挖 | J4: =COUNTIF('2.土方開挖'!E:E,"*監造*") -> 8 | K4: =IFERROR(J4/C4,"") -> 0.5 | L4: =COUNTIF('2.土方開挖'!E:E,"*業主*") -> 0 | M4: =IFERROR(L4/C4,"") -> 0
A5: =ROW()-2 -> 3 | B5: 土方回填(含級配) | C5: =COUNTA('3.土方回填'!A:A)-4 -> 0 | G5: C | H5: =A5&"."&B5 -> 3.土方回填(含級配) | I5: =B5 -> 土方回填(含級配) | J5: =COUNTIF('3.土方回填'!E:E,"*監造*") -> 0 | K5: =IFERROR(J5/C5,"") | L5: =COUNTIF('3.土方回填'!E:E,"*業主*") -> 0 | M5: =IFERROR(L5/C5,"")
A6: =ROW()-2 -> 4 | B6: 鋼筋工程 | C6: =COUNTA('4.鋼筋'!A:A)-4 -> 14 | G6: D | H6: =A6&"."&B6 -> 4.鋼筋工程 | I6: =B6 -> 鋼筋工程 | J6: =COUNTIF('4.鋼筋'!E:E,"*監造*") -> 12 | K6: =IFERROR(J6/C6,"") -> 0.85714286 | L6: =COUNTIF('4.鋼筋'!E:E,"*業主*") -> 0 | M6: =IFERROR(L6/C6,"") -> 0
A7: =ROW()-2 -> 5 | B7: 模板工程 | C7: =COUNTA('5.模板'!A:A)-4 -> 2 | G7: E | H7: =A7&"."&B7 -> 5.模板工程 | I7: =B7 -> 模板工程 | J7: =COUNTIF('5.模板'!E:E,"*監造*") -> 1 | K7: =IFERROR(J7/C7,"") -> 0.5 | L7: =COUNTIF('5.模板'!E:E,"*業主*") -> 0 | M7: =IFERROR(L7/C7,"") -> 0
A8: =ROW()-2 -> 6 | B8: 混凝土工程 | C8: =COUNTA('6.混凝土'!A:A)-4 -> 14 | G8: F | H8: =A8&"."&B8 -> 6.混凝土工程 | I8: =B8 -> 混凝土工程 | J8: =COUNTIF('6.混凝土'!E:E,"*監造*") -> 13 | K8: =IFERROR(J8/C8,"") -> 0.92857143 | L8: =COUNTIF('6.混凝土'!E:E,"*業主*") -> 1 | M8: =IFERROR(L8/C8,"") -> 0.071428571
A9: =ROW()-2 -> 7 | B9: 植筋工程 | C9: =COUNTA('7.植筋'!A:A)-4 -> 0 | G9: G | H9: =A9&"."&B9 -> 7.植筋工程 | I9: =B9 -> 植筋工程 | J9: =COUNTIF('7.植筋'!E:E,"*監造*") -> 0 | K9: =IFERROR(J9/C9,"") | L9: =COUNTIF('7.植筋'!E:E,"*業主*") -> 0 | M9: =IFERROR(L9/C9,"")
A10: =ROW()-2 -> 8 | B10: 預力混凝土基樁 | C10: =COUNTA('8.預力混凝土基樁'!A:A)-4 -> 3 | G10: H | H10: =A10&"."&B10 -> 8.預力混凝土基樁 | I10: =B10 -> 預力混凝土基樁 | J10: =COUNTIF('8.預力混凝土基樁'!E:E,"*監造*") -> 2 | K10: =IFERROR(J10/C10,"") -> 0.66666667 | L10: =COUNTIF('8.預力混凝土基樁'!E:E,"*業主*") -> 2 | M10: =IFERROR(L10/C10,"") -> 0.66666667
A11: =ROW()-2 -> 9 | B11: 砌塊石護岸 | C11: =COUNTA('9.砌塊石護岸'!A:A)-4 -> 0 | G11: I | H11: =A11&"."&B11 -> 9.砌塊石護岸 | I11: =B11 -> 砌塊石護岸 | J11: =COUNTIF('9.砌塊石護岸'!E:E,"*監造*") -> 0 | K11: =IFERROR(J11/C11,"") | L11: =COUNTIF('9.砌塊石護岸'!E:E,"*業主*") -> 0 | M11: =IFERROR(L11/C11,"")
A12: =ROW()-2 -> 10 | B12: 低水護岸 | C12: =COUNTA('10.低水護岸'!A:A)-4 -> 0 | G12: J | H12: =A12&"."&B12 -> 10.低水護岸 | I12: =B12 -> 低水護岸 | J12: =COUNTIF('10.低水護岸'!E:E,"*監造*") -> 0 | K12: =IFERROR(J12/C12,"") | L12: =COUNTIF('10.低水護岸'!E:E,"*業主*") -> 0 | M12: =IFERROR(L12/C12,"")
A13: =ROW()-2 -> 11 | B13: 固床工 | C13: =COUNTA('11.固床工'!A:A)-4 -> 0 | G13: K | H13: =A13&"."&B13 -> 11.固床工 | I13: =B13 -> 固床工 | J13: =COUNTIF('11.固床工'!E:E,"*監造*") -> 0 | K13: =IFERROR(J13/C13,"") | L13: =COUNTIF('11.固床工'!E:E,"*業主*") -> 0 | M13: =IFERROR(L13/C13,"")
A14: =ROW()-2 -> 12 | B14: 全套管基樁 | C14: =COUNTA('12.全套管基樁'!A:A)-4 -> 14 | G14: L | H14: =A14&"."&B14 -> 12.全套管基樁 | I14: =B14 -> 全套管基樁 | J14: =COUNTIF('12.全套管基樁'!E:E,"*監造*") -> 11 | K14: =IFERROR(J14/C14,"") -> 0.78571429 | L14: =COUNTIF('12.全套管基樁'!E:E,"*業主*") -> 1 | M14: =IFERROR(L14/C14,"") -> 0.071428571
A15: =ROW()-2 -> 13 | B15: 鋼筋混凝土管 | C15: =COUNTA('13.鋼筋混凝土管工程'!A:A)-4 -> 0 | G15: M | H15: =A15&"."&B15 -> 13.鋼筋混凝土管 | I15: =B15 -> 鋼筋混凝土管 | J15: =COUNTIF('13.鋼筋混凝土管工程'!E:E,"*監造*") -> 0 | K15: =IFERROR(J15/C15,"") | L15: =COUNTIF('13.鋼筋混凝土管工程'!E:E,"*業主*") -> 0 | M15: =IFERROR(L15/C15,"")
A16: =ROW()-2 -> 14 | B16: 鋼版樁 | C16: =COUNTA('14.鋼版樁'!A:A)-4 -> 2 | G16: N | H16: =A16&"."&B16 -> 14.鋼版樁 | I16: =B16 -> 鋼版樁 | J16: =COUNTIF('14.鋼版樁'!E:E,"*監造*") -> 2 | K16: =IFERROR(J16/C16,"") -> 1 | L16: =COUNTIF('14.鋼版樁'!E:E,"*業主*") -> 0 | M16: =IFERROR(L16/C16,"") -> 0
A17: =ROW()-2 -> 15 | B17: 路床/路基高程 | C17: =COUNTA('15.路床 路基高程'!A:A)-4 -> 0 | G17: O | H17: =A17&"."&B17 -> 15.路床/路基高程 | I17: =B17 -> 路床/路基高程 | J17: =COUNTIF('15.路床 路基高程'!E:E,"*監造*") -> 0 | K17: =IFERROR(J17/C17,"") | L17: =COUNTIF('15.路床 路基高程'!E:E,"*業主*") -> 0 | M17: =IFERROR(L17/C17,"")
A18: =ROW()-2 -> 16 | B18: 瀝青混凝土 | C18: =COUNTA('16.瀝青混凝土'!A:A)-4 -> 0 | G18: P | H18: =A18&"."&B18 -> 16.瀝青混凝土 | I18: =B18 -> 瀝青混凝土 | J18: =COUNTIF('6.混凝土'!E:E,"*監造*") -> 13 | K18: =IFERROR(J18/C18,"") | L18: =COUNTIF('6.混凝土'!E:E,"*業主*") -> 1 | M18: =IFERROR(L18/C18,"")
A19: =ROW()-2 -> 17 | B19: 景觀鋪面(一) | C19: =COUNTA('17.景觀鋪面(一)'!A:A)-4 -> 0 | G19: Q | H19: =A19&"."&B19 -> 17.景觀鋪面(一) | I19: =B19 -> 景觀鋪面(一) | J19: =COUNTIF('17.景觀鋪面(一)'!E:E,"*監造*") -> 0 | K19: =IFERROR(J19/C19,"") | L19: =COUNTIF('17.景觀鋪面(一)'!E:E,"*業主*") -> 0 | M19: =IFERROR(L19/C19,"")
A20: =ROW()-2 -> 18 | B20: 景觀鋪面(二) | C20: =COUNTA('18.景觀鋪面(二)'!A:A)-4 -> 0 | G20: R | H20: =A20&"."&B20 -> 18.景觀鋪面(二) | I20: =B20 -> 景觀鋪面(二) | J20: =COUNTIF('18.景觀鋪面(二)'!E:E,"*監造*") -> 0 | K20: =IFERROR(J20/C20,"") | L20: =COUNTIF('18.景觀鋪面(二)'!E:E,"*業主*") -> 0 | M20: =IFERROR(L20/C20,"")
A21: =ROW()-2 -> 19 | B21: 預鑄緣石 | C21: =COUNTA('19.預鑄緣石'!A:A)-4 -> 0 | G21: S | H21: =A21&"."&B21 -> 19.預鑄緣石 | I21: =B21 -> 預鑄緣石 | J21: =COUNTIF('19.預鑄緣石'!E:E,"*監造*") -> 0 | K21: =IFERROR(J21/C21,"") | L21: =COUNTIF('19.預鑄緣石'!E:E,"*業主*") -> 0 | M21: =IFERROR(L21/C21,"")
A22: =ROW()-2 -> 20 | B22: 鋼構工程吊裝 | C22: =COUNTA('20.鋼構工程吊裝'!A:A)-4 -> 0 | G22: T | H22: =A22&"."&B22 -> 20.鋼構工程吊裝 | I22: =B22 -> 鋼構工程吊裝 | J22: =COUNTIF('20.鋼構工程吊裝'!E:E,"*監造*") -> 0 | K22: =IFERROR(J22/C22,"") | L22: =COUNTIF('20.鋼構工程吊裝'!E:E,"*業主*") -> 0 | M22: =IFERROR(L22/C22,"")
A23: =ROW()-2 -> 21 | B23: 鋼構工程塗裝 | C23: =COUNTA('21.鋼構工程塗裝'!A:A)-4 -> 0 | G23: U | H23: =A23&"."&B23 -> 21.鋼構工程塗裝 | I23: =B23 -> 鋼構工程塗裝 | J23: =COUNTIF('21.鋼構工程塗裝'!E:E,"*監造*") -> 0 | K23: =IFERROR(J23/C23,"") | L23: =COUNTIF('21.鋼構工程塗裝'!E:E,"*業主*") -> 0 | M23: =IFERROR(L23/C23,"")
A24: =ROW()-2 -> 22 | B24: 排水設施(一) | C24: =COUNTA('22.排水設施(一)'!A:A)-4 -> 0 | G24: V | H24: =A24&"."&B24 -> 22.排水設施(一) | I24: =B24 -> 排水設施(一) | J24: =COUNTIF('22.排水設施(一)'!E:E,"*監造*") -> 0 | K24: =IFERROR(J24/C24,"") | L24: =COUNTIF('22.排水設施(一)'!E:E,"*業主*") -> 0 | M24: =IFERROR(L24/C24,"")
A25: =ROW()-2 -> 23 | B25: 排水設施(二) | C25: =COUNTA('23.排水設施(二)'!A:A)-4 -> 0 | G25: W | H25: =A25&"."&B25 -> 23.排水設施(二) | I25: =B25 -> 排水設施(二) | J25: =COUNTIF('23.排水設施(二)'!E:E,"*監造*") -> 0 | K25: =IFERROR(J25/C25,"") | L25: =COUNTIF('23.排水設施(二)'!E:E,"*業主*") -> 0 | M25: =IFERROR(L25/C25,"")
A26: =ROW()-2 -> 24 | B26: 木構造 | C26: =COUNTA('24.木構造'!A:A)-4 -> 0 | G26: X | H26: =A26&"."&B26 -> 24.木構造 | I26: =B26 -> 木構造 | J26: =COUNTIF('24.木構造'!E:E,"*監造*") -> 0 | K26: =IFERROR(J26/C26,"") | L26: =COUNTIF('24.木構造'!E:E,"*業主*") -> 0 | M26: =IFERROR(L26/C26,"")
A27: =ROW()-2 -> 25 | B27: 管路 | C27: =COUNTA('25.管路'!A:A)-4 -> 0 | G27: Y | H27: =A27&"."&B27 -> 25.管路 | I27: =B27 -> 管路 | J27: =COUNTIF('25.管路'!E:E,"*監造*") -> 0 | K27: =IFERROR(J27/C27,"") | L27: =COUNTIF('25.管路'!E:E,"*業主*") -> 0 | M27: =IFERROR(L27/C27,"")
A28: =ROW()-2 -> 26 | B28: 植栽(移植) | C28: =COUNTA('26.植栽(移植)'!A:A)-4 -> 7 | G28: Z | H28: =A28&"."&B28 -> 26.植栽(移植) | I28: =B28 -> 植栽(移植) | J28: =COUNTIF('26.植栽(移植)'!E:E,"*監造*") -> 3 | K28: =IFERROR(J28/C28,"") -> 0.42857143 | L28: =COUNTIF('26.植栽(移植)'!E:E,"*業主*") -> 0 | M28: =IFERROR(L28/C28,"") -> 0
A29: =ROW()-2 -> 27 | B29: 植栽(新植) | C29: =COUNTA('27.植栽(新植)'!A:A)-4 -> 0 | G29: AA | H29: =A29&"."&B29 -> 27.植栽(新植) | I29: =B29 -> 植栽(新植) | J29: =COUNTIF('27.植栽(新植)'!E:E,"*監造*") -> 0 | K29: =IFERROR(J29/C29,"") | L29: =COUNTIF('27.植栽(新植)'!E:E,"*業主*") -> 0 | M29: =IFERROR(L29/C29,"")
A30: =ROW()-2 -> 28 | B30: 照明 | C30: =COUNTA('28.照明'!A:A)-4 -> 0 | H30: =A30&"."&B30 -> 28.照明 | I30: =B30 -> 照明 | J30: =COUNTIF('28.照明'!E:E,"*監造*") -> 0 | K30: =IFERROR(J30/C30,"") | L30: =COUNTIF('28.照明'!E:E,"*業主*") -> 0 | M30: =IFERROR(L30/C30,"")
A31: =ROW()-2 -> 29 | B31: 既有橋梁拆除 | C31: =COUNTA('29.既有橋梁拆除'!A:A)-4 -> 14 | G31: AB | H31: =A31&"."&B31 -> 29.既有橋梁拆除 | I31: =B31 -> 既有橋梁拆除 | J31: =COUNTIF('29.既有橋梁拆除'!E:E,"*監造*") -> 6 | K31: =IFERROR(J31/C31,"") -> 0.42857143 | L31: =COUNTIF('29.既有橋梁拆除'!E:E,"*業主*") -> 0 | M31: =IFERROR(L31/C31,"") -> 0
A32: 合計 | C32: =SUM(C3:C31) -> 93

Sheet 1.測量放樣
A1: 臺北市政府工務局水利工程處 | F1: =CELL("filename",A1) -> \\上溢北投\d\雲端\A.上溢\1.磺港溪再造C段護岸及步道整建工程（延壽橋至三合橋）\9.施工\4.自主檢查\自主檢查統計\[磺港溪C-A自主檢查統計1130311.xlsx]1.測量放樣
A2: 磺港溪再造C段護岸及步道整建工程（延壽橋至三合橋） | G2: =RIGHT(F1,LEN(F1)-FIND("]",F1)) -> 1.測量放樣
A3: =G13&"自主檢查表統計" -> 測量放樣自主檢查表統計 | F3: . | G3: =SUBSTITUTE(G2,F3,"") -> 1測量放樣
A4: 次數 | B4: 編號 | C4: 檢查日期 | D4: 檢查部位 | E4: 備註 | F4: 0 | G4: =SUBSTITUTE(G3,F4,"") -> 1測量放樣
A5: =ROW()-4 -> 1 | B5: EA-1121113 | C5: 45243 | D5: 新設河道(0K+300~0K+450) | E5: 監造 | F5: 1 | G5: =SUBSTITUTE(G4,F5,"") -> 測量放樣
A6: =ROW()-4 -> 2 | B6: EA-1121120 | C6: 45250 | D6: 新設河道(0K+450~0K+650) | E6: 監造 | F6: 2 | G6: =SUBSTITUTE(G5,F6,"") -> 測量放樣
A7: =ROW()-4 -> 3 | B7: EA-1121202 | C7: 45262 | D7: 新設河道(0K+300~0K+450) | E7: 監造 | F7: 3 | G7: =SUBSTITUTE(G6,F7,"") -> 測量放樣
A8: =ROW()-4 -> 4 | B8: EA-1121203 | C8: 45263 | D8: 新設河道(0K+450~0K+650) | F8: 4 | G8: =SUBSTITUTE(G7,F8,"") -> 測量放樣
A9: =ROW()-4 -> 5 | B9: EA-1130106 | C9: 45297 | D9: 新設河道(0K+500~0K+650) | E9: 監造 | F9: 5 | G9: =SUBSTITUTE(G8,F9,"") -> 測量放樣
A10: =ROW()-4 -> 6 | B10: EA-1130216 | C10: 45338 | D10: 地梁(0K+500~0K+625) | F10: 6 | G10: =SUBSTITUTE(G9,F10,"") -> 測量放樣
A11: =ROW()-4 -> 7 | B11: EA-1130304 | C11: 45355 | D11: 砌石(0K+500~0K+625) | F11: 7 | G11: =SUBSTITUTE(G10,F11,"") -> 測量放樣
F12: 8 | G12: =SUBSTITUTE(G11,F12,"") -> 測量放樣
F13: 9 | G13: =SUBSTITUTE(G12,F13,"") -> 測量放樣

Sheet 2.土方開挖
A1: 臺北市政府工務局水利工程處 | F1: =CELL("filename",A1) -> \\上溢北投\d\雲端\A.上溢\1.磺港溪再造C段護岸及步道整建工程（延壽橋至三合橋）\9.施工\4.自主檢查\自主檢查統計\[磺港溪C-A自主檢查統計1130311.xlsx]2.土方開挖
A2: 磺港溪再造C段護岸及步道整建工程（延壽橋至三合橋） | G2: =RIGHT(F1,LEN(F1)-FIND("]",F1)) -> 2.土方開挖
A3: =G13&"自主檢查表統計" -> 土方開挖自主檢查表統計 | F3: . | G3: =SUBSTITUTE(G2,F3,"") -> 2土方開挖
A4: 次數 | B4: 編號 | C4: 檢查日期 | D4: 檢查部位 | E4: 備註 | F4: 0 | G4: =SUBSTITUTE(G3,F4,"") -> 2土方開挖
A5: =ROW()-4 -> 1 | B5: EB-1121108 | C5: 45238 | D5: 新設河道(0K+500~0K+550)第1層 | E5: 監造 | F5: 1 | G5: =SUBSTITUTE(G4,F5,"") -> 2土方開挖
A6: =ROW()-4 -> 2 | B6: EB-1121113 | C6: 45243 | D6: 新設河道(0K+500~0K+550)第1層 | E6: 監造 | F6: 2 | G6: =SUBSTITUTE(G5,F6,"") -> 土方開挖
A7: =ROW()-4 -> 3 | B7: EB-1121116 | C7: 45246 | D7: 新設河道(0K+500~0K+550)第1層 | F7: 3 | G7: =SUBSTITUTE(G6,F7,"") -> 土方開挖
A8: =ROW()-4 -> 4 | B8: EB-1121122 | C8: 45252 | D8: 新設河道(0K+550~0K+600)第1層 | E8: 監造 | F8: 4 | G8: =SUBSTITUTE(G7,F8,"") -> 土方開挖
A9: =ROW()-4 -> 5 | B9: EB-1121123 | C9: 45253 | D9: 新設河道(0K+550~0K+600)第1層 | F9: 5 | G9: =SUBSTITUTE(G8,F9,"") -> 土方開挖
A10: =ROW()-4 -> 6 | B10: EB-1121127 | C10: 45257 | D10: 新設河道(0K+550~0K+600)第1層 | F10: 6 | G10: =SUBSTITUTE(G9,F10,"") -> 土方開挖
A11: =ROW()-4 -> 7 | B11: EB-1121204 | C11: 45264 | D11: 新設河道(0K+500~0K+550)第2層 | E11: 監造 | F11: 7 | G11: =SUBSTITUTE(G10,F11,"") -> 土方開挖
A12: =ROW()-4 -> 8 | B12: EB-1121205 | C12: 45265 | D12: 新設河道(0K+500~0K+550)第2層 | F12: 8 | G12: =SUBSTITUTE(G11,F12,"") -> 土方開挖
A13: =ROW()-4 -> 9 | B13: EB-1121206 | C13: 45266 | D13: 新設河道(0K+550~0K+600)第2層 | E13: 監造 | F13: 9 | G13: =SUBSTITUTE(G12,F13,"") -> 土方開挖
A14: =ROW()-4 -> 10 | B14: EB-1121207 | C14: 45267 | D14: 新設河道(0K+550~0K+600)第2層
A15: =ROW()-4 -> 11 | B15: EB-1121209 | C15: 45269 | D15: 新設河道(0K+550~0K+600)第2層
A16: =ROW()-4 -> 12 | B16: EB-1121210 | C16: 45270 | D16: 新設河道(0K+550~0K+600)第2層 | E16: 監造
A17: =ROW()-4 -> 13 | B17: EB-1130102 | C17: 45293 | D17: 新設河道(0K+500~0K+550)第3層 | E17: 監造
A18: =ROW()-4 -> 14 | B18: EB-1130103 | C18: 45294 | D18: 新設河道(0K+550~0K+600)第3層
A19: =ROW()-4 -> 15 | B19: EB-1130104 | C19: 45295 | D19: 新設河道(0K+550~0K+600)第3層 | E19: 監造
A20: =ROW()-4 -> 16 | B20: EB-1130216 | C20: 45338 | D20: 地梁(0K+500~0K+625)

Sheet 3.土方回填
A1: 臺北市政府工務局水利工程處 | F1: =CELL("filename",A1) -> \\上溢北投\d\雲端\A.上溢\1.磺港溪再造C段護岸及步道整建工程（延壽橋至三合橋）\9.施工\4.自主檢查\自主檢查統計\[磺港溪C-A自主檢查統計1130311.xlsx]3.土方回填
A2: 磺港溪再造C段護岸及步道整建工程（延壽橋至三合橋） | G2: =RIGHT(F1,LEN(F1)-FIND("]",F1)) -> 3.土方回填
A3: =G13&"自主檢查表統計" -> 土方回填自主檢查表統計 | F3: . | G3: =SUBSTITUTE(G2,F3,"") -> 3土方回填
A4: 次數 | B4: 編號 | C4: 檢查日期 | D4: 檢查部位 | E4: 備註 | F4: 0 | G4: =SUBSTITUTE(G3,F4,"") -> 3土方回填
B5: EC- | F5: 1 | G5: =SUBSTITUTE(G4,F5,"") -> 3土方回填
F6: 2 | G6: =SUBSTITUTE(G5,F6,"") -> 3土方回填
F7: 3 | G7: =SUBSTITUTE(G6,F7,"") -> 土方回填
F8: 4 | G8: =SUBSTITUTE(G7,F8,"") -> 土方回填
F9: 5 | G9: =SUBSTITUTE(G8,F9,"") -> 土方回填
F10: 6 | G10: =SUBSTITUTE(G9,F10,"") -> 土方回填
F11: 7 | G11: =SUBSTITUTE(G10,F11,"") -> 土方回填
F12: 8 | G12: =SUBSTITUTE(G11,F12,"") -> 土方回填
F13: 9 | G13: =SUBSTITUTE(G12,F13,"") -> 土方回填

Sheet 4.鋼筋
A1: 臺北市政府工務局水利工程處 | F1: =CELL("filename",A1) -> \\上溢北投\d\雲端\A.上溢\1.磺港溪再造C段護岸及步道整建工程（延壽橋至三合橋）\9.施工\4.自主檢查\自主檢查統計\[磺港溪C-A自主檢查統計1130311.xlsx]4.鋼筋
A2: 磺港溪再造C段護岸及步道整建工程（延壽橋至三合橋） | G2: =RIGHT(F1,LEN(F1)-FIND("]",F1)) -> 4.鋼筋
A3: =G13&"自主檢查表統計" -> 鋼筋自主檢查表統計 | F3: . | G3: =SUBSTITUTE(G2,F3,"") -> 4鋼筋
A4: 次數 | B4: 編號 | C4: 檢查日期 | D4: 檢查部位 | E4: 備註 | F4: 0 | G4: =SUBSTITUTE(G3,F4,"") -> 4鋼筋
A5: =ROW()-4 -> 1 | B5: ED-1121225 | C5: 45285 | D5: 共月橋全套管基樁1鋼筋籠 | F5: 1 | G5: =SUBSTITUTE(G4,F5,"") -> 4鋼筋
A6: =ROW()-4 -> 2 | B6: ED-1121226 | C6: 45286 | D6: 共月橋全套管基樁1鋼筋籠 | E6: 監造 | F6: 2 | G6: =SUBSTITUTE(G5,F6,"") -> 4鋼筋
A7: =ROW()-4 -> 3 | B7: ED-1121226-1 | C7: 45286 | D7: 共月橋全套管基樁2鋼筋籠 | E7: 監造 | F7: 3 | G7: =SUBSTITUTE(G6,F7,"") -> 4鋼筋
A8: =ROW()-4 -> 4 | B8: ED-1130108 | C8: 45299 | D8: 共月橋全套管基樁3鋼筋籠 | E8: 監造 | F8: 4 | G8: =SUBSTITUTE(G7,F8,"") -> 鋼筋
A9: =ROW()-4 -> 5 | B9: ED-1130109 | C9: 45300 | D9: 共月橋全套管基樁4鋼筋籠 | E9: 監造 | F9: 5 | G9: =SUBSTITUTE(G8,F9,"") -> 鋼筋
A10: =ROW()-4 -> 6 | B10: ED-1130116 | C10: 45307 | D10: 共月橋全套管基樁5鋼筋籠 | E10: 主辦、監造 | F10: 6 | G10: =SUBSTITUTE(G9,F10,"") -> 鋼筋
A11: =ROW()-4 -> 7 | B11: ED-1130119 | C11: 45310 | D11: 共月橋全套管基樁6鋼筋籠 | E11: 監造 | F11: 7 | G11: =SUBSTITUTE(G10,F11,"") -> 鋼筋
A12: =ROW()-4 -> 8 | B12: ED-1130119-1 | C12: 45310 | D12: 共月橋全套管基樁7鋼筋籠 | E12: 監造 | F12: 8 | G12: =SUBSTITUTE(G11,F12,"") -> 鋼筋
A13: =ROW()-4 -> 9 | B13: ED-1130119-2 | C13: 45310 | D13: 共月橋全套管基樁8鋼筋籠 | E13: 監造 | F13: 9 | G13: =SUBSTITUTE(G12,F13,"") -> 鋼筋
A14: =ROW()-4 -> 10 | B14: ED-1130130 | C14: 45321 | D14: 共月橋全套管基樁9鋼筋籠 | E14: 監造
A15: =ROW()-4 -> 11 | B15: ED-1130130-1 | C15: 45321 | D15: 共月橋全套管基樁10鋼筋籠 | E15: 監造
A16: =ROW()-4 -> 12 | B16: ED-1130130-2 | C16: 45321 | D16: 共月橋全套管基樁11鋼筋籠 | E16: 監造
A17: =ROW()-4 -> 13 | B17: ED-1130220 | C17: 45342 | D17: 地梁(0K+540~0K+625) | E17: 監造
A18: =ROW()-4 -> 14 | B18: ED-1130306 | C18: 45357 | D18: 共月橋P1、P2橋台基礎

Sheet 5.模板
A1: 臺北市政府工務局水利工程處 | F1: =CELL("filename",A1) -> \\上溢北投\d\雲端\A.上溢\1.磺港溪再造C段護岸及步道整建工程（延壽橋至三合橋）\9.施工\4.自主檢查\自主檢查統計\[磺港溪C-A自主檢查統計1130311.xlsx]5.模板
A2: 磺港溪再造C段護岸及步道整建工程（延壽橋至三合橋） | G2: =RIGHT(F1,LEN(F1)-FIND("]",F1)) -> 5.模板
A3: =G13&"自主檢查表統計" -> 模板自主檢查表統計 | F3: . | G3: =SUBSTITUTE(G2,F3,"") -> 5模板
A4: 次數 | B4: 編號 | C4: 檢查日期 | D4: 檢查部位 | E4: 備註 | F4: 0 | G4: =SUBSTITUTE(G3,F4,"") -> 5模板
A5: =ROW()-4 -> 1 | B5: EE-1130221 | C5: 45343 | D5: 地梁(0K+540~0K+625) | E5: 監造 | F5: 1 | G5: =SUBSTITUTE(G4,F5,"") -> 5模板
A6: =ROW()-4 -> 2 | B6: EE-1130307 | C6: 45358 | D6: 共月橋P1、P2橋台基礎 | F6: 2 | G6: =SUBSTITUTE(G5,F6,"") -> 5模板
F7: 3 | G7: =SUBSTITUTE(G6,F7,"") -> 5模板
F8: 4 | G8: =SUBSTITUTE(G7,F8,"") -> 5模板
F9: 5 | G9: =SUBSTITUTE(G8,F9,"") -> 模板
F10: 6 | G10: =SUBSTITUTE(G9,F10,"") -> 模板
F11: 7 | G11: =SUBSTITUTE(G10,F11,"") -> 模板
F12: 8 | G12: =SUBSTITUTE(G11,F12,"") -> 模板
F13: 9 | G13: =SUBSTITUTE(G12,F13,"") -> 模板

Sheet 6.混凝土
A1: 臺北市政府工務局水利工程處 | F1: =CELL("filename",A1) -> \\上溢北投\d\雲端\A.上溢\1.磺港溪再造C段護岸及步道整建工程（延壽橋至三合橋）\9.施工\4.自主檢查\自主檢查統計\[磺港溪C-A自主檢查統計1130311.xlsx]6.混凝土
A2: 磺港溪再造C段護岸及步道整建工程（延壽橋至三合橋） | G2: =RIGHT(F1,LEN(F1)-FIND("]",F1)) -> 6.混凝土
A3: =G13&"自主檢查表統計" -> 混凝土自主檢查表統計 | F3: . | G3: =SUBSTITUTE(G2,F3,"") -> 6混凝土
A4: 次數 | B4: 編號 | C4: 檢查日期 | D4: 檢查部位 | E4: 備註 | F4: 0 | G4: =SUBSTITUTE(G3,F4,"") -> 6混凝土
A5: =ROW()-4 -> 1 | B5: EF-1121229 | C5: 45289 | D5: 共月橋全套管基樁1 | E5: 監造 | F5: 1 | G5: =SUBSTITUTE(G4,F5,"") -> 6混凝土
A6: =ROW()-4 -> 2 | B6: EF-1130105 | C6: 45296 | D6: 共月橋全套管基樁2 | E6: 監造 | F6: 2 | G6: =SUBSTITUTE(G5,F6,"") -> 6混凝土
A7: =ROW()-4 -> 3 | B7: EF-1130109 | C7: 45300 | D7: 共月橋全套管基樁4 | E7: 監造 | F7: 3 | G7: =SUBSTITUTE(G6,F7,"") -> 6混凝土
A8: =ROW()-4 -> 4 | B8: EF-1130112 | C8: 45303 | D8: 共月橋全套管基樁3 | E8: 監造、業主 | F8: 4 | G8: =SUBSTITUTE(G7,F8,"") -> 6混凝土
A9: =ROW()-4 -> 5 | B9: EF-1130118 | C9: 45309 | D9: 共月橋全套管基樁5 | E9: 監造 | F9: 5 | G9: =SUBSTITUTE(G8,F9,"") -> 6混凝土
A10: =ROW()-4 -> 6 | B10: EF-1130120 | C10: 45311 | D10: 共月橋全套管基樁6 | E10: 監造 | F10: 6 | G10: =SUBSTITUTE(G9,F10,"") -> 混凝土
A11: =ROW()-4 -> 7 | B11: EF-1130123 | C11: 45314 | D11: 共月橋全套管基樁7 | E11: 監造 | F11: 7 | G11: =SUBSTITUTE(G10,F11,"") -> 混凝土
A12: =ROW()-4 -> 8 | B12: EF-1130129 | C12: 45320 | D12: 共月橋全套管基樁8 | E12: 監造 | F12: 8 | G12: =SUBSTITUTE(G11,F12,"") -> 混凝土
A13: =ROW()-4 -> 9 | B13: EF-1130130 | C13: 45321 | D13: 共月橋全套管基樁9 | E13: 監造 | F13: 9 | G13: =SUBSTITUTE(G12,F13,"") -> 混凝土
A14: =ROW()-4 -> 10 | B14: EF-1130201 | C14: 45323 | D14: 共月橋全套管基樁10、11 | E14: 監造
A15: =ROW()-4 -> 11 | B15: EF-1130217 | C15: 45339 | D15: 地梁(0K+540~0K+625)底PC | E15: 監造
A16: =ROW()-4 -> 12 | B16: EF-1130222 | C16: 45344 | D16: 地梁(0K+540~0K+625) | E16: 監造
A17: =ROW()-4 -> 13 | B17: EF-1130305 | C17: 45356 | D17: 共月橋P1、P2橋台、砌石0K+540~0K+625底
A18: =ROW()-4 -> 14 | B18: EF-1130307 | C18: 45358 | D18: 共月橋P1、P2橋台基礎 | E18: 監造

Sheet 7.植筋
A1: 臺北市政府工務局水利工程處 | F1: =CELL("filename",A1) -> \\上溢北投\d\雲端\A.上溢\1.磺港溪再造C段護岸及步道整建工程（延壽橋至三合橋）\9.施工\4.自主檢查\自主檢查統計\[磺港溪C-A自主檢查統計1130311.xlsx]7.植筋
A2: 磺港溪再造C段護岸及步道整建工程（延壽橋至三合橋） | G2: =RIGHT(F1,LEN(F1)-FIND("]",F1)) -> 7.植筋
A3: =G13&"自主檢查表統計" -> 植筋自主檢查表統計 | F3: . | G3: =SUBSTITUTE(G2,F3,"") -> 7植筋
A4: 次數 | B4: 編號 | C4: 檢查日期 | D4: 檢查部位 | E4: 備註 | F4: 0 | G4: =SUBSTITUTE(G3,F4,"") -> 7植筋
B5: EG- | F5: 1 | G5: =SUBSTITUTE(G4,F5,"") -> 7植筋
F6: 2 | G6: =SUBSTITUTE(G5,F6,"") -> 7植筋
F7: 3 | G7: =SUBSTITUTE(G6,F7,"") -> 7植筋
F8: 4 | G8: =SUBSTITUTE(G7,F8,"") -> 7植筋
F9: 5 | G9: =SUBSTITUTE(G8,F9,"") -> 7植筋
F10: 6 | G10: =SUBSTITUTE(G9,F10,"") -> 7植筋
F11: 7 | G11: =SUBSTITUTE(G10,F11,"") -> 植筋
F12: 8 | G12: =SUBSTITUTE(G11,F12,"") -> 植筋
F13: 9 | G13: =SUBSTITUTE(G12,F13,"") -> 植筋

Sheet 8.預力混凝土基樁
A1: 臺北市政府工務局水利工程處 | F1: =CELL("filename",A1) -> \\上溢北投\d\雲端\A.上溢\1.磺港溪再造C段護岸及步道整建工程（延壽橋至三合橋）\9.施工\4.自主檢查\自主檢查統計\[磺港溪C-A自主檢查統計1130311.xlsx]8.預力混凝土基樁
A2: 磺港溪再造C段護岸及步道整建工程（延壽橋至三合橋） | G2: =RIGHT(F1,LEN(F1)-FIND("]",F1)) -> 8.預力混凝土基樁
A3: =G13&"自主檢查表統計" -> 預力混凝土基樁自主檢查表統計 | F3: . | G3: =SUBSTITUTE(G2,F3,"") -> 8預力混凝土基樁
A4: 次數 | B4: 編號 | C4: 檢查日期 | D4: 檢查部位 | E4: 備註 | F4: 0 | G4: =SUBSTITUTE(G3,F4,"") -> 8預力混凝土基樁
A5: =ROW()-4 -> 1 | B5: EH-1121225 | C5: 45285 | D5: 擋土牆TYPE3(施工前) | E5: 業主、監造 | F5: 1 | G5: =SUBSTITUTE(G4,F5,"") -> 8預力混凝土基樁
A6: =ROW()-4 -> 2 | B6: EH-1121227 | C6: 45287 | D6: 擋土牆TYPE3 | E6: 業主、監造 | F6: 2 | G6: =SUBSTITUTE(G5,F6,"") -> 8預力混凝土基樁
A7: =ROW()-4 -> 3 | B7: EH-1121228 | C7: 45288 | D7: 擋土牆TYPE3 | F7: 3 | G7: =SUBSTITUTE(G6,F7,"") -> 8預力混凝土基樁
F8: 4 | G8: =SUBSTITUTE(G7,F8,"") -> 8預力混凝土基樁
F9: 5 | G9: =SUBSTITUTE(G8,F9,"") -> 8預力混凝土基樁
F10: 6 | G10: =SUBSTITUTE(G9,F10,"") -> 8預力混凝土基樁
F11: 7 | G11: =SUBSTITUTE(G10,F11,"") -> 8預力混凝土基樁
F12: 8 | G12: =SUBSTITUTE(G11,F12,"") -> 預力混凝土基樁
F13: 9 | G13: =SUBSTITUTE(G12,F13,"") -> 預力混凝土基樁

Sheet 9.砌塊石護岸
A1: 臺北市政府工務局水利工程處 | F1: =CELL("filename",A1) -> \\上溢北投\d\雲端\A.上溢\1.磺港溪再造C段護岸及步道整建工程（延壽橋至三合橋）\9.施工\4.自主檢查\自主檢查統計\[磺港溪C-A自主檢查統計1130311.xlsx]9.砌塊石護岸
A2: 磺港溪再造C段護岸及步道整建工程（延壽橋至三合橋） | G2: =RIGHT(F1,LEN(F1)-FIND("]",F1)) -> 9.砌塊石護岸
A3: =G13&"自主檢查表統計" -> 砌塊石護岸自主檢查表統計 | F3: . | G3: =SUBSTITUTE(G2,F3,"") -> 9砌塊石護岸
A4: 次數 | B4: 編號 | C4: 檢查日期 | D4: 檢查部位 | E4: 備註 | F4: 0 | G4: =SUBSTITUTE(G3,F4,"") -> 9砌塊石護岸
B5: EI- | F5: 1 | G5: =SUBSTITUTE(G4,F5,"") -> 9砌塊石護岸
F6: 2 | G6: =SUBSTITUTE(G5,F6,"") -> 9砌塊石護岸
F7: 3 | G7: =SUBSTITUTE(G6,F7,"") -> 9砌塊石護岸
F8: 4 | G8: =SUBSTITUTE(G7,F8,"") -> 9砌塊石護岸
F9: 5 | G9: =SUBSTITUTE(G8,F9,"") -> 9砌塊石護岸
F10: 6 | G10: =SUBSTITUTE(G9,F10,"") -> 9砌塊石護岸
F11: 7 | G11: =SUBSTITUTE(G10,F11,"") -> 9砌塊石護岸
F12: 8 | G12: =SUBSTITUTE(G11,F12,"") -> 9砌塊石護岸
F13: 9 | G13: =SUBSTITUTE(G12,F13,"") -> 砌塊石護岸

Sheet 10.低水護岸
A1: 臺北市政府工務局水利工程處 | F1: =CELL("filename",A1) -> \\上溢北投\d\雲端\A.上溢\1.磺港溪再造C段護岸及步道整建工程（延壽橋至三合橋）\9.施工\4.自主檢查\自主檢查統計\[磺港溪C-A自主檢查統計1130311.xlsx]10.低水護岸
A2: 磺港溪再造C段護岸及步道整建工程（延壽橋至三合橋） | G2: =RIGHT(F1,LEN(F1)-FIND("]",F1)) -> 10.低水護岸
A3: =G13&"自主檢查表統計" -> 低水護岸自主檢查表統計 | F3: . | G3: =SUBSTITUTE(G2,F3,"") -> 10低水護岸
A4: 次數 | B4: 編號 | C4: 檢查日期 | D4: 檢查部位 | E4: 備註 | F4: 0 | G4: =SUBSTITUTE(G3,F4,"") -> 1低水護岸
B5: EJ- | F5: 1 | G5: =SUBSTITUTE(G4,F5,"") -> 低水護岸
F6: 2 | G6: =SUBSTITUTE(G5,F6,"") -> 低水護岸
F7: 3 | G7: =SUBSTITUTE(G6,F7,"") -> 低水護岸
F8: 4 | G8: =SUBSTITUTE(G7,F8,"") -> 低水護岸
F9: 5 | G9: =SUBSTITUTE(G8,F9,"") -> 低水護岸
F10: 6 | G10: =SUBSTITUTE(G9,F10,"") -> 低水護岸
F11: 7 | G11: =SUBSTITUTE(G10,F11,"") -> 低水護岸
F12: 8 | G12: =SUBSTITUTE(G11,F12,"") -> 低水護岸
F13: 9 | G13: =SUBSTITUTE(G12,F13,"") -> 低水護岸

Sheet 11.固床工
A1: 臺北市政府工務局水利工程處 | F1: =CELL("filename",A1) -> \\上溢北投\d\雲端\A.上溢\1.磺港溪再造C段護岸及步道整建工程（延壽橋至三合橋）\9.施工\4.自主檢查\自主檢查統計\[磺港溪C-A自主檢查統計1130311.xlsx]11.固床工
A2: 磺港溪再造C段護岸及步道整建工程（延壽橋至三合橋） | G2: =RIGHT(F1,LEN(F1)-FIND("]",F1)) -> 11.固床工
A3: =G13&"自主檢查表統計" -> 固床工自主檢查表統計 | F3: . | G3: =SUBSTITUTE(G2,F3,"") -> 11固床工
A4: 次數 | B4: 編號 | C4: 檢查日期 | D4: 檢查部位 | E4: 備註 | F4: 0 | G4: =SUBSTITUTE(G3,F4,"") -> 11固床工
B5: EK- | F5: 1 | G5: =SUBSTITUTE(G4,F5,"") -> 固床工
F6: 2 | G6: =SUBSTITUTE(G5,F6,"") -> 固床工
F7: 3 | G7: =SUBSTITUTE(G6,F7,"") -> 固床工
F8: 4 | G8: =SUBSTITUTE(G7,F8,"") -> 固床工
F9: 5 | G9: =SUBSTITUTE(G8,F9,"") -> 固床工
F10: 6 | G10: =SUBSTITUTE(G9,F10,"") -> 固床工
F11: 7 | G11: =SUBSTITUTE(G10,F11,"") -> 固床工
F12: 8 | G12: =SUBSTITUTE(G11,F12,"") -> 固床工
F13: 9 | G13: =SUBSTITUTE(G12,F13,"") -> 固床工

Sheet 12.全套管基樁
A1: 臺北市政府工務局水利工程處 | F1: =CELL("filename",A1) -> \\上溢北投\d\雲端\A.上溢\1.磺港溪再造C段護岸及步道整建工程（延壽橋至三合橋）\9.施工\4.自主檢查\自主檢查統計\[磺港溪C-A自主檢查統計1130311.xlsx]12.全套管基樁
A2: 磺港溪再造C段護岸及步道整建工程（延壽橋至三合橋） | G2: =RIGHT(F1,LEN(F1)-FIND("]",F1)) -> 12.全套管基樁
A3: =G11&"自主檢查表統計" -> 全套管基樁自主檢查表統計 | F3: . | G3: =SUBSTITUTE(G2,F3,"") -> 12全套管基樁
A4: 次數 | B4: 編號 | C4: 檢查日期 | D4: 檢查部位 | E4: 備註 | F4: 0 | G4: =SUBSTITUTE(G3,F4,"") -> 12全套管基樁
A5: =ROW()-4 -> 1 | B5: EL-1121229 | C5: 45289 | D5: 共月橋全套管基樁1 | E5: 監造 | F5: 1 | G5: =SUBSTITUTE(G4,F5,"") -> 2全套管基樁
A6: =ROW()-4 -> 2 | B6: EL-1130105 | C6: 45296 | D6: 共月橋全套管基樁2 | E6: 監造 | F6: 2 | G6: =SUBSTITUTE(G5,F6,"") -> 全套管基樁
A7: =ROW()-4 -> 3 | B7: EL-1130109 | C7: 45300 | D7: 共月橋全套管基樁4 | E7: 監造 | F7: 3 | G7: =SUBSTITUTE(G6,F7,"") -> 全套管基樁
A8: =ROW()-4 -> 4 | B8: EL-1130111 | C8: 45302 | D8: 共月橋全套管基樁3 | E8: 監造 | F8: 4 | G8: =SUBSTITUTE(G7,F8,"") -> 全套管基樁
A9: =ROW()-4 -> 5 | B9: EL-1130112 | C9: 45303 | D9: 共月橋全套管基樁3澆置 | F9: 5 | G9: =SUBSTITUTE(G8,F9,"") -> 全套管基樁
A10: =ROW()-4 -> 6 | B10: EL-1130117 | C10: 45308 | D10: 共月橋全套管基樁5 | E10: 監造 | F10: 6 | G10: =SUBSTITUTE(G9,F10,"") -> 全套管基樁
A11: =ROW()-4 -> 7 | B11: EL-1130118 | C11: 45309 | D11: 共月橋全套管基樁5澆置 | F11: 7 | G11: =SUBSTITUTE(G10,F11,"") -> 全套管基樁
A12: =ROW()-4 -> 8 | B12: EL-1130120 | C12: 45311 | D12: 共月橋全套管基樁6 | E12: 監造 | F12: 8 | G12: =SUBSTITUTE(G11,F12,"") -> 全套管基樁
A13: =ROW()-4 -> 9 | B13: EL-1130123 | C13: 45314 | D13: 共月橋全套管基樁7 | E13: 監造 | F13: 9 | G13: =SUBSTITUTE(G12,F13,"") -> 全套管基樁
A14: =ROW()-4 -> 10 | B14: EL-1130129 | C14: 45320 | D14: 共月橋全套管基樁8 | E14: 監造
A15: =ROW()-4 -> 11 | B15: EL-1130130 | C15: 45321 | D15: 共月橋全套管基樁9 | E15: 監造
A16: =ROW()-4 -> 12 | B16: EL-1130131 | C16: 45322 | D16: 共月橋全套管基樁10 | E16: 監造
A17: =ROW()-4 -> 13 | B17: EL-1130201 | C17: 45323 | D17: 共月橋全套管基樁11 | E17: 業主、監造
A18: =ROW()-4 -> 14 | B18: EL-1130201-1 | C18: 45323 | D18: 共月橋全套管基樁10、11澆置

Sheet 13.鋼筋混凝土管工程
A1: 臺北市政府工務局水利工程處 | F1: =CELL("filename",A1) -> \\上溢北投\d\雲端\A.上溢\1.磺港溪再造C段護岸及步道整建工程（延壽橋至三合橋）\9.施工\4.自主檢查\自主檢查統計\[磺港溪C-A自主檢查統計1130311.xlsx]13.鋼筋混凝土管工程
A2: 磺港溪再造C段護岸及步道整建工程（延壽橋至三合橋） | G2: =RIGHT(F1,LEN(F1)-FIND("]",F1)) -> 13.鋼筋混凝土管工程
A3: =G13&"自主檢查表統計" -> 鋼筋混凝土管工程自主檢查表統計 | F3: . | G3: =SUBSTITUTE(G2,F3,"") -> 13鋼筋混凝土管工程
A4: 次數 | B4: 編號 | C4: 檢查日期 | D4: 檢查部位 | E4: 備註 | F4: 0 | G4: =SUBSTITUTE(G3,F4,"") -> 13鋼筋混凝土管工程
B5: EM- | F5: 1 | G5: =SUBSTITUTE(G4,F5,"") -> 3鋼筋混凝土管工程
F6: 2 | G6: =SUBSTITUTE(G5,F6,"") -> 3鋼筋混凝土管工程
F7: 3 | G7: =SUBSTITUTE(G6,F7,"") -> 鋼筋混凝土管工程
F8: 4 | G8: =SUBSTITUTE(G7,F8,"") -> 鋼筋混凝土管工程
F9: 5 | G9: =SUBSTITUTE(G8,F9,"") -> 鋼筋混凝土管工程
F10: 6 | G10: =SUBSTITUTE(G9,F10,"") -> 鋼筋混凝土管工程
F11: 7 | G11: =SUBSTITUTE(G10,F11,"") -> 鋼筋混凝土管工程
F12: 8 | G12: =SUBSTITUTE(G11,F12,"") -> 鋼筋混凝土管工程
F13: 9 | G13: =SUBSTITUTE(G12,F13,"") -> 鋼筋混凝土管工程

Sheet 14.鋼版樁
A1: 臺北市政府工務局水利工程處 | F1: =CELL("filename",A1) -> \\上溢北投\d\雲端\A.上溢\1.磺港溪再造C段護岸及步道整建工程（延壽橋至三合橋）\9.施工\4.自主檢查\自主檢查統計\[磺港溪C-A自主檢查統計1130311.xlsx]14.鋼版樁
A2: 磺港溪再造C段護岸及步道整建工程（延壽橋至三合橋） | G2: =RIGHT(F1,LEN(F1)-FIND("]",F1)) -> 14.鋼版樁
A3: =G13&"自主檢查表統計" -> 鋼版樁自主檢查表統計 | F3: . | G3: =SUBSTITUTE(G2,F3,"") -> 14鋼版樁
A4: 次數 | B4: 編號 | C4: 檢查日期 | D4: 檢查部位 | E4: 備註 | F4: 0 | G4: =SUBSTITUTE(G3,F4,"") -> 14鋼版樁
A5: =ROW()-4 -> 1 | B5: EN-1121207 | C5: 45267 | D5: 共月橋圍堰 | E5: 監造 | F5: 1 | G5: =SUBSTITUTE(G4,F5,"") -> 4鋼版樁
A6: =ROW()-4 -> 2 | B6: EN-1121219 | C6: 45279 | D6: 擋土牆TYPE3 | E6: 監造 | F6: 2 | G6: =SUBSTITUTE(G5,F6,"") -> 4鋼版樁
F7: 3 | G7: =SUBSTITUTE(G6,F7,"") -> 4鋼版樁
F8: 4 | G8: =SUBSTITUTE(G7,F8,"") -> 鋼版樁
F9: 5 | G9: =SUBSTITUTE(G8,F9,"") -> 鋼版樁
F10: 6 | G10: =SUBSTITUTE(G9,F10,"") -> 鋼版樁
F11: 7 | G11: =SUBSTITUTE(G10,F11,"") -> 鋼版樁
F12: 8 | G12: =SUBSTITUTE(G11,F12,"") -> 鋼版樁
F13: 9 | G13: =SUBSTITUTE(G12,F13,"") -> 鋼版樁

Sheet 15.路床 路基高程
A1: 臺北市政府工務局水利工程處 | F1: =CELL("filename",A1) -> \\上溢北投\d\雲端\A.上溢\1.磺港溪再造C段護岸及步道整建工程（延壽橋至三合橋）\9.施工\4.自主檢查\自主檢查統計\[磺港溪C-A自主檢查統計1130311.xlsx]15.路床 路基高程
A2: 磺港溪再造C段護岸及步道整建工程（延壽橋至三合橋） | G2: =RIGHT(F1,LEN(F1)-FIND("]",F1)) -> 15.路床 路基高程
A3: =G13&"自主檢查表統計" -> 路床 路基高程自主檢查表統計 | F3: . | G3: =SUBSTITUTE(G2,F3,"") -> 15路床 路基高程
A4: 次數 | B4: 編號 | C4: 檢查日期 | D4: 檢查部位 | E4: 備註 | F4: 0 | G4: =SUBSTITUTE(G3,F4,"") -> 15路床 路基高程
B5: EO- | F5: 1 | G5: =SUBSTITUTE(G4,F5,"") -> 5路床 路基高程
F6: 2 | G6: =SUBSTITUTE(G5,F6,"") -> 5路床 路基高程
F7: 3 | G7: =SUBSTITUTE(G6,F7,"") -> 5路床 路基高程
F8: 4 | G8: =SUBSTITUTE(G7,F8,"") -> 5路床 路基高程
F9: 5 | G9: =SUBSTITUTE(G8,F9,"") -> 路床 路基高程
F10: 6 | G10: =SUBSTITUTE(G9,F10,"") -> 路床 路基高程
F11: 7 | G11: =SUBSTITUTE(G10,F11,"") -> 路床 路基高程
F12: 8 | G12: =SUBSTITUTE(G11,F12,"") -> 路床 路基高程
F13: 9 | G13: =SUBSTITUTE(G12,F13,"") -> 路床 路基高程

Sheet 16.瀝青混凝土
A1: 臺北市政府工務局水利工程處 | F1: =CELL("filename",A1) -> \\上溢北投\d\雲端\A.上溢\1.磺港溪再造C段護岸及步道整建工程（延壽橋至三合橋）\9.施工\4.自主檢查\自主檢查統計\[磺港溪C-A自主檢查統計1130311.xlsx]16.瀝青混凝土
A2: 磺港溪再造C段護岸及步道整建工程（延壽橋至三合橋） | G2: =RIGHT(F1,LEN(F1)-FIND("]",F1)) -> 16.瀝青混凝土
A3: =G13&"自主檢查表統計" -> 瀝青混凝土自主檢查表統計 | F3: . | G3: =SUBSTITUTE(G2,F3,"") -> 16瀝青混凝土
A4: 次數 | B4: 編號 | C4: 檢查日期 | D4: 檢查部位 | E4: 備註 | F4: 0 | G4: =SUBSTITUTE(G3,F4,"") -> 16瀝青混凝土
B5: EP- | F5: 1 | G5: =SUBSTITUTE(G4,F5,"") -> 6瀝青混凝土
F6: 2 | G6: =SUBSTITUTE(G5,F6,"") -> 6瀝青混凝土
F7: 3 | G7: =SUBSTITUTE(G6,F7,"") -> 6瀝青混凝土
F8: 4 | G8: =SUBSTITUTE(G7,F8,"") -> 6瀝青混凝土
F9: 5 | G9: =SUBSTITUTE(G8,F9,"") -> 6瀝青混凝土
F10: 6 | G10: =SUBSTITUTE(G9,F10,"") -> 瀝青混凝土
F11: 7 | G11: =SUBSTITUTE(G10,F11,"") -> 瀝青混凝土
F12: 8 | G12: =SUBSTITUTE(G11,F12,"") -> 瀝青混凝土
F13: 9 | G13: =SUBSTITUTE(G12,F13,"") -> 瀝青混凝土

Sheet 17.景觀鋪面(一)
A1: 臺北市政府工務局水利工程處 | F1: =CELL("filename",A1) -> \\上溢北投\d\雲端\A.上溢\1.磺港溪再造C段護岸及步道整建工程（延壽橋至三合橋）\9.施工\4.自主檢查\自主檢查統計\[磺港溪C-A自主檢查統計1130311.xlsx]17.景觀鋪面(一)
A2: 磺港溪再造C段護岸及步道整建工程（延壽橋至三合橋） | G2: =RIGHT(F1,LEN(F1)-FIND("]",F1)) -> 17.景觀鋪面(一)
A3: =G13&"自主檢查表統計" -> 景觀鋪面(一)自主檢查表統計 | F3: . | G3: =SUBSTITUTE(G2,F3,"") -> 17景觀鋪面(一)
A4: 次數 | B4: 編號 | C4: 檢查日期 | D4: 檢查部位 | E4: 備註 | F4: 0 | G4: =SUBSTITUTE(G3,F4,"") -> 17景觀鋪面(一)
B5: EQ- | F5: 1 | G5: =SUBSTITUTE(G4,F5,"") -> 7景觀鋪面(一)
F6: 2 | G6: =SUBSTITUTE(G5,F6,"") -> 7景觀鋪面(一)
F7: 3 | G7: =SUBSTITUTE(G6,F7,"") -> 7景觀鋪面(一)
F8: 4 | G8: =SUBSTITUTE(G7,F8,"") -> 7景觀鋪面(一)
F9: 5 | G9: =SUBSTITUTE(G8,F9,"") -> 7景觀鋪面(一)
F10: 6 | G10: =SUBSTITUTE(G9,F10,"") -> 7景觀鋪面(一)
F11: 7 | G11: =SUBSTITUTE(G10,F11,"") -> 景觀鋪面(一)
F12: 8 | G12: =SUBSTITUTE(G11,F12,"") -> 景觀鋪面(一)
F13: 9 | G13: =SUBSTITUTE(G12,F13,"") -> 景觀鋪面(一)

Sheet 18.景觀鋪面(二)
A1: 臺北市政府工務局水利工程處 | F1: =CELL("filename",A1) -> \\上溢北投\d\雲端\A.上溢\1.磺港溪再造C段護岸及步道整建工程（延壽橋至三合橋）\9.施工\4.自主檢查\自主檢查統計\[磺港溪C-A自主檢查統計1130311.xlsx]18.景觀鋪面(二)
A2: 磺港溪再造C段護岸及步道整建工程（延壽橋至三合橋） | G2: =RIGHT(F1,LEN(F1)-FIND("]",F1)) -> 18.景觀鋪面(二)
A3: =G13&"自主檢查表統計" -> 景觀鋪面(二)自主檢查表統計 | F3: . | G3: =SUBSTITUTE(G2,F3,"") -> 18景觀鋪面(二)
A4: 次數 | B4: 編號 | C4: 檢查日期 | D4: 檢查部位 | E4: 備註 | F4: 0 | G4: =SUBSTITUTE(G3,F4,"") -> 18景觀鋪面(二)
B5: ER- | F5: 1 | G5: =SUBSTITUTE(G4,F5,"") -> 8景觀鋪面(二)
F6: 2 | G6: =SUBSTITUTE(G5,F6,"") -> 8景觀鋪面(二)
F7: 3 | G7: =SUBSTITUTE(G6,F7,"") -> 8景觀鋪面(二)
F8: 4 | G8: =SUBSTITUTE(G7,F8,"") -> 8景觀鋪面(二)
F9: 5 | G9: =SUBSTITUTE(G8,F9,"") -> 8景觀鋪面(二)
F10: 6 | G10: =SUBSTITUTE(G9,F10,"") -> 8景觀鋪面(二)
F11: 7 | G11: =SUBSTITUTE(G10,F11,"") -> 8景觀鋪面(二)
F12: 8 | G12: =SUBSTITUTE(G11,F12,"") -> 景觀鋪面(二)
F13: 9 | G13: =SUBSTITUTE(G12,F13,"") -> 景觀鋪面(二)

Sheet 19.預鑄緣石
A1: 臺北市政府工務局水利工程處 | F1: =CELL("filename",A1) -> \\上溢北投\d\雲端\A.上溢\1.磺港溪再造C段護岸及步道整建工程（延壽橋至三合橋）\9.施工\4.自主檢查\自主檢查統計\[磺港溪C-A自主檢查統計1130311.xlsx]19.預鑄緣石
A2: 磺港溪再造C段護岸及步道整建工程（延壽橋至三合橋） | G2: =RIGHT(F1,LEN(F1)-FIND("]",F1)) -> 19.預鑄緣石
A3: =G13&"自主檢查表統計" -> 預鑄緣石自主檢查表統計 | F3: . | G3: =SUBSTITUTE(G2,F3,"") -> 19預鑄緣石
A4: 次數 | B4: 編號 | C4: 檢查日期 | D4: 檢查部位 | E4: 備註 | F4: 0 | G4: =SUBSTITUTE(G3,F4,"") -> 19預鑄緣石
B5: ES- | F5: 1 | G5: =SUBSTITUTE(G4,F5,"") -> 9預鑄緣石
F6: 2 | G6: =SUBSTITUTE(G5,F6,"") -> 9預鑄緣石
F7: 3 | G7: =SUBSTITUTE(G6,F7,"") -> 9預鑄緣石
F8: 4 | G8: =SUBSTITUTE(G7,F8,"") -> 9預鑄緣石
F9: 5 | G9: =SUBSTITUTE(G8,F9,"") -> 9預鑄緣石
F10: 6 | G10: =SUBSTITUTE(G9,F10,"") -> 9預鑄緣石
F11: 7 | G11: =SUBSTITUTE(G10,F11,"") -> 9預鑄緣石
F12: 8 | G12: =SUBSTITUTE(G11,F12,"") -> 9預鑄緣石
F13: 9 | G13: =SUBSTITUTE(G12,F13,"") -> 預鑄緣石

Sheet 20.鋼構工程吊裝
A1: 臺北市政府工務局水利工程處 | F1: =CELL("filename",A1) -> \\上溢北投\d\雲端\A.上溢\1.磺港溪再造C段護岸及步道整建工程（延壽橋至三合橋）\9.施工\4.自主檢查\自主檢查統計\[磺港溪C-A自主檢查統計1130311.xlsx]20.鋼構工程吊裝
A2: 磺港溪再造C段護岸及步道整建工程（延壽橋至三合橋） | G2: =RIGHT(F1,LEN(F1)-FIND("]",F1)) -> 20.鋼構工程吊裝
A3: =G13&"自主檢查表統計" -> 鋼構工程吊裝自主檢查表統計 | F3: . | G3: =SUBSTITUTE(G2,F3,"") -> 20鋼構工程吊裝
A4: 次數 | B4: 編號 | C4: 檢查日期 | D4: 檢查部位 | E4: 備註 | F4: 0 | G4: =SUBSTITUTE(G3,F4,"") -> 2鋼構工程吊裝
B5: ET- | F5: 1 | G5: =SUBSTITUTE(G4,F5,"") -> 2鋼構工程吊裝
F6: 2 | G6: =SUBSTITUTE(G5,F6,"") -> 鋼構工程吊裝
F7: 3 | G7: =SUBSTITUTE(G6,F7,"") -> 鋼構工程吊裝
F8: 4 | G8: =SUBSTITUTE(G7,F8,"") -> 鋼構工程吊裝
F9: 5 | G9: =SUBSTITUTE(G8,F9,"") -> 鋼構工程吊裝
F10: 6 | G10: =SUBSTITUTE(G9,F10,"") -> 鋼構工程吊裝
F11: 7 | G11: =SUBSTITUTE(G10,F11,"") -> 鋼構工程吊裝
F12: 8 | G12: =SUBSTITUTE(G11,F12,"") -> 鋼構工程吊裝
F13: 9 | G13: =SUBSTITUTE(G12,F13,"") -> 鋼構工程吊裝

Sheet 21.鋼構工程塗裝
A1: 臺北市政府工務局水利工程處 | F1: =CELL("filename",A1) -> \\上溢北投\d\雲端\A.上溢\1.磺港溪再造C段護岸及步道整建工程（延壽橋至三合橋）\9.施工\4.自主檢查\自主檢查統計\[磺港溪C-A自主檢查統計1130311.xlsx]21.鋼構工程塗裝
A2: 磺港溪再造C段護岸及步道整建工程（延壽橋至三合橋） | G2: =RIGHT(F1,LEN(F1)-FIND("]",F1)) -> 21.鋼構工程塗裝
A3: =G13&"自主檢查表統計" -> 鋼構工程塗裝自主檢查表統計 | F3: . | G3: =SUBSTITUTE(G2,F3,"") -> 21鋼構工程塗裝
A4: 次數 | B4: 編號 | C4: 檢查日期 | D4: 檢查部位 | E4: 備註 | F4: 0 | G4: =SUBSTITUTE(G3,F4,"") -> 21鋼構工程塗裝
B5: EU- | F5: 1 | G5: =SUBSTITUTE(G4,F5,"") -> 2鋼構工程塗裝
F6: 2 | G6: =SUBSTITUTE(G5,F6,"") -> 鋼構工程塗裝
F7: 3 | G7: =SUBSTITUTE(G6,F7,"") -> 鋼構工程塗裝
F8: 4 | G8: =SUBSTITUTE(G7,F8,"") -> 鋼構工程塗裝
F9: 5 | G9: =SUBSTITUTE(G8,F9,"") -> 鋼構工程塗裝
F10: 6 | G10: =SUBSTITUTE(G9,F10,"") -> 鋼構工程塗裝
F11: 7 | G11: =SUBSTITUTE(G10,F11,"") -> 鋼構工程塗裝
F12: 8 | G12: =SUBSTITUTE(G11,F12,"") -> 鋼構工程塗裝
F13: 9 | G13: =SUBSTITUTE(G12,F13,"") -> 鋼構工程塗裝

Sheet 22.排水設施(一)
A1: 臺北市政府工務局水利工程處 | F1: =CELL("filename",A1) -> \\上溢北投\d\雲端\A.上溢\1.磺港溪再造C段護岸及步道整建工程（延壽橋至三合橋）\9.施工\4.自主檢查\自主檢查統計\[磺港溪C-A自主檢查統計1130311.xlsx]22.排水設施(一)
A2: 磺港溪再造C段護岸及步道整建工程（延壽橋至三合橋） | G2: =RIGHT(F1,LEN(F1)-FIND("]",F1)) -> 22.排水設施(一)
A3: =G13&"自主檢查表統計" -> 排水設施(一)自主檢查表統計 | F3: . | G3: =SUBSTITUTE(G2,F3,"") -> 22排水設施(一)
A4: 次數 | B4: 編號 | C4: 檢查日期 | D4: 檢查部位 | E4: 備註 | F4: 0 | G4: =SUBSTITUTE(G3,F4,"") -> 22排水設施(一)
B5: EV- | F5: 1 | G5: =SUBSTITUTE(G4,F5,"") -> 22排水設施(一)
F6: 2 | G6: =SUBSTITUTE(G5,F6,"") -> 排水設施(一)
F7: 3 | G7: =SUBSTITUTE(G6,F7,"") -> 排水設施(一)
F8: 4 | G8: =SUBSTITUTE(G7,F8,"") -> 排水設施(一)
F9: 5 | G9: =SUBSTITUTE(G8,F9,"") -> 排水設施(一)
F10: 6 | G10: =SUBSTITUTE(G9,F10,"") -> 排水設施(一)
F11: 7 | G11: =SUBSTITUTE(G10,F11,"") -> 排水設施(一)
F12: 8 | G12: =SUBSTITUTE(G11,F12,"") -> 排水設施(一)
F13: 9 | G13: =SUBSTITUTE(G12,F13,"") -> 排水設施(一)

Sheet 23.排水設施(二)
A1: 臺北市政府工務局水利工程處 | F1: =CELL("filename",A1) -> \\上溢北投\d\雲端\A.上溢\1.磺港溪再造C段護岸及步道整建工程（延壽橋至三合橋）\9.施工\4.自主檢查\自主檢查統計\[磺港溪C-A自主檢查統計1130311.xlsx]23.排水設施(二)
A2: 磺港溪再造C段護岸及步道整建工程（延壽橋至三合橋） | G2: =RIGHT(F1,LEN(F1)-FIND("]",F1)) -> 23.排水設施(二)
A3: =G13&"自主檢查表統計" -> 排水設施(二)自主檢查表統計 | F3: . | G3: =SUBSTITUTE(G2,F3,"") -> 23排水設施(二)
A4: 次數 | B4: 編號 | C4: 檢查日期 | D4: 檢查部位 | E4: 備註 | F4: 0 | G4: =SUBSTITUTE(G3,F4,"") -> 23排水設施(二)
B5: EW- | F5: 1 | G5: =SUBSTITUTE(G4,F5,"") -> 23排水設施(二)
F6: 2 | G6: =SUBSTITUTE(G5,F6,"") -> 3排水設施(二)
F7: 3 | G7: =SUBSTITUTE(G6,F7,"") -> 排水設施(二)
F8: 4 | G8: =SUBSTITUTE(G7,F8,"") -> 排水設施(二)
F9: 5 | G9: =SUBSTITUTE(G8,F9,"") -> 排水設施(二)
F10: 6 | G10: =SUBSTITUTE(G9,F10,"") -> 排水設施(二)
F11: 7 | G11: =SUBSTITUTE(G10,F11,"") -> 排水設施(二)
F12: 8 | G12: =SUBSTITUTE(G11,F12,"") -> 排水設施(二)
F13: 9 | G13: =SUBSTITUTE(G12,F13,"") -> 排水設施(二)

Sheet 24.木構造
A1: 臺北市政府工務局水利工程處 | F1: =CELL("filename",A1) -> \\上溢北投\d\雲端\A.上溢\1.磺港溪再造C段護岸及步道整建工程（延壽橋至三合橋）\9.施工\4.自主檢查\自主檢查統計\[磺港溪C-A自主檢查統計1130311.xlsx]24.木構造
A2: 磺港溪再造C段護岸及步道整建工程（延壽橋至三合橋） | G2: =RIGHT(F1,LEN(F1)-FIND("]",F1)) -> 24.木構造
A3: =G13&"自主檢查表統計" -> 木構造自主檢查表統計 | F3: . | G3: =SUBSTITUTE(G2,F3,"") -> 24木構造
A4: 次數 | B4: 編號 | C4: 檢查日期 | D4: 檢查部位 | E4: 備註 | F4: 0 | G4: =SUBSTITUTE(G3,F4,"") -> 24木構造
B5: EX- | F5: 1 | G5: =SUBSTITUTE(G4,F5,"") -> 24木構造
F6: 2 | G6: =SUBSTITUTE(G5,F6,"") -> 4木構造
F7: 3 | G7: =SUBSTITUTE(G6,F7,"") -> 4木構造
F8: 4 | G8: =SUBSTITUTE(G7,F8,"") -> 木構造
F9: 5 | G9: =SUBSTITUTE(G8,F9,"") -> 木構造
F10: 6 | G10: =SUBSTITUTE(G9,F10,"") -> 木構造
F11: 7 | G11: =SUBSTITUTE(G10,F11,"") -> 木構造
F12: 8 | G12: =SUBSTITUTE(G11,F12,"") -> 木構造
F13: 9 | G13: =SUBSTITUTE(G12,F13,"") -> 木構造

Sheet 25.管路
A1: 臺北市政府工務局水利工程處 | F1: =CELL("filename",A1) -> \\上溢北投\d\雲端\A.上溢\1.磺港溪再造C段護岸及步道整建工程（延壽橋至三合橋）\9.施工\4.自主檢查\自主檢查統計\[磺港溪C-A自主檢查統計1130311.xlsx]25.管路
A2: 磺港溪再造C段護岸及步道整建工程（延壽橋至三合橋） | G2: =RIGHT(F1,LEN(F1)-FIND("]",F1)) -> 25.管路
A3: =G13&"自主檢查表統計" -> 管路自主檢查表統計 | F3: . | G3: =SUBSTITUTE(G2,F3,"") -> 25管路
A4: 次數 | B4: 編號 | C4: 檢查日期 | D4: 檢查部位 | E4: 備註 | F4: 0 | G4: =SUBSTITUTE(G3,F4,"") -> 25管路
B5: EY- | F5: 1 | G5: =SUBSTITUTE(G4,F5,"") -> 25管路
F6: 2 | G6: =SUBSTITUTE(G5,F6,"") -> 5管路
F7: 3 | G7: =SUBSTITUTE(G6,F7,"") -> 5管路
F8: 4 | G8: =SUBSTITUTE(G7,F8,"") -> 5管路
F9: 5 | G9: =SUBSTITUTE(G8,F9,"") -> 管路
F10: 6 | G10: =SUBSTITUTE(G9,F10,"") -> 管路
F11: 7 | G11: =SUBSTITUTE(G10,F11,"") -> 管路
F12: 8 | G12: =SUBSTITUTE(G11,F12,"") -> 管路
F13: 9 | G13: =SUBSTITUTE(G12,F13,"") -> 管路

Sheet 26.植栽(移植)
A1: 臺北市政府工務局水利工程處 | F1: =CELL("filename",A1) -> \\上溢北投\d\雲端\A.上溢\1.磺港溪再造C段護岸及步道整建工程（延壽橋至三合橋）\9.施工\4.自主檢查\自主檢查統計\[磺港溪C-A自主檢查統計1130311.xlsx]26.植栽(移植)
A2: 磺港溪再造C段護岸及步道整建工程（延壽橋至三合橋） | G2: =RIGHT(F1,LEN(F1)-FIND("]",F1)) -> 26.植栽(移植)
A3: =G13&"自主檢查表統計" -> 植栽(移植)自主檢查表統計 | F3: . | G3: =SUBSTITUTE(G2,F3,"") -> 26植栽(移植)
A4: 次數 | B4: 編號 | C4: 檢查日期 | D4: 檢查部位 | E4: 備註 | F4: 0 | G4: =SUBSTITUTE(G3,F4,"") -> 26植栽(移植)
A5: =ROW()-4 -> 1 | B5: EAA-1120923 | C5: 45192 | D5: 奇岩一號公園喬木 | F5: 1 | G5: =SUBSTITUTE(G4,F5,"") -> 26植栽(移植)
A6: =ROW()-4 -> 2 | B6: EAA-1120925 | C6: 45194 | D6: 奇岩一號公園喬木 | F6: 2 | G6: =SUBSTITUTE(G5,F6,"") -> 6植栽(移植)
A7: =ROW()-4 -> 3 | B7: EAA-1121116 | C7: 45246 | D7: 奇岩一號公園喬木 | E7: 監造 | F7: 3 | G7: =SUBSTITUTE(G6,F7,"") -> 6植栽(移植)
A8: =ROW()-4 -> 4 | B8: EAA-1121117 | C8: 45247 | D8: 奇岩一號公園喬木 | E8: 監造 | F8: 4 | G8: =SUBSTITUTE(G7,F8,"") -> 6植栽(移植)
A9: =ROW()-4 -> 5 | B9: EAA-1121222 | C9: 45282 | D9: 奇岩一號公園喬木 | E9: 監造 | F9: 5 | G9: =SUBSTITUTE(G8,F9,"") -> 6植栽(移植)
A10: =ROW()-4 -> 6 | B10: EAA-1121224 | C10: 45284 | D10: 奇岩一號公園喬木 | F10: 6 | G10: =SUBSTITUTE(G9,F10,"") -> 植栽(移植)
A11: =ROW()-4 -> 7 | B11: EAA-1121225 | C11: 45285 | D11: 奇岩一號公園喬木 | F11: 7 | G11: =SUBSTITUTE(G10,F11,"") -> 植栽(移植)
F12: 8 | G12: =SUBSTITUTE(G11,F12,"") -> 植栽(移植)
F13: 9 | G13: =SUBSTITUTE(G12,F13,"") -> 植栽(移植)

Sheet 27.植栽(新植)
A1: 臺北市政府工務局水利工程處 | F1: =CELL("filename",A1) -> \\上溢北投\d\雲端\A.上溢\1.磺港溪再造C段護岸及步道整建工程（延壽橋至三合橋）\9.施工\4.自主檢查\自主檢查統計\[磺港溪C-A自主檢查統計1130311.xlsx]27.植栽(新植)
A2: 磺港溪再造C段護岸及步道整建工程（延壽橋至三合橋） | G2: =RIGHT(F1,LEN(F1)-FIND("]",F1)) -> 27.植栽(新植)
A3: =G13&"自主檢查表統計" -> 植栽(新植)自主檢查表統計 | F3: . | G3: =SUBSTITUTE(G2,F3,"") -> 27植栽(新植)
A4: 次數 | B4: 編號 | C4: 檢查日期 | D4: 檢查部位 | E4: 備註 | F4: 0 | G4: =SUBSTITUTE(G3,F4,"") -> 27植栽(新植)
B5: EAB- | F5: 1 | G5: =SUBSTITUTE(G4,F5,"") -> 27植栽(新植)
F6: 2 | G6: =SUBSTITUTE(G5,F6,"") -> 7植栽(新植)
F7: 3 | G7: =SUBSTITUTE(G6,F7,"") -> 7植栽(新植)
F8: 4 | G8: =SUBSTITUTE(G7,F8,"") -> 7植栽(新植)
F9: 5 | G9: =SUBSTITUTE(G8,F9,"") -> 7植栽(新植)
F10: 6 | G10: =SUBSTITUTE(G9,F10,"") -> 7植栽(新植)
F11: 7 | G11: =SUBSTITUTE(G10,F11,"") -> 植栽(新植)
F12: 8 | G12: =SUBSTITUTE(G11,F12,"") -> 植栽(新植)
F13: 9 | G13: =SUBSTITUTE(G12,F13,"") -> 植栽(新植)

Sheet 28.照明
A1: 臺北市政府工務局水利工程處 | F1: =CELL("filename",A1) -> \\上溢北投\d\雲端\A.上溢\1.磺港溪再造C段護岸及步道整建工程（延壽橋至三合橋）\9.施工\4.自主檢查\自主檢查統計\[磺港溪C-A自主檢查統計1130311.xlsx]28.照明
A2: 磺港溪再造C段護岸及步道整建工程（延壽橋至三合橋） | G2: =RIGHT(F1,LEN(F1)-FIND("]",F1)) -> 28.照明
A3: =G13&"自主檢查表統計" -> 照明自主檢查表統計 | F3: . | G3: =SUBSTITUTE(G2,F3,"") -> 28照明
A4: 次數 | B4: 編號 | C4: 檢查日期 | D4: 檢查部位 | E4: 備註 | F4: 0 | G4: =SUBSTITUTE(G3,F4,"") -> 28照明
B5: EAB- | F5: 1 | G5: =SUBSTITUTE(G4,F5,"") -> 28照明
F6: 2 | G6: =SUBSTITUTE(G5,F6,"") -> 8照明
F7: 3 | G7: =SUBSTITUTE(G6,F7,"") -> 8照明
F8: 4 | G8: =SUBSTITUTE(G7,F8,"") -> 8照明
F9: 5 | G9: =SUBSTITUTE(G8,F9,"") -> 8照明
F10: 6 | G10: =SUBSTITUTE(G9,F10,"") -> 8照明
F11: 7 | G11: =SUBSTITUTE(G10,F11,"") -> 8照明
F12: 8 | G12: =SUBSTITUTE(G11,F12,"") -> 照明
F13: 9 | G13: =SUBSTITUTE(G12,F13,"") -> 照明

Sheet 29.既有橋梁拆除
A1: 臺北市政府工務局水利工程處 | F1: =CELL("filename",A1) -> \\上溢北投\d\雲端\A.上溢\1.磺港溪再造C段護岸及步道整建工程（延壽橋至三合橋）\9.施工\4.自主檢查\自主檢查統計\[磺港溪C-A自主檢查統計1130311.xlsx]29.既有橋梁拆除
A2: 磺港溪再造C段護岸及步道整建工程（延壽橋至三合橋） | G2: =RIGHT(F1,LEN(F1)-FIND("]",F1)) -> 29.既有橋梁拆除
A3: =G13&"自主檢查表統計" -> 既有橋梁拆除自主檢查表統計 | F3: . | G3: =SUBSTITUTE(G2,F3,"") -> 29既有橋梁拆除
A4: 次數 | B4: 編號 | C4: 檢查日期 | D4: 檢查部位 | E4: 備註 | F4: 0 | G4: =SUBSTITUTE(G3,F4,"") -> 29既有橋梁拆除
A5: =ROW()-4 -> 1 | B5: EAC-1121011 | C5: 45210 | D5: 磺港溪1號橋AC刨除 | F5: 1 | G5: =SUBSTITUTE(G4,F5,"") -> 29既有橋梁拆除
A6: =ROW()-4 -> 2 | B6: EAC-1121017 | C6: 45216 | D6: 磺港溪1號橋(跨距1)切割 | E6: 監造 | F6: 2 | G6: =SUBSTITUTE(G5,F6,"") -> 9既有橋梁拆除
A7: =ROW()-4 -> 3 | B7: EAC-1121018 | C7: 45217 | D7: 磺港溪1號橋(跨距1)切割 | F7: 3 | G7: =SUBSTITUTE(G6,F7,"") -> 9既有橋梁拆除
A8: =ROW()-4 -> 4 | B8: EAC-1121019 | C8: 45218 | D8: 磺港溪1號橋(跨距1)吊運 | F8: 4 | G8: =SUBSTITUTE(G7,F8,"") -> 9既有橋梁拆除
A9: =ROW()-4 -> 5 | B9: EAC-1121020 | C9: 45219 | D9: 磺港溪1號橋(跨距1)吊運 | F9: 5 | G9: =SUBSTITUTE(G8,F9,"") -> 9既有橋梁拆除
A10: =ROW()-4 -> 6 | B10: EAC-1121021 | C10: 45220 | D10: 磺港溪1號橋(跨距2)切割 | E10: 監造 | F10: 6 | G10: =SUBSTITUTE(G9,F10,"") -> 9既有橋梁拆除
A11: =ROW()-4 -> 7 | B11: EAC-1121022 | C11: 45221 | D11: 磺港溪1號橋(跨距2)切割 | E11: 監造 | F11: 7 | G11: =SUBSTITUTE(G10,F11,"") -> 9既有橋梁拆除
A12: =ROW()-4 -> 8 | B12: EAC-1121023 | C12: 45222 | D12: 磺港溪1號橋(跨距2)吊運 | E12: 監造 | F12: 8 | G12: =SUBSTITUTE(G11,F12,"") -> 9既有橋梁拆除
A13: =ROW()-4 -> 9 | B13: EAC-1121024 | C13: 45223 | D13: 磺港溪1號橋(跨距2)吊運 | F13: 9 | G13: =SUBSTITUTE(G12,F13,"") -> 既有橋梁拆除
A14: =ROW()-4 -> 10 | B14: EAC-1121026 | C14: 45225 | D14: 磺港溪1號橋(跨距2)吊運 | E14: 監造
A15: =ROW()-4 -> 11 | B15: EAC-1121027 | C15: 45226 | D15: 人行路橋切割
A16: =ROW()-4 -> 12 | B16: EAC-1121128 | C16: 45258 | D16: 人行路橋吊運
A17: =ROW()-4 -> 13 | B17: EAC-1130305 | C17: 45356 | D17: 三合橋切割
A18: =ROW()-4 -> 14 | B18: EAC-1130311 | C18: 45362 | D18: 三合橋吊運 | E18: 監造

Sheet 鋼筋取樣
A1: 鋼筋材料進場統計表
A2: 編號 | B2: 批次 | C2: 進場日期 | D2: 申請取樣 | E2: 取樣日期 | F2: 鋼筋 | G2: 爐號 | H2: 號數 | I2: 數量 | J2: 累計數量 | K2: 實驗室 | L2: 拿到 | M2: 提送 | N2: 歸檔
A3: 1 | B3: 第一次 | C3: 45275 | D3: 45278 | E3: 45282 | F3: SD420W | G3: U205068 | H3: D19 | I3: 5500 | J3: =SUMIFS(I:I,F:F,F3,A:A,"<=1") -> 5500 | K3: 今塘 | L3: O | M3: O | N3: O
A4: =A3+1 -> 2 | B4: 第一次 | C4: 45275 | D4: 45278 | E4: 45282 | F4: SD420W | G4: U205069 | H4: D19 | I4: 19500 | J4: =SUMIFS(I:I,F:F,F4,A:A,"<=2") -> 25000 | K4: 今塘 | L4: O | M4: O | N4: O
A5: =A4+1 -> 3 | B5: 第一次 | C5: 45275 | D5: 45278 | E5: 45282 | F5: SD420W | G5: U204904 | H5: D25 | I5: 13500 | J5: =SUMIFS(I:I,F:F,F5,A:A,"<=3") -> 38500 | K5: 今塘 | L5: O | M5: O | N5: O
A6: =A5+1 -> 4 | B6: 第一次 | C6: 45275 | D6: 45278 | E6: 45282 | F6: SD420W | G6: U204905 | H6: D25 | I6: 10500 | J6: =SUMIFS(I:I,F:F,F6,A:A,"<=4") -> 49000 | K6: 今塘 | L6: O | M6: O | N6: O
A7: =A6+1 -> 5 | B7: 第二次 | C7: 45282 | D7: 45282 | E7: 45287 | F7: SD280W | G7: U203012 | H7: D10 | I7: 25000 | J7: =SUMIFS(I:I,F:F,F7,A:A,"<=5") -> 25000 | K7: 今塘、臺北市工務局 | L7: O | M7: O | N7: O
A8: =A7+1 -> 6 | B8: 第二次 | C8: 45282 | D8: 45282 | E8: 45287 | F8: SD280W | G8: U204705 | H8: D13 | I8: 23000 | J8: =SUMIFS(I:I,F:F,F8,A:A,"<=6") -> 48000 | K8: 今塘 | L8: O | M8: O | N8: O
A9: =A8+1 -> 7 | B9: 第二次 | C9: 45282 | D9: 45282 | E9: 45287 | F9: SD280W | G9: U206648 | H9: D16 | I9: 13500 | J9: =SUMIFS(I:I,F:F,F9,A:A,"<=7") -> 61500 | K9: 今塘 | L9: O | M9: O | N9: O
A10: =A9+1 -> 8 | B10: 第二次 | C10: 45282 | D10: 45282 | E10: 45287 | F10: SD280W | G10: U206649 | H10: D16 | I10: 11500 | J10: =SUMIFS(I:I,F:F,F10,A:A,"<=8") -> 73000 | K10: 今塘 | L10: O | M10: O | N10: O
A11: =A10+1 -> 9 | B11: 第三次 | C11: 45316 | D11: 45317 | E11: 45321 | F11: SD420W | G11: U206275 | H11: D13 | I11: 17000 | J11: =SUMIFS(I:I,F:F,F11,A:A,"<=9") -> 66000 | K11: 今塘 | L11: O | M11: O | N11: O | T11: =SUMIFS(F:F,H:H,U11) -> 0 | U11: #3
A12: =A11+1 -> 10 | B12: 第三次 | C12: 45316 | D12: 45317 | E12: 45321 | F12: SD420W | G12: U206276 | H12: D13 | I12: 8500 | J12: =SUMIFS(I:I,F:F,F12,A:A,"<=10") -> 74500 | K12: 今塘 | L12: O | M12: O | N12: O | T12: =SUMIFS(F:F,H:H,U12) -> 0 | U12: #4
A13: =A12+1 -> 11 | B13: 第三次 | C13: 45316 | D13: 45317 | E13: 45321 | F13: SD420W | G13: U204365 | H13: D16 | I13: 2500 | J13: =SUMIFS(I:I,F:F,F13,A:A,"<=11") -> 77000 | K13: 今塘 | L13: O | M13: O | N13: O | T13: =SUMIFS(F:F,H:H,U13) -> 0 | U13: #5
A14: =A13+1 -> 12 | B14: 第三次 | C14: 45316 | D14: 45317 | E14: 45321 | F14: SD420W | G14: U204366 | H14: D16 | I14: 23000 | J14: =SUMIFS(I:I,F:F,F14,A:A,"<=12") -> 100000 | K14: 今塘 | L14: O | M14: O | N14: O | T14: =SUMIFS(F:F,H:H,U14) -> 0 | U14: #6
A15: =A14+1 -> 13 | B15: 第三次 | C15: 45316 | D15: 45317 | E15: 45321 | F15: SD420W | G15: U205366 | H15: D19 | I15: 25000 | J15: =SUMIFS(I:I,F:F,F15,A:A,"<=13") -> 125000 | K15: 今塘 | L15: O | M15: O | N15: O | T15: =SUMIFS(F:F,H:H,U15) -> 0 | U15: #7
A16: =A15+1 -> 14 | B16: 第三次 | C16: 45316 | D16: 45317 | E16: 45321 | F16: SD420W | G16: U205501 | H16: D22 | I16: 23000 | J16: =SUMIFS(I:I,F:F,F16,A:A,"<=14") -> 148000 | K16: 今塘 | L16: O | M16: O | N16: O | T16: =SUMIFS(F:F,H:H,U16) -> 0 | U16: #8
A17: =A16+1 -> 15 | B17: 第三次 | C17: 45316 | D17: 45317 | E17: 45321 | F17: SD420W | G17: U206196 | H17: D25 | I17: 2500 | J17: =SUMIFS(I:I,F:F,F17,A:A,"<=15") -> 150500 | K17: 今塘 | L17: O | M17: O | N17: O | T17: =SUMIFS(F:F,H:H,U17) -> 0 | U17: #9
A18: =A17+1 -> 16 | B18: 第三次 | C18: 45316 | D18: 45317 | E18: 45321 | F18: SD420W | G18: U206541 | H18: D25 | I18: 20000 | J18: =SUMIFS(I:I,F:F,F18,A:A,"<=16") -> 170500 | K18: 今塘 | L18: O | M18: O | N18: O | T18: =SUMIFS(F:F,H:H,U18) -> 0 | U18: #10
A19: =A18+1 -> 17 | B19: 第三次 | C19: 45316 | D19: 45317 | E19: 45321 | F19: SD420W | G19: U205423 | H19: D32 | I19: 22000 | J19: =SUMIFS(I:I,F:F,F19,A:A,"<=17") -> 192500 | K19: 今塘 | L19: O | M19: O | N19: O
A20: =A19+1 -> 18 | B20: 第三次 | C20: 45316 | D20: 45317 | E20: 45321 | F20: SD420W | G20: U205654 | H20: D32 | I20: 2500 | J20: =SUMIFS(I:I,F:F,F20,A:A,"<=18") -> 195000 | K20: 今塘 | L20: O | M20: O | N20: O

Sheet PC樁
A1: 預力混凝土基樁材料進場統計表
A2: 編號 | B2: 進場日期 | C2: 申請取樣 | D2: 取樣日期 | E2: 數量 | F2: 累計數量 | G2: 實驗室 | H2: 拿到 | I2: 提送 | J2: 歸檔
A3: 1 | B3: 45285 | C3: 45239 | D3: 45254 | E3: 41支 | F3: =E3 -> 41支 | G3: 聯合大學 | H3: O | I3: O | J3: O

Sheet 混凝土取樣
A1: 編號 | B1: 日期 | C1: 星期 | D1: 混凝土 | E1: 代表數量 | F1: 組數 | G1: 結構部位 | H1: 會同 | I1: 7天 | J1: 星期 | K1: 28天 | L1: 星期 | M1: 供料 | N1: 實驗室 | O1: 拿到 | P1: 提送 | Q1: 歸檔 | R1: 業主 | S1: 監造 | T1: 廠商
A2: 1 | B2: 45181 | C2: =CHOOSE(WEEKDAY(B2),"日","一","二","三","四","五","六") -> 二 | D2: 140 | E2: 0 | F2: 1 | G2: 廠拌 | H2: 李晏然、游文圃、康祐銓 | I2: =IF(F2="免驗","",B2+7) -> 45188 | J2: =IF(F2="免驗","",CHOOSE(WEEKDAY(I2),"日","一","二","三","四","五","六")) -> 二 | K2: =IF(F2="免驗","",B2+28)+2 -> 45211 | L2: =IF(F2="免驗","",CHOOSE(WEEKDAY(K2),"日","一","二","三","四","五","六")) -> 四 | M2: 大象實業股份有限公司 | N2: 台隆 | O2: O | P2: O | Q2: O | R2: 李晏然 | S2: 游文圃 | T2: 康祐銓
A3: =A2+1 -> 2 | B3: 45181 | C3: =CHOOSE(WEEKDAY(B3),"日","一","二","三","四","五","六") -> 二 | D3: 210 | E3: 0 | F3: 1 | G3: 廠拌 | H3: 李晏然、游文圃、康祐銓 | I3: =IF(F3="免驗","",B3+7) -> 45188 | J3: =IF(F3="免驗","",CHOOSE(WEEKDAY(I3),"日","一","二","三","四","五","六")) -> 二 | K3: =IF(F3="免驗","",B3+28)+2 -> 45211 | L3: =IF(F3="免驗","",CHOOSE(WEEKDAY(K3),"日","一","二","三","四","五","六")) -> 四 | M3: 大象實業股份有限公司 | N3: 台隆 | O3: O | P3: O | Q3: O | R3: 李晏然 | S3: 游文圃 | T3: 康祐銓
A4: =A3+1 -> 3 | B4: 45181 | C4: =CHOOSE(WEEKDAY(B4),"日","一","二","三","四","五","六") -> 二 | D4: 280 | E4: 0 | F4: 1 | G4: 廠拌 | H4: 李晏然、游文圃、康祐銓 | I4: =IF(F4="免驗","",B4+7) -> 45188 | J4: =IF(F4="免驗","",CHOOSE(WEEKDAY(I4),"日","一","二","三","四","五","六")) -> 二 | K4: =IF(F4="免驗","",B4+28)+2 -> 45211 | L4: =IF(F4="免驗","",CHOOSE(WEEKDAY(K4),"日","一","二","三","四","五","六")) -> 四 | M4: 大象實業股份有限公司 | N4: 台隆 | O4: O | P4: O | Q4: O | R4: 李晏然 | S4: 游文圃 | T4: 康祐銓
A5: =A4+1 -> 4 | B5: 45181 | C5: =CHOOSE(WEEKDAY(B5),"日","一","二","三","四","五","六") -> 二 | D5: 280W | E5: 0 | F5: 1 | G5: 廠拌 | H5: 李晏然、游文圃、康祐銓 | I5: =IF(F5="免驗","",B5+7) -> 45188 | J5: =IF(F5="免驗","",CHOOSE(WEEKDAY(I5),"日","一","二","三","四","五","六")) -> 二 | K5: =IF(F5="免驗","",B5+28)+2 -> 45211 | L5: =IF(F5="免驗","",CHOOSE(WEEKDAY(K5),"日","一","二","三","四","五","六")) -> 四 | M5: 大象實業股份有限公司 | N5: 台隆 | O5: O | P5: O | Q5: O | R5: 李晏然 | S5: 游文圃 | T5: 康祐銓
A6: =A5+1 -> 5 | B6: ='6.混凝土'!C5 -> 45289 | C6: =CHOOSE(WEEKDAY(B6),"日","一","二","三","四","五","六") -> 五 | D6: 280W | E6: 58 | F6: =IF(E6<20,0,ROUNDUP(E6/100,0)) -> 1 | G6: ='6.混凝土'!D5 -> 共月橋全套管基樁1 | H6: 游文圃、康祐銓 | I6: =IF(F6="免驗","",B6+7) -> 45296 | J6: =IF(F6="免驗","",CHOOSE(WEEKDAY(I6),"日","一","二","三","四","五","六")) -> 五 | K6: =IF(F6="免驗","",B6+28) -> 45317 | L6: =IF(F6="免驗","",CHOOSE(WEEKDAY(K6),"日","一","二","三","四","五","六")) -> 五 | M6: 龍形企業股份有限公司 | N6: 今塘 | O6: O | P6: O | Q6: O | S6: 游文圃 | T6: 康祐銓
A7: =A6+1 -> 6 | B7: ='6.混凝土'!C6 -> 45296 | C7: =CHOOSE(WEEKDAY(B7),"日","一","二","三","四","五","六") -> 五 | D7: 280W | E7: 58 | F7: =IF(E7<20,0,ROUNDUP(E7/100,0)) -> 1 | G7: ='6.混凝土'!D6 -> 共月橋全套管基樁2 | H7: 游文圃、康祐銓 | I7: =IF(F7="免驗","",B7+7) -> 45303 | J7: =IF(F7="免驗","",CHOOSE(WEEKDAY(I7),"日","一","二","三","四","五","六")) -> 五 | K7: =IF(F7="免驗","",B7+28) -> 45324 | L7: =IF(F7="免驗","",CHOOSE(WEEKDAY(K7),"日","一","二","三","四","五","六")) -> 五 | M7: 龍形企業股份有限公司 | N7: 今塘 | O7: O | P7: O | Q7: O | S7: 游文圃 | T7: 康祐銓
A8: =A7+1 -> 7 | B8: ='6.混凝土'!C7 -> 45300 | C8: =CHOOSE(WEEKDAY(B8),"日","一","二","三","四","五","六") -> 二 | D8: 280W | E8: 58 | F8: =IF(E8<20,0,ROUNDUP(E8/100,0)) -> 1 | G8: ='6.混凝土'!D7 -> 共月橋全套管基樁4 | H8: 游文圃、郭冠廷 | I8: =IF(F8="免驗","",B8+7) -> 45307 | J8: =IF(F8="免驗","",CHOOSE(WEEKDAY(I8),"日","一","二","三","四","五","六")) -> 二 | K8: =IF(F8="免驗","",B8+28) -> 45328 | L8: =IF(F8="免驗","",CHOOSE(WEEKDAY(K8),"日","一","二","三","四","五","六")) -> 二 | M8: 龍形企業股份有限公司 | N8: 今塘 | O8: O | P8: O | S8: 游文圃 | T8: 郭冠廷
A9: =A8+1 -> 8 | B9: ='6.混凝土'!C8 -> 45303 | C9: =CHOOSE(WEEKDAY(B9),"日","一","二","三","四","五","六") -> 五 | D9: 280W | E9: 58 | F9: =IF(E9<20,0,ROUNDUP(E9/100,0)) -> 1 | G9: ='6.混凝土'!D8 -> 共月橋全套管基樁3 | H9: 李晏然、游文圃、郭冠廷 | I9: =IF(F9="免驗","",B9+7) -> 45310 | J9: =IF(F9="免驗","",CHOOSE(WEEKDAY(I9),"日","一","二","三","四","五","六")) -> 五 | K9: =IF(F9="免驗","",B9+28) -> 45331 | L9: =IF(F9="免驗","",CHOOSE(WEEKDAY(K9),"日","一","二","三","四","五","六")) -> 五 | M9: 龍形企業股份有限公司 | N9: 臺北市工務局 | O9: O | P9: O | R9: 李晏然 | S9: 游文圃 | T9: 郭冠廷
A10: =A9+1 -> 9 | B10: ='6.混凝土'!C9 -> 45309 | C10: =CHOOSE(WEEKDAY(B10),"日","一","二","三","四","五","六") -> 四 | D10: 280W | E10: 58 | F10: =IF(E10<20,0,ROUNDUP(E10/100,0)) -> 1 | G10: ='6.混凝土'!D9 -> 共月橋全套管基樁5 | H10: 游文圃、郭冠廷 | I10: =IF(F10="免驗","",B10+7) -> 45316 | J10: =IF(F10="免驗","",CHOOSE(WEEKDAY(I10),"日","一","二","三","四","五","六")) -> 四 | K10: =IF(F10="免驗","",B10+28) -> 45337 | L10: =IF(F10="免驗","",CHOOSE(WEEKDAY(K10),"日","一","二","三","四","五","六")) -> 四 | M10: 龍形企業股份有限公司 | N10: 今塘 | O10: O | S10: 游文圃 | T10: 郭冠廷
A11: =A10+1 -> 10 | B11: ='6.混凝土'!C10 -> 45311 | C11: =CHOOSE(WEEKDAY(B11),"日","一","二","三","四","五","六") -> 六 | D11: 280W | E11: 58 | F11: =IF(E11<20,0,ROUNDUP(E11/100,0)) -> 1 | G11: ='6.混凝土'!D10 -> 共月橋全套管基樁6 | H11: 白博文、郭冠廷 | I11: =IF(F11="免驗","",B11+7) -> 45318 | J11: =IF(F11="免驗","",CHOOSE(WEEKDAY(I11),"日","一","二","三","四","五","六")) -> 六 | K11: =IF(F11="免驗","",B11+28) -> 45339 | L11: =IF(F11="免驗","",CHOOSE(WEEKDAY(K11),"日","一","二","三","四","五","六")) -> 六 | M11: 龍形企業股份有限公司 | N11: 今塘 | O11: O | S11: 白博文 | T11: 郭冠廷
A12: =A11+1 -> 11 | B12: ='6.混凝土'!C11 -> 45314 | C12: =CHOOSE(WEEKDAY(B12),"日","一","二","三","四","五","六") -> 二 | D12: 280W | E12: 58 | F12: =IF(E12<20,0,ROUNDUP(E12/100,0)) -> 1 | G12: ='6.混凝土'!D11 -> 共月橋全套管基樁7 | H12: 白博文、郭冠廷 | I12: =IF(F12="免驗","",B12+7) -> 45321 | J12: =IF(F12="免驗","",CHOOSE(WEEKDAY(I12),"日","一","二","三","四","五","六")) -> 二 | K12: =IF(F12="免驗","",B12+28) -> 45342 | L12: =IF(F12="免驗","",CHOOSE(WEEKDAY(K12),"日","一","二","三","四","五","六")) -> 二 | M12: 龍形企業股份有限公司 | N12: 今塘 | S12: 白博文 | T12: 郭冠廷
A13: =A12+1 -> 12 | B13: ='6.混凝土'!C12 -> 45320 | C13: =CHOOSE(WEEKDAY(B13),"日","一","二","三","四","五","六") -> 一 | D13: 280W | E13: 58 | F13: =IF(E13<20,0,ROUNDUP(E13/100,0)) -> 1 | G13: ='6.混凝土'!D12 -> 共月橋全套管基樁8 | H13: 白博文、郭冠廷 | I13: =IF(F13="免驗","",B13+7) -> 45327 | J13: =IF(F13="免驗","",CHOOSE(WEEKDAY(I13),"日","一","二","三","四","五","六")) -> 一 | K13: =IF(F13="免驗","",B13+28) -> 45348 | L13: =IF(F13="免驗","",CHOOSE(WEEKDAY(K13),"日","一","二","三","四","五","六")) -> 一 | M13: 正誠工業有限公司 | N13: 今塘 | S13: 白博文 | T13: 郭冠廷
A14: =A13+1 -> 13 | B14: ='6.混凝土'!C13 -> 45321 | C14: =CHOOSE(WEEKDAY(B14),"日","一","二","三","四","五","六") -> 二 | D14: 280W | E14: 35 | F14: =IF(E14<20,0,ROUNDUP(E14/100,0)) -> 1 | G14: ='6.混凝土'!D13 -> 共月橋全套管基樁9 | H14: 白博文、郭冠廷 | I14: =IF(F14="免驗","",B14+7) -> 45328 | J14: =IF(F14="免驗","",CHOOSE(WEEKDAY(I14),"日","一","二","三","四","五","六")) -> 二 | K14: =IF(F14="免驗","",B14+28) -> 45349 | L14: =IF(F14="免驗","",CHOOSE(WEEKDAY(K14),"日","一","二","三","四","五","六")) -> 二 | M14: 龍形企業股份有限公司 | N14: 今塘 | S14: 白博文 | T14: 郭冠廷
A15: =A14+1 -> 14 | B15: ='6.混凝土'!C14 -> 45323 | C15: =CHOOSE(WEEKDAY(B15),"日","一","二","三","四","五","六") -> 四 | D15: 280W | E15: 58 | F15: =IF(E15<20,0,ROUNDUP(E15/100,0)) -> 1 | G15: ='6.混凝土'!D14 -> 共月橋全套管基樁10、11 | H15: 白博文、郭冠廷 | I15: =IF(F15="免驗","",B15+7) -> 45330 | J15: =IF(F15="免驗","",CHOOSE(WEEKDAY(I15),"日","一","二","三","四","五","六")) -> 四 | K15: =IF(F15="免驗","",B15+28) -> 45351 | L15: =IF(F15="免驗","",CHOOSE(WEEKDAY(K15),"日","一","二","三","四","五","六")) -> 四 | M15: 正誠工業有限公司 | N15: 今塘 | S15: 白博文 | T15: 郭冠廷
A16: =A15+1 -> 15 | B16: ='6.混凝土'!C15 -> 45339 | C16: =CHOOSE(WEEKDAY(B16),"日","一","二","三","四","五","六") -> 六 | D16: 140 | E16: 8 | F16: 1 | G16: ='6.混凝土'!D15 -> 地梁(0K+540~0K+625)底PC | H16: 白博文、郭冠廷 | I16: =IF(F16="免驗","",B16+7) -> 45346 | J16: =IF(F16="免驗","",CHOOSE(WEEKDAY(I16),"日","一","二","三","四","五","六")) -> 六 | K16: =IF(F16="免驗","",B16+28) -> 45367 | L16: =IF(F16="免驗","",CHOOSE(WEEKDAY(K16),"日","一","二","三","四","五","六")) -> 六 | M16: 龍形企業股份有限公司 | N16: 今塘 | S16: 白博文 | T16: 郭冠廷
A17: =A16+1 -> 16 | B17: ='6.混凝土'!C16 -> 45344 | C17: =CHOOSE(WEEKDAY(B17),"日","一","二","三","四","五","六") -> 四 | D17: 280二型 | E17: 98 | F17: =IF(E17<20,0,ROUNDUP(E17/100,0)) -> 1 | G17: ='6.混凝土'!D16 -> 地梁(0K+540~0K+625) | H17: 游文圃、郭冠廷 | I17: =IF(F17="免驗","",B17+7) -> 45351 | J17: =IF(F17="免驗","",CHOOSE(WEEKDAY(I17),"日","一","二","三","四","五","六")) -> 四 | K17: =IF(F17="免驗","",B17+28) -> 45372 | L17: =IF(F17="免驗","",CHOOSE(WEEKDAY(K17),"日","一","二","三","四","五","六")) -> 四 | M17: 龍形企業股份有限公司 | N17: 今塘 | S17: 游文圃 | T17: 郭冠廷
A18: =A17+1 -> 17 | B18: ='6.混凝土'!C17 -> 45356 | C18: =CHOOSE(WEEKDAY(B18),"日","一","二","三","四","五","六") -> 二 | D18: 140 | E18: 18 | F18: =IF(E18<20,0,ROUNDUP(E18/100,0)) -> 0 | G18: ='6.混凝土'!D17 -> 共月橋P1、P2橋台、砌石0K+540~0K+625底 | H18: 白博文、郭冠廷 | I18: =IF(F18="免驗","",B18+7) -> 45363 | J18: =IF(F18="免驗","",CHOOSE(WEEKDAY(I18),"日","一","二","三","四","五","六")) -> 二 | K18: =IF(F18="免驗","",B18+28) -> 45384 | L18: =IF(F18="免驗","",CHOOSE(WEEKDAY(K18),"日","一","二","三","四","五","六")) -> 二 | M18: 龍形企業股份有限公司 | N18: 今塘 | S18: 白博文 | T18: 郭冠廷
A19: =A18+1 -> 18 | B19: ='6.混凝土'!C18 -> 45358 | C19: =CHOOSE(WEEKDAY(B19),"日","一","二","三","四","五","六") -> 四 | D19: 280二型 | E19: 60 | F19: =IF(E19<20,0,ROUNDUP(E19/100,0)) -> 1 | G19: ='6.混凝土'!D18 -> 共月橋P1、P2橋台基礎 | H19: 白博文、郭冠廷 | I19: =IF(F19="免驗","",B19+7) -> 45365 | J19: =IF(F19="免驗","",CHOOSE(WEEKDAY(I19),"日","一","二","三","四","五","六")) -> 四 | K19: =IF(F19="免驗","",B19+28) -> 45386 | L19: =IF(F19="免驗","",CHOOSE(WEEKDAY(K19),"日","一","二","三","四","五","六")) -> 四 | M19: 龍形企業股份有限公司 | N19: 今塘 | S19: 白博文 | T19: 郭冠廷

Sheet 混凝土送驗單
A1: 裕全顧問有限公司五股實驗室
A2: 混凝土圓柱試體試驗委託單
U3: 報告編號：
A4: 地址：新北市蘆洲區集賢路378-1號 電話：(02)2293-9177 傳真：(02)2293-9178 | U4: □會驗 □不會驗 □需拍照 | AC4: 40
A5: 工程名稱： | D5: 磺港溪再造C段護岸及步道整建工程（延壽橋至三合橋）
A6: 業 主： | D6: 臺北市政府工務局水利工程處
A7: 監造單位： | D7: 盛禹工程顧問有限公司
A8: 承包廠商： | D8: 上溢營造股份有限公司
A9: 委託單位： | D9: 臺北市政府工務局水利工程處
A10: 聯絡資訊： | D10: 北投區致遠三路158號4樓
A11: 結構部位：
A12: 供料廠商：
A13: 取樣單位/人員： | E13: 業主 | I13: 監造 | J13: 蔡雄輝 | M13: 承包
A14: 送驗單位/人員： | E14: 業主 | I14: 監造 | M14: 承包 | Q14: 供料 | V14: □熟客；□是 □否 核對證件
A15: 會驗單位/人員： | E15: 業主 | I15: 監造 | M15: 承包 | V15: □熟客；□是 □否 核對證件
A16: 樣品保留□是(最多3天為限) □否(清理清運)；報告份數 | M16: 5 | O16: 份，未說明者 5 份。
A17: 發票抬頭： | D17: 上溢營造股份有限公司 | N17: 聯絡人姓名： | Q17: 曾晧哲 | U17: 手機： | W17: 908262883
A18: 統一編號： | D18: 84965983 | N18: 聯絡市話： | Q18: (02)2894-1204 | U18: 傳真：
A19: 發票Æ | C19: □自取 □郵寄 | N19: 報告Æ | P19: □自取 □郵寄
A21: 請款資訊請填寫完整 | F21: 一併委外試驗項目： | P21: 數量： | T21: 委外單位：
A22: 混凝土圓柱試體尺寸： | F22: □∮12*24 □∮15*30 □其他：
A23: 試驗項目 | F23: 試驗方法 | K23: 數量 | N23: 設計強度 (kgf/cm²) | R23: 製作日期 | U23: 試驗日期 | X23: 材齡
A25: 混凝土試體抗壓試驗 | F25: CNS 1232(2002)
A27: 試樣製作： | D27: □同供料廠商 □其他：
A28: 廠商養護-養護單位： | E28: □同供料廠商 □工地養護 □其他： 養護方式：□飽和石灰水 其他：□自然曝氣 □清水 養護條件：□23±2℃ 其他：□常溫
A29: 廠商養護-養護時間： | F29: 年 | H29: 月 | J29: 日 | L29: 時 | N29: 分 至 | Q29: 年 | S29: 月 | U29: 日 | W29: 時 | Y29: 分
A30: 特別協議事項:
A33: 本實驗室不出具符合性聲明報告。
A34: *以上粗框資訊由委託者提供、本實驗室將有關顧客資訊和測試資料均予以保密。
A35: ※以下資訊由實驗室登載事項:
A36: 收件方式：樣品接收時間： 年 月 日 時 分 □實驗室 □工地現場 □郵寄/貨運 □其他：
A37: 收件時試體承壓面狀態：□貼試體單 □表面自然狀態 □嚴重不良 □已做處裡 收件時試體乾溼狀態：□面乾 □潮濕
A38: 實驗室養護：養護方式：□飽和石灰水 養護條件：□23±2℃ | M38: 養護方式:□飽和石灰水□其他: | T38: 養護條件:□23±2℃□其他:
A39: 養護時間： 年 月 日 時 分 至 年 月 日 時 分
A40: 試驗時試體乾溼狀態：□面乾 □潮濕 試體承壓面處理方式：□蓋平 □磨平 處理單位：□本實驗室
A41: 說明:委託單位同意本實驗室將本單之資訊回報予TAF | J41: □樣品符合允收標準 □樣品退件說明
A42: 1.本委託單經送驗者及收件者簽名即完成委託流程。 | J42: 缺失：□裂紋 □缺角 □凹凸嚴重 □變形 □材質、質量不足 □尺寸不符 □受損 □其他：
A43: 2.若試樣在端面處裡後不符合規範要求時，將另行通知。
A44: 3.實驗室僅做標準方法養護。
A45: 4.材齡少於7天，則製作時間需填至"時"。
...
