Workbook
Name _290_2_0.15_0.2_12_5_0.15_0.2: '數量計算(FOR4變)'!$G$9
Name _290_2_0.15_0.2_12_5_0.15_0.2: '數量計算(FOR5變) '!$G$9
Name _290_2_0.15_0.2_12_5_0.15_0.2: '數量計算(勇哥)'!$G$9
Name 鋼筋資料: 鋼筋!$AD$4:$AM$13

Sheet CON
C1: 臺北市政府工務局水利工程處
C2: 第4次變更項目對照詳細表
A3: 工程名稱：磺港溪再造C段護岸及步道整建工程(三合橋至奇岩抽水站) | K3: 日期： | L3: 45653
A4: 原契約分為 10 部分 本次變更 4 部分原有 393 項 | J4: 訂約總價 | L4: 257600000
A5: 前經 3 次變更設計，計新增 43 項，減少 3 項，變更 27 項，變更後合計 438 項 | J5: 前次變更後總價(綜簽) | L5: 308240521
A6: 本次變更設計，計新增 項，減少 項，變更 項，變更後合計 項 | J6: 本次變更後總價 | L6: =J9 -> #VALUE!
A7: 項次 | B7: 項目名稱 | C7: 單位 | D7: 原 定 數 量 | E7: 變更後 數 量 | F7: 增 減 數 量 | G7: 契 約 單 價 | H7: 新 增 單 價 | I7: 原 訂 合 價 | J7: 變更後 合價 | K7: 追加 | L7: 追減 | M7: 備註 | O7: 變更依據 | P7: 數量計算式 | Q7: 變更原因
A9: 壹 | B9: 發包工程費 | C9: 式 | G9: =I9 -> 3.0824052e+08 | I9: =I10+I358+I384+I424+I428+I448+I468+I471+I472+I474 -> 3.0824052e+08 | J9: =J10+J358+J384+J424+J428+J448+J468+J471+J472+J474 -> #VALUE! | K9: =K10+K358+K384+K424+K428+K448+K468+K471+K472+K474 -> #VALUE! | L9: =L10+L358+L384+L424+L428+L448+L468+L471+L472+L474 -> #VALUE! | O9: =K9+L9 -> #VALUE!
A10: 一 | B10: 工程費 | C10: 式 | G10: =I10 -> 2.3286809e+08 | I10: =I11+I37+I128+I170+I199+I219+I236+I314+I348 -> 2.3286809e+08 | J10: =J11+J37+J128+J170+J199+J219+J236+J314+J348 -> #VALUE! | K10: =K11+K37+K128+K170+K199+K219+K236+K314+K348 -> #VALUE! | L10: =L11+L37+L128+L170+L199+L219+L236+L314+L348 -> #VALUE!
A11: (一) | B11: 整備工程 | C11: 式 | G11: 61233816 | I11: =SUM(I12:I36) -> 61233816 | J11: =SUM(J12:J36) -> #VALUE! | K11: =SUM(K12:K36) -> #VALUE! | L11: =SUM(L12:L36) -> #VALUE!
A12: 1 | B12: 機械拆除，瀝青混凝土，未含運費 | C12: M3 | D12: 720.24 | E12: =估驗單!F8 -> 720.24 | G12: 193.11 | I12: =ROUND(D12*G12,2) -> 139085.55 | J12: =ROUND(E12*G12,2) -> 139085.55 | K12: =J12-I12 -> 0 | L12: =I12-J12 -> 0
A13: 2 | B13: 機械拆除，鋼筋混凝土，未含運費 | C13: M3 | D13: 4813.44 | E13: =估驗單!F9 -> 4813.44 | G13: 1046.16 | I13: =ROUND(D13*G13,2) -> 5035628.4 | J13: =ROUND(E13*G13,2) -> 5035628.4 | K13: =J13-I13 -> 0 | L13: =I13-J13 -> 0
A14: 3 | B14: 盤踞切割 | C14: M | D14: 1743 | E14: =估驗單!F10 -> 1743 | G14: 6199.66 | I14: =ROUND(D14*G14,2) -> 10806007 | J14: =ROUND(E14*G14,2) -> 10806007 | K14: =J14-I14 -> 0 | L14: =I14-J14 -> 0 | M14: #磺港路橋(奇岩抽水站旁)1533.9m、希冀橋208.6m
A15: 4 | B15: 基地及路幅開挖，未含運費，(機械挖，0.7～0.79m3開挖機) | C15: B.M3 | D15: 28009.56 | E15: =估驗單!F11 -> 28009.56 | G15: 48.28 | I15: =ROUND(D15*G15,2) -> 1352301.6 | J15: =ROUND(E15*G15,2) -> 1352301.6 | K15: =J15-I15 -> 0 | L15: =I15-J15 -> 0 | O15: 112年12月12日 北市工水工字第1126067256號 | P15: 新設磺港橋及希冀橋橋台辦理既有基樁與新設基樁清障開挖+單孔過路段及清江公園 ((5*6*6.5*2)+(13*3.5*6.8)+(3.2*8.5*1.6))+((747.2+149.44)) | Q15: 機關/現場需求 (百齡)
A16: 5 | B16: 瀝青混凝土面層刨除，刨除料運費 | C16: M3 | D16: 4726.67 | E16: =估驗單!F12 -> 4726.67 | G16: 599.71 | I16: =ROUND(D16*G16,2) -> 2834631.3 | J16: =ROUND(E16*G16,2) -> 2834631.3 | K16: =J16-I16 -> 0 | L16: =I16-J16 -> 0
A17: 6 | B17: 利用填方，含夯實 | C17: M3 | D17: 13120 | E17: =估驗單!F13 -> 13120 | G17: 104.64 | I17: =ROUND(D17*G17,2) -> 1372876.8 | J17: =ROUND(E17*G17,2) -> 1372876.8 | K17: =J17-I17 -> 0 | L17: =I17-J17 -> 0
A18: 7 | B18: 餘方遠運處理(台北港) | C18: B.M3 | D18: 13251 | E18: =估驗單!F14 -> 4994 | G18: 1027.37 | I18: =ROUND(D18*G18,2) -> 13613680 | J18: =ROUND(E18*G18,2) -> 5130685.8 | K18: =J18-I18 -> -8482994.1 | L18: =I18-J18 -> 8482994.1 | M18: 僅含運費(運距約<20K)(土方管理費檢據核銷)
A19: 8 | B19: 餘方自行處理(房屋廢方，含水土保持) | C19: M3 | D19: 4601.44 | E19: =估驗單!F15 -> 0_x000D_ | G19: 1084.98 | I19: =ROUND(D19*G19,2) -> 4992470.4 | J19: =ROUND(E19*G19,2) -> #VALUE! | K19: =J19-I19 -> #VALUE! | L19: =I19-J19 -> #VALUE!
A20: 9 | B20: 瀝青混凝土面層刨除，厚5cm，刨除機1.2m寬，含瀝青鋪面打毛(未含運費) | C20: M2 | D20: 2588.5 | E20: =估驗單!F16 -> 2588.5 | G20: 30.45 | I20: =ROUND(D20*G20,2) -> 78819.83 | J20: =ROUND(E20*G20,2) -> 78819.83 | K20: =J20-I20 -> 0 | L20: =I20-J20 -> 0 | M20: #含瀝青鋪面打毛
A21: 10 | B21: 瀝青混凝土面層刨除，厚10cm，刨除機2.2m寬，未含運費 | C21: M2 | D21: 9177 | E21: =估驗單!F17 -> 9177 | G21: 28.48 | I21: =ROUND(D21*G21,2) -> 261360.96 | J21: =ROUND(E21*G21,2) -> 261360.96 | K21: =J21-I21 -> 0 | L21: =I21-J21 -> 0
A22: 11 | B22: 切割瀝青混凝土或無筋混凝土，5cm≦切割深度＜10cm | C22: M | D22: 162.5 | E22: =估驗單!F18 -> 162.5 | G22: 65.4 | I22: =ROUND(D22*G22,2) -> 10627.5 | J22: =ROUND(E22*G22,2) -> 10627.5 | K22: =J22-I22 -> 0 | L22: =I22-J22 -> 0
A23: 12 | B23: 清除及掘除，雜草雜木，含垃圾撿除，人工割 | C23: M2 | D23: 5217.7 | E23: =估驗單!F19 -> 5217.7 | G23: 20.19 | I23: =ROUND(D23*G23,2) -> 105345.36 | J23: =ROUND(E23*G23,2) -> 105345.36 | K23: =J23-I23 -> 0 | L23: =I23-J23 -> 0
A24: 13 | B24: 垃圾及廢棄物(以體積計)清運 | C24: M3 | D24: 782.66 | E24: =估驗單!F20 -> 782.66 | G24: 2286.68 | I24: =ROUND(D24*G24,2) -> 1789693 | J24: =ROUND(E24*G24,2) -> 1789693 | K24: =J24-I24 -> 0 | L24: =I24-J24 -> 0 | M24: #
A25: 14 | B25: 節塊吊放 | C25: 次 | D25: 425 | E25: =估驗單!F21 -> 425 | G25: 521.15 | I25: =ROUND(D25*G25,2) -> 221488.75 | J25: =ROUND(E25*G25,2) -> 221488.75 | K25: =J25-I25 -> 0 | L25: =I25-J25 -> 0 | M25: #磺港路橋、共月橋、三合橋
A26: 15 | B26: 機械拆除，工地雜項拆除清理，欄杆，含運費 | C26: M | D26: 255.5 | E26: =估驗單!F22 -> 415.08 | F26: =E26-D26 -> 159.58 | G26: 289.67 | I26: =ROUND(D26*G26,2) -> 74010.69 | J26: =ROUND(E26*G26,2) -> 120236.22 | K26: =J26-I26 -> 46225.53
A27: 16 | B27: 土方運送(百齡抽水站) | C27: 趟 | D27: 2204 | E27: =估驗單!F23 -> 2204 | G27: 3082.11 | I27: =ROUND(D27*G27,2) -> 6792970.4 | J27: =ROUND(E27*G27,2) -> 6792970.4 | K27: =J27-I27 -> 0 | L27: =I27-J27 -> 0
A28: 17 | B28: 既有路燈拆除繳回 | C28: 盞 | D28: 66 | E28: =估驗單!F24 -> 66 | G28: 3311.26 | I28: =ROUND(D28*G28,2) -> 218543.16 | J28: =ROUND(E28*G28,2) -> 218543.16 | K28: =J28-I28 -> 0 | L28: =I28-J28 -> 0 | M28: #料繳回，含運費。
A29: 18 | B29: 座椅拆除繳回 | C29: 座 | D29: 18 | E29: =估驗單!F25 -> 18 | G29: 1199.93 | I29: =ROUND(D29*G29,2) -> 21598.74 | J29: =ROUND(E29*G29,2) -> 21598.74 | K29: =J29-I29 -> 0 | L29: =I29-J29 -> 0 | M29: #料繳回，含運費。
A30: 19 | B30: 解說牌拆除 | C30: 座 | D30: 4 | E30: =估驗單!F26 -> 4 | G30: 2999.84 | I30: =ROUND(D30*G30,2) -> 11999.36 | J30: =ROUND(E30*G30,2) -> 11999.36 | K30: =J30-I30 -> 0 | L30: =I30-J30 -> 0 | M30: #料繳回，含運費。
A31: 20 | B31: 自行車架拆除 | C31: 座 | D31: 20 | E31: =估驗單!F27 -> 20 | G31: 2999.84 | I31: =ROUND(D31*G31,2) -> 59996.8 | J31: =ROUND(E31*G31,2) -> 59996.8 | K31: =J31-I31 -> 0 | L31: =I31-J31 -> 0 | M31: #料繳回，含運費。
A32: 21 | B32: 交通牌誌拆除 | C32: 座 | D32: 15 | E32: =估驗單!F28 -> 15 | G32: 2999.84 | I32: =ROUND(D32*G32,2) -> 44997.6 | J32: =ROUND(E32*G32,2) -> 44997.6 | K32: =J32-I32 -> 0 | L32: =I32-J32 -> 0 | M32: #料繳回，含運費。
A33: 22 | B33: 既有水利設施拆除及運送 | C33: 式 | D33: 1 | E33: =估驗單!F29 -> 1 | G33: 399978.19 | I33: =ROUND(D33*G33,2) -> 399978.19 | J33: =ROUND(E33*G33,2) -> 399978.19 | K33: =J33-I33 -> 0 | L33: =I33-J33 -> 0 | M33: 水閘門
A34: 23 | B34: 交通維持，道路管制人員，日間(06-22時)，義交 | C34: 時 | D34: 30800 | E34: =估驗單!F30 -> 30800 | F34: =E34-D34 -> 0 | G34: 280 | I34: =ROUND(D34*G34,2) -> 8624000 | J34: =ROUND(E34*G34,2) -> 8624000 | K34: =J34-I34 -> 0 | L34: =I34-J34 -> 0 | M34: [人力工項不打折]
A35: 24 | B35: 表土清除，堆置，及回填費，t=30cm | C35: M2 | D35: 2150 | E35: =估驗單!F31 -> 2150 | F35: =E35-D35 -> 0 | G35: 70.56 | I35: =ROUND(D35*G35,2) -> 151704 | J35: =ROUND(E35*G35,2) -> 151704 | K35: =J35-I35 -> 0 | L35: =I35-J35 -> 0 | M35: 百齡暫置場整地需求
A36: 25 | B36: 餘土分類處理 | C36: 日 | D36: 111 | E36: =估驗單!F32 -> 111 | F36: =E36-D36 -> 0 | G36: 20000 | I36: =ROUND(D36*G36,2) -> 2220000 | J36: =ROUND(E36*G36,2) -> 2220000 | K36: =J36-I36 -> 0 | L36: =I36-J36 -> 0 | M36: 新增工項 02323M00AC | O36: 北市工水工字第1126063128號 第6點 | P36: 數量=餘方遠運處理(台北港)/ 每日約120m3 | Q36: 屬後續擴充5000萬工項 既有磺港路、公園開挖摻雜混合物 | S36: 監造提供數量?
A37: (二) | B37: 土建景觀工程 | C37: 式 | E37: =估驗單!F33 -> 0 | F37: =E37-D37 -> 0 | G37: 30807124 | I37: =SUM(I38:I127) -> 30807124 | J37: =SUM(J38:J127) -> 32286203 | K37: =SUM(K38:K127) -> 3305690.7 | L37: =SUM(L38:L127) -> -1826612.4
A38: 1 | B38: 構造物回填，回填及夯實(實際) | C38: C.M3 | D38: 1887.64 | E38: =估驗單!F34 -> 1887.64 | F38: =E38-D38 -> 0 | G38: 320.72 | I38: =ROUND(D38*G38,2) -> 605403.9 | J38: =ROUND(E38*G38,2) -> 605403.9 | K38: =J38-I38 -> 0
A39: 2 | B39: 構造物回填，回填及夯實，人工夯實 | C39: C.M3 | D39: 402.21 | E39: =估驗單!F35 -> 402.21 | F39: =E39-D39 -> 0 | G39: 346.06 | I39: =ROUND(D39*G39,2) -> 139188.79 | J39: =ROUND(E39*G39,2) -> 139188.79 | K39: =J39-I39 -> 0
A40: 3 | B40: 鋼筋，SD280W | C40: KG | D40: 18865.76 | E40: =估驗單!F36 -> 18865.76 | F40: =E40-D40 -> 0 | G40: 36.4 | I40: =ROUND(D40*G40,2) -> 686713.66 | J40: =ROUND(E40*G40,2) -> 686713.66 | K40: =J40-I40 -> 0 | M40: 本項納入(鋼筋)物價指數調整
A41: 項次 | B41: 項目名稱 | C41: 單位 | D41: 原 定 數 量 | E41: 變更後 數 量 | F41: 增 減 數 量 | G41: 契 約 單 價 | H41: 新 增 單 價 | I41: 原 訂 合 價 | J41: 變更後 合價 | K41: 追加 | L41: 追減 | M41: 備註
...

Sheet 模板(全)
C1: 臺北市政府工務局水利工程處 | O1: =759925.2+3237744.6-1826612.36+355445.15+94917.34+240906+651749+802562.58-298416.97 -> 4018220.5 | P1: =759925+1411132+651749+802562+240906+450362 -> 4316636
C2: 第4次變更項目對照詳細表
A3: 工程名稱：磺港溪再造C段護岸及步道整建工程(三合橋至奇岩抽水站) | K3: 日期： | L3: 45653
A4: 原契約分為 10 部分 本次變更 4 部分原有 393 項 | J4: 訂約總價 | L4: 257600000
A5: 前經 3 次變更設計，計新增 43 項，減少 3 項，變更 27 項，變更後合計 438 項 | J5: 前次變更後總價(綜簽) | L5: 308240521
A6: 本次變更設計，計新增 項，減少 項，變更 項，變更後合計 項 | J6: 本次變更後總價 | L6: =J9 -> #VALUE!
A7: 項次 | B7: 項目名稱 | C7: 單位 | D7: 原 定 數 量 | E7: 變更後 數 量 | F7: 增 減 數 量 | G7: 契 約 單 價 | H7: 新 增 單 價 | I7: 原 訂 合 價 | J7: 變更後 合價 | K7: 追加 | L7: 追減 | M7: 備註 | O7: 變更依據 | P7: 數量計算式 | Q7: 變更原因
A9: 壹 | B9: 發包工程費 | C9: 式 | G9: =I9 -> 3.0689606e+08 | I9: =I10+I356+I382+I422+I426+I446+I466+I469+I470+I472 -> 3.0689606e+08 | J9: =J10+J356+J382+J422+J426+J446+J466+J469+J470+J472 -> #VALUE! | K9: =K10+K356+K382+K422+K426+K446+K466+K469+K470+K472 -> #VALUE! | L9: =L10+L356+L382+L422+L426+L446+L466+L469+L470+L472 -> #VALUE! | O9: =K9+L9 -> #VALUE!
A10: 一 | B10: 工程費 | C10: 式 | G10: =I10 -> 2.3152362e+08 | I10: =I11+I37+I127+I167+I197+I217+I234+I312+I346 -> 2.3152362e+08 | J10: =J11+J37+J127+J167+J197+J217+J234+J312+J346 -> #VALUE! | K10: =K11+K37+K127+K167+K197+K217+K234+K312+K346 -> #VALUE! | L10: =L11+L37+L127+L167+L197+L217+L234+L312+L346 -> #VALUE!
A11: (一) | B11: 整備工程 | C11: 式 | G11: 61233816 | I11: =SUM(I12:I36) -> 61233816 | J11: =SUM(J12:J36) -> #VALUE! | K11: =SUM(K12:K36) -> #VALUE! | L11: =SUM(L12:L36) -> #VALUE!
A12: 1 | B12: 機械拆除，瀝青混凝土，未含運費 | C12: M3 | D12: 720.24 | E12: =估驗單!F8 -> 720.24 | G12: 193.11 | I12: =ROUND(D12*G12,2) -> 139085.55 | J12: =ROUND(E12*G12,2) -> 139085.55 | K12: =J12-I12 -> 0 | L12: =I12-J12 -> 0
A13: 2 | B13: 機械拆除，鋼筋混凝土，未含運費 | C13: M3 | D13: 4813.44 | E13: =估驗單!F9 -> 4813.44 | G13: 1046.16 | I13: =ROUND(D13*G13,2) -> 5035628.4 | J13: =ROUND(E13*G13,2) -> 5035628.4 | K13: =J13-I13 -> 0 | L13: =I13-J13 -> 0
A14: 3 | B14: 盤踞切割 | C14: M | D14: 1743 | E14: =估驗單!F10 -> 1743 | G14: 6199.66 | I14: =ROUND(D14*G14,2) -> 10806007 | J14: =ROUND(E14*G14,2) -> 10806007 | K14: =J14-I14 -> 0 | L14: =I14-J14 -> 0 | M14: #磺港路橋(奇岩抽水站旁)1533.9m、希冀橋208.6m
A15: 4 | B15: 基地及路幅開挖，未含運費，(機械挖，0.7～0.79m3開挖機) | C15: B.M3 | D15: 28009.56 | E15: =估驗單!F11 -> 28009.56 | G15: 48.28 | I15: =ROUND(D15*G15,2) -> 1352301.6 | J15: =ROUND(E15*G15,2) -> 1352301.6 | K15: =J15-I15 -> 0 | L15: =I15-J15 -> 0 | O15: 112年12月12日 北市工水工字第1126067256號 | P15: 新設磺港橋及希冀橋橋台辦理既有基樁與新設基樁清障開挖+單孔過路段及清江公園 ((5*6*6.5*2)+(13*3.5*6.8)+(3.2*8.5*1.6))+((747.2+149.44)) | Q15: 機關/現場需求 (百齡)
A16: 5 | B16: 瀝青混凝土面層刨除，刨除料運費 | C16: M3 | D16: 4726.67 | E16: =估驗單!F12 -> 4726.67 | G16: 599.71 | I16: =ROUND(D16*G16,2) -> 2834631.3 | J16: =ROUND(E16*G16,2) -> 2834631.3 | K16: =J16-I16 -> 0 | L16: =I16-J16 -> 0
A17: 6 | B17: 利用填方，含夯實 | C17: M3 | D17: 13120 | E17: =估驗單!F13 -> 13120 | G17: 104.64 | I17: =ROUND(D17*G17,2) -> 1372876.8 | J17: =ROUND(E17*G17,2) -> 1372876.8 | K17: =J17-I17 -> 0 | L17: =I17-J17 -> 0
A18: 7 | B18: 餘方遠運處理(台北港) | C18: B.M3 | D18: 13251 | E18: =估驗單!F14 -> 4994 | G18: 1027.37 | I18: =ROUND(D18*G18,2) -> 13613680 | J18: =ROUND(E18*G18,2) -> 5130685.8 | K18: =J18-I18 -> -8482994.1 | L18: =I18-J18 -> 8482994.1 | M18: 僅含運費(運距約<20K)(土方管理費檢據核銷)
A19: 8 | B19: 餘方自行處理(房屋廢方，含水土保持) | C19: M3 | D19: 4601.44 | E19: =估驗單!F15 -> 0_x000D_ | G19: 1084.98 | I19: =ROUND(D19*G19,2) -> 4992470.4 | J19: =ROUND(E19*G19,2) -> #VALUE! | K19: =J19-I19 -> #VALUE! | L19: =I19-J19 -> #VALUE!
A20: 9 | B20: 瀝青混凝土面層刨除，厚5cm，刨除機1.2m寬，含瀝青鋪面打毛(未含運費) | C20: M2 | D20: 2588.5 | E20: =估驗單!F16 -> 2588.5 | G20: 30.45 | I20: =ROUND(D20*G20,2) -> 78819.83 | J20: =ROUND(E20*G20,2) -> 78819.83 | K20: =J20-I20 -> 0 | L20: =I20-J20 -> 0 | M20: #含瀝青鋪面打毛
A21: 10 | B21: 瀝青混凝土面層刨除，厚10cm，刨除機2.2m寬，未含運費 | C21: M2 | D21: 9177 | E21: =估驗單!F17 -> 9177 | G21: 28.48 | I21: =ROUND(D21*G21,2) -> 261360.96 | J21: =ROUND(E21*G21,2) -> 261360.96 | K21: =J21-I21 -> 0 | L21: =I21-J21 -> 0
A22: 11 | B22: 切割瀝青混凝土或無筋混凝土，5cm≦切割深度＜10cm | C22: M | D22: 162.5 | E22: =估驗單!F18 -> 162.5 | G22: 65.4 | I22: =ROUND(D22*G22,2) -> 10627.5 | J22: =ROUND(E22*G22,2) -> 10627.5 | K22: =J22-I22 -> 0 | L22: =I22-J22 -> 0
A23: 12 | B23: 清除及掘除，雜草雜木，含垃圾撿除，人工割 | C23: M2 | D23: 5217.7 | E23: =估驗單!F19 -> 5217.7 | G23: 20.19 | I23: =ROUND(D23*G23,2) -> 105345.36 | J23: =ROUND(E23*G23,2) -> 105345.36 | K23: =J23-I23 -> 0 | L23: =I23-J23 -> 0
A24: 13 | B24: 垃圾及廢棄物(以體積計)清運 | C24: M3 | D24: 782.66 | E24: =估驗單!F20 -> 782.66 | G24: 2286.68 | I24: =ROUND(D24*G24,2) -> 1789693 | J24: =ROUND(E24*G24,2) -> 1789693 | K24: =J24-I24 -> 0 | L24: =I24-J24 -> 0 | M24: #
A25: 14 | B25: 節塊吊放 | C25: 次 | D25: 425 | E25: =估驗單!F21 -> 425 | G25: 521.15 | I25: =ROUND(D25*G25,2) -> 221488.75 | J25: =ROUND(E25*G25,2) -> 221488.75 | K25: =J25-I25 -> 0 | L25: =I25-J25 -> 0 | M25: #磺港路橋、共月橋、三合橋
A26: 15 | B26: 機械拆除，工地雜項拆除清理，欄杆，含運費 | C26: M | D26: 255.5 | E26: =估驗單!F22 -> 415.08 | F26: =E26-D26 -> 159.58 | G26: 289.67 | I26: =ROUND(D26*G26,2) -> 74010.69 | J26: =ROUND(E26*G26,2) -> 120236.22 | K26: =J26-I26 -> 46225.53
A27: 16 | B27: 土方運送(百齡抽水站) | C27: 趟 | D27: 2204 | E27: =估驗單!F23 -> 2204 | G27: 3082.11 | I27: =ROUND(D27*G27,2) -> 6792970.4 | J27: =ROUND(E27*G27,2) -> 6792970.4 | K27: =J27-I27 -> 0 | L27: =I27-J27 -> 0
A28: 17 | B28: 既有路燈拆除繳回 | C28: 盞 | D28: 66 | E28: =估驗單!F24 -> 66 | G28: 3311.26 | I28: =ROUND(D28*G28,2) -> 218543.16 | J28: =ROUND(E28*G28,2) -> 218543.16 | K28: =J28-I28 -> 0 | L28: =I28-J28 -> 0 | M28: #料繳回，含運費。
A29: 18 | B29: 座椅拆除繳回 | C29: 座 | D29: 18 | E29: =估驗單!F25 -> 18 | G29: 1199.93 | I29: =ROUND(D29*G29,2) -> 21598.74 | J29: =ROUND(E29*G29,2) -> 21598.74 | K29: =J29-I29 -> 0 | L29: =I29-J29 -> 0 | M29: #料繳回，含運費。
A30: 19 | B30: 解說牌拆除 | C30: 座 | D30: 4 | E30: =估驗單!F26 -> 4 | G30: 2999.84 | I30: =ROUND(D30*G30,2) -> 11999.36 | J30: =ROUND(E30*G30,2) -> 11999.36 | K30: =J30-I30 -> 0 | L30: =I30-J30 -> 0 | M30: #料繳回，含運費。
A31: 20 | B31: 自行車架拆除 | C31: 座 | D31: 20 | E31: =估驗單!F27 -> 20 | G31: 2999.84 | I31: =ROUND(D31*G31,2) -> 59996.8 | J31: =ROUND(E31*G31,2) -> 59996.8 | K31: =J31-I31 -> 0 | L31: =I31-J31 -> 0 | M31: #料繳回，含運費。
A32: 21 | B32: 交通牌誌拆除 | C32: 座 | D32: 15 | E32: =估驗單!F28 -> 15 | G32: 2999.84 | I32: =ROUND(D32*G32,2) -> 44997.6 | J32: =ROUND(E32*G32,2) -> 44997.6 | K32: =J32-I32 -> 0 | L32: =I32-J32 -> 0 | M32: #料繳回，含運費。
A33: 22 | B33: 既有水利設施拆除及運送 | C33: 式 | D33: 1 | E33: =估驗單!F29 -> 1 | G33: 399978.19 | I33: =ROUND(D33*G33,2) -> 399978.19 | J33: =ROUND(E33*G33,2) -> 399978.19 | K33: =J33-I33 -> 0 | L33: =I33-J33 -> 0 | M33: 水閘門
A34: 23 | B34: 交通維持，道路管制人員，日間(06-22時)，義交 | C34: 時 | D34: 30800 | E34: =估驗單!F30 -> 30800 | F34: =E34-D34 -> 0 | G34: 280 | I34: =ROUND(D34*G34,2) -> 8624000 | J34: =ROUND(E34*G34,2) -> 8624000 | K34: =J34-I34 -> 0 | L34: =I34-J34 -> 0 | M34: [人力工項不打折]
A35: 24 | B35: 表土清除，堆置，及回填費，t=30cm | C35: M2 | D35: 2150 | E35: =估驗單!F31 -> 2150 | F35: =E35-D35 -> 0 | G35: 70.56 | I35: =ROUND(D35*G35,2) -> 151704 | J35: =ROUND(E35*G35,2) -> 151704 | K35: =J35-I35 -> 0 | L35: =I35-J35 -> 0 | M35: 百齡暫置場整地需求
A36: 25 | B36: 餘土分類處理 | C36: 日 | D36: 111 | E36: =估驗單!F32 -> 111 | F36: =E36-D36 -> 0 | G36: 20000 | I36: =ROUND(D36*G36,2) -> 2220000 | J36: =ROUND(E36*G36,2) -> 2220000 | K36: =J36-I36 -> 0 | L36: =I36-J36 -> 0 | M36: 新增工項 02323M00AC | O36: 北市工水工字第1126063128號 第6點 | P36: 數量=餘方遠運處理(台北港)/ 每日約120m3 | Q36: 屬後續擴充5000萬工項 既有磺港路、公園開挖摻雜混合物 | S36: 監造提供數量?
A37: (二) | B37: 土建景觀工程 | C37: 式 | E37: =估驗單!F33 -> 0 | F37: =E37-D37 -> 0 | G37: 30807124 | I37: =SUM(I38:I126) -> 29778927 | J37: =SUM(J38:J126) -> 31258006 | K37: =SUM(K38:K126) -> 3305690.7 | L37: =SUM(L38:L126) -> -1826612.4
A38: 1 | B38: 構造物回填，回填及夯實(實際) | C38: C.M3 | D38: 1887.64 | E38: =估驗單!F34 -> 1887.64 | F38: =E38-D38 -> 0 | G38: 320.72 | I38: =ROUND(D38*G38,2) -> 605403.9 | J38: =ROUND(E38*G38,2) -> 605403.9 | K38: =J38-I38 -> 0
A39: 2 | B39: 構造物回填，回填及夯實，人工夯實 | C39: C.M3 | D39: 402.21 | E39: =估驗單!F35 -> 402.21 | F39: =E39-D39 -> 0 | G39: 346.06 | I39: =ROUND(D39*G39,2) -> 139188.79 | J39: =ROUND(E39*G39,2) -> 139188.79 | K39: =J39-I39 -> 0
A40: 3 | B40: 鋼筋，SD280W | C40: KG | D40: 18865.76 | E40: =估驗單!F36 -> 18865.76 | F40: =E40-D40 -> 0 | G40: 36.4 | I40: =ROUND(D40*G40,2) -> 686713.66 | J40: =ROUND(E40*G40,2) -> 686713.66 | K40: =J40-I40 -> 0 | M40: 本項納入(鋼筋)物價指數調整
A41: 4 | B41: 結構用混凝土，預拌，140kgf/cm2 | C41: M3 | D41: 107.91 | E41: =估驗單!F37 -> 107.91 | F41: =E41-D41 -> 0 | G41: 3114.97 | I41: =ROUND(D41*G41,2) -> 336136.41 | J41: =ROUND(E41*G41,2) -> 336136.41 | K41: =J41-I41 -> 0
...

Sheet 鋼筋280420
C1: 臺北市政府工務局水利工程處 | O1: =759925.2+3237744.6-1826612.36+355445.15+94917.34+240906+651749+802562.58-298416.97 -> 4018220.5 | P1: =759925+1411132+651749+802562+240906+450362 -> 4316636
C2: 第4次變更項目對照詳細表
A3: 工程名稱：磺港溪再造C段護岸及步道整建工程(三合橋至奇岩抽水站) | K3: 日期： | L3: 45653
A4: 原契約分為 10 部分 本次變更 4 部分原有 393 項 | J4: 訂約總價 | L4: 257600000
A5: 前經 3 次變更設計，計新增 43 項，減少 3 項，變更 27 項，變更後合計 438 項 | J5: 前次變更後總價(綜簽) | L5: 308240521
A6: 本次變更設計，計新增 項，減少 項，變更 項，變更後合計 項 | J6: 本次變更後總價 | L6: =J9 -> #VALUE!
A7: 項次 | B7: 項目名稱 | C7: 單位 | D7: 原 定 數 量 | E7: 變更後 數 量 | F7: 增 減 數 量 | G7: 契 約 單 價 | H7: 新 增 單 價 | I7: 原 訂 合 價 | J7: 變更後 合價 | K7: 追加 | L7: 追減 | M7: 備註 | O7: 變更依據 | P7: 數量計算式 | Q7: 變更原因
A9: 壹 | B9: 發包工程費 | C9: 式 | G9: =I9 -> 3.0755381e+08 | I9: =I10+I357+I383+I423+I427+I447+I467+I470+I471+I473 -> 3.0755381e+08 | J9: =J10+J357+J383+J423+J427+J447+J467+J470+J471+J473 -> #VALUE! | K9: =K10+K357+K383+K423+K427+K447+K467+K470+K471+K473 -> #VALUE! | L9: =L10+L357+L383+L423+L427+L447+L467+L470+L471+L473 -> #VALUE! | O9: =K9+L9 -> #VALUE!
A10: 一 | B10: 工程費 | C10: 式 | G10: =I10 -> 2.3218137e+08 | I10: =I11+I37+I127+I169+I198+I218+I235+I313+I347 -> 2.3218137e+08 | J10: =J11+J37+J127+J169+J198+J218+J235+J313+J347 -> #VALUE! | K10: =K11+K37+K127+K169+K198+K218+K235+K313+K347 -> #VALUE! | L10: =L11+L37+L127+L169+L198+L218+L235+L313+L347 -> #VALUE!
A11: (一) | B11: 整備工程 | C11: 式 | G11: 61233816 | I11: =SUM(I12:I36) -> 61233816 | J11: =SUM(J12:J36) -> #VALUE! | K11: =SUM(K12:K36) -> #VALUE! | L11: =SUM(L12:L36) -> #VALUE!
A12: 1 | B12: 機械拆除，瀝青混凝土，未含運費 | C12: M3 | D12: 720.24 | E12: =估驗單!F8 -> 720.24 | G12: 193.11 | I12: =ROUND(D12*G12,2) -> 139085.55 | J12: =ROUND(E12*G12,2) -> 139085.55 | K12: =J12-I12 -> 0 | L12: =I12-J12 -> 0
A13: 2 | B13: 機械拆除，鋼筋混凝土，未含運費 | C13: M3 | D13: 4813.44 | E13: =估驗單!F9 -> 4813.44 | G13: 1046.16 | I13: =ROUND(D13*G13,2) -> 5035628.4 | J13: =ROUND(E13*G13,2) -> 5035628.4 | K13: =J13-I13 -> 0 | L13: =I13-J13 -> 0
A14: 3 | B14: 盤踞切割 | C14: M | D14: 1743 | E14: =估驗單!F10 -> 1743 | G14: 6199.66 | I14: =ROUND(D14*G14,2) -> 10806007 | J14: =ROUND(E14*G14,2) -> 10806007 | K14: =J14-I14 -> 0 | L14: =I14-J14 -> 0 | M14: #磺港路橋(奇岩抽水站旁)1533.9m、希冀橋208.6m
A15: 4 | B15: 基地及路幅開挖，未含運費，(機械挖，0.7～0.79m3開挖機) | C15: B.M3 | D15: 28009.56 | E15: =估驗單!F11 -> 28009.56 | G15: 48.28 | I15: =ROUND(D15*G15,2) -> 1352301.6 | J15: =ROUND(E15*G15,2) -> 1352301.6 | K15: =J15-I15 -> 0 | L15: =I15-J15 -> 0 | O15: 112年12月12日 北市工水工字第1126067256號 | P15: 新設磺港橋及希冀橋橋台辦理既有基樁與新設基樁清障開挖+單孔過路段及清江公園 ((5*6*6.5*2)+(13*3.5*6.8)+(3.2*8.5*1.6))+((747.2+149.44)) | Q15: 機關/現場需求 (百齡)
A16: 5 | B16: 瀝青混凝土面層刨除，刨除料運費 | C16: M3 | D16: 4726.67 | E16: =估驗單!F12 -> 4726.67 | G16: 599.71 | I16: =ROUND(D16*G16,2) -> 2834631.3 | J16: =ROUND(E16*G16,2) -> 2834631.3 | K16: =J16-I16 -> 0 | L16: =I16-J16 -> 0
A17: 6 | B17: 利用填方，含夯實 | C17: M3 | D17: 13120 | E17: =估驗單!F13 -> 13120 | G17: 104.64 | I17: =ROUND(D17*G17,2) -> 1372876.8 | J17: =ROUND(E17*G17,2) -> 1372876.8 | K17: =J17-I17 -> 0 | L17: =I17-J17 -> 0
A18: 7 | B18: 餘方遠運處理(台北港) | C18: B.M3 | D18: 13251 | E18: =估驗單!F14 -> 4994 | G18: 1027.37 | I18: =ROUND(D18*G18,2) -> 13613680 | J18: =ROUND(E18*G18,2) -> 5130685.8 | K18: =J18-I18 -> -8482994.1 | L18: =I18-J18 -> 8482994.1 | M18: 僅含運費(運距約<20K)(土方管理費檢據核銷)
A19: 8 | B19: 餘方自行處理(房屋廢方，含水土保持) | C19: M3 | D19: 4601.44 | E19: =估驗單!F15 -> 0_x000D_ | G19: 1084.98 | I19: =ROUND(D19*G19,2) -> 4992470.4 | J19: =ROUND(E19*G19,2) -> #VALUE! | K19: =J19-I19 -> #VALUE! | L19: =I19-J19 -> #VALUE!
A20: 9 | B20: 瀝青混凝土面層刨除，厚5cm，刨除機1.2m寬，含瀝青鋪面打毛(未含運費) | C20: M2 | D20: 2588.5 | E20: =估驗單!F16 -> 2588.5 | G20: 30.45 | I20: =ROUND(D20*G20,2) -> 78819.83 | J20: =ROUND(E20*G20,2) -> 78819.83 | K20: =J20-I20 -> 0 | L20: =I20-J20 -> 0 | M20: #含瀝青鋪面打毛
A21: 10 | B21: 瀝青混凝土面層刨除，厚10cm，刨除機2.2m寬，未含運費 | C21: M2 | D21: 9177 | E21: =估驗單!F17 -> 9177 | G21: 28.48 | I21: =ROUND(D21*G21,2) -> 261360.96 | J21: =ROUND(E21*G21,2) -> 261360.96 | K21: =J21-I21 -> 0 | L21: =I21-J21 -> 0
A22: 11 | B22: 切割瀝青混凝土或無筋混凝土，5cm≦切割深度＜10cm | C22: M | D22: 162.5 | E22: =估驗單!F18 -> 162.5 | G22: 65.4 | I22: =ROUND(D22*G22,2) -> 10627.5 | J22: =ROUND(E22*G22,2) -> 10627.5 | K22: =J22-I22 -> 0 | L22: =I22-J22 -> 0
A23: 12 | B23: 清除及掘除，雜草雜木，含垃圾撿除，人工割 | C23: M2 | D23: 5217.7 | E23: =估驗單!F19 -> 5217.7 | G23: 20.19 | I23: =ROUND(D23*G23,2) -> 105345.36 | J23: =ROUND(E23*G23,2) -> 105345.36 | K23: =J23-I23 -> 0 | L23: =I23-J23 -> 0
A24: 13 | B24: 垃圾及廢棄物(以體積計)清運 | C24: M3 | D24: 782.66 | E24: =估驗單!F20 -> 782.66 | G24: 2286.68 | I24: =ROUND(D24*G24,2) -> 1789693 | J24: =ROUND(E24*G24,2) -> 1789693 | K24: =J24-I24 -> 0 | L24: =I24-J24 -> 0 | M24: #
A25: 14 | B25: 節塊吊放 | C25: 次 | D25: 425 | E25: =估驗單!F21 -> 425 | G25: 521.15 | I25: =ROUND(D25*G25,2) -> 221488.75 | J25: =ROUND(E25*G25,2) -> 221488.75 | K25: =J25-I25 -> 0 | L25: =I25-J25 -> 0 | M25: #磺港路橋、共月橋、三合橋
A26: 15 | B26: 機械拆除，工地雜項拆除清理，欄杆，含運費 | C26: M | D26: 255.5 | E26: =估驗單!F22 -> 415.08 | F26: =E26-D26 -> 159.58 | G26: 289.67 | I26: =ROUND(D26*G26,2) -> 74010.69 | J26: =ROUND(E26*G26,2) -> 120236.22 | K26: =J26-I26 -> 46225.53
A27: 16 | B27: 土方運送(百齡抽水站) | C27: 趟 | D27: 2204 | E27: =估驗單!F23 -> 2204 | G27: 3082.11 | I27: =ROUND(D27*G27,2) -> 6792970.4 | J27: =ROUND(E27*G27,2) -> 6792970.4 | K27: =J27-I27 -> 0 | L27: =I27-J27 -> 0
A28: 17 | B28: 既有路燈拆除繳回 | C28: 盞 | D28: 66 | E28: =估驗單!F24 -> 66 | G28: 3311.26 | I28: =ROUND(D28*G28,2) -> 218543.16 | J28: =ROUND(E28*G28,2) -> 218543.16 | K28: =J28-I28 -> 0 | L28: =I28-J28 -> 0 | M28: #料繳回，含運費。
A29: 18 | B29: 座椅拆除繳回 | C29: 座 | D29: 18 | E29: =估驗單!F25 -> 18 | G29: 1199.93 | I29: =ROUND(D29*G29,2) -> 21598.74 | J29: =ROUND(E29*G29,2) -> 21598.74 | K29: =J29-I29 -> 0 | L29: =I29-J29 -> 0 | M29: #料繳回，含運費。
A30: 19 | B30: 解說牌拆除 | C30: 座 | D30: 4 | E30: =估驗單!F26 -> 4 | G30: 2999.84 | I30: =ROUND(D30*G30,2) -> 11999.36 | J30: =ROUND(E30*G30,2) -> 11999.36 | K30: =J30-I30 -> 0 | L30: =I30-J30 -> 0 | M30: #料繳回，含運費。
A31: 20 | B31: 自行車架拆除 | C31: 座 | D31: 20 | E31: =估驗單!F27 -> 20 | G31: 2999.84 | I31: =ROUND(D31*G31,2) -> 59996.8 | J31: =ROUND(E31*G31,2) -> 59996.8 | K31: =J31-I31 -> 0 | L31: =I31-J31 -> 0 | M31: #料繳回，含運費。
A32: 21 | B32: 交通牌誌拆除 | C32: 座 | D32: 15 | E32: =估驗單!F28 -> 15 | G32: 2999.84 | I32: =ROUND(D32*G32,2) -> 44997.6 | J32: =ROUND(E32*G32,2) -> 44997.6 | K32: =J32-I32 -> 0 | L32: =I32-J32 -> 0 | M32: #料繳回，含運費。
A33: 22 | B33: 既有水利設施拆除及運送 | C33: 式 | D33: 1 | E33: =估驗單!F29 -> 1 | G33: 399978.19 | I33: =ROUND(D33*G33,2) -> 399978.19 | J33: =ROUND(E33*G33,2) -> 399978.19 | K33: =J33-I33 -> 0 | L33: =I33-J33 -> 0 | M33: 水閘門
A34: 23 | B34: 交通維持，道路管制人員，日間(06-22時)，義交 | C34: 時 | D34: 30800 | E34: =估驗單!F30 -> 30800 | F34: =E34-D34 -> 0 | G34: 280 | I34: =ROUND(D34*G34,2) -> 8624000 | J34: =ROUND(E34*G34,2) -> 8624000 | K34: =J34-I34 -> 0 | L34: =I34-J34 -> 0 | M34: [人力工項不打折]
A35: 24 | B35: 表土清除，堆置，及回填費，t=30cm | C35: M2 | D35: 2150 | E35: =估驗單!F31 -> 2150 | F35: =E35-D35 -> 0 | G35: 70.56 | I35: =ROUND(D35*G35,2) -> 151704 | J35: =ROUND(E35*G35,2) -> 151704 | K35: =J35-I35 -> 0 | L35: =I35-J35 -> 0 | M35: 百齡暫置場整地需求
A36: 25 | B36: 餘土分類處理 | C36: 日 | D36: 111 | E36: =估驗單!F32 -> 111 | F36: =E36-D36 -> 0 | G36: 20000 | I36: =ROUND(D36*G36,2) -> 2220000 | J36: =ROUND(E36*G36,2) -> 2220000 | K36: =J36-I36 -> 0 | L36: =I36-J36 -> 0 | M36: 新增工項 02323M00AC | O36: 北市工水工字第1126063128號 第6點 | P36: 數量=餘方遠運處理(台北港)/ 每日約120m3 | Q36: 屬後續擴充5000萬工項 既有磺港路、公園開挖摻雜混合物 | S36: 監造提供數量?
A37: (二) | B37: 土建景觀工程 | C37: 式 | E37: =估驗單!F33 -> 0 | F37: =E37-D37 -> 0 | G37: 30807124 | I37: =SUM(I38:I126) -> 30120411 | J37: =SUM(J38:J126) -> 31599489 | K37: =SUM(K38:K126) -> 3305690.7 | L37: =SUM(L38:L126) -> -1826612.4
A38: 1 | B38: 構造物回填，回填及夯實(實際) | C38: C.M3 | D38: 1887.64 | E38: =估驗單!F34 -> 1887.64 | F38: =E38-D38 -> 0 | G38: 320.72 | I38: =ROUND(D38*G38,2) -> 605403.9 | J38: =ROUND(E38*G38,2) -> 605403.9 | K38: =J38-I38 -> 0
A39: 2 | B39: 構造物回填，回填及夯實，人工夯實 | C39: C.M3 | D39: 402.21 | E39: =估驗單!F35 -> 402.21 | F39: =E39-D39 -> 0 | G39: 346.06 | I39: =ROUND(D39*G39,2) -> 139188.79 | J39: =ROUND(E39*G39,2) -> 139188.79 | K39: =J39-I39 -> 0
A40: 項次 | B40: 項目名稱 | C40: 單位 | D40: 原 定 數 量 | E40: 變更後 數 量 | F40: 增 減 數 量 | G40: 契 約 單 價 | H40: 新 增 單 價 | I40: 原 訂 合 價 | J40: 變更後 合價 | K40: 追加 | L40: 追減 | M40: 備註
A42: 4 | B42: 結構用混凝土，預拌，140kgf/cm2 | C42: M3 | D42: 107.91 | E42: =估驗單!F37 -> 107.91 | F42: =E42-D42 -> 0 | G42: 3114.97 | I42: =ROUND(D42*G42,2) -> 336136.41 | J42: =ROUND(E42*G42,2) -> 336136.41 | K42: =J42-I42 -> 0
...

Sheet 估驗單
A1: 臺北市政府工務局水利工程處
A2: 變更項目對照詳細表
A3: 工程名稱：磺港溪再造C段護岸及步道整建工程(三合橋至奇岩抽水站) | O3: 估驗日期： | P3: 45596
A4: 項次 | B4: 項目說明 | C4: 單位 | D4: 原契約 數量 | E4: 3 變 後 核定數量 | F4: 4 變 後 數量 | G4: 應做數量 | H4: 追加數量 | I4: 追加金額 | J4: 追減數量 | K4: 追減金額 | L4: 估驗 單價 | M4: 本 次 估驗數量 | N4: 本次止累計 估驗數量 | O4: 本 次 估驗金額 | P4: 本次止累計 估驗金額 | Q4: 備 註
A5: 壹 | B5: 發包工程費 | C5: 式 | D5: 1 | L5: 304975279 | M5: 1 | N5: 1 | O5: 7397700 | P5: 191886300
A6: 一 | B6: 工程費 | C6: 式 | D6: 1 | L6: 2.3286809e+08 | M6: 1 | N6: 1 | O6: 5673978.8 | P6: 1.4020001e+08
A7: (一) | B7: 整備工程 | C7: 式 | D7: 1 | L7: 61233816 | M7: 1 | N7: 1 | O7: 927832.41 | P7: 44630848
A8: 1 | B8: 機械拆除，瀝青混凝土，未含運費 | C8: M3 | D8: 720.24 | F8: 720.24 | L8: 193.11 | M8: 18.75 | N8: 148.93 | O8: 3620.81 | P8: 28759.87
A9: 2 | B9: 機械拆除，鋼筋混凝土，未含運費 | C9: M3 | D9: 4813.44 | F9: 4813.44 | L9: 1046.16 | M9: 0 | N9: 4091.17 | O9: 0 | P9: 4280018.4
A10: 3 | B10: 盤踞切割 | C10: M | D10: 1743 | F10: 1743 | L10: 6199.66 | M10: 0 | N10: 1741.3 | O10: 0 | P10: 10795468
A11: 4 | B11: 基地及路幅開挖，未含運費，(機械挖，0.7～0.79m3開挖機) | C11: B.M3 | D11: 26370 | E11: 28009.56 | F11: ='數量計算(FOR4變)'!I39 -> 28009.56 | L11: 48.28 | M11: 75 | N11: 26684 | O11: 3621 | P11: 1288303.5
A12: 5 | B12: 瀝青混凝土面層刨除，刨除料運費 | C12: M3 | D12: 4726.67 | F12: 4726.67 | L12: 599.71 | M12: 0 | N12: 569.4 | O12: 0 | P12: 341474.87
A13: 6 | B13: 利用填方，含夯實 | C13: M3 | D13: 13120 | F13: ='數量計算(FOR4變)'!I47 -> 13120 | L13: 104.64 | M13: 864 | N13: 8670.22 | O13: 90408.96 | P13: 907251.82
A14: 7 | B14: 餘方遠運處理(台北港) | C14: B.M3 | D14: 13251 | F14: ='數量計算(FOR4變)'!J54 -> 4994 | L14: 1027.37 | M14: 156 | N14: 10560 | O14: 160269.72 | P14: 10849027
A15: 8 | B15: 餘方自行處理(房屋廢方，含水土保持) | C15: M3 | D15: 4601.44 | F15: ='數量計算(FOR4變)'!I59 -> 0_x000D_ | L15: 1084.98 | M15: 0 | N15: 0 | O15: 0 | P15: 0
A16: 9 | B16: 瀝青混凝土面層刨除，厚5cm，刨除機1.2m寬，含瀝青鋪面打毛(未含運費) | C16: M2 | D16: 2588.5 | F16: 2588.5 | L16: 30.45 | M16: 0 | N16: 0 | O16: 0 | P16: 0
A17: 10 | B17: 瀝青混凝土面層刨除，厚10cm，刨除機2.2m寬，未含運費 | C17: M2 | D17: 9177 | F17: 9177 | L17: 28.48 | M17: 0 | N17: 4745 | O17: 0 | P17: 135137.6
A18: 11 | B18: 切割瀝青混凝土或無筋混凝土，5cm≦切割深度＜10cm | C18: M | D18: 162.5 | F18: 162.5 | L18: 65.4 | M18: 0 | N18: 52.1 | O18: 0 | P18: 3407.34
A19: 12 | B19: 清除及掘除，雜草雜木，含垃圾撿除，人工割 | C19: M2 | D19: 5217.7 | F19: 5217.7 | L19: 20.19 | M19: 0 | N19: 3717 | O19: 0 | P19: 75046.23
A20: 13 | B20: 垃圾及廢棄物(以體積計)清運 | C20: M3 | D20: 782.66 | F20: 782.66 | L20: 2286.68 | M20: 0 | N20: 108 | O20: 0 | P20: 246961.44
A21: 14 | B21: 節塊吊放 | C21: 次 | D21: 425 | F21: 425 | L21: 521.15 | M21: 0 | N21: 425 | O21: 0 | P21: 221488.75
A22: 15 | B22: 機械拆除，工地雜項拆除清理，欄杆，含運費 | C22: M | D22: 255.5 | F22: =G22 -> 415.08 | G22: ='數量計算(FOR4變)'!I70 -> 415.08 | H22: =G22-D22 -> 159.58 | I22: =ROUND(H22*L22,2) -> 46225.54 | L22: 289.67 | M22: 0 | N22: 255.5 | O22: 0 | P22: 74010.69
A23: 16 | B23: 土方運送(百齡抽水站) | C23: 趟 | D23: 2204 | F23: 2204 | L23: 3082.11 | M23: 72 | N23: 2107 | O23: 221911.92 | P23: 6494005.8
A24: 17 | B24: 既有路燈拆除繳回 | C24: 盞 | D24: 66 | F24: 66 | L24: 3311.26 | M24: 0 | N24: 65 | O24: 0 | P24: 215231.9
A25: 18 | B25: 座椅拆除繳回 | C25: 座 | D25: 18 | F25: 18 | L25: 1199.93 | M25: 0 | N25: 18 | O25: 0 | P25: 21598.74
A26: 19 | B26: 解說牌拆除 | C26: 座 | D26: 4 | F26: 4 | L26: 2999.84 | M26: 0 | N26: 4 | O26: 0 | P26: 11999.36
A27: 20 | B27: 自行車架拆除 | C27: 座 | D27: 20 | F27: 20 | L27: 2999.84 | M27: 0 | N27: 20 | O27: 0 | P27: 59996.8
A28: 21 | B28: 交通牌誌拆除 | C28: 座 | D28: 15 | F28: 15 | L28: 2999.84 | M28: 0 | N28: 15 | O28: 0 | P28: 44997.6
A29: 22 | B29: 既有水利設施拆除及運送 | C29: 式 | D29: 1 | F29: 1 | L29: 399978.19 | M29: 0 | N29: 1 | O29: 0 | P29: 399978.19 | Q29: (估驗比率約:100%)
A30: 23 | B30: 交通維持，道路管制人員，日間(06-22時)，義交 | C30: 時 | D30: 30800 | F30: 30800 | L30: 280 | M30: 1600 | N30: 21303.5 | O30: 448000 | P30: 5964980
A31: 24 | B31: 表土清除，堆置，及回填費，t=30cm | C31: M2 | D31: 0 | E31: 2150 | F31: 2150 | L31: 70.56 | M31: 0 | N31: 2150 | O31: 0 | P31: 151704
A32: 25 | B32: 餘土分類處理 | C32: 日 | D32: 0 | E32: 111 | F32: 111 | L32: 20000 | M32: 0 | N32: 101 | O32: 0 | P32: 2020000
A33: (二) | B33: 土建景觀工程 | C33: 式 | D33: 1 | L33: 30807124 | M33: 1 | N33: 1 | O33: 140646.04 | P33: 1083872.9
A34: 1 | B34: 構造物回填，回填及夯實(實際) | C34: C.M3 | D34: 1887.64 | F34: =D34 -> 1887.64 | L34: 320.72 | M34: 0 | N34: 0 | O34: 0 | P34: 0
A35: 2 | B35: 構造物回填，回填及夯實，人工夯實 | C35: C.M3 | D35: 402.21 | F35: =D35 -> 402.21 | L35: 346.06 | M35: 0 | N35: 0 | O35: 0 | P35: 0
A36: 3 | B36: 鋼筋，SD280W | C36: KG | D36: 18865.76 | F36: =D36 -> 18865.76 | L36: 36.4 | M36: 0 | N36: 5167.44 | O36: 0 | P36: 188094.82
A37: 4 | B37: 結構用混凝土，預拌，140kgf/cm2 | C37: M3 | D37: 107.91 | F37: =D37 -> 107.91 | L37: 3114.97 | M37: 0 | N37: 4.73 | O37: 0 | P37: 14733.81
A38: 5 | B38: 結構用混凝土，預拌，210kgf/cm2 | C38: M3 | D38: 564.01 | F38: =D38 -> 564.01 | L38: 3320.96 | M38: 0 | N38: 59.94 | O38: 0 | P38: 199058.34
A39: 6 | B39: 普通模板，丙種 | C39: M2 | D39: 1926.87 | F39: =D39 -> 1926.87 | L39: 533.61 | M39: 0 | N39: 374.32 | O39: 0 | P39: 199740.9
A40: 7 | B40: 清水模板，鋼模 | C40: M2 | D40: 301.33 | F40: =D40 -> 301.33 | L40: 1299.82 | M40: 0 | N40: 0 | O40: 0 | P40: 0
...

Sheet 契約
A1: 臺北市政府工務局水利工程處
A2: 詳 細 價 目 表
A4: 工程名稱：磺港溪再造C段護岸及步道整建工程(三合橋至奇岩抽水站)
A5: 施工地點：北投磺港溪 | F5: 工程編號：111 070020302 038 02
A6: 項次 | B6: 項 目 及 說 明 | C6: 單位 | D6: 數量 | E6: 單 價 | F6: 複 價 | G6: 備 註
A7: 壹 | B7: 發包工程費 | C7: 式 | D7: 1 | F7: 257600000
A8: 一 | B8: 工程費 | C8: 式 | D8: 1 | F8: 2.0448708e+08
A9: (一) | B9: 整備工程 | C9: 式 | D9: 1 | F9: 58782954
A10: 1.1.1 | B10: 機械拆除，瀝青混凝土，未含運費 | C10: M3 | D10: 720.24 | E10: 193.11 | F10: 139085.55 | G10: 0222010123 分析表1_x000D_
A11: 1.1.2 | B11: 機械拆除，鋼筋混凝土，未含運費 | C11: M3 | D11: 4813.44 | E11: 1046.16 | F11: 5035628.4 | G11: 0222010E23 分析表2_x000D_
A12: 1.1.3 | B12: 盤踞切割 | C12: M | D12: 1743 | E12: 6199.66 | F12: 10806007 | G12: 0222011101 #磺港路橋(奇岩抽水站旁)1533.9m、希冀橋208.6m
A13: 1.1.4 | B13: 基地及路幅開挖，未含運費，(機械挖，0.7～0.79m3開挖機) | C13: B.M3 | D13: 26370 | E13: 48.28 | F13: 1273143.6 | G13: 02321PWD05AB1 分析表3_x000D_
A14: 1.1.5 | B14: 瀝青混凝土面層刨除，刨除料運費 | C14: M3 | D14: 4726.67 | E14: 599.71 | F14: 2834631.3 | G14: 0296103003 分析表4_x000D_
A15: 1.1.6 | B15: 利用填方，含夯實 | C15: M3 | D15: 13120 | E15: 104.64 | F15: 1372876.8 | G15: 02931BDD101 分析表5_x000D_
A16: 1.1.7 | B16: 餘方遠運處理(台北港) | C16: B.M3 | D16: 13251 | E16: 1027.37 | F16: 13613680 | G16: 023235X46A 分析表6_x000D_ 僅含運費(運距約<20K)(土方管理費檢據核銷)
A17: 1.1.8 | B17: 餘方自行處理(房屋廢方，含水土保持) | C17: M3 | D17: 4601.44 | E17: 1084.98 | F17: 4992470.4 | G17: 0232340063a 分析表7_x000D_
A18: 1.1.9 | B18: 瀝青混凝土面層刨除，厚5cm，刨除機1.2m寬，含瀝青鋪面打毛(未含運費) | C18: M2 | D18: 2588.5 | E18: 30.45 | F18: 78819.83 | G18: 02961403321 分析表8_x000D_ #含瀝青鋪面打毛
A19: 1.1.10 | B19: 瀝青混凝土面層刨除，厚10cm，刨除機2.2m寬，未含運費 | C19: M2 | D19: 9177 | E19: 28.48 | F19: 261360.96 | G19: 0296190432 分析表9_x000D_
A20: 1.1.11 | B20: 切割瀝青混凝土或無筋混凝土，5cm≦切割深度＜10cm | C20: M | D20: 162.5 | E20: 65.4 | F20: 10627.5 | G20: 02220PWD00021 分析表10_x000D_
A21: 1.1.12 | B21: 清除及掘除，雜草雜木，含垃圾撿除，人工割 | C21: M2 | D21: 5217.7 | E21: 20.19 | F21: 105345.36 | G21: 0223109002 分析表11_x000D_
... A32: 1.1.23 | B32: 交通維持，道路管制人員，日間(06-22時)，義交 | C32: 時 | D32: 30800 | E32: 280 | F32: 8624000 | G32: L015566G01001 [人力工項不打折]
A33: (二) | B33: 土建景觀工程 | C33: 式 | D33: 1 | F33: 30807124
A34: 1.2.1 | B34: 構造物回填，回填及夯實(實際) | C34: C.M3 | D34: 1887.64 | E34: 320.72 | F34: 605403.9 | G34: 023174000A 分析表17_x000D_
A35: 1.2.2 | B35: 構造物回填，回填及夯實，人工夯實 | C35: C.M3 | D35: 402.21 | E35: 346.06 | F35: 139188.79 | G35: 0231740#M1 分析表18_x000D_
A36: 1.2.3 | B36: 鋼筋，SD280W | C36: KG | D36: 18865.76 | E36: 36.4 | F36: 686713.66 | G36: 0321040009z 分析表19_x000D_ 本項納入(鋼筋)物價指數調整
A37: 1.2.4 | B37: 結構用混凝土，預拌，140kgf/cm2 | C37: M3 | D37: 107.91 | E37: 3114.97 | F37: 336136.41 | G37: 0331023003 分析表20_x000D_
A38: 1.2.5 | B38: 結構用混凝土，預拌，210kgf/cm2 | C38: M3 | D38: 564.01 | E38: 3320.96 | F38: 1873054.6 | G38: 0331025003 分析表21_x000D_
A39: 1.2.6 | B39: 普通模板，丙種 | C39: M2 | D39: 1926.87 | E39: 533.61 | F39: 1028197.1 | G39: 0311011302z 分析表22_x000D_ U型構，集水井，排水箱涵等。本項納入(普通模板)物價指數調整
A40: 1.2.7 | B40: 清水模板，鋼模 | C40: M2 | D40: 301.33 | E40: 1299.82 | F40: 391674.76 | G40: 03110212A1a 分析表23_x000D_ 本項納入「金屬製品類」物價指數調整
A41: 1.2.8 | B41: 鍍鋅鋼料 | C41: KG | D41: 5991.34 | E41: 60 | F41: 359480.4 | G41: 05500R0009A 分析表24_x000D_ #本項納入「金屬製品類」物價指數調整
A42: 1.2.9 | B42: 金屬材料，鋼料，裁切加工銲製(工廠加工) | C42: KG | D42: 5991.34 | E42: 31.9 | F42: 191123.75 | G42: 050606B009
A43: 1.2.10 | B43: 結構用鋼材，銲接結構用軋鋼料，SM400B鋼構工程及製作、組立工程(含加勁板、續接板、螺絲、螺栓、螺帽等) | C43: KG | D43: 1180.03 | E43: 107.3 | F43: 126617.22 | G43: 0512540009A2 分析表25_x000D_ #本項納入「金屬製品類」物價指數調整
A44: 1.2.11 | B44: 透水磚紙模地坪 | C44: M2 | D44: 3879.21 | E44: 3092.69 | F44: 11997194 | G44: 0279400002 分析表26_x000D_
A45: 1.2.12 | B45: 梯形磚鋪面，149.5x(30,20)x8cmTH | C45: M2 | D45: 462.9 | E45: 3961.37 | F45: 1833718.2 | G45: 0278600342 分析表27_x000D_
... A118: 1.2.85 | B118: 雨水回收槽 | C118: 座 | D118: 2 | E118: 913306.18 | F118: 1826612.4 | G118: 0263121DWA 分析表99_x000D_ #
A119: (三) | B119: 橋梁工程 | C119: 式 | D119: 1 | F119: 40947246
A120: 1.3.1 | B120: 構造物回填，回填及夯實(實際) | C120: C.M3 | D120: 185.59 | E120: 320.72 | F120: 59522.42 | G120: 023174000A 分析表17_x000D_
A121: 1.3.2 | B121: 結構用混凝土，預拌，140kgf/cm2 | C121: M3 | D121: 26.33 | E121: 3114.97 | F121: 82017.16 | G121: 0331023003 分析表20_x000D_
A122: 1.3.3 | B122: 結構用混凝土，預拌，210kgf/cm2 | C122: M3 | D122: 36.86 | E122: 3320.96 | F122: 122410.59 | G122: 0331025003 分析表21_x000D_
A123: 1.3.4 | B123: 結構用混凝土，預拌，280kgf/cm2 | C123: M3 | D123: 654.83 | E123: 3643.53 | F123: 2385892.8 | G123: 0331027003 分析表100_x000D_
...

Sheet 數量計算(勇哥)
A1: 臺北市政府工務局水利工程處
A2: 數量計算書
A3: 工程名稱：磺港溪再造C段護岸及步道整建工程(三合橋至奇岩抽水站)
A4: 施工地點：北投磺港溪 | F4: 工程編號：111 070020302 038 02
A5: 項次 | B5: 項目及說明 | C5: 單位 | D5: 原契約數量 | E5: 變更後數量 | F5: 計算式 | H5: 113/7施作數量 | I5: 合計 | M5: 113/7累計計價數量 | N5: 尚未計價 | O5: 113/8數量=
A6: 壹 | B6: 發包工程費 | C6: 式 | D6: 1
A7: 一 | B7: 工程費 | C7: 式 | D7: 1
A8: (一) | B8: 整備工程 | C8: 式 | D8: 1
A9: 1.1.1 | B9: 機械拆除，瀝青混凝土，未含運費 | C9: M3 | D9: 720.24 | F9: 緣石邊及人孔處(河.LT000~290+RT000~060) | G9: =(290*2*0.15*0.2+12*5*0.15*0.2)+(53*2*0.14*0.2+3*4*0.15*0.2) | H9: =(290*2*0.15*0.2+12*5*0.15*0.2)+(53*2*0.15*0.2+3*4*0.14*0.2) -> 22.716 | I9: =SUM(H9:H13) -> 200.247 | M9: 123.7 | N9: =I9-M9 -> 76.547
F10: 既有磺港橋橋面 | G10: =27.2*10.5*0.25 | H10: =27.2*10.5*0.25 -> 71.4
F11: 既有磺港橋南側 | G11: =11.5*(7.5+4.5)/2*0.23 | H11: =11.5*(7.5+4.5)/2*0.23 -> 15.87
F12: 自行車道AC打除(圖說面積尚未檢核) | G12: (77.5+169.3+170.9+49.4)*0.15 | H12: =(77.5+169.3+170.9+49.4)*0.15 -> 70.065
F13: 抽水站旁 | G13: =10.8*(7.5+9.5)/2*0.22 | H13: =10.8*(7.5+9.5)/2*0.22 -> 20.196
A15: 1.1.2 | B15: 機械拆除，鋼筋混凝土，未含運費 | C15: M3 | D15: 4813.44 | F15: 路側RC護欄(河.LT000~290+RT000~060) | G15: =(1.2*0.5*8*39)+(1.2*0.5*8*7) | H15: =(1.2*0.5*8*39)+(1.2*0.5*8*7) -> 220.8 | I15: =SUM(H15:H34) -> 4091.1705 | M15: 4069.6 | N15: =I15-M15 -> 21.570509
F16: 磺港橋(橋面及護欄+I梁+橫隔樑+帽梁+中墩柱) | G16: ((27.2*10.3*0.3+0.3*1.1*27.2*2)+(13.2*1.25*0.6*7*2)+(6.8*1.25*0.5*7)+(((1.9+0.8)/2*1.2*7.8)+1.9*2.5*1.2)+((1.25*1.25*3.14*3.6))) | H16: =((27.2*10.3*0.3+0.3*1.1*27.2*2)+(13.2*1.25*0.6*7*2)+(6.8*1.25*0.5*7)+(((1.9+0.8)/2*1.2*7.8)+1.9*2.5*1.2)+((1.25*1.25*3.14*3.6))) -> 306.3485
F17: 橋台+基礎+進橋台 | G17: (10.3*1.8*4.2+10.3*1.8*2.8)*2+(10.3*2.8*1.8)*2+((60.65*(3.9+2.2)/2*0.55)+(10.3*3.9*0.6)) | H17: =(10.3*1.8*4.2+10.3*1.8*2.8)*2+(10.3*2.8*1.8)*2+((60.65*(3.9+2.2)/2*0.55)+(10.3*3.9*0.6)) -> 489.22638
F18: 既有橋北側堤牆(含基礎)+既有河道底(含新舊河道銜接段) | G18: ((3.75*(0.3+0.6)/2*63.7)+(5.5*0.85*63.7))+(26.8*7*0.6+18.5*7*0.35) | H18: =((3.75*(0.3+0.6)/2*63.7)+(5.5*0.85*63.7))+(26.8*7*0.6+18.5*7*0.35) -> 563.17625
F19: 人行橋+橋台+基礎+既有河道底+樓梯 | G19: ((19.3*0.52*0.8*4)+(19.3*7.2*0.3)+(6.8*2.2*0.8*2)+(9.5*3*0.8+9.5*1.8*0.3)+(17.8*0.55*2.8*2)) | H19: =((19.3*0.52*0.8*4)+(19.3*7.2*0.3)+(6.8*2.2*0.8*2)+(9.5*3*0.8+9.5*1.8*0.3)+(17.8*0.55*2.8*2)) -> 180.4932
F20: 既有人行道(路.S120~200+河.LT017~280+河.RT005~280含護欄柱) | G20: ((0.9*0.25*80)+(1.25*0.25*263)+(1.15*0.2*263+0.5*0.5*1.05*31)) | H20: =((0.9*0.25*80)+(1.25*0.25*263)+(1.15*0.2*263+0.5*0.5*1.05*31)) -> 168.815
F21: 既有台電(路N.河.LT017~280含手孔) | G21: ((1.1*0.8-(0.04*0.04*3.14*6))*263+(1.15*5)) | H21: =((1.1*0.8-(0.04*0.04*3.14*6))*263+(1.15*5)) -> 229.26213
F22: 既有箱涵+閘門平台 | G22: ((2.1*2.4)-(1.5*1.75))*25.7+(2.1*1.25*0.6) | H22: =((2.1*2.4)-(1.5*1.75))*25.7+(2.1*1.25*0.6) -> 63.6405
F23: 新舊河道銜接段既有堤牆 | G23: ((3.75*(0.3+0.6)/2*35.65)+(5.5*0.85*35.65)) | H23: =((3.75*(0.3+0.6)/2*35.65)+(5.5*0.85*35.65)) -> 226.82312
F24: 河.070處樓梯+既有牆 | G24: ((3.75*(0.3+0.6)/2*6.7)+(2.1*0.6*18.7)+(0.35*1.5*18.7)+(0.35*3.75*3.2)) | H24: =((3.75*(0.3+0.6)/2*6.7)+(2.1*0.6*18.7)+(0.35*1.5*18.7)+(0.35*3.75*3.2)) -> 48.88575
F25: 既有排水溝(含蓋板)(路.N130~420) | G25: (277.6*0.525) | H25: =(277.6*0.525) -> 145.74
F26: 既有管涵+集水井 | G26: (1.1*0.35*196.3)+((0.38*0.38*3.14-0.3*0.3*3.14)*196.3)+2.85*2 | H26: =(1.1*0.35*196.3)+((0.38*0.38*3.14-0.3*0.3*3.14)*196.3)+2.85*2 -> 114.80668
F27: 公園步道及鋪面(圖說面積尚未檢核) | G27: (401.1+1104.5+1276+169.3+767.7+52.1)*0.3 | H27: =(401.1+1104.5+1276+169.3+767.7+52.1)*0.3 -> 1131.21
F28: 自行車道基礎(圖說面積尚未檢核) | G28: (77.5+169.3+170.9+49.4)*0.25 | H28: =(77.5+169.3+170.9+49.4)*0.25 -> 116.775
F29: 綠帶槽緣石+石椅(尚未檢核) | G29: ((112.1+241.1+229.5+0+60.8+0)*0.033)+((3+8+5.7+2.9)*0.5*0.75) | H29: =((112.1+241.1+229.5+0+60.8+0)*0.033)+((3+8+5.7+2.9)*0.5*0.75) -> 28.5855
F30: 河.260~280處既有基礎+路燈基礎 | G30: (0.8*(0.75+0.35)/2*18.2)+(0.8*0.8*1.45*7) | H30: =(0.8*(0.75+0.35)/2*18.2)+(0.8*0.8*1.45*7) -> 14.504
F31: 單孔000~064(清江+2處過路堤牆+抽水井處) | G31: (0.25*1.65*39)+((3.5*(0.3+0.6)/2*5.6)+(2.1*0.6*2.3))+(6.2*5.3*0.35+2.1*2.2*0.6) | H31: =(0.25*1.65*39)+((3.5*(0.3+0.6)/2*5.6)+(2.1*0.6*2.3))+(6.2*5.3*0.35+2.1*2.2*0.6) -> 42.0785
A35: 1.1.3 | B35: 盤踞切割 | C35: M | D35: 1743 | F35: 磺港橋(橋面及護欄+I梁+橫隔樑+帽梁+墩柱) | G35: =(27.2*16+10.5*6)+(1.25*6*12*5)+(2.3*6*7*2)+(3.8*6+5.2*8)+(2.5*3.14*6) | H35: =(27.2*16+10.5*6)+(1.25*6*12*5)+(2.3*6*7*2)+(3.8*6+5.2*8)+(2.5*3.14*6) -> 1252.9 | I35: =SUM(H35:H37) -> 1747.3 | M35: 1741.3 | N35: =I35-M35 -> 6
F36: 人行橋(希冀橋)含下方基礎 | G36: =18*12+8.5*4+(1.1*6*12*3+0.8)+(3*2) | H36: =18*12+8.5*4+(1.1*6*12*3+0.8)+(3*2) -> 494.4
A38: 1.1.4 | B38: 基地及路幅開挖，未含運費，(機械挖，0.7～0.79m3開挖機) | C38: B.M3 | D38: 26370 | E38: 28009.56 | F38: 新設河道斷面計算(尚未檢核) | G38: 新設河道斷面計算 | H38: 26370 | I38: =SUM(H38:H41) -> 28009.56 | M38: 25080 | N38: =I38-M38 -> 2929.56
F39: 磺港橋及希冀橋橋台清障開挖+單孔過路段及清江公園 | G39: ((5*6*6.5*2)+(13*3.5*6.8)+(3.2*8.5*1.6))+((747.2+149.44)) | H39: =((5*6*6.5*2)+(13*3.5*6.8)+(3.2*8.5*1.6))+((747.2+149.44)) -> 1639.56
A42: 1.1.5 | B42: 瀝青混凝土面層刨除，刨除料運費 | C42: M3 | D42: 4726.67 | F42: 既有道路(路.S145~200+路.N140~420) | G42: (7.5*55*0.24)+(9.6*37*0.25)+(7.1*243*0.24) | H42: =(7.5*55*0.24)+(9.6*37*0.25)+(7.1*243*0.24) -> 601.872 | I42: =SUM(H42:H44) -> 601.872 | M42: 569.4 | N42: =I42-M42 -> 32.472
A45: 1.1.6 | B45: 利用填方，含夯實 | C45: M3 | D45: 13120 | F45: 磺港橋及希冀橋基樁區回填 | G45: (16.5*9.2*4.6+21.2*4.7*4.2)+(11.2*3.2*4.6)+(9.5*3.5*2.9) | H45: =(16.5*9.2*4.6+21.2*4.7*4.2)+(11.2*3.2*4.6)+(9.5*3.5*2.9) -> 1378.057 | I45: =SUM(H45:H51) -> 3967.777 | M45: 2172 | N45: =I45-M45 -> 1795.777
F46: 新設LT堤牆(L=52.3M)回填 | G46: (0.8*4.5*52.3)+(1.2*4.5*52.3) | H46: =(0.8*4.5*52.3)+(1.2*4.5*52.3) -> 470.7
F47: 砌石RT植栽槽回填(面積尚未檢核) | G47: 381.5*0.8 | H47: =381.5*0.8 -> 305.2
F48: 單孔箱涵過路段及清江公園 | G48: (0.8*1.9*2*23+3.4*2.7*23)+(0.8*2.1*2*41) | H48: =(0.8*1.9*2*23+3.4*2.7*23)+(0.8*2.1*2*41) -> 418.82
F49: 單孔箱涵064~300
...

Sheet 4變 (變更項目)
C1: 臺北市政府工務局水利工程處 | R1: 1
C2: 第4次變更項目對照詳細表 | R2: 1
A3: 工程名稱：磺港溪再造C段護岸及步道整建工程(三合橋至奇岩抽水站) | K3: 日期： | L3: 45672 | R3: 1
A4: 原契約分為 10 部分 本次變更 5 部分原有 393 項 | J4: 訂約總價 | L4: 257600000 | R4: 1
A5: 前經 3 次變更設計，計新增 43 項，減少 3 項，變更 27 項，變更後合計 438 項 | J5: 前次變更後總價(綜簽) | L5: 308240521 | R5: 1
A6: 本次變更設計，計新增 項，減少 項，變更 項，變更後合計 項 | J6: 本次變更後總價 | L6: =J9 -> 3.2364757e+08 | R6: 1
A7: 項次 | B7: 項目名稱 | C7: 單位 | D7: 原 定 數 量 | E7: 變更後 數 量 | F7: 增 減 數 量 | G7: 契 約 單 價 | H7: 新 增 單 價 | I7: 原 訂 合 價 | J7: 變更後 合價 | K7: 追加 | L7: 追減 | M7: 備註 | O7: 變更依據 | P7: 數量計算式 | Q7: 變更原因 | R7: 1
R8: 1
A9: 壹 | B9: 發包工程費 | C9: 式 | G9: =I9 -> 3.0824052e+08 | I9: =I10+I354+I380+I420+I424+I444+I464+I467+I468+I470 -> 3.0824052e+08 | J9: =J10+J354+J380+J420+J424+J444+J464+J467+J468+J470 -> 3.2364757e+08 | K9: =K10+K354+K380+K420+K424+K444+K464+K467+K468+K470 -> 23104847 | L9: =L10+L354+L380+L420+L424+L444+L464+L467+L468+L470 -> -7697802.7 | O9: =K9+L9 -> 15407045 | P9: =J9-I9 -> 15407045 | R9: 1
A10: 一 | B10: 工程費 | C10: 式 | G10: =I10 -> 2.3286809e+08 | I10: =I11+I37+I126+I166+I195+I215+I232+I310+I344 -> 2.3286809e+08 | J10: =J11+J37+J126+J166+J195+J215+J232+J310+J344 -> 2.4546399e+08 | K10: =K11+K37+K126+K166+K195+K215+K232+K310+K344 -> 20293706 | L10: =L11+L37+L126+L166+L195+L215+L232+L310+L344 -> -7697802.7 | R10: 1
A11: (一) | B11: 整備工程 | C11: 式 | G11: 61233816 | I11: =SUM(I12:I36) -> 61233816 | J11: =SUM(J12:J36) -> 61418256 | K11: =SUM(K12:K36) -> 5176911.3 | L11: =SUM(L12:L36) -> -4992470.4 | R11: 1
A12: 1 | B12: 機械拆除，瀝青混凝土，未含運費 | C12: M3 | D12: 720.24 | E12: =估驗單!F8 -> 720.24 | G12: 193.11 | I12: =ROUND(D12*G12,2) -> 139085.55 | J12: =ROUND(E12*G12,2) -> 139085.55 | K12: =J12-I12 -> 0 | L12: =I12-J12 -> 0
A13: 2 | B13: 機械拆除，鋼筋混凝土，未含運費 | C13: M3 | D13: 4813.44 | E13: =估驗單!F9 -> 4813.44 | G13: 1046.16 | I13: =ROUND(D13*G13,2) -> 5035628.4 | J13: =ROUND(E13*G13,2) -> 5035628.4 | K13: =J13-I13 -> 0 | L13: =I13-J13 -> 0
A14: 3 | B14: 盤踞切割 | C14: M | D14: 1743 | E14: =估驗單!F10 -> 1743 | G14: 6199.66 | I14: =ROUND(D14*G14,2) -> 10806007 | J14: =ROUND(E14*G14,2) -> 10806007 | K14: =J14-I14 -> 0 | L14: =I14-J14 -> 0
A15: 4 | B15: 基地及路幅開挖，未含運費，(機械挖，0.7～0.79m3開挖機) | C15: B.M3 | D15: 28009.56 | E15: =估驗單!F11 -> 28009.56 | G15: 48.28 | I15: =ROUND(D15*G15,2) -> 1352301.6 | J15: =ROUND(E15*G15,2) -> 1352301.6 | O15: 112.12.12北市工水工字第1126067256號結論5 113.7.2北市工水工字第1136038674號 | Q15: 集水井、管涵減作挖方減少 箱涵高程調整
A16: 5 | B16: 瀝青混凝土面層刨除，刨除料運費 | C16: M3 | D16: 4726.67 | E16: =估驗單!F12 -> 4726.67 | G16: 599.71 | I16: =ROUND(D16*G16,2) -> 2834631.3 | J16: =ROUND(E16*G16,2) -> 2834631.3 | K16: =J16-I16 -> 0 | L16: =I16-J16 -> 0
A17: 6 | B17: 利用填方，含夯實 | C17: M3 | D17: 13120 | E17: =估驗單!F13 -> 13120 | G17: 104.64 | I17: =ROUND(D17*G17,2) -> 1372876.8 | J17: =ROUND(E17*G17,2) -> 1372876.8 | K17: =J17-I17 -> 0 | O17: 113.1.15北市工水工字第1136007935號結論3 113.7.2北市工水工字第1136038674號 | P17: (5.46*7.42/2-5.46*3.71/2)*50=506.42 | Q17: 低水護岸坡度調整1:2 箱涵高程調整
A18: 7 | B18: 餘方遠運處理(台北港) | C18: B.M3 | D18: 13251 | E18: ='數量計算(FOR4變)'!I54 -> 18245 | F18: =E18-D18 -> 4994 | G18: 1027.37 | I18: =ROUND(D18*G18,2) -> 13613680 | J18: =ROUND(E18*G18,2) -> 18744366 | K18: =J18-I18 -> 5130685.8 | M18: 不含基樁產出375.67，只請聯單不另給價 | O18: 發公文呈請簽核 | P18: 4601.44+231.09+161.39=4994 | Q18: 房屋廢方、基樁、PC樁產出餘方(非泥漿)改運台北港 | R18: 1
A19: 8 | B19: 餘方自行處理(房屋廢方，含水土保持) | C19: M3 | D19: 4601.44 | E19: =估驗單!F15 -> 0_x000D_ | F19: =0-D19 -> -4601.44 | G19: 1084.98 | I19: =ROUND(D19*G19,2) -> 4992470.4 | J19: 0 | L19: =J19-I19 -> -4992470.4 | O19: 發公文呈請簽核 | Q19: 自行處理擬運送台北港收容 | R19: 1
A20: 9 | B20: 瀝青混凝土面層刨除，厚5cm，刨除機1.2m寬，含瀝青鋪面打毛(未含運費) | C20: M2 | D20: 2588.5 | E20: =估驗單!F16 -> 2588.5 | G20: 30.45 | I20: =ROUND(D20*G20,2) -> 78819.83 | J20: =ROUND(E20*G20,2) -> 78819.83 | K20: =J20-I20 -> 0 | L20: =I20-J20 -> 0
A21: 10 | B21: 瀝青混凝土面層刨除，厚10cm，刨除機2.2m寬，未含運費 | C21: M2 | D21: 9177 | E21: =估驗單!F17 -> 9177 | G21: 28.48 | I21: =ROUND(D21*G21,2) -> 261360.96 | J21: =ROUND(E21*G21,2) -> 261360.96 | K21: =J21-I21 -> 0 | L21: =I21-J21 -> 0
A22: 11 | B22: 切割瀝青混凝土或無筋混凝土，5cm≦切割深度＜10cm | C22: M | D22: 162.5 | E22: =估驗單!F18 -> 162.5 | G22: 65.4 | I22: =ROUND(D22*G22,2) -> 10627.5 | J22: =ROUND(E22*G22,2) -> 10627.5 | K22: =J22-I22 -> 0 | L22: =I22-J22 -> 0
A23: 12 | B23: 清除及掘除，雜草雜木，含垃圾撿除，人工割 | C23: M2 | D23: 5217.7 | E23: =估驗單!F19 -> 5217.7 | G23: 20.19 | I23: =ROUND(D23*G23,2) -> 105345.36 | J23: =ROUND(E23*G23,2) -> 105345.36 | K23: =J23-I23 -> 0 | L23: =I23-J23 -> 0
A24: 13 | B24: 垃圾及廢棄物(以體積計)清運 | C24: M3 | D24: 782.66 | E24: =估驗單!F20 -> 782.66 | G24: 2286.68 | I24: =ROUND(D24*G24,2) -> 1789693 | J24: =ROUND(E24*G24,2) -> 1789693 | K24: =J24-I24 -> 0 | L24: =I24-J24 -> 0
A25: 14 | B25: 節塊吊放 | C25: 次 | D25: 425 | E25: =估驗單!F21 -> 425 | G25: 521.15 | I25: =ROUND(D25*G25,2) -> 221488.75 | J25: =ROUND(E25*G25,2) -> 221488.75 | K25: =J25-I25 -> 0 | L25: =I25-J25 -> 0
A26: 15 | B26: 機械拆除，工地雜項拆除清理，欄杆，含運費 | C26: M | D26: 255.5 | E26: =估驗單!F22 -> 415.08 | F26: =E26-D26 -> 159.58 | G26: 289.67 | I26: =ROUND(D26*G26,2) -> 74010.69 | J26: =ROUND(E26*G26,2) -> 120236.22 | K26: =J26-I26 -> 46225.53 | O26: 113.8.20北市工水工字第1136047137號結論(8) | P26: 34.27+66.51+58.80 | Q26: 既有欄杆老舊損傷，為維護行人通行安全及美觀 | R26: 1
A27: 16 | B27: 土方運送(百齡抽水站) | C27: 趟 | D27: 2204 | E27: =估驗單!F23 -> 2204 | G27: 3082.11 | I27: =ROUND(D27*G27,2) -> 6792970.4 | J27: =ROUND(E27*G27,2) -> 6792970.4 | K27: =J27-I27 -> 0 | L27: =I27-J27 -> 0
A28: 17 | B28: 既有路燈拆除繳回 | C28: 盞 | D28: 66 | E28: =估驗單!F24 -> 66 | G28: 3311.26 | I28: =ROUND(D28*G28,2) -> 218543.16 | J28: =ROUND(E28*G28,2) -> 218543.16 | K28: =J28-I28 -> 0 | L28: =I28-J28 -> 0
A29: 18 | B29: 座椅拆除繳回 | C29: 座 | D29: 18 | E29: =估驗單!F25 -> 18 | G29: 1199.93 | I29: =ROUND(D29*G29,2) -> 21598.74 | J29: =ROUND(E29*G29,2) -> 21598.74 | K29: =J29-I29 -> 0 | L29: =I29-J29 -> 0
A30: 19 | B30: 解說牌拆除 | C30: 座 | D30: 4 | E30: =估驗單!F26 -> 4 | G30: 2999.84 | I30: =ROUND(D30*G30,2) -> 11999.36 | J30: =ROUND(E30*G30,2) -> 11999.36 | K30: =J30-I30 -> 0 | L30: =I30-J30 -> 0
A31: 20 | B31: 自行車架拆除 | C31: 座 | D31: 20 | E31: =估驗單!F27 -> 20 | G31: 2999.84 | I31: =ROUND(D31*G31,2) -> 59996.8 | J31: =ROUND(E31*G31,2) -> 59996.8 | K31: =J31-I31 -> 0 | L31: =I31-J31 -> 0
A32: 21 | B32: 交通牌誌拆除 | C32: 座 | D32: 15 | E32: =估驗單!F28 -> 15 | G32: 2999.84 | I32: =ROUND(D32*G32,2) -> 44997.6 | J32: =ROUND(E32*G32,2) -> 44997.6 | K32: =J32-I32 -> 0 | L32: =I32-J32 -> 0
A33: 22 | B33: 既有水利設施拆除及運送 | C33: 式 | D33: 1 | E33: =估驗單!F29 -> 1 | G33: 399978.19 | I33: =ROUND(D33*G33,2) -> 399978.19 | J33: =ROUND(E33*G33,2) -> 399978.19 | K33: =J33-I33 -> 0 | L33: =I33-J33 -> 0
A34: 23 | B34: 交通維持，道路管制人員，日間(06-22時)，義交 | C34: 時 | D34: 30800 | E34: =估驗單!F30 -> 30800 | F34: =E34-D34 -> 0 | G34: 280 | I34: =ROUND(D34*G34,2) -> 8624000 | J34: =ROUND(E34*G34,2) -> 8624000 | K34: =J34-I34 -> 0 | L34: =I34-J34 -> 0
A35: 24 | B35: 表土清除，堆置，及回填費，t=30cm | C35: M2 | D35: 2150 | E35: =估驗單!F31 -> 2150 | F35: =E35-D35 -> 0 | G35: 70.56 | I35: =ROUND(D35*G35,2) -> 151704 | J35: =ROUND(E35*G35,2) -> 151704 | K35: =J35-I35 -> 0 | L35: =I35-J35 -> 0
A36: 25 | B36: 餘土分類處理 | C36: 日 | D36: 111 | E36: =估驗單!F32 -> 111 | F36: =E36-D36 -> 0 | G36: 20000 | I36: =ROUND(D36*G36,2) -> 2220000 | J36: =ROUND(E36*G36,2) -> 2220000 | K36: =J36-I36 -> 0 | L36: =I36-J36 -> 0
A37: (二) | B37: 土建景觀工程 | C37: 式 | E37: =估驗單!F33 -> 0 | F37: =E37-D37 -> 0 | G37: 30807124 | I37: =SUM(I38:I125) -> 30807124 | J37: =SUM(J38:J125) -> 32286203 | K37: =SUM(K38:K125) -> 3305690.7 | L37: =SUM(L38:L125) -> -1826612.4 | R37: 1
A38: 1 | B38: 構造物回填，回填及夯實(實際) | C38: C.M3 | D38: 1887.64 | E38: =估驗單!F34 -> 1887.64 | F38: =E38-D38 -> 0 | G38: 320.72 | I38: =ROUND(D38*G38,2) -> 605403.9 | J38: =ROUND(E38*G38,2) -> 605403.9 | K38: =J38-I38 -> 0
A39: 2 | B39: 構造物回填，回填及夯實，人工夯實 | C39: C.M3 | D39: 402.21 | E39: =估驗單!F35 -> 402.21 | F39: =E39-D39 -> 0 | G39: 346.06 | I39: =ROUND(D39*G39,2) -> 139188.79 | J39: =ROUND(E39*G39,2) -> 139188.79 | K39: =J39-I39 -> 0
A40: 3 | B40: 鋼筋，SD280W | C40: KG | D40: 18865.76 | E40: =估驗單!F36 -> 18865.76 | F40: =E40-D40 -> 0 | G40: 36.4 | I40: =ROUND(D40*G40,2) -> 686713.66 | J40: =ROUND(E40*G40,2) -> 686713.66 | K40: =J40-I40 -> 0
...

Sheet 4變 (總表)
C1: 臺北市政府工務局水利工程處
C2: 第4次變更項目對照詳細表
A3: 工程名稱：磺港溪再造C段護岸及步道整建工程(三合橋至奇岩抽水站) | K3: 日期： | L3: 45672
A4: 原契約分為 10 部分 本次變更 5 部分原有 393 項 | J4: 訂約總價 | L4: 257600000
A5: 前經 3 次變更設計，計新增 43 項，減少 3 項，變更 27 項，變更後合計 438 項 | J5: 前次變更後總價(綜簽) | L5: 308240521
A6: 本次變更設計，計新增 項，減少 項，變更 項，變更後合計 項 | J6: 本次變更後總價 | L6: =J9 -> 3.2364757e+08
A7: 項次 | B7: 項目名稱 | C7: 單位 | D7: 原 定 數 量 | E7: 變更後 數 量 | F7: 增 減 數 量 | G7: 契 約 單 價 | H7: 新 增 單 價 | I7: 原 訂 合 價 | J7: 變更後 合價 | K7: 追加 | L7: 追減 | M7: 備註 | O7: 變更依據 | P7: 數量計算式 | Q7: 變更原因
A9: 壹 | B9: 發包工程費 | C9: 式 | G9: =I9 -> 3.0824052e+08 | I9: =I10+I354+I380+I420+I424+I444+I464+I467+I468+I470 -> 3.0824052e+08 | J9: =J10+J354+J380+J420+J424+J444+J464+J467+J468+J470 -> 3.2364757e+08 | K9: =K10+K354+K380+K420+K424+K444+K464+K467+K468+K470 -> 23104847 | L9: =L10+L354+L380+L420+L424+L444+L464+L467+L468+L470 -> -7697802.7 | O9: =K9+L9 -> 15407045 | P9: =J9-I9 -> 15407045
A10: 一 | B10: 工程費 | C10: 式 | G10: =I10 -> 2.3286809e+08 | I10: =I11+I37+I126+I166+I195+I215+I232+I310+I344 -> 2.3286809e+08 | J10: =J11+J37+J126+J166+J195+J215+J232+J310+J344 -> 2.4546399e+08 | K10: =K11+K37+K126+K166+K195+K215+K232+K310+K344 -> 20293706 | L10: =L11+L37+L126+L166+L195+L215+L232+L310+L344 -> -7697802.7
A11: (一) | B11: 整備工程 | C11: 式 | G11: 61233816 | I11: =SUM(I12:I36) -> 61233816 | J11: =SUM(J12:J36) -> 61418256 | K11: =SUM(K12:K36) -> 5176911.3 | L11: =SUM(L12:L36) -> -4992470.4 | O11: =K11+L11 -> 184440.94
A12: 1 | B12: 機械拆除，瀝青混凝土，未含運費 | C12: M3 | D12: 720.24 | E12: =估驗單!F8 -> 720.24 | G12: 193.11 | I12: =ROUND(D12*G12,2) -> 139085.55 | J12: =ROUND(E12*G12,2) -> 139085.55 | K12: =J12-I12 -> 0 | L12: =I12-J12 -> 0
A13: 2 | B13: 機械拆除，鋼筋混凝土，未含運費 | C13: M3 | D13: 4813.44 | E13: =估驗單!F9 -> 4813.44 | G13: 1046.16 | I13: =ROUND(D13*G13,2) -> 5035628.4 | J13: =ROUND(E13*G13,2) -> 5035628.4 | K13: =J13-I13 -> 0 | L13: =I13-J13 -> 0
A14: 3 | B14: 盤踞切割 | C14: M | D14: 1743 | E14: =估驗單!F10 -> 1743 | G14: 6199.66 | I14: =ROUND(D14*G14,2) -> 10806007 | J14: =ROUND(E14*G14,2) -> 10806007 | K14: =J14-I14 -> 0 | L14: =I14-J14 -> 0
A15: 4 | B15: 基地及路幅開挖，未含運費，(機械挖，0.7～0.79m3開挖機) | C15: B.M3 | D15: 28009.56 | E15: =估驗單!F11 -> 28009.56 | G15: 48.28 | I15: =ROUND(D15*G15,2) -> 1352301.6 | J15: =ROUND(E15*G15,2) -> 1352301.6 | O15: 112.12.12北市工水工字第1126067256號結論5 113.7.2北市工水工字第1136038674號 | Q15: 集水井、管涵減作挖方減少 箱涵高程調整
A16: 5 | B16: 瀝青混凝土面層刨除，刨除料運費 | C16: M3 | D16: 4726.67 | E16: =估驗單!F12 -> 4726.67 | G16: 599.71 | I16: =ROUND(D16*G16,2) -> 2834631.3 | J16: =ROUND(E16*G16,2) -> 2834631.3 | K16: =J16-I16 -> 0 | L16: =I16-J16 -> 0
A17: 6 | B17: 利用填方，含夯實 | C17: M3 | D17: 13120 | E17: =估驗單!F13 -> 13120 | G17: 104.64 | I17: =ROUND(D17*G17,2) -> 1372876.8 | J17: =ROUND(E17*G17,2) -> 1372876.8 | K17: =J17-I17 -> 0 | O17: 113.1.15北市工水工字第1136007935號結論3 113.7.2北市工水工字第1136038674號 | P17: (5.46*7.42/2-5.46*3.71/2)*50=506.42 | Q17: 低水護岸坡度調整1:2 箱涵高程調整
A18: 7 | B18: 餘方遠運處理(台北港) | C18: B.M3 | D18: 13251 | E18: ='數量計算(FOR4變)'!I54 -> 18245 | F18: =E18-D18 -> 4994 | G18: 1027.37 | I18: =ROUND(D18*G18,2) -> 13613680 | J18: =ROUND(E18*G18,2) -> 18744366 | K18: =J18-I18 -> 5130685.8 | M18: 其中375.67為基樁產出，只請聯單不另給價 | O18: 發公文呈請簽核 | Q18: 房屋廢方、基樁、PC樁產出餘方(非泥漿)改運台北港
A19: 8 | B19: 餘方自行處理(房屋廢方，含水土保持) | C19: M3 | D19: 4601.44 | E19: =估驗單!F15 -> 0_x000D_ | F19: =0-D19 -> -4601.44 | G19: 1084.98 | I19: =ROUND(D19*G19,2) -> 4992470.4 | J19: 0 | L19: =J19-I19 -> -4992470.4 | O19: 發公文呈請簽核 | Q19: 自行處理擬運送台北港收容
A20: 9 | B20: 瀝青混凝土面層刨除，厚5cm，刨除機1.2m寬，含瀝青鋪面打毛(未含運費) | C20: M2 | D20: 2588.5 | E20: =估驗單!F16 -> 2588.5 | G20: 30.45 | I20: =ROUND(D20*G20,2) -> 78819.83 | J20: =ROUND(E20*G20,2) -> 78819.83 | K20: =J20-I20 -> 0 | L20: =I20-J20 -> 0
A21: 10 | B21: 瀝青混凝土面層刨除，厚10cm，刨除機2.2m寬，未含運費 | C21: M2 | D21: 9177 | E21: =估驗單!F17 -> 9177 | G21: 28.48 | I21: =ROUND(D21*G21,2) -> 261360.96 | J21: =ROUND(E21*G21,2) -> 261360.96 | K21: =J21-I21 -> 0 | L21: =I21-J21 -> 0
A22: 11 | B22: 切割瀝青混凝土或無筋混凝土，5cm≦切割深度＜10cm | C22: M | D22: 162.5 | E22: =估驗單!F18 -> 162.5 | G22: 65.4 | I22: =ROUND(D22*G22,2) -> 10627.5 | J22: =ROUND(E22*G22,2) -> 10627.5 | K22: =J22-I22 -> 0 | L22: =I22-J22 -> 0
A23: 12 | B23: 清除及掘除，雜草雜木，含垃圾撿除，人工割 | C23: M2 | D23: 5217.7 | E23: =估驗單!F19 -> 5217.7 | G23: 20.19 | I23: =ROUND(D23*G23,2) -> 105345.36 | J23: =ROUND(E23*G23,2) -> 105345.36 | K23: =J23-I23 -> 0 | L23: =I23-J23 -> 0
A24: 13 | B24: 垃圾及廢棄物(以體積計)清運 | C24: M3 | D24: 782.66 | E24: =估驗單!F20 -> 782.66 | G24: 2286.68 | I24: =ROUND(D24*G24,2) -> 1789693 | J24: =ROUND(E24*G24,2) -> 1789693 | K24: =J24-I24 -> 0 | L24: =I24-J24 -> 0
A25: 14 | B25: 節塊吊放 | C25: 次 | D25: 425 | E25: =估驗單!F21 -> 425 | G25: 521.15 | I25: =ROUND(D25*G25,2) -> 221488.75 | J25: =ROUND(E25*G25,2) -> 221488.75 | K25: =J25-I25 -> 0 | L25: =I25-J25 -> 0
A26: 15 | B26: 機械拆除，工地雜項拆除清理，欄杆，含運費 | C26: M | D26: 255.5 | E26: =估驗單!F22 -> 415.08 | F26: =E26-D26 -> 159.58 | G26: 289.67 | I26: =ROUND(D26*G26,2) -> 74010.69 | J26: =ROUND(E26*G26,2) -> 120236.22 | K26: =J26-I26 -> 46225.53 | O26: 113.8.20北市工水工字第1136047137號結論(8) | P26: 34.27+66.51+58.80 | Q26: 既有欄杆老舊損傷，為維護行人通行安全及美觀 | R26: =34.27+66.51+58.8 -> 159.58
A27: 16 | B27: 土方運送(百齡抽水站) | C27: 趟 | D27: 2204 | E27: =估驗單!F23 -> 2204 | G27: 3082.11 | I27: =ROUND(D27*G27,2) -> 6792970.4 | J27: =ROUND(E27*G27,2) -> 6792970.4 | K27: =J27-I27 -> 0 | L27: =I27-J27 -> 0
A28: 17 | B28: 既有路燈拆除繳回 | C28: 盞 | D28: 66 | E28: =估驗單!F24 -> 66 | G28: 3311.26 | I28: =ROUND(D28*G28,2) -> 218543.16 | J28: =ROUND(E28*G28,2) -> 218543.16 | K28: =J28-I28 -> 0 | L28: =I28-J28 -> 0
A29: 18 | B29: 座椅拆除繳回 | C29: 座 | D29: 18 | E29: =估驗單!F25 -> 18 | G29: 1199.93 | I29: =ROUND(D29*G29,2) -> 21598.74 | J29: =ROUND(E29*G29,2) -> 21598.74 | K29: =J29-I29 -> 0 | L29: =I29-J29 -> 0
A30: 19 | B30: 解說牌拆除 | C30: 座 | D30: 4 | E30: =估驗單!F26 -> 4 | G30: 2999.84 | I30: =ROUND(D30*G30,2) -> 11999.36 | J30: =ROUND(E30*G30,2) -> 11999.36 | K30: =J30-I30 -> 0 | L30: =I30-J30 -> 0
A31: 20 | B31: 自行車架拆除 | C31: 座 | D31: 20 | E31: =估驗單!F27 -> 20 | G31: 2999.84 | I31: =ROUND(D31*G31,2) -> 59996.8 | J31: =ROUND(E31*G31,2) -> 59996.8 | K31: =J31-I31 -> 0 | L31: =I31-J31 -> 0
A32: 21 | B32: 交通牌誌拆除 | C32: 座 | D32: 15 | E32: =估驗單!F28 -> 15 | G32: 2999.84 | I32: =ROUND(D32*G32,2) -> 44997.6 | J32: =ROUND(E32*G32,2) -> 44997.6 | K32: =J32-I32 -> 0 | L32: =I32-J32 -> 0
A33: 22 | B33: 既有水利設施拆除及運送 | C33: 式 | D33: 1 | E33: =估驗單!F29 -> 1 | G33: 399978.19 | I33: =ROUND(D33*G33,2) -> 399978.19 | J33: =ROUND(E33*G33,2) -> 399978.19 | K33: =J33-I33 -> 0 | L33: =I33-J33 -> 0
A34: 23 | B34: 交通維持，道路管制人員，日間(06-22時)，義交 | C34: 時 | D34: 30800 | E34: =估驗單!F30 -> 30800 | F34: =E34-D34 -> 0 | G34: 280 | I34: =ROUND(D34*G34,2) -> 8624000 | J34: =ROUND(E34*G34,2) -> 8624000 | K34: =J34-I34 -> 0 | L34: =I34-J34 -> 0
A35: 24 | B35: 表土清除，堆置，及回填費，t=30cm | C35: M2 | D35: 2150 | E35: =估驗單!F31 -> 2150 | F35: =E35-D35 -> 0 | G35: 70.56 | I35: =ROUND(D35*G35,2) -> 151704 | J35: =ROUND(E35*G35,2) -> 151704 | K35: =J35-I35 -> 0 | L35: =I35-J35 -> 0
A36: 25 | B36: 餘土分類處理 | C36: 日 | D36: 111 | E36: =估驗單!F32 -> 111 | F36: =E36-D36 -> 0 | G36: 20000 | I36: =ROUND(D36*G36,2) -> 2220000 | J36: =ROUND(E36*G36,2) -> 2220000 | K36: =J36-I36 -> 0 | L36: =I36-J36 -> 0 | S36: 監造提供數量?
A37: (二) | B37: 土建景觀工程 | C37: 式 | E37: =估驗單!F33 -> 0 | F37: =E37-D37 -> 0 | G37: 30807124 | I37: =SUM(I38:I125) -> 30807124 | J37: =SUM(J38:J125) -> 32286203 | K37: =SUM(K38:K125) -> 3305690.7 | L37: =SUM(L38:L125) -> -1826612.4 | O37: =K37+L37 -> 1479078.4
A38: 1 | B38: 構造物回填，回填及夯實(實際) | C38: C.M3 | D38: 1887.64 | E38: =估驗單!F34 -> 1887.64 | F38: =E38-D38 -> 0 | G38: 320.72 | I38: =ROUND(D38*G38,2) -> 605403.9 | J38: =ROUND(E38*G38,2) -> 605403.9 | K38: =J38-I38 -> 0
A39: 2 | B39: 構造物回填，回填及夯實，人工夯實 | C39: C.M3 | D39: 402.21 | E39: =估驗單!F35 -> 402.21 | F39: =E39-D39 -> 0 | G39: 346.06 | I39: =ROUND(D39*G39,2) -> 139188.79 | J39: =ROUND(E39*G39,2) -> 139188.79 | K39: =J39-I39 -> 0
A40: 3 | B40: 鋼筋，SD280W | C40: KG | D40: 18865.76 | E40: =估驗單!F36 -> 18865.76 | F40: =E40-D40 -> 0 | G40: 36.4 | I40: =ROUND(D40*G40,2) -> 686713.66 | J40: =ROUND(E40*G40,2) -> 686713.66 | K40: =J40-I40 -> 0
A41: 4 | B41: 結構用混凝土，預拌，140kgf/cm2 | C41: M3 | D41: 107.91 | E41: =估驗單!F37 -> 107.91 | F41: =E41-D41 -> 0 | G41: 3114.97 | I41: =ROUND(D41*G41,2) -> 336136.41 | J41: =ROUND(E41*G41,2) -> 336136.41 | K41: =J41-I41 -> 0
...

Sheet 數量計算(FOR4變)
A1: 臺北市政府工務局水利工程處
A2: 數量計算書
A3: 工程名稱：磺港溪再造C段護岸及步道整建工程(三合橋至奇岩抽水站)
A4: 施工地點：北投磺港溪 | F4: 工程編號：111 070020302 038 02 | J4: 114/1/14
A5: 項次 | B5: 項目及說明 | C5: 單位 | D5: 原契約數量 | E5: 變更後數量 | F5: 計算式 | H5: 數量小計 | I5: 實作數量合計 | J5: 應追加數量
A6: 壹 | B6: 發包工程費 | C6: 式 | D6: 1
A7: 一 | B7: 工程費 | C7: 式 | D7: 1
A8: (一) | B8: 整備工程 | C8: 式 | D8: 1
A9: 1.1.1 | B9: 機械拆除，瀝青混凝土，未含運費 | C9: M3 | D9: 720.24 | F9: 緣石邊及人孔處(河.LT000~290+RT000~060) | G9: =(290*2*0.15*0.2+12*5*0.15*0.2)+(53*2*0.14*0.2+3*4*0.15*0.2) | H9: =(290*2*0.15*0.2+12*5*0.15*0.2)+(53*2*0.15*0.2+3*4*0.14*0.2) -> 22.716 | I9: =SUM(H9:H15) -> 715.674 | J9: 尚未完成
F10: 既有磺港橋橋面 | G10: =27.2*10.5*0.25 | H10: =27.2*10.5*0.25 -> 71.4
F11: 既有磺港橋南側 | G11: =11.5*(7.5+4.5)/2*0.23 | H11: =11.5*(7.5+4.5)/2*0.23 -> 15.87
F12: 自行車道AC打除 | G12: (77.5+169.3+170.9+49.4)*0.2 | H12: =(77.5+169.3+170.9+49.4)*0.2 -> 93.42
F13: 抽水站旁 | G13: =10.8*(7.5+9.5)/2*0.22 | H13: =10.8*(7.5+9.5)/2*0.22 -> 20.196
F14: 左岸及工區七 | G14: (605.74+547.65+571.09+245.16+490.72)*0.2 | H14: =(605.74+547.65+571.09+245.16+490.72)*0.2 -> 492.072
A16: 1.1.2 | B16: 機械拆除，鋼筋混凝土，未含運費 | C16: M3 | D16: 4813.44 | F16: 路側RC護欄(河.LT000~290+RT000~060) | G16: =(1.2*0.5*8*39)+(1.2*0.5*8*7) | H16: =(1.2*0.5*8*39)+(1.2*0.5*8*7) -> 220.8 | I16: =SUM(H16:H32) -> 4091.1705 | J16: 尚未完成
F17: 磺港橋(橋面及護欄+I梁+橫隔樑+帽梁+中墩柱) | G17: ((27.2*10.3*0.3+0.3*1.1*27.2*2)+(13.2*1.25*0.6*7*2)+(6.8*1.25*0.5*7)+(((1.9+0.8)/2*1.2*7.8)+1.9*2.5*1.2)+((1.25*1.25*3.14*3.6))) | H17: =((27.2*10.3*0.3+0.3*1.1*27.2*2)+(13.2*1.25*0.6*7*2)+(6.8*1.25*0.5*7)+(((1.9+0.8)/2*1.2*7.8)+1.9*2.5*1.2)+((1.25*1.25*3.14*3.6))) -> 306.3485
F18: 橋台+基礎+進橋台 | G18: (10.3*1.8*4.2+10.3*1.8*2.8)*2+(10.3*2.8*1.8)*2+((60.65*(3.9+2.2)/2*0.55)+(10.3*3.9*0.6)) | H18: =(10.3*1.8*4.2+10.3*1.8*2.8)*2+(10.3*2.8*1.8)*2+((60.65*(3.9+2.2)/2*0.55)+(10.3*3.9*0.6)) -> 489.22638
F19: 既有橋北側堤牆(含基礎)+既有河道底(含新舊河道銜接段) | G19: ((3.75*(0.3+0.6)/2*63.7)+(5.5*0.85*63.7))+(26.8*7*0.6+18.5*7*0.35) | H19: =((3.75*(0.3+0.6)/2*63.7)+(5.5*0.85*63.7))+(26.8*7*0.6+18.5*7*0.35) -> 563.17625
F20: 人行橋+橋台+基礎+既有河道底+樓梯 | G20: ((19.3*0.52*0.8*4)+(19.3*7.2*0.3)+(6.8*2.2*0.8*2)+(9.5*3*0.8+9.5*1.8*0.3)+(17.8*0.55*2.8*2)) | H20: =((19.3*0.52*0.8*4)+(19.3*7.2*0.3)+(6.8*2.2*0.8*2)+(9.5*3*0.8+9.5*1.8*0.3)+(17.8*0.55*2.8*2)) -> 180.4932
F21: 既有人行道(路.S120~200+河.LT017~280+河.RT005~280含護欄柱) | G21: ((0.9*0.25*80)+(1.25*0.25*263)+(1.15*0.2*263+0.5*0.5*1.05*31)) | H21: =((0.9*0.25*80)+(1.25*0.25*263)+(1.15*0.2*263+0.5*0.5*1.05*31)) -> 168.815
F22: 既有台電(路N.河.LT017~280含手孔) | G22: ((1.1*0.8-(0.04*0.04*3.14*6))*263+(1.15*5)) | H22: =((1.1*0.8-(0.04*0.04*3.14*6))*263+(1.15*5)) -> 229.26213
F23: 既有箱涵+閘門平台 | G23: ((2.1*2.4)-(1.5*1.75))*25.7+(2.1*1.25*0.6) | H23: =((2.1*2.4)-(1.5*1.75))*25.7+(2.1*1.25*0.6) -> 63.6405
F24: 新舊河道銜接段既有堤牆 | G24: ((3.75*(0.3+0.6)/2*35.65)+(5.5*0.85*35.65)) | H24: =((3.75*(0.3+0.6)/2*35.65)+(5.5*0.85*35.65)) -> 226.82312
F25: 河.070處樓梯+既有牆 | G25: ((3.75*(0.3+0.6)/2*6.7)+(2.1*0.6*18.7)+(0.35*1.5*18.7)+(0.35*3.75*3.2)) | H25: =((3.75*(0.3+0.6)/2*6.7)+(2.1*0.6*18.7)+(0.35*1.5*18.7)+(0.35*3.75*3.2)) -> 48.88575
F26: 既有排水溝(含蓋板)(路.N130~420) | G26: (277.6*0.525) | H26: =(277.6*0.525) -> 145.74
F27: 既有管涵+集水井 | G27: (1.1*0.35*196.3)+((0.38*0.38*3.14-0.3*0.3*3.14)*196.3)+2.85*2 | H27: =(1.1*0.35*196.3)+((0.38*0.38*3.14-0.3*0.3*3.14)*196.3)+2.85*2 -> 114.80668
