Workbook

Sheet 單價分析表 (3)
A1: 臺北市政府工務局水利工程處
A2: 新增工項單價分析表
A3: 工程名稱：磺港溪再造C段護岸及步道整建工程(延壽橋至三合橋)
A4: 項次 | B4: 項目及說明 | C4: 單位 | D4: 數量 | E4: 單 價 | F4: 複 價 | G4: 備 註
A5: 1.1.25 | B5: 餘土分類處理 | C5: 日 | D5: 1 | E5: =F11 -> 20064.4 | G5: 02323M00AC
A6: 1 | B6: 開挖機，70~79KW，(作為破碎機用) | C6: 時 | D6: 8 | E6: 1500 | F6: =D6*E6 -> 12000 | G6: E000004407001
A7: 2 | B7: 操作手，開挖機 | C7: 時 | D7: 8 | E7: 375 | F7: =D7*E7 -> 3000 | G7: L000005100001
A8: 3 | B8: 小工 | C8: 時 | D8: 16 | E8: 280 | F8: =D8*E8 -> 4480 | G8: L000006100001
A9: 4 | B9: 零星工料 | C9: 式 | D9: 1 | E9: =(F6+F7+F8)*3% -> 584.4 | F9: =D9*E9 -> 584.4 | G9: W0127110004
B10: ** 小計 ** | C10: 日 | D10: 1 | F10: =F6+F7+F8+F9 -> 20064.4
B11: ** 單價計 ** | C11: 日 | F11: =F10/D10 -> 20064.4
A13: 項次 | B13: 項目及說明 | C13: 單位 | D13: 數量 | E13: 單 價 | F13: 複 價 | G13: 備 註
A14: 1.1.27 | B14: 路線漆標線，12公尺以下道路及零星路段繪設 | C14: M2 | D14: 1 | E14: =F19 -> 165.2223 | G14: 02898120E2
A15: 1 | B15: 產品，標線路線漆 | C15: L | D15: 0.09 | E15: 324 | F15: =D15*E15 -> 29.16 | G15: M02898A000A
A16: 2 | B16: 標線，技術工 | C16: 時 | D16: 0.35 | E16: 375 | F16: =D16*E16 -> 131.25 | G16: L028985000001
A17: 3 | B17: 零星工料 | C17: 式 | D17: 1 | E17: =(F14+F15+F16)*3% -> 4.8123 | F17: =D17*E17 -> 4.8123 | G17: W0127110004
B18: ** 小計 ** | C18: M2 | D18: 1 | F18: =F15+F16+F17 -> 165.2223
B19: ** 單價計 ** | C19: M2 | F19: =F18/D18 -> 165.2223
A21: 項次 | B21: 項目及說明 | C21: 單位 | D21: 數量 | E21: 單 價 | F21: 複 價 | G21: 備 註
A22: 1.3.41 | B22: 鋼構吊裝 | C22: KG | D22: 10000 | E22: =F28 -> 16.2122 | G22: 055000A009
A23: 1 | B23: 吊車，20T以上 | C23: 時 | D23: 40 | E23: 3000 | F23: =D23*E23 -> 120000 | G23: E000004400711
A24: 2 | B24: 操作手，吊收機具 | C24: 時 | D24: 40 | E24: 375 | F24: =D24*E24 -> 15000 | G24: L000005100001
A25: 3 | B25: 小工 | C25: 時 | D25: 80 | E25: 280 | F25: =D25*E25 -> 22400 | G25: L000006100001
A26: 4 | B26: 零星工料 | C26: 式 | D26: 1 | E26: =(F23+F24+F25)*3% -> 4722 | F26: =D26*E26 -> 4722 | G26: W0127110004
B27: ** 小計 ** | C27: KG | D27: 10000 | F27: =F23+F24+F25+F26 -> 162122
B28: ** 單價計 ** | C28: KG | F28: =F27/D27 -> 16.2122
A30: 項次 | B30: 項目及說明 | C30: 單位 | D30: 數量 | E30: 單 價 | F30: 複 價 | G30: 備 註
A31: 1.4.22 | B31: 砌排石工，混凝土砌石(卵石均厚70cm) | C31: M2 | D31: 1 | E31: =F41 -> 3458.3875 | G31: 0238632202b #卵石，厚70cm
A32: 1 | B32: 結構用混凝土，預拌，140kgf/cm2 | C32: M3 | D32: 0.06 | E32: 3115.13 | F32: =D32*E32 -> 186.9078 | G32: 0331023003 分析表20
A33: 2 | B33: 產品，砌排石工，(卵石，均厚70cm，未含勾縫) | C33: L.M3 | D33: 0.7 | E33: 2300 | F33: =D33*E33 -> 1610 | G33: M023860140A1
A34: 3 | B34: 技術工，砌石 | C34: 時 | D34: 0.8 | E34: 375 | F34: =D34*E34 -> 300 | G34: L000005000011
A35: 4 | B35: 小工 | C35: 時 | D35: 1.44 | E35: 280 | F35: =D35*E35 -> 403.2 | G35: L000006100001
A36: 5 | B36: 砌排石工，水泥砂漿表面勾縫，1：3 | C36: M2 | D36: 1 | E36: 327.55 | F36: =D36*E36 -> 327.55 | G36: 02386PWDA1302 分析表282
A37: 6 | B37: 產品，硬質聚氯乙烯塑膠管(A管薄管)，洩水孔用 | C37: 式 | D37: 1 | E37: 30 | F37: =D37*E37 -> 30 | G37: M1510710000B4
A38: 7 | B38: 塊石搬運 | C38: L.M3 | D38: 1 | E38: 500 | F38: =D38*E38 -> 500 | G38: 00006701000
A39: 8 | B39: 零星工料 | C39: 式 | D39: 1 | E39: =SUM(F32:F38)*3% -> 100.72973 | F39: =D39*E39 -> 100.72973 | G39: W0127110004
B40: ** 小計 ** | C40: M2 | D40: 1 | F40: =SUM(F32:F39) -> 3458.3875
B41: ** 單價計 ** | C41: M2 | F41: =F40/D40 -> 3458.3875
A44: 項次 | B44: 項目及說明 | C44: 單位 | D44: 數量 | E44: 單 價 | F44: 複 價 | G44: 備 註
A45: 1.4.23 | B45: 預力混凝土基樁，D=600mm，(打樁，含樁，空打及PC版樁隱蔽障礙物清除處理) | C45: M | D45: 10 | E45: =F60 -> 5734.0515 | G45: 新增工項 0245760011a
...

Sheet 變更對照項目詳細表
C1: 臺北市政府工務局水利工程處
C2: 變更項目對照詳細表
L3: 日期： | M3: 45657.381
A4: 原契約分為 10 部分 本次變更 0 部分原有 424 項 | K4: 訂約總價 | M4: 324912089
A5: 前經 1 次變更設計，計新增 10 項，減少 0 項，變更 10 項，變更後合計 434 項 | K5: 第4次變更後總價(綜簽) | M5: =SUM(J11:J514)-J513-J507-J487-J466-J462-J422-J392-J384-J342-J252-J234-J215-J189-J141-J40-J11-J511 -> 3.8048764e+08
A6: 本次變更設計，計新增 0 項，減少 0 項，變更 0 項，變更後合計 434 項 | K6: 本次變更後總價 | M6: =K9 -> 3.8398004e+08 | P6: =M6-M5 -> 3492398.5
A7: 項次 | B7: 項目名稱 | C7: 單位 | D7: 四 變 數 量 | E7: 變更後 數 量 | F7: 增 減 數 量 | G7: 契 約 單 價 | H7: 新 增 單 價 | I7: 新 增 單 價 | J7: 原 訂 合 價 | K7: 變更後 合價 | L7: 追加 | M7: 追減 | N7: 備註 | P7: 變更依據 | Q7: 數量計算式 | R7: 變更原因 | S7: 有沒有找到紀錄 | T7: 分類
A9: 壹 | B9: 發包工程費 | C9: 式 | D9: 1 | G9: 361528714 | J9: 365478534 | K9: =K10+K392+K422+K462+K466+K487+K507+K510+K511+K513 -> 3.8398004e+08 | L9: =K9-J9 -> 18501506
A10: 一 | B10: 工程費 | C10: 式 | D10: 1 | G10: 275489625 | J10: =J11+J40+J141+J189+J215+J234+J252+J342+J384 -> 2.9044548e+08 | K10: =K11+K40+K141+K189+K215+K234+K252+K342+K384 -> 2.918183e+08 | L10: =L11+L40+L141+L189+L215+L234+L252+L342+L384 -> 1754816.5 | M10: =M11+M40+M141+M189+M215+M234+M252+M342+M384 -> -382003.22
A11: (一) | B11: 整備工程 | C11: 式 | D11: 1 | G11: =J11 -> 90501931 | J11: =SUM(J12:J39) -> 90501931 | K11: =SUM(K12:K39) -> 92643799 | L11: =SUM(L12:L39) -> 2432892 | M11: =SUM(M12:M39) -> -291024.77
A12: 1 | B12: 機械拆除，瀝青混凝土，未含運費 | C12: M3 | D12: 544.66 | E12: ='整備工程(1)'!J8 -> 525.96 | F12: =E12-D12 -> -18.7 | G12: 193.12 | J12: =D12*G12 -> 105184.74 | K12: =E12*G12 -> 101573.4 | L12: =K12-J12 -> -3611.344
A13: 2 | B13: 機械拆除，鋼筋混凝土，未含運費 | C13: M3 | D13: 7089.42 | E13: ='整備工程(1)'!J11 -> 7029.4502 | F13: =E13-D13 -> -59.9698 | G13: 1046.22 | J13: =D13*G13 -> 7417093 | K13: =E13*G13 -> 7354351.4 | L13: =K13-J13 -> -62741.604
A14: 3 | B14: 盤踞切割 | C14: M | D14: 4616 | E14: ='整備工程(1)'!J26 -> 4615.0765 | F14: =E14-D14 -> -0.9235 | G14: 6200 | J14: =D14*G14 -> 28619200 | K14: =E14*G14 -> 28613474 | L14: =K14-J14 -> -5725.7 | N14: #磺港路橋2993.02m、共月橋505.61m、三合橋1117.33
A15: 4 | B15: 基地及路幅開挖，未含運費，(機械挖，0.7～0.79m3開挖機) | C15: B.M3 | D15: 31759 | E15: ='整備工程(1)'!J31 -> 32863 | F15: =E15-D15 -> 1104 | G15: 48.28 | J15: =D15*G15 -> 1533324.5 | K15: =E15*G15 -> 1586625.6 | L15: =K15-J15 -> 53301.12 | Q15: 詳挖填方數量表
A16: 5 | B16: 瀝青混凝土面層刨除，刨除料運費 | C16: M3 | D16: 731.44 | E16: ='整備工程(1)'!J34 -> 735.538 | F16: =E16-D16 -> 4.098 | G16: 599.75 | J16: =D16*G16 -> 438681.14 | K16: =E16*G16 -> 441138.92 | L16: =K16-J16 -> 2457.7755
A17: 6 | B17: 利用填方，含夯實 | C17: M3 | D17: 7519 | E17: ='整備工程(1)'!J41 -> 4737.8 | F17: =E17-D17 -> -2781.2 | G17: 104.64 | J17: =D17*G17 -> 786788.16 | K17: =E17*G17 -> 495763.39 | M17: =K17-J17 -> -291024.77
A18: 7 | B18: 餘方遠運處理(台北港) | C18: B.M3 | D18: =22240+355 -> 22595 | E18: ='整備工程(1)'!J46 -> 28125.2 | F18: =E18-D18 -> 5530.2 | G18: 1027.43 | J18: =D18*G18 -> 23214781 | K18: =E18*G18 -> 28896674 | L18: =K18-J18 -> 5681893.4 | N18: 僅含運費(運距約<20K)(土方管理費檢據核銷) | S18: 沒紀錄 | T18: 現場需求
A19: 8 | B19: 餘方自行處理(房屋廢方，含水土保持) | C19: M3 | D19: 6730.42 | E19: ='整備工程(1)'!J49 -> 6730.42 | F19: =E19-D19 -> 0 | G19: 1085.04 | J19: =D19*G19 -> 7302774.9 | K19: =E19*G19 -> 7302774.9 | L19: =K19-J19 -> 0
A20: 9 | B20: 瀝青混凝土面層刨除，厚5cm，刨除機1.2m寬，含瀝青鋪面打毛(未含運費) | C20: M2 | D20: 3735.5 | E20: ='整備工程(1)'!J51 -> 2160 | F20: =E20-D20 -> -1575.5 | G20: 30.45 | J20: =D20*G20 -> 113745.97 | K20: =E20*G20 -> 65772 | L20: =K20-J20 -> -47973.975 | N20: #含瀝青鋪面打毛
A21: 10 | B21: 瀝青混凝土面層刨除，厚10cm，刨除機2.2m寬，未含運費 | C21: M2 | D21: 10205 | E21: ='整備工程(1)'!J55 -> 7540.34 | F21: =E21-D21 -> -2664.66 | G21: 28.48 | J21: =D21*G21 -> 290638.4 | K21: =E21*G21 -> 214748.88 | L21: =K21-J21 -> -75889.517
A22: 11 | B22: 切割瀝青混凝土或無筋混凝土，5cm≦切割深度＜10cm | C22: M | D22: 142.6 | E22: ='整備工程(1)'!J64 -> 1284.7 | F22: =E22-D22 -> 1142.1 | G22: 65.4 | J22: =D22*G22 -> 9326.04 | K22: =E22*G22 -> 84019.38 | L22: =K22-J22 -> 74693.34
A23: 12 | B23: 清除及掘除，雜草雜木，含垃圾撿除，人工割 | C23: M2 | D23: 8459.3 | E23: ='整備工程(1)'!J69 -> 8305.2 | F23: =E23-D23 -> -154.1 | G23: 20.19 | J23: =D23*G23 -> 170793.27 | K23: =E23*G23 -> 167681.99 | L23: =K23-J23 -> -3111.279
A24: 13 | B24: 垃圾及廢棄物(以體積計)清運 | C24: M3 | D24: 1268.9 | E24: ='整備工程(1)'!J76 -> 108 | F24: =E24-D24 -> -1160.9 | G24: 2492.81 | J24: =D24*G24 -> 3163126.6 | K24: =E24*G24 -> 269223.48 | L24: =K24-J24 -> -2893903.1 | N24: #
A25: 14 | B25: 節塊吊放 | C25: 次 | D25: 659 | E25: ='整備工程(1)'!J76 -> 108 | F25: =E25-D25 -> -551 | G25: 521.18 | J25: =D25*G25 -> 343457.62 | K25: =E25*G25 -> 56287.44 | L25: =K25-J25 -> -287170.18 | N25: #磺港路橋、共月橋、三合橋
A26: 15 | B26: 機械拆除，工地雜項拆除清理，欄杆，含運費 | C26: M | D26: 253.3 | E26: ='整備工程(1)'!J82 -> 253 | F26: =E26-D26 -> -0.3 | G26: 289.69 | J26: =D26*G26 -> 73378.477 | K26: =E26*G26 -> 73291.57 | L26: =K26-J26 -> -86.907
A27: 16 | B27: 既有路燈拆除繳回 | C27: 盞 | D27: 80 | E27: ='整備工程(1)'!J87 -> 80 | F27: =E27-D27 -> 0 | G27: 3311.45 | J27: =D27*G27 -> 264916 | K27: =E27*G27 -> 264916 | L27: =K27-J27 -> 0 | N27: #料繳回，含運費。
A28: 17 | B28: 土方運送(百齡抽水站) | C28: 趟 | D28: 1278 | E28: ='整備工程(1)'!J89 -> 1278 | F28: =E28-D28 -> 0 | G28: 3082.28 | J28: =D28*G28 -> 3939153.8 | K28: =E28*G28 -> 3939153.8 | L28: =K28-J28 -> 0
A29: 18 | B29: 座椅拆除繳回 | C29: 座 | D29: 30 | E29: ='整備工程(1)'!J92 -> 30 | F29: =E29-D29 -> 0 | G29: 1200 | J29: =D29*G29 -> 36000 | K29: =E29*G29 -> 36000 | L29: =K29-J29 -> 0 | N29: #料繳回，含運費。
A30: 19 | B30: 解說牌拆除 | C30: 座 | D30: 12 | E30: ='整備工程(1)'!J94 -> 12 | F30: =E30-D30 -> 0 | G30: 3000 | J30: =D30*G30 -> 36000 | K30: =E30*G30 -> 36000 | L30: =K30-J30 -> 0 | N30: #料繳回，含運費。
A31: 20 | B31: 自行車架拆除 | C31: 座 | D31: 20 | E31: ='整備工程(1)'!J96 -> 20 | F31: =E31-D31 -> 0 | G31: 3000 | J31: =D31*G31 -> 60000 | K31: =E31*G31 -> 60000 | L31: =K31-J31 -> 0 | N31: #料繳回，含運費。
A32: 21 | B32: 交通牌誌拆除 | C32: 座 | D32: 19 | E32: ='整備工程(1)'!J98 -> 19 | F32: =E32-D32 -> 0 | G32: 3000 | J32: =D32*G32 -> 57000 | K32: =E32*G32 -> 57000 | L32: =K32-J32 -> 0 | N32: #料繳回，含運費。
A33: 22 | B33: 既有水利設施拆除及運送 | C33: 式 | D33: 1 | E33: ='整備工程(1)'!J100 -> 1 | F33: =E33-D33 -> 0 | G33: 400000 | J33: =D33*G33 -> 400000 | K33: =E33*G33 -> 400000 | L33: =K33-J33 -> 0 | N33: 抽水設施、水閘門
A34: 23 | B34: 交通維持，道路管制人員，日間(06-22時)，義交 | C34: 時 | D34: 30800 | E34: ='整備工程(1)'!J102 -> 30800 | F34: =E34-D34 -> 0 | G34: 280 | J34: =D34*G34 -> 8624000 | K34: =E34*G34 -> 8624000 | L34: =K34-J34 -> 0 | N34: [人力工項不打折]日間7時-18時
A35: 24 | B35: 表土清除，堆置，及回填費，t=30cm | C35: M2 | D35: 2405 | E35: ='整備工程(1)'!J118 -> 2405.05 | F35: =E35-D35 -> 0.05 | G35: 70.23 | J35: =D35*G35 -> 168903.15 | K35: =E35*G35 -> 168906.66 | L35: =K35-J35 -> 3.5115 | N35: 百齡暫置場整地需求
A36: 26 | B36: 餘土分類處理 | C36: 日 | D36: 150 | E36: ='整備工程(1)'!J120 -> 150 | F36: =E36-D36 -> 0 | G36: 20000 | J36: =D36*G36 -> 3000000 | K36: =E36*G36 -> 3000000 | L36: =K36-J36 -> 0 | N36: 新增工項 02323M00AC
A37: 27 | B37: 路線漆標線，12公尺以下道路及零星路段繪設 | C37: M2 | D37: 138.05 | E37: ='整備工程(1)'!J122 -> 138.053 | F37: =E37-D37 -> 0.003 | G37: 165.22 | J37: =D37*G37 -> 22808.621 | K37: =E37*G37 -> 22809.117 | L37: =K37-J37 -> 0.49566 | N37: 新增工項02898120E2
A38: 28 | B38: 餘方近運1km小搬運 | C38: B.M3 | D38: 2000 | E38: ='整備工程(1)'!J128 -> 2007 | F38: =E38-D38 -> 7 | G38: 100 | J38: =D38*G38 -> 200000 | K38: =E38*G38 -> 200700 | L38: =K38-J38 -> 700 | N38: 新增工項02323M00AA
A39: 29 | B39: 細整地 | C39: M2 | D39: 3324.02 | E39: ='整備工程(1)'!J131 -> 3325.7 | F39: =E39-D39 -> 1.68 | G39: 33.35 | J39: =D39*G39 -> 110856.07 | K39: =E39*G39 -> 110912.1 | L39: =K39-J39 -> 56.028 | N39: 新增工項 0223160P02
A40: (二) | B40: 土建景觀工程 | C40: 式 | G40: =J40 -> 42752872 | J40: =SUM(J41:J134) -> 42752872 | K40: =SUM(K41:K134) -> 41028603 | L40: =SUM(L41:L134) -> -1724268.9 | M40: =SUM(M41:M134) -> 0
A41: 1 | B41: 構造物回填，回填及夯實(實際) | C41: C.M3 | D41: 2347.79 | E41: ='土建景觀工程(2)'!J7 -> 2347.7873 | F41: =E41-D41 -> -0.002689 | G41: 320.74 | J41: =D41*G41 -> 753030.16 | K41: =E41*G41 -> 753029.3 | L41: =K41-J41 -> -0.86246986
...

Sheet 整備工程(1)
A1: 臺北市政府工務局水利工程處
A2: 數量計算式
A3: 工程名稱：磺港溪再造C段護岸及步道整建工程(延壽橋至三合橋)
A4: 施工地點：北投磺港溪 | G4: 工程編號：111 070020302 038 02
A5: 項次 | B5: 項 目 及 說 明 | C5: 單位 | D5: 原契約數量 | E5: 變更後數量 | F5: 項目 | G5: 小計 | H5: 數量 | I5: 2月估價數量 | J5: 數量計算累計
A6: 一 | B6: 工程費 | C6: 式 | D6: 1
A7: (一) | B7: 整備工程 | C7: 式 | D7: 1
A8: 1.1.1 | B8: 機械拆除，瀝青混凝土，未含運費 | C8: M3 | D8: 544.66 | F8: 現況整備圖: 自行車道打除(131+146.5+160.4+149.8+24.6+311.1)*0.1 | G8: (131+146.5+160.4+149.8+24.6+311.1)*0.1 | H8: =(131+146.5+160.4+149.8+24.6+311.1)*0.1 -> 92.34 | I8: =SUM(H8:H9) -> 525.96 | J8: =SUM(H8:H9) -> 525.96
F9: 現況整備圖: 東側磺港路AC打除(339.4+542.2+512+774.5)*0.2 | G9: (339.4+542.2+512+774.5)*0.2 | H9: =(339.4+542.2+512+774.5)*0.2 -> 433.62
A11: 1.1.2 | B11: 機械拆除，鋼筋混凝土，未含運費 | C11: M3 | D11: 7089.42 | F11: 鋪面打除 | G11: (825.8+623.9+1160.3+964.3+522.6+839.7)*0.3 | H11: =(825.8+623.9+1160.3+964.3+522.6+839.7)*0.3 -> 1480.98 | I11: =SUM(H11:H24)-H13-H15-H16 -> 6176.5003 | J11: =SUM(H11:H24) -> 7029.4502
F12: 堤防拆除 | G12: (69.3+116+83.4+87+0+34.5)*2.6 | H12: =(69.3+116+83.4+87+0+34.5)*2.6 -> 1014.52
F13: 結構物、管涵打除 | G13: (52.8+101.5+85+42.9+18.9+17.9)*1 | H13: =(52.8+101.5+85+42.9+18.9+17.9)*1 -> 319
F14: 階梯打除 | G14: (16.7+14.8+0+0+0+5.1)*2.2 | H14: =(16.7+14.8+0+0+0+5.1)*2.2 -> 80.52
F15: 排水溝打除 | G15: (209.5+221.3+250.5+260.6+0+218.8)*0.44 | H15: =(209.5+221.3+250.5+260.6+0+218.8)*0.44 -> 510.708
F16: 緣石打除 | G16: (144+162+145.7+151.7+0+100.9)*0.033 | H16: =(144+162+145.7+151.7+0+100.9)*0.033 -> 23.2419
F17: 擋牆部分打除 | G17: (0+0+0+0+0+3.3)*0.4 | H17: =(0+0+0+0+0+3.3)*0.4 -> 1.32
F18: 磺港路橋 | G18: (9.32-6.28)*54.61/2*7.2 + 2.5*52.14*8.7 + (9.28-8.01)*22.33/2*7.2 | H18: =(9.32-6.28)*54.61/2*7.2 + 2.5*52.14*8.7 + (9.28-8.01)*22.33/2*7.2 -> 1833.7896
F19: 人行橋(共月處) | G19: 6.2*19.95*1.5+6.2*19.95*1.5+3*1.5*2.2/2*2+1.95*1.05*1.8/2*2 | H19: =6.2*19.95*1.5+6.2*19.95*1.5+3*1.5*2.2/2*2+1.95*1.05*1.8/2*2 -> 384.6555
F20: 三合橋 | G20: 11.78*13.55*2+11.78*13.55*2 | H20: =11.78*13.55*2+11.78*13.55*2 -> 638.476
F21: 既有雙孔箱涵部分拆除 | G21: 20.98*3*0.5*2.5+三合橋下版面236.2*0.5+鄰近人行道20*2.5*0.3 | H21: =20.98*3*0.5*2.5+236.2*0.5+20*2.5*0.3 -> 211.775
F22: 延壽橋既有河底打除(PC樁) | G22: 0.6深*長80*河道寬3 | H22: =0.6*80*3 -> 144
F23: 磺港路上既有堤牆打除 | G23: 長度300*既有版厚0.3*人行道寬2+堤牆厚0.3*高度1.5*長度300+既有陰井5座*厚度0.3*長度1.2*4邊 | H23: =300*0.3*2+0.3*1.5*300+5*0.3*1.2*4 -> 322.2
F24: 既有排水設施(單孔箱涵，W*H=1.6m*1.4m)部分拆除 | G24: 11.77*5.46 | H24: =11.77*5.46 -> 64.2642
A26: 1.1.3 | B26: 盤踞切割 | C26: M | D26: 4616 | F26: 磺港路橋 | G26: 橋面版長度橫切54.61+縱切54.61*平均寬度(9.32-6.28)/間距1M 2*2 + 梁長52.14*8.7*6刀 + 護欄長橫切22.33+護欄縱切22.33*(9.28-8.01)/2*2 | H26: =54.61+54.61*(9.32-6.28)/2*2 + 52.14*8.7*6 + 22.33+22.33*(9.28-8.01)/2*2 -> 2993.0215 | I26: =SUM(H26:H28) -> 4615.0765 | J26: =SUM(H26:H28) -> 4615.0765
F27: 人行橋(共月處) | G27: 橋面板長度-19.95*6.2*4+樓梯寬1.5*高2.2/2*3*左右兩邊2+樓梯平台1.05*1.8/2 | H27: =19.95*6.2*4 + 1.5*2.2/2*3*2 + 1.05*1.8/2 -> 505.605
F28: 三合橋 | G28: 橋面板長度橫切13.55+縱切13.55*14刀*厚度0.8+護欄11.78*高度0.8*8*2邊+11.78*1*13.55*2+13.55*(21.3-1.5)/2*2+11.78*(13.55/0.6)*0.8 | H28: =ROUND(13.55+13.55*14*0.8+11.78*0.8*8*2+11.78*1*13.55*2+13.55*(21.3-1.5)/2*2+11.78*(13.55/0.6)*0.8,2) -> 1116.45
A31: 1.1.4 | B31: 基地及路幅開挖，未含運費，(機械挖，0.7～0.79m3開挖機) | C31: B.M3 | D31: 29759 | F31: 詳挖方計算式 | G31: 32863 | H31: =G31 -> 32863 | I31: =H31 -> 32863 | J31: =I31 -> 32863
A34: 1.1.5 | B34: 瀝青混凝土面層刨除，刨除料運費 | C34: M3 | D34: 731.44 | F34: 舊磺港陸橋 | G34: 892.19*0.1 | H34: =892.19*0.1 -> 89.219 | I34: =SUM(H34:H37)-H37-H39 -> 328.89 | J34: =SUM(H34:H39) -> 735.538
F35: 西側磺港路(由南至北) | G35: (613.36+615.86+589.71+964.58)*0.1 | H35: =(613.36+615.86+589.71+964.58)*0.1 -> 278.351
F36: 三合街一段 | G36: 346.6*0.2 | H36: =346.6*0.2 -> 69.32
F37: 三合街二段 | G37: 605.24*0.2 | H37: =605.24*0.2 -> 121.048
F38: 三合橋施工便橋AC刨除 | G38: 69.6*10*0.1 | H38: =69.6*10*0.1 -> 69.6
F39: 東側磺港路第一次舖設完後 ，面層重鋪改道N0k+440~800 | G39: (800-440)*路寬(4+2)*0.05 | H39: =(800-440)*6*0.05 -> 108
A41: 1.1.6 | B41: 利用填方，含夯實 | C41: M3 | D41: 7519 | F41: 0 | G41: 0 | H41: 0 | I41: 0 | J41: =SUM(H41:H44) -> 4737.8
F42: 0K+440~620雙孔箱涵與既有堤牆側回填 | G42: 1590.6 | H42: =G42 -> 1590.6 | I42: =H42 -> 1590.6
F43: 0K+280~440雙孔箱涵與既有堤牆側回填 | G43: 1147.2 | H43: =G43 -> 1147.2
F44: 公園景觀回填 | G44: 2000 | H44: 2000
A46: 1.1.7 | B46: 餘方遠運處理(台北港) | C46: B.M3 | D46: 22240 | F46: 路幅開挖-利用填方-構造物回填 | H46: =J31-J41 -> 28125.2 | I46: =H46 -> 28125.2 | J46: =I46 -> 28125.2
A49: 1.1.8 | B49: 餘方自行處理(房屋廢方，含水土保持) | C49: M3 | D49: 6730.42 | F49: 詳聯單 | G49: 4956 | H49: =G49 -> 4956 | I49: =H49 -> 4956 | J49: 6730.42
A51: 1.1.9 | B51: 瀝青混凝土面層刨除，厚5cm，刨除機1.2m寬，含瀝青鋪面打毛(未含運費) | C51: M2 | D51: 3735.5 | F51: 東側磺港路第一次舖設完後 ，面層重鋪改道N0k+440~800 | G51: (800-440)*路寬(4+2) | H51: =(800-440)*6 -> 2160 | I51: 0 | J51: =H51 -> 2160
...

Sheet 土建景觀工程(2)
A1: 臺北市政府工務局水利工程處
A2: 數量計算式
A3: 工程名稱：磺港溪再造C段護岸及步道整建工程(延壽橋至三合橋)
A4: 施工地點：北投磺港溪 | G4: 工程編號：111 070020302 038 02
A5: 項次 | B5: 項 目 及 說 明 | C5: 單位 | D5: 原契約數量 | E5: 變更後數量 | F5: 項目 | G5: 小計 | H5: 數量 | I5: 2月估價數量 | J5: 數量計算累計
A6: (二) | B6: 土建景觀工程 | C6: 式 | D6: 1
A7: 1.2.1 | B7: 構造物回填，回填及夯實(實際) | C7: C.M3 | D7: 2347.79 | F7: 透水磚紙模地坪 | G7: 1*1*0.39*5207.01 | H7: =1*1*0.39*5207.01 -> 2030.7339 | I7: 0 | J7: =SUM(H7:H20) -> 2347.7873
F8: 石材鋪面 | G8: 1*1*0.23*375.23 | H8: =1*1*0.23*375.23 -> 86.3029
F9: 卵石鋪面 | G9: 1*1*0.28 | H9: 0
F10: 露骨材地坪 | G10: 1*1*0.2*34.8 | H10: =1*1*0.2*34.8 -> 6.96
F11: PC地坪 | G11: 1*1*0.2*11.98 | H11: =1*1*0.2*11.98 -> 2.396
F12: 格柵鋪面A | G12: 2.425*0.6*0.45*8 | H12: =2.425*0.6*0.45*8 -> 5.238
F13: 混凝土板地坪 | G13: 1.1*0.9*0.33*19 | H13: =1.1*0.9*0.33*19 -> 6.2073
F14: 界石收邊 | G14: 1*0.1*0.29*360.35 | H14: =1*0.1*0.29*360.35 -> 10.45015
F15: 緣石收邊 | G15: 1*0.23*0.33*691.14 | H15: =1*0.23*0.33*691.14 -> 52.457526
F16: 道路緣石收邊 | G16: 1*0.15*0.3*890.62 | H16: =1*0.15*0.3*890.62 -> 40.0779
F17: 道路緣石斜坡式 | G17: 1*0.15*0.27*85.77 | H17: =1*0.15*0.27*85.77 -> 3.473685
F18: 場鑄道路緣石 | G18: 1*0.15*0.15*187.82 | H18: =1*0.15*0.15*187.82 -> 4.22595
F19: 警示帶定位磚 | G19: 1*1*0.3*20.48 | H19: =1*1*0.3*20.48 -> 6.144
F20: 雨水積磚 | H20: 93.12
A22: 1.2.2 | B22: 構造物回填，回填及夯實，人工夯實 | C22: C.M3 | D22: 755.76 | F22: 座台A | G22: 1*0.2*0.29*354.7 | H22: =1*0.2*0.29*354.7 -> 20.5726 | I22: 0 | J22: =SUM(H22:H67) -> 742.90104
F23: 座台B | G23: 1*0.3*0.29*44.7 | H23: =1*0.3*0.29*44.7 -> 3.8889
F24: 座台C | G24: 1*0.8*0.45*31 | H24: =1*0.8*0.45*31 -> 11.16
F25: 座台D | G25: 1*0.3*0.7*18.1 | H25: =1*0.3*0.7*18.1 -> 3.801
F26: 座台E | G26: 1*0.4*0.29*180.4 | H26: =1*0.4*0.29*180.4 -> 20.9264
F27: 座台F | G27: 1*0.3*0.29*25.6 | H27: =1*0.3*0.29*25.6 -> 2.2272
F28: 座椅A | G28: (1.5*0.647*0.29)+(1*0.225*0.29)*7 | H28: =(1.5*0.647*0.29)+(1*0.225*0.29)*7 -> 0.738195
F29: 座椅B | G29: 1*0.5*0.29*7.8 | H29: =1*0.5*0.29*7.8 -> 1.131
F30: 座椅C | G30: 0.3*0.2*0.367*2 | H30: =0.3*0.2*0.367*2 -> 0.04404
F31: 座椅D-1 | G31: 0.56*0.56*0.192*3 | H31: =0.56*0.56*0.192*3 -> 0.1806336
F32: 草地座階 | G32: 1*0.8*0.4*18 | H32: =1*0.8*0.4*18 -> 5.76
F33: 擋牆a' | G33: 1*1.2*1.1*17.1 | H33: =1*1.2*1.1*17.1 -> 22.572
F34: 擋牆b' | G34: 1*0.45*0.45*(21.7+17.6) | H34: =1*0.45*0.45*(21.7+17.6) -> 7.95825
F35: 擋牆c' | G35: 1*0.3*1.48*32.5 | H35: =1*0.3*1.48*32.5 -> 14.43
F36: 樓梯A | G36: 13.89*2*0.55 | H36: =13.89*2*0.55 -> 15.279
F37: 樓梯B | G37: 0.66*1.2*0.3 | H37: =0.66*1.2*0.3 -> 0.2376
F38: 樓梯C | G38: 1.32*1.2*0.4 | H38: =1.32*1.2*0.4 -> 0.6336
F39: 樓梯I | G39: 1.98*1.2*0.47 | H39: =1.98*1.2*0.47 -> 1.11672
F40: 樓梯L | G40: 0.3*6.63*0.35 | H40: =0.3*6.63*0.35 -> 0.69615
F41: 地圖牌 | G41: 1.6*0.7*0.76 | H41: =1.6*0.7*0.76 -> 0.8512
...

Sheet 橋梁工程 (3)
A1: 臺北市政府工務局水利工程處
A2: 數量計算式
A3: 工程名稱：磺港溪再造C段護岸及步道整建工程(延壽橋至三合橋)
A4: 施工地點：北投磺港溪 | G4: 工程編號：111 070020302 038 02
A5: 項次 | B5: 項 目 及 說 明 | C5: 單位 | D5: 原契約數量 | E5: 變更後數量 | F5: 項目 | G5: 小計 | H5: 數量 | I5: 小計 | J5: 數量計算累計
A6: (三) | B6: 橋梁工程 | C6: 式 | D6: 1
A7: 1.3.1 | B7: 構造物回填，回填及夯實(實際) | C7: C.M3 | D7: 274.45 | F7: 0 | G7: 0 | H7: 0 | I7: 0 | J7: =SUM(H8:H14) -> 270.851
F8: 三合橋路基回填 | G8: (1.5*1.25+0.5*1.5+0.5*0.42)*(15.6+15) | H8: =(1.5*1.25+0.5*1.5+0.5*0.42)*(15.6+15) -> 86.751 | I8: =H8 -> 86.751
F9: 共月橋 | G9: 5*6*1.1*2+8.42+5*2*1.1 | H9: =5*6*1.1*2+8.42+5*2*1.1 -> 85.42
F10: 共月橋無障礙警示帶(斬石子) | G10: 0 | H10: 0
F11: 共月橋園內引道 | G11: 19.6 | H11: =G11 -> 19.6
F12: 共月橋人行道引道 | G12: 65.68 | H12: =G12 -> 65.68
F13: P1、P2橋墩造型混凝土牆 | G13: 13.4 | H13: =G13 -> 13.4
A15: 1.3.2 | B15: 結構用混凝土，預拌，140kgf/cm2 | C15: M3 | D15: 44.22 | F15: 三合橋A1 | G15: 長16.5*寬1.92*0.1 | H15: =16.5*1.92*0.1 -> 3.168 | I15: =SUM(H15:H17) -> 16.986 | J15: =SUM(H15:H22) -> 36.316
F16: 三合橋A2 | G16: 長16.5*寬(1+1.5+0.42)*0.1 | H16: =16.5*(1+1.5+0.42)*0.1 -> 4.818
F17: 三合橋進橋板 | G17: 9*5*2*0.1 | H17: =9*5*2*0.1 -> 9
F18: 混凝土表面處理，晶化地坪，含分割縫 | G18: 136*0.1 | H18: =136*0.1 -> 13.6
F19: 共月橋園內引道 | G19: 詳數量統計表1.05 | H19: 1.05
F20: 共月橋人行道引道 | G20: 詳數量統計表58.25 | H20: 3.28
F21: P1、P2橋墩造型混凝土牆 | G21: 1.4 | H21: =G21 -> 1.4
A23: 1.3.3 | B23: 結構用混凝土，預拌，210kgf/cm2 | C23: M3 | D23: 95.97 | F23: 共月橋無障礙警示帶(斬石子) | G23: 0 | H23: 0 | I23: 0 | J23: =SUM(H23:H26) -> 86.51
F24: 共月橋園內引道牆身L=10.52 | G24: 詳數量統計表16.26 | H24: 16.26
F25: 共月橋人行道引道 | G25: 詳數量統計表58.25 | H25: 58.25
F26: P1、P2橋墩造型混凝土牆 | G26: 12 | H26: 12
A30: 1.3.4 | B30: 結構用混凝土，預拌，280kgf/cm2 | C30: M3 | D30: 1216.8 | F30: 共月橋P1P2橋墩結構(含帽梁) | G30: 6*8*1.2+1.1*0.9*1.2*2+0.4*0.4*0.25*2+0.4*0.4*3.14*(5-3.2)*2 | H30: =6*8*1.2+1.1*0.9*1.2*2+0.4*0.4*0.25*2+0.4*0.4*3.14*(5-3.2)*2 -> 61.86464 | I30: =SUM(H30:H39)-H38 -> 542.32667 | J30: =SUM(H30:H41) -> 709.04667
F31: 共月橋P3P4橋墩結構(含帽梁) | G31: 6*5*1+2*(5-3.2)*0.4*0.4*3.14+(1.86+1.3)/2*1.18*1.2+0.2*0.3*2*1.2+0.4*0.4*0.25*2 | H31: =6*5*1+2*(5-3.2)*0.4*0.4*3.14+(1.86+1.3)/2*1.18*1.2+0.2*0.3*2*1.2+0.4*0.4*0.25*2 -> 34.26992
F32: 共月橋P5橋墩結構(含帽梁) | G32: (1.2+0.8)/2*1.8*1.29*1.71+(5-3.2)*0.4*0.4*3.14+5*2*1+1.2*0.3*0.27*2+0.4*0.4*0.25*2 | H32: =(1.2+0.8)/2*1.8*1.29*1.71+(5-3.2)*0.4*0.4*3.14+5*2*1+1.2*0.3*0.27*2+0.4*0.4*0.25*2 -> 15.14934
F33: 共月橋A2橋墩結構(含帽梁) | G33: 1.5*1.15*1.836+(0.5+0.42)*1.836*(1.15+0.5+1.05)+0.4*0.4*0.25*2+0.3*0.5*2++0.5*0.35*1.836 | H33: =1.5*1.15*1.836+(0.5+0.42)*1.836*(1.15+0.5+1.05)+0.4*0.4*0.25*2+0.3*0.5*2+0.5*0.35*1.836 -> 8.429024
F34: 三合橋A1橋台 | G34: 詳數量計算表 | H34: =18.1*1.92*1.15+(0.92*1.5-0.42*0.35+2*1.2)*18.1+0.4*0.4*0.25*8+1.044*1.5*0.3*2 -> 106.9817
F35: 三合橋A2橋台 | G35: 詳數量計算表 | H35: =16.5*(1+1.5+0.42)*0.5+16.5*1.92*1.05-16.5*0.42*0.35+0.4*0.4*0.25*8+1.05*0.3*2.92*2+16.5*0.3*0.5 -> 59.5631
F36: 便橋護墩及銜接道路 | G36: 16.5*1.2*1.5*2+0.3*23.5*12.5 | H36: =16.5*1.2*1.5*2+0.3*23.5*12.5 -> 147.525
F37: 三合橋進橋板 | G37: 12*0.3*5+12*0.3*5 | H37: =12*0.3*5+12*0.3*5 -> 36
F38: 共月橋進橋板
F39: 三合橋橋面板 | G39: ((17.81+22.3)*0.5*15*1.06)*0.2275 | H39: =((17.81+22.3)*0.5*15*1.06)*0.2275 -> 72.543949
F40: 三合橋A1橋台與既有堤牆側回填(箱涵側) | G40: 4.76*20 | H40: =4.76*20 -> 95.2
F41: 三合橋A2橋台與既有堤牆側回填(箱涵側) | G41: 3.576*20 | H41: =3.576*20 -> 71.52
A44: 1.3.5 | B44: 鋼筋，SD280W | C44: KG | D44: 4788.77 | F44: P1P2造型牆面 | G44: 2040 | H44: 2040 | I44: =H45+H46 -> 182.27972 | J44: =SUM(H44:H50) -> 12591.66
F45: 三合橋A1溫度鋼筋 | G45: 0.994*18.1*(1.5/0.3)*1.06 | H45: =0.994*18.1*(1.5/0.3)*1.06 -> 95.35442 | I45: =SUM(H44:H48)-H44-H47-H48 -> 182.27972
F46: 三合橋A2溫度鋼筋 | G46: 0.994*16.5*(1.5/0.3)*1.06 | H46: =0.994*16.5*(1.5/0.3)*1.06 -> 86.9253
F47: 共月橋園內引道 | G47: 864.68 | H47: =G47 -> 864.68
...

Sheet 河川工程 (4)
A1: 臺北市政府工務局水利工程處
A2: 數量計算式
A3: 工程名稱：磺港溪再造C段護岸及步道整建工程(延壽橋至三合橋)
A4: 施工地點：北投磺港溪 | G4: 工程編號：111 070020302 038 02
A5: 項次 | B5: 項 目 及 說 明 | C5: 單位 | D5: 原契約數量 | E5: 變更後數量 | F5: 項目 | G5: 小計 | H5: 數量 | I5: 施作數量 | J5: 數量計算累計
A6: (四) | B6: 河川工程
A7: 1.4.1 | B7: 結構用混凝土，預拌，140kgf/cm2 | C7: M3 | D7: 20 | F7: 低水護岸三合橋上游0K+307~618.1 | G7: (618.1-307)*(0.75*0.05) | H7: =(618.1-307)*(0.75*0.05) -> 11.66625 | I7: =SUM(H7:H11)-H9 -> 12.29625 | J7: =SUM(H7:H11) -> 19.58925
F8: 低水護岸三合下游280~287.7 | G8: 16.8*(0.75*0.05) | H8: =16.8*(0.75*0.05) -> 0.63 | I8: =SUM(H7:H11) -> 19.58925
F9: 護岸型式TYPEⅢ 0K+563.95~0K+606.85 | G9: 42.9*1.7*0.1 | H9: =42.9*1.7*0.1 -> 7.293
F10: 三合橋右岸堤牆復原0K+277~0K+308 | G10: 長29.8*2.5*0.1 | I10: 移至下水道工程
F11: 三合橋左岸堤牆復原 | G11: (4+5+8)*2.5*0.1 | I11: 移至下水道工程
A13: 1.4.2 | B13: 結構用混凝土，預拌，210kgf/cm2 | C13: M3 | D13: 354 | F13: 0 | G13: 0 | H13: 0 | I13: 0 | J13: =SUM(H13:H20) -> 327.6715
F14: PC樁樁內灌漿 | G14: 41*0.3*0.3*3.14*10 | H14: =41*0.3*0.3*3.14*10 -> 115.866 | I14: =SUM(H14:H16) -> 139.086
F15: RC護坡0K+280~290 | G15: 10*0.2*5.4 | H15: =10*0.2*5.4 -> 10.8
F16: RC護坡0K+580~591.5 | G16: (591.5-580)*0.2*5.4 | H16: =(591.5-580)*0.2*5.4 -> 12.42
F17: 側流井 | G17: 底版(10.4+0.25+0.25)*(4.6+8.2+1.2+1.2)/2*0.45+牆身(10.4+0.25+0.25+4.6+8.2)*0.25*2+頂版(10.4+0.25+0.25)*(4.6+8.2)/2*0.45-2.6*3.6*0.45+立柱5*0.25*0.25*2+溢流牆11.5*0.35*0.1 | H17: =(10.4+0.25+0.25)*(4.6+8.2+1.2+1.2)/2*0.45+(10.4+0.25+0.25+4.6+8.2)*0.25*2+(10.4+0.25+0.25)*(4.6+8.2)/2*0.45-2.6*3.6*0.45+5*0.25*0.25*2+11.5*0.35*0.1 -> 77.3355
F18: 雙孔箱涵BK+560~570 | G18: (570-560)*雙孔箱涵數量計算7.525 | H18: =(570-560)*7.525 -> 75.25
F19: 雙孔箱涵BK+280~300 | G19: (300-280)*雙孔箱涵數量計算1.8 | H19: =(320-300)*1.8 -> 36
A21: 1.4.3 | B21: 結構用混凝土，預拌，280kgf/cm2 | C21: M3 | D21: 690 | E21: 0 | F21: 改二型水泥 | G21: 0 | H21: 0
A23: 1.4.4 | B23: 結構用混凝土，泵送及澆注費 | C23: M3 | D23: 1065 | G23: 140kgf+210kgf+二型280kgf/cm2 | H23: =I7+I115 -> 705.45875 | I23: =H23 -> 705.45875 | J23: =J13+J7+J115 -> 1874.0785
G24: 140kgf+210kgf+二型280kgf/cm2 | I24: =I14+I8+I116 -> 1106.842
A26: 1.4.5 | B26: 清水模板，乙種 | C26: M2 | D26: 1229 | F26: 低水護岸三合下游280~296.8 | G26: 16.8*(1.5*2) | H26: =16.8*(1.5*2) -> 50.4 | I26: =H26+H27+H30+H31 -> 1118.3063 | J26: =SUM(H26:H32) -> 1437.4812
F27: 低水護岸三合橋上游0K+307~620 | G27: (618.1-307)*(1.5*2)+(620-307)/20*1.5*0.75 | H27: =(618.1-307)*(1.5*2)+(620-307)/20*1.5*0.75 -> 950.90625 | I27: =SUM(H26:H32) -> 1437.4812
F28: 護岸型式TYPEⅢ 臨河側0K+563.95~0K+606.85 | G28: 42.9*(3.4) | H28: =42.9*(3.4) -> 145.86
F29: 護岸型式TYPE 2 臨河側0K+606.85~0K+625.1 | G29: (625.1-606.85)*3.4 | H29: =(625.1-606.85)*3.4 -> 62.05
F30: 三合橋右岸堤牆復原(臨河側)0K+277~0K+308 | G30: 長29.8*(2.5) | H30: =29.8*2.5 -> 74.5
F31: 三合橋左岸堤牆復原(臨河側) | G31: (4+5+8)*(2.5) | H31: =(4+5+8)*2.5 -> 42.5
F32: 新設擋土牆護欄(0k+523.95~0k+625.1) | G32: (625.1-523.95)*0.55*2 | H32: =(625.1-523.95)*0.55*2 -> 111.265
A34: 1.4.6 | B34: 普通模板，乙種 | C34: M2 | D34: 285 | F34: 護岸型式TYPEⅢ 臨路側0K+563.95~0K+606.85 | G34: 42.9*(0.6*2)+42.9*(3.4) | H34: =42.9*(0.6*2)+42.9*(3.4) -> 197.34 | I34: =H36+H37+H38+H39+H40+H41 -> 379.63125 | J34: =SUM(H34:H42) -> 685.44625
F35: 護岸型式TYPE 2 臨路側 0K+606.85~0K+625.1 | G35: (625.1-606.85)*(3.4+0.45*2) | H35: =(625.1-606.85)*(3.4+0.45*2) -> 78.475 | I35: =SUM(H34:H41) -> 655.44625
F36: 三合橋右岸堤牆復原(臨路側)0K+277~0K+308 | G36: 長29.8*(2.5+(0.5+1)*2) | H36: =29.8*(2.5+(0.5+1)*2) -> 163.9
F37: 三合橋左岸堤牆復原(臨路側) | G37: (4+5+8)*(2.5+(0.5+1)*2) | H37: =(4+5+8)*(2.5+(0.5+1)*2) -> 93.5
F38: 右岸砌石護岸底層 0K+278.1~599.6 | G38: 0.25*(599.6-278.1)+(599.6-278.1)/20*1.4*0.25 | H38: =0.25*(599.6-278.1)+(599.6-278.1)/20*1.4*0.25 -> 86.00125
F39: 衛工人孔底板 | G39: (6+1.5)*厚0.25*寬2 | H39: =(6+1.5)*0.25*2 -> 3.75
F40: 衛工人孔頂板 | G40: ((6+1.5)*寬1.5-1*1)+(6+1.5)*2*0.25 | H40: =((6+1.5)*1.5-1*1)+(6+1.5)*2*0.25 -> 14
F41: 三合橋下衛工砌石舖面 | G41: A2(1.55-0.35)*2*8*0.42+A1(0.42*(1.15+0.4)*2*8) | H41: =(1.55-0.35)*2*8*0.42+0.42*(1.15+0.4)*2*8 -> 18.48
F42: 三合橋上游地梁調整(0K+308~338) | G42: 30*0.5*2 | H42: =30*0.5*2 -> 30
A44: 1.4.7 | B44: 鋼筋，SD280W | C44: KG | D44: 13716 | F44: 低水護岸三合下游 | G44: 16.8*鋼筋表21.53 | H44: =16.8*21.53 -> 361.704 | I44: =H44+H45+H48+H49+H50+H51 -> 13452.891 | J44: =SUM(H44:H53) -> 18482.547
F45: 低水護岸三合橋上游0K+307~618.1 | G45: (618.1-307)*鋼筋表21.53 | H45: =(618.1-307)*21.53 -> 6697.983 | I45: =SUM(H44:H52) -> 17878.195
F46: 護岸型式TYPEⅢ 臨河側0K+563.95~0K+606.85 | G46: 42.9*鋼筋表49.43 | H46: =42.9*49.43 -> 2120.547
...

Sheet 下水道工程 (5)
A1: 臺北市政府工務局水利工程處
A2: 數量計算式
A3: 工程名稱：磺港溪再造C段護岸及步道整建工程(延壽橋至三合橋)
A4: 施工地點：北投磺港溪 | G4: 工程編號：111 070020302 038 02
A5: 項次 | B5: 項 目 及 說 明 | C5: 單位 | D5: 原契約數量 | E5: 變更後數量 | F5: 項目 | G5: 小計 | H5: 數量 | I5: 施作數量 | J5: 數量計算累計
A6: (五) | B6: 下水道工程
A7: 1.5.1 | B7: 結構用混凝土，預拌，140kgf/cm2 | C7: M3 | D7: 250 | F7: 三合橋右岸堤牆復原0K+277~0K+308 | G7: 長29.8*2.5*0.1 | H7: =29.8*2.5*0.1 -> 7.45 | J7: =H7+H8 -> 11.7
F8: 三合橋左岸堤牆復原 | G8: (4+5+8)*2.5*0.1 | H8: =(4+5+8)*2.5*0.1 -> 4.25
A13: 1.5.2 | B13: 結構用混凝土，預拌，210kgf/cm2 | C13: M3 | D13: 2474 | F13: 單孔箱涵BK+280~300 | G13: (300-280)**單孔箱涵數量計算1.8 | H13: =(300-280)*1.8 -> 36 | I13: =SUM(H14:H25)-H14-H18-H20-H21-H19-H22-H23-H25 -> 518.4 | J13: =SUM(H13:H25) -> 2593.7
F14: 單孔箱涵BK+300~320 | G14: (320-300)**單孔箱涵數量計算1.8 | H14: =(320-300)*1.8 -> 36
F15: 單孔箱涵BK+320~580 | G15: (580-320)*單孔箱涵數量計算1.8 | H15: =(580-320)*1.8 -> 468
F16: 單孔箱涵BK+580~608 | G16: (608-580)*單孔箱涵數量計算1.8 | H16: =(608-580)*1.8 -> 50.4
F17: 雙孔箱涵BK+280~300 | G17: (300-280)*雙孔箱涵數量計算1.8 | I17: 移至河川工程
F18: 雙孔箱涵BK+300~320 | G18: (320-300)*雙孔箱涵數量計算7.525 | H18: =(320-300)*7.525 -> 150.5
F19: 雙孔箱涵BK+320~340 | G19: (340-320)*雙孔箱涵數量計算7.525 | H19: =(340-320)*7.525 -> 150.5
F20: 變形雙孔箱涵BK+340~360 | G20: (360-340)*雙孔箱涵數量計算8.11 | H20: =(360-340)*8.11 -> 162.2
F21: 變形雙孔箱涵BK+360~420 | G21: (420-360)*雙孔箱涵數量計算8.11 | H21: =(420-360)*8.11 -> 486.6
F22: 雙孔箱涵BK+420~440 | G22: (440-420)*雙孔箱涵數量計算7.525 | H22: =(440-420)*7.525 -> 150.5
F23: 雙孔箱涵BK+440~560 | G23: (560-440)*雙孔箱涵數量計算7.525 | H23: =(560-440)*7.525 -> 903
F24: 雙孔箱涵BK+560~570 | G24: (570-560)*雙孔箱涵數量計算7.525 | I24: 移至河川工程
F25: 側流井 | G25: 底版(10.4+0.25+0.25)*(4.6+8.2+1.2+1.2)/2*0.45+牆身(10.4+0.25+0.25+4.6+8.2)*0.25*2+頂版(10.4+0.25+0.25)*(4.6+8.2)/2*0.45-2.6*3.6*0.45+立柱5*0.25*0.25*2+溢流牆11.5*0.35*0.1 | I25: 移至河川工程
A27: 1.5.3 | B27: 控制性低強度回填材料及澆置 | C27: M3 | D27: 1187 | F27: 0 | G27: 0 | H27: 0 | I27: 0 | J27: =SUM(H28:H33) -> 1256.15
F28: 三合橋A1橋台0k+280~360 (雙孔箱涵及橋台空隙) | G28: 詳道路回填計算396.2+橋台空隙(15*(3.52*1.29+1.29*11.83/2)) | H28: =396.2+(15*(3.52*1.29+1.29*11.83/2)) -> 578.76725
F29: 三合橋A2台電clsm回填 | G29: 9*5*0.4*1 | H29: =9*5*0.4*1 -> 18
F30: 0k+440~620 CLSM回填 | G30: 371.2 | H30: 371.2
F31: 0k+360~440 CLSM回填 | G31: 217.8 | H31: 217.8
F32: 600RCP澆置clsm | G32: 49.1*(0.3*0.88*2+1.2*0.4) | H32: =49.1*(0.3*0.88*2+1.4*0.4) -> 53.4208
F33: 300RCP澆置clsm | G33: 25.7*(0.3*0.5*2+0.9*0.4) | H33: =25.7*(0.3*0.5*2+0.9*0.4) -> 16.962
A35: 1.5.4 | B35: 結構用混凝土，泵送及澆注費 | C35: M3 | D35: 3911 | F35: 140kgf+210kgf+clsm | H35: =I13+I7+I27 -> 518.4 | I35: =H35 -> 518.4 | J35: =J27+J13+J7 -> 3861.55
F36: 140kgf+210kgf+clsm | I36: =I28+I14 -> 0
A38: 1.5.5 | B38: 清水模板，乙種 | C38: M2 | D38: 3820 | E38: 4730 | F38: 單孔箱涵BK+280~300 | G38: (300-280)**單孔箱涵數量計算3.6 | H38: =(300-280)*3.6 -> 72 | I38: =H40+H38+H41 -> 1384.8 | J38: =SUM(H38:H48) -> 5411.06
F39: 單孔箱涵BK+300~320 | G39: (320-300)**單孔箱涵數量計算3.6 | H39: =(320-300)*3.6 -> 72
F40: 單孔箱涵BK+320~608 | G40: (608-320)*單孔箱涵數量計算3.6 | H40: =(608-320)*3.6 -> 1036.8
F41: 雙孔箱涵BK+280~300 | G41: (300-280)*雙孔箱涵數量計算13.8 | H41: =(300-280)*13.8 -> 276
F42: 雙孔箱涵BK+300~320 | G42: (320-300)*雙孔箱涵數量計算13.8 | H42: =(320-300)*13.8 -> 276
F43: 雙孔箱涵BK+320~340 | G43: (340-320)*雙孔箱涵數量計算13.8 | H43: =(340-320)*13.8 -> 276
F44: 變形雙孔箱涵BK+340~360 | G44: (360-340)*雙孔箱涵數量計算14.5 | H44: =(360-340)*14.5 -> 290
F45: 變形雙孔箱涵BK+360~420 | G45: (420-360)*雙孔箱涵數量計算14.5 | H45: =(420-360)*14.5 -> 870
F46: 雙孔箱涵BK+420~440 | G46: (440-420)*雙孔箱涵數量計算13.8 | H46: =(440-420)*13.8 -> 276
F47: 雙孔箱涵BK+440~570 | G47: (570-440)*雙孔箱涵數量計算13.8 | H47: =(570-440)*13.8 -> 1794
...

Sheet 道路附屬工程 (6)
A1: 臺北市政府工務局水利工程處
A2: 數量計算式
A3: 工程名稱：磺港溪再造C段護岸及步道整建工程(延壽橋至三合橋)
A4: 施工地點：北投磺港溪 | G4: 工程編號：111 070020302 038 02
A5: 項次 | B5: 項 目 及 說 明 | C5: 單位 | D5: 原契約數量 | E5: 變更後數量 | F5: 項目 | G5: 小計 | H5: 數量 | I5: 施作數量 | J5: 數量計算累計 | K5: 113/8累計計價數量 | L5: 尚未計價
A6: (六) | B6: 道路附屬工程
A7: 1.6.1 | B7: 瀝青混凝土舖面，粗粒料9.5mm，黏度AC(1)-20 | C7: M3 | D7: 256 | F7: 三合橋便橋 | G7: 69.6*10*0.1 | H7: =69.6*10*0.1 -> 69.6 | I7: =H7 -> 69.6 | J7: =SUM(H7:H10) -> 380.675 | K7: 69.6
F8: 工區舖設道路面積(N0K+420~N0K+835.6-分隔島內-三合橋面板及進橋板 | G8: (6170.45-426.27)*0.05-5.5 | H8: =(6170.45-426.27)*0.05-5.5 -> 281.709 | I8: =H7+H9+H10 -> 98.966
F9: 三合橋第一次舖設 | G9: (A2-11*7.3+橋面板及進橋板10.5*9+A1-7*9)*0.05 | H9: =(11*7.3+10.5*9+7*9)*0.05 -> 11.89
F10: 三合橋路口第二次舖設(0k+020~045、0k+070~090) | G10: 0.05*(11.5*7.4+(20.9-(8.5+5.9)/2)*9.0+(8.5+5.9)/2*19.6) | H10: =0.05*(11.5*7.4+(20.9-(8.5+5.9)/2)*9+(8.5+5.9)/2*19.6) -> 17.476
F11: 磺港路西側道路通行、面層二次舖設(後擴項目) | G11: 300*4*0.1 | H11: =300*4*0.1 -> 120
A13: 1.6.2 | B13: 瀝青混凝土舖面，粗粒料19.0mm，黏度AC(1)-20 | C13: M3 | D13: 766 | F13: 0 | G13: 0 | H13: 0 | I13: =SUM(H13:H16)-H14 -> 56.447 | J13: =SUM(H13:H16) -> 917.2484 | K13: 0
F14: 工區舖設道路面積(N0K+420~N0K+835.6-分隔島內-三合橋面板及進橋板 | G14: (6170.45-426.27-((18.71+21.45)/2+進橋板9*5*2)*0.05)*0.15 | H14: =(6170.45-426.27-((18.71+21.45)/2+9*5*2)*0.05)*0.15 -> 860.8014
F15: 三合橋第一次舖設 | G15: (11*7.3+7*9)*0.15 | H15: =(11*7.3+7*9)*0.15 -> 21.495
F16: 三合橋第二次舖設(0k+020~045、0k+070~090) | G16: 0.10*(11.5*7.4+(20.9-(8.5+5.9)/2)*9.0+(8.5+5.9)/2*19.6) | H16: =0.1*(11.5*7.4+(20.9-(8.5+5.9)/2)*9+(8.5+5.9)/2*19.6) -> 34.952
A18: 1.6.3 | B18: 路基整理 | C18: M2 | D18: 5103 | F18: 道路AC舖設面積 | G18: 工區道路6067-分隔島539-橋面板及進橋板20.22/0.05 | H18: =6067-428-20.55/0.05 -> 5228 | K18: 0
A23: 1.6.4 | B23: 瀝青透層，中凝油溶瀝青，MC-70 | C23: M2 | D23: 5103 | F23: 三合橋便橋 | G23: 69.6*10 | H23: =69.6*10 -> 696 | I23: =H23 -> 696 | J23: =SUM(H23:H25) -> 6734.4 | K23: 696
F24: 三合橋橋面板及進橋板 | G24: (A2-11*7.3+橋面板及進橋板29*9++A1-7*9)*1 | H24: =(11*7.3+29*9+7*9)*1 -> 404.3 | I24: =H23+H24+H25 -> 6734.4
F25: 工區舖設道路面積(N0K+420~N0K+835.6-分隔島內-三合橋面板及進橋板 | G25: (6170.45-426.27)-110.08 | H25: =(6170.45-426.27)-110.08 -> 5634.1
F26: 磺港路西側道路通行、面層二次舖設(後擴項目) | G26: 300*4*0.05 | H26: =300*4*0.05 -> 60
A28: 1.6.5 | B28: 瀝青黏層，快凝油溶瀝青，RC-70 | C28: M2 | D28: 15307 | F28: 三合橋第一次舖設 | G28: (11*7.3+7*9)*3 | H28: =(11*7.3+7*9)*3 -> 429.9 | I28: =SUM(H28:H31)-H29 -> 2124.9 | J28: =SUM(H28:H31) -> 19027.2 | K28: 0
F29: 工區舖設道路面積(N0K+420~N0K+835.6-分隔島內-三合橋面板及進橋板 | G29: (6170.45-426.27-110.08)*3 | H29: =(6170.45-426.27-110.08)*3 -> 16902.3
F30: 三合橋便橋 | G30: 69.6*10*1 | H30: =69.6*10*1 -> 696
F31: 三合橋第二次舖設(0k+020~045、0k+070~090) | G31: (45-20+90-70)*(9-0.8-0.8)*3 | H31: =(45-20+90-70)*(9-0.8-0.8)*3 -> 999
A33: 1.6.6 | B33: 結構用混凝土，預拌，140kgf/cm2 | C33: M3 | D33: 24 | F33: 道路側溝 | G33: 總長556.6*0.8*0.05 | H33: =556.6*0.8*0.05 -> 22.264 | J33: =H33 -> 22.264 | K33: 0
A35: 1.6.7 | B35: 結構用混凝土，預拌，210kgf/cm2 | C35: M3 | D35: 237 | F35: 三合橋既有U溝更新 | G35: 17*0.8*1.0-0.4*0.4*1.0*3 | H35: =17*0.8*1-0.4*0.4*1*3 -> 13.12 | I35: =H35 -> 13.12 | J35: =SUM(H35:H38) -> 338.278 | K35: 0
F36: 道路側溝 | G36: 總長556.6*單位面積0.53 | H36: =556.6*0.53 -> 294.998
F37: 陰井 | G37: 29顆*1.04 | H37: =29*1.04 -> 30.16
A39: 1.6.8 | B39: 結構用混凝土，泵送及澆注費 | C39: M3 | D39: 261 | H39: =I35+I33 -> 13.12 | I39: =H39 -> 13.12 | J39: =J35+J33 -> 360.542 | K39: 0
A41: 1.6.9 | B41: 清水模板，丙種 | C41: M2 | D41: 745 | F41: 三合橋既有U溝更新 | G41: 0 | H41: 0 | I41: =H41 -> 0 | J41: =SUM(H41:H44) -> 971.5728 | K41: 0
F42: 道路側溝 | G42: 總長556.6*單位面積1.608 | H42: =556.6*1.608 -> 895.0128
F43: 陰井 | G43: 29顆*2.64 | H43: =29*2.64 -> 76.56
A45: 1.6.10 | B45: 普通模板，丙種 | C45: M2 | D45: 915 | F45: 三合橋既有U溝更新 | G45: 17*2*1.0 | H45: =17*2*1 -> 34 | I45: =H45 -> 34 | J45: =SUM(H45:H48) -> 1229.0677 | K45: 0
F46: 道路側溝 | G46: 總長556.6*單位面積1.9095 | H46: =556.6*1.9095 -> 1062.8277
F47: 陰井 | G47: 29顆*4.56 | H47: =29*4.56 -> 132.24
A49: 1.6.11 | B49: 鋼筋，SD280W | C49: KG | D49: 9227 | F49: 道路側溝 | G49: 總長556.6*單位重89.8 | H49: =556.6*89.8 -> 49982.68 | J49: =SUM(H49:H50) -> 52733.62 | K49: 0
F50: 陰井 | G50: 29顆*94.86 | H50: =29*94.86 -> 2750.94
A52: 1.6.12 | B52: 鋼筋，植筋，D10mm，鑽孔(含空氣槍清孔)及化學藥劑 | C52: 孔 | D52: 189 | K52: 0
A54: 1.6.13 | B54: 鍍鋅格柵蓋板，(框53.6cm，蓋45cm)，細目型 | C54: 組 | D54: 118 | F54: 118 | G54: 118 | H54: =G54 -> 118 | K54: 0
A56: 1.6.14 | B56: 鍍鋅格柵板及框座，止滑花紋加工，含搬運安裝 | C56: KG | D56: 2773 | F56: 118座 | G56: 118*規格表(16+27.9) | H56: =118*(16+27.9) -> 5180.2 | J56: =H56 -> 5180.2 | K56: 0
...

Sheet 植栽工程 (8)
A1: 臺北市政府工務局水利工程處
A2: 數量計算式
A3: 工程名稱：磺港溪再造C段護岸及步道整建工程(延壽橋至三合橋)
A4: 施工地點：北投磺港溪 | G4: 工程編號：111 070020302 038 02
A5: 項次 | B5: 項 目 及 說 明 | C5: 單位 | D5: 原契約數量 | E5: 變更後數量 | F5: 項目 | G5: 小計 | H5: 數量 | I5: 施作數量 | J5: 數量計算累計 | K5: 113/8累計計價數量 | L5: 尚未計價
A6: (七) | B6: 道路附屬工程
A7: 1.7.1 | B7: 植栽，客土，砂質壤土 | C7: C.M3 | D7: 2596.7 | F7: 灌木 | G7: (606.5+39.6+83.2+130.9+84.3)*0.5 | H7: =(606.5+39.6+83.2+130.9+84.3)*0.5 -> 472.25 | K7: 0
F8: 草皮 | G8: (1488.5+138.3+7062.4)*0.3 | H8: =(1488.5+138.3+7062.4)*0.3 -> 2606.76
A10: 1.7.2 | B10: 植栽，透氣管，HDPE | C10: 支 | D10: 126 | F10: 喬木126 | G10: 126 | K10: 0
A12: 1.7.3 | B12: 移植，喬木類移植，5≦米高直徑<10cm | C12: 株 | D12: 12 | F12: 詳樹木清冊 | G12: 11 | H12: =G12 -> 11 | I12: =H12 -> 11 | K12: 0 | L12: =I12-K12 -> 11
A14: 1.7.4 | B14: 移植，喬木類移植，10cm≦米高直徑＜15cm | C14: 株 | D14: 18 | F14: 詳樹木清冊 | G14: 12 | H14: =G14 -> 12 | I14: =H14 -> 12 | K14: 5 | L14: =I14-K14 -> 7
A16: 1.7.5 | B16: 移植，喬木類移植，15cm≦米高直徑＜20cm | C16: 株 | D16: 5 | F16: 詳樹木清冊 | G16: 4 | H16: =G16 -> 4 | I16: =H16 -> 4 | K16: 5 | L16: =I16-K16 -> -1
A18: 1.7.6 | B18: 移植，喬木類移植，20cm≦米高直徑＜25cm | C18: 株 | D18: 5 | F18: 詳樹木清冊 | G18: 3 | H18: =G18 -> 3 | I18: =H18 -> 3 | K18: 5 | L18: =I18-K18 -> -2
A20: 1.7.7 | B20: 移植，喬木類移植，25cm≦米高直徑＜30cm | C20: 株 | D20: 2 | F20: 詳樹木清冊 | G20: 1 | H20: =G20 -> 1 | I20: =H20 -> 1 | K20: 2 | L20: =I20-K20 -> -1
A22: 1.7.8 | B22: 移植，喬木類移植，30cm≦米高直徑＜35cm | C22: 株 | D22: 6 | F22: 詳樹木清冊 | G22: 1 | H22: =G22 -> 1 | I22: =H22 -> 1 | K22: 6 | L22: =I22-K22 -> -5
A24: 1.7.9 | B24: 移植，喬木類移植，40cm≦米高直徑＜45cm | C24: 株 | D24: 3 | F24: 詳樹木清冊 | G24: 2 | H24: =G24 -> 2 | I24: =H24 -> 2 | K24: 3 | L24: =I24-K24 -> -1
A26: 1.7.10 | B26: 移植，喬木類移植，45cm≦米高直徑＜50cm | C26: 株 | D26: 2 | F26: 詳樹木清冊 | G26: 1 | H26: =G26 -> 1 | I26: =H26 -> 1 | K26: 2 | L26: =I26-K26 -> -1
A28: 1.7.11 | B28: 移植，喬木類移植，60cm≦米高直徑＜65cm | C28: 株 | D28: 3 | F28: 詳樹木清冊 | G28: 3 | H28: =G28 -> 3 | I28: =H28 -> 3 | K28: 3 | L28: =I28-K28 -> 0
A30: 1.7.12 | B30: 移植，喬木類移植，65cm≦米高直徑＜70cm | C30: 株 | D30: 3 | F30: 詳樹木清冊 | G30: 1 | H30: =G30 -> 1 | I30: =H30 -> 1 | K30: 3 | L30: =I30-K30 -> -2
I31: =SUM(H31:H42)-H32-H35 -> 34
A32: 1.7.13 | B32: 移植，喬木類移植，70cm≦米高直徑＜75cm | C32: 株 | D32: 1 | F32: 詳樹木清冊 | G32: 0 | H32: =G32 -> 0 | I32: =H32 -> 0 | K32: 1 | L32: =I32-K32 -> -1
A34: 1.7.14 | B34: 植栽維護，喬木類，樹木修剪，E級 | C34: 株 | D34: 6 | F34: 詳樹木清冊 | G34: 6 | H34: =G34 -> 6 | I34: =H34 -> 6 | K34: 0 | L34: =I34-K34 -> 6
A36: 1.7.15 | B36: 植栽維護，喬木類，枯木移除(喬木類)，10cm≦米高直徑＜20cm | C36: 株 | D36: 3 | F36: 詳樹木清冊 | G36: 4 | H36: =G36 -> 4 | I36: =H36 -> 4 | K36: 3 | L36: =I36-K36 -> 1
A38: 1.7.16 | B38: 植栽維護，喬木類，枯木移除(喬木類)，20cm≦米高直徑＜30cm | C38: 株 | D38: 5 | F38: 詳樹木清冊 | G38: 7 | H38: =G38 -> 7 | I38: =H38 -> 7 | K38: 5 | L38: =I38-K38 -> 2
A40: 1.7.17 | B40: 植栽維護，喬木類，枯木移除(喬木類)，30cm≦米高直徑＜40cm | C40: 株 | D40: 7 | E40: 17 | F40: 詳樹木清冊 | G40: 14 | H40: =G40 -> 14 | I40: =H40 -> 14 | K40: 7 | L40: =I40-K40 -> 7
A42: 1.7.18 | B42: 植栽維護，喬木類，枯木移除(喬木類)，40cm≦米高直徑＜50cm | C42: 株 | D42: 3 | F42: 詳樹木清冊 | G42: 3 | H42: 3 | I42: =H42 -> 3 | K42: 3 | L42: =I42-K42 -> 0
A45: 1.7.19 | B45: 植栽維護，喬木類，枯木移除(喬木類)，50cm≦米高直徑＜60cm | C45: 株 | D45: 4 | F45: 詳樹木清冊 | G45: 4 | H45: =G45 -> 4 | I45: =SUM(H45:H53)-H46 -> 51.01 | K45: 4 | L45: =I45-K45 -> 47.01
A47: 1.7.20 | B47: 植栽維護，喬木類，枯木移除，70cm＜米高直徑≦80cm | C47: 株 | D47: 1 | F47: 詳樹木清冊 | G47: 0 | H47: =G47 -> 0 | I47: =H47 -> 0 | K47: 1 | L47: =I47-K47 -> -1
A49: 1.7.21 | B49: 植栽維護，喬木類，枯木移除，90㎝＜米高直徑 | C49: 株 | D49: 1 | F49: 詳樹木清冊 | G49: 0 | H49: =G49 -> 0 | I49: =H49 -> 0 | K49: 1 | L49: =I49-K49 -> -1
A51: 1.7.22 | B51: 施工圍籬，組合式活動，1.8m ≦高度＜ 2.1m | C51: M | D51: 47.01 | G51: 47.01 | H51: =G51 -> 47.01 | I51: =H51 -> 47.01 | K51: 47.01 | L51: =I51-K51 -> 0
A54: 1.7.23 | B54: 產品，植栽，包覆材料，草繩及保護墊片，三支組 | C54: 組 | D54: 63 | G54: 63 | H54: =G54 -> 63 | I54: =H54 -> 63 | K54: 63 | L54: =I54-K54 -> 0
A56: 1.7.24 | B56: 產品，植栽，包覆材料，麻布袋，L=90~120cm，W=60~90cm | C56: 個 | D56: 315 | G56: 315 | H56: =G56 -> 315 | I56: =H56 -> 315 | K56: 315 | L56: =I56-K56 -> 0
A58: 1.7.25 | B58: 產品，平面式塑膠警示帶，聚氯乙烯(PVC)，寬度=200mm | C58: M | D58: 1200 | G58: 1200 | K58: 0
A60: 1.7.26 | B60: 產品，防水毯 | C60: M2 | D60: 30.85 | G60: 30.85 | H60: =G60 -> 30.85 | I60: =H60 -> 30.85 | K60: 30.85 | L60: =I60-K60 -> 0
A62: 1.7.27 | B62: 圍水，砂包堆置 | C62: M3 | D62: 3.7 | G62: 3.7 | H62: =G62 -> 3.7 | I62: =H62 -> 3.7 | K62: 3.7 | L62: =I62-K62 -> 0
A64: 1.7.28 | B64: 樹木生長監控 | C64: 式 | D64: 1 | G64: 1 | K64: 0
A65: 1.7.29 | B65: 植栽，鬆土(空氣挖掘機) | C65: M2 | D65: 1448.32 | G65: 1448.32 | K65: 0
A66: 1.7.30 | B66: 烏心石，450 ≦ 樹高 < 500㎝，220≦樹幅＜240cm，14 ≦ 米高直徑 < 16㎝ | C66: 株 | D66: 42 | G66: 42 | J66: =G66 -> 42 | K66: 0
A67: 1.7.31 | B67: 水茄苳，300 ≦ 樹高 < 350㎝，200≦樹幅＜250cm，8 ≦ 米高直徑 < 10㎝ | C67: 株 | D67: 19 | G67: 19 | J67: =G67 -> 19 | K67: 0
A68: 1.7.32 | B68: 光蠟樹，450 ≦ 樹高 < 500㎝，220≦樹幅＜240cm，14 ≦ 米高直徑 < 16㎝ | C68: 株 | D68: 8 | G68: 8 | J68: =G68 -> 8 | K68: 0
...

Sheet 臨時動員及圍排水設施費 9)
A1: 臺北市政府工務局水利工程處
A2: 數量計算式
A3: 工程名稱：磺港溪再造C段護岸及步道整建工程(延壽橋至三合橋)
A4: 施工地點：北投磺港溪 | G4: 工程編號：111 070020302 038 02
A5: 項次 | B5: 項 目 及 說 明 | C5: 單位 | D5: 原契約數量 | E5: 變更後數量 | F5: 項目 | G5: 小計 | H5: 數量 | I5: 施作數量 | J5: 數量計算累計 | K5: 113/8累計計價數量 | L5: 尚未計價
A6: (九) | B6: 臨時動員及圍排水設施費
A8: 1 | B8: 臨時擋土樁設施，鋼軌樁 50kg/m | C8: M | D8: 1088 | E8: 975 | F8: 共月橋樹木保護鋼軌樁：長6M*20支 | G8: 1*6*20 | H8: =120 -> 120 | I8: =SUM(H8:H13) -> 2893 | J8: =SUM(H8:H13) -> 2893 | K8: 360 | L8: =I8-K8 -> 2533
F9: 三合橋下地梁長6m*42支 | G9: 1*6*42 | H9: =1*6*42 -> 252
F10: 低水護岸坡趾基礎擋土樁設施 | G10: 1*6*276 | H10: =1*6*276 -> 1656
F11: 三合橋衛工幹管明挖保護 | G11: 1*9*13 | H11: =1*9*13 -> 117
F12: RCP過路管埋設 | G12: (49.1+25.7)*2*5 | H12: =(49.1+25.7)*2*5 -> 748
A15: 2 | B15: 臨時擋土樁設施，鋼軌樁 50kg/m(含運費)，打拔 | C15: M | D15: 1088 | E15: 975 | F15: 共月橋樹木保護鋼軌樁：長6M*20支 | G15: 1*6*20 | H15: =120 -> 120 | I15: =SUM(H15:H19) -> 2893 | J15: =SUM(H15:H20) -> 2893 | K15: 360 | L15: =I15-K15 -> 2533
F16: 三合橋下地梁長6m*42支 | G16: 1*6*42 | H16: =1*6*42 -> 252
F17: 低水護岸坡趾基礎擋土樁設施 | G17: 1*6*276 | H17: =1*6*276 -> 1656
F18: 三合橋衛工幹管明挖保護 | G18: 1*9*13 | H18: =1*9*13 -> 117
F19: RCP過路管埋設 | G19: (49.1+25.7)*2*5 | H19: =(49.1+25.7)*2*5 -> 748
A22: 3 | B22: 臨時通道用鋼板，厚15mm | C22: M2/月 | D22: 6984 | E22: 8744 | F22: 工區通道 | G22: L(649.2-300)*W2.5*3(左右岸及河道)*3個月 | H22: =(649.2-300)*2.5*3*3 -> 7857 | I22: =SUM(H22:H26) -> 9795.5 | J22: =SUM(H22:H26) -> 9795.5 | K22: 7744 | L22: =I22-K22 -> 2051.5
F23: RCP過路管埋設 | G23: (49.1+25.7)*2.5*2 | H23: =(49.1+25.7)*2.5*2 -> 374
F24: 暫置區鐵板 | G24: 852 | H24: 852
F25: 低水護岸坡趾基礎擋土樁設施 | G25: 285*2.5 | H25: =285*2.5 -> 712.5
A27: 4 | B27: 施工期間動復員費(含颱風、暴雨或機關指定之動員及設施設備費用) | C27: 式 | D27: 1 | H27: 1 | I27: 1 | K27: 1 | L27: =I27-K27 -> 0
A29: 5 | B29: 臨時設施，排水設備，引擎抽水機，D=10cm，租金 | C29: 時 | D29: 1 | E29: 2480 | F29: 詳日報表 | G29: 1164 | H29: =G29 -> 1164 | I29: =H29 -> 1164 | J29: =SUM(H29:H33) -> 3149 | K29: 1164 | L29: =I29-K29 -> 0
F30: 9/23 大雨抽水 | G30: 40*8 | H30: =40*8 -> 320 | I30: =SUM(H29:H32) -> 1996
F31: 山陀兒颱風抽水 | G31: 4*8*8 | H31: =4*8*8 -> 256
F32: 康芮颱風抽水 | G32: 4*8*8 | H32: =4*8*8 -> 256
F33: 豪大雨抽水 | G33: 1153 | H33: 1153
A35: 6 | B35: 圍水，砂包堆置 | C35: M3 | D35: 1 | E35: 291 | F35: PC樁圍水 | G35: 長70m*3包 | H35: =70*3 -> 210 | I35: =H35 -> 210 | J35: =SUM(H35:H42) -> 554 | K35: 251 | L35: =I35-K35 -> -41
F36: 三合橋圍水(基礎施作) | G36: 河道側長30m*2包+既有箱涵20*2包 | H36: =30*2+20*2 -> 100
F37: 三合橋圍水(固床工施作) | G37: 長30m*2包 | H37: =30*2 -> 60
F38: 側流井圍水(上游砌石施作) | G38: 長28m*2包 | H38: =28*2 -> 56
F39: 側流井圍水(砌石分段施作) | G39: 長22m*2包 | H39: =23*2 -> 46
F40: 共月橋P1P2圍水 | G40: 長10m*2包 | H40: =10*2 -> 20
F41: 新做擋牆圍水 | G41: 31M*2包 | H41: =31*2 -> 62
A44: 7 | B44: 臨時河道圍水設施，鋼板樁，L=13cm，(單邊水平長度，未含擋土支撐系統) | C44: M | D44: 0 | E44: 130 | F44: 三合橋鋼板樁(12m)+共月橋鋼板樁(25m)+延壽橋鋼板樁擋水(25m)*2雙邊 | G44: (12+25+25)*2 | H44: =(12+25+25)*2 -> 124 | I44: =H44+H45 -> 138 | J44: =H44+H45 -> 138 | K44: 74 | L44: =I44-K44 -> 64
F45: 共月橋P5(6M)+三合橋(8M*2) | G45: 14 | H45: 14 | I45: =H44+H45 -> 138
F84: 三合橋下衛工砌石舖面
H86: 152.4 | I86: =SUM(H86:H95)-H87-H90 -> 179.066
H87: =172.33*20 -> 3446.6
I89: =SUM(H89:H91) -> 0
F92: 共月橋 | G92: (3.5+1.92)*2*1.15+3.5*1.7*2+1*0.5*4+0.5*0.3*2 | H92: =(3.5+1.92)*2*1.15+3.5*1.7*2+1*0.5*4+0.5*0.3*2 -> 26.666
...

Sheet 蜂巢隔網計算
A1: 磺港路土方石計算
A2: 里程 | B2: 蜂巢隔網長度 | C2: 蜂巢隔網面積(m2) | D2: 客土包數量 (每1m2 10包客土包) | E2: 低水護岸底層客土包 2包 | F2: Q5頂層客土包 2包 | G2: 備註
A3: 280 | B3: 0
A4: 300 | B4: 5.41 | C4: =B4*10 -> 54.1 | D4: =(A4-A3)*10 -> 200 | E4: =ROUND((A4-A3)/0.3*2,0) -> 133 | F4: =ROUND((A4-A3)*2/0.3,0) -> 133 | G4: 砌石邊坡
A5: 320 | B5: 0 | G5: 砌石邊坡
A6: 340 | B6: 9.22 | C6: =B6*20 -> 184.4 | D6: =(A6-A5)*10 -> 200 | E6: =ROUND((A6-A5)/0.3*2,0) -> 133 | F6: =ROUND((A6-A5)*2/0.3,0) -> 133
A7: 360 | B7: 6.5 | C7: =B7*20 -> 130 | D7: =(A7-A6)*10 -> 200 | E7: =ROUND((A7-A6)/0.3*2,0) -> 133 | F7: =ROUND((A7-A6)*2/0.3,0) -> 133
A8: 380 | B8: 5.5 | C8: =B8*20 -> 110 | D8: =(A8-A7)*10 -> 200 | E8: =ROUND((A8-A7)/0.3*2,0) -> 133 | F8: =ROUND((A8-A7)*2/0.3,0) -> 133
A9: 400 | B9: 5.28 | C9: =B9*20 -> 105.6 | D9: =(A9-A8)*10 -> 200 | E9: =ROUND((A9-A8)/0.3*2,0) -> 133 | F9: =ROUND((A9-A8)*2/0.3,0) -> 133
A10: 420 | B10: 4.08 | C10: =B10*20 -> 81.6 | D10: =(A10-A9)*10 -> 200 | E10: =ROUND((A10-A9)/0.3*2,0) -> 133 | F10: =ROUND((A10-A9)*2/0.3,0) -> 133
A11: 440 | B11: 4.99 | C11: =B11*20 -> 99.8 | D11: =(A11-A10)*10 -> 200 | E11: =ROUND((A11-A10)/0.3*2,0) -> 133 | F11: =ROUND((A11-A10)*2/0.3,0) -> 133
A12: 460 | B12: 5.84 | C12: =B12*20 -> 116.8 | D12: =(A12-A11)*10 -> 200 | E12: =ROUND((A12-A11)/0.3*2,0) -> 133 | F12: =ROUND((A12-A11)*2/0.3,0) -> 133
A13: 480 | B13: 8.4 | C13: =B13*20 -> 168 | D13: =(A13-A12)*10 -> 200 | E13: =ROUND((A13-A12)/0.3*2,0) -> 133 | F13: =ROUND((A13-A12)*2/0.3,0) -> 133
A14: 500 | B14: 3.54 | C14: =B14*20 -> 70.8 | D14: =(A14-A13)*10 -> 200 | E14: =ROUND((A14-A13)/0.3*2,0) -> 133 | F14: =ROUND((A14-A13)*2/0.3,0) -> 133
A15: 520 | B15: 3.38 | C15: =B15*20 -> 67.6 | D15: =(A15-A14)*10 -> 200 | E15: =ROUND((A15-A14)/0.3*2,0) -> 133 | F15: =ROUND((A15-A14)*2/0.3,0) -> 133
A16: 540 | B16: 7.03 | C16: =B16*20 -> 140.6 | D16: =(A16-A15)*10 -> 200 | E16: =ROUND((A16-A15)/0.3*2,0) -> 133 | F16: =ROUND((A16-A15)*2/0.3,0) -> 133
A17: 560 | B17: 6.08 | C17: =B17*20 -> 121.6 | D17: =(A17-A16)*10 -> 200 | E17: =ROUND((A17-A16)/0.3*2,0) -> 133 | F17: =ROUND((A17-A16)*2/0.3,0) -> 133
... A20: 620 | B20: 5.25 | C20: =B20*20 -> 105 | D20: =(A20-A19)*10 -> 200 | E20: =ROUND((A20-A19)/0.3*2,0) -> 133 | F20: =ROUND((A20-A19)*2/0.3,0) -> 133
A21: 640 | B21: 0 | E21: =ROUND((A21-A20)/0.3*2,0) -> 133 | F21: =ROUND((A21-A20)*2/0.3,0) -> 133
A22: 649.2 | B22: 0 | E22: =ROUND((A22-A21)/0.3*2,0) -> 61 | F22: =ROUND((A22-A21)*2/0.3,0) -> 61
A24: 蜂巢隔網小計 | C24: =SUM(C3:C23) -> 1795.5 | D24: =SUM(D4:D23) -> 3200 | E24: =SUM(E4:E23) -> 2322 | F24: =SUM(F4:F23) -> 2322

Sheet 整備工程-表土清除
