Workbook
Name _290_2_0.15_0.2_12_5_0.15_0.2: 大宗資材!#REF!
Name _290_2_0.15_0.2_12_5_0.15_0.2: '數量計算(FOR4變)'!$G$9
Name _290_2_0.15_0.2_12_5_0.15_0.2: '數量計算(勇哥)'!$G$9
Name 鋼筋資料: 鋼筋!$AD$4:$AM$13

Sheet 估驗單
A1: 臺北市政府工務局水利工程處
A2: 變更項目對照詳細表
A3: 工程名稱：磺港溪再造C段護岸及步道整建工程(三合橋至奇岩抽水站) | O3: 估驗日期： | P3: 45596
A4: 項次 | B4: 項目說明 | C4: 單位 | D4: 原契約 數量 | E4: 3 變 後 核定數量 | F4: 4 變 後 數量 | G4: 應做數量 | H4: 追加數量 | I4: 追加金額 | J4: 追減數量 | K4: 追減金額 | L4: 估驗 單價 | M4: 本 次 估驗數量 | N4: 本次止累計 估驗數量 | O4: 本 次 估驗金額 | P4: 本次止累計 估驗金額 | Q4: 備 註
A5: 壹 | B5: 發包工程費 | C5: 式 | D5: 1 | L5: 304975279 | M5: 1 | N5: 1 | O5: 7397700 | P5: 191886300
A6: 一 | B6: 工程費 | C6: 式 | D6: 1 | L6: 2.3286809e+08 | M6: 1 | N6: 1 | O6: 5673978.8 | P6: 1.4020001e+08
A7: (一) | B7: 整備工程 | C7: 式 | D7: 1 | L7: 61233816 | M7: 1 | N7: 1 | O7: 927832.41 | P7: 44630848
A8: 1 | B8: 機械拆除，瀝青混凝土，未含運費 | C8: M3 | D8: 720.24 | F8: 720.24 | L8: 193.11 | M8: 18.75 | N8: 148.93 | O8: 3620.81 | P8: 28759.87
A9: 2 | B9: 機械拆除，鋼筋混凝土，未含運費 | C9: M3 | D9: 4813.44 | F9: 4813.44 | L9: 1046.16 | M9: 0 | N9: 4091.17 | O9: 0 | P9: 4280018.4
A10: 3 | B10: 盤踞切割 | C10: M | D10: 1743 | F10: 1743 | L10: 6199.66 | M10: 0 | N10: 1741.3 | O10: 0 | P10: 10795468
A11: 4 | B11: 基地及路幅開挖，未含運費，(機械挖，0.7～0.79m3開挖機) | C11: B.M3 | D11: 26370 | E11: 28009.56 | F11: 28009.56 | L11: 48.28 | M11: 75 | N11: 26684 | O11: 3621 | P11: 1288303.5
A12: 5 | B12: 瀝青混凝土面層刨除，刨除料運費 | C12: M3 | D12: 4726.67 | F12: 4726.67 | L12: 599.71 | M12: 0 | N12: 569.4 | O12: 0 | P12: 341474.87
A13: 6 | B13: 利用填方，含夯實 | C13: M3 | D13: 13120 | F13: 13120 | L13: 104.64 | M13: 864 | N13: 8670.22 | O13: 90408.96 | P13: 907251.82
A14: 7 | B14: 餘方遠運處理(台北港) | C14: B.M3 | D14: 13251 | F14: 13251 | L14: 1027.37 | M14: 156 | N14: 10560 | O14: 160269.72 | P14: 10849027
A15: 8 | B15: 餘方自行處理(房屋廢方，含水土保持) | C15: M3 | D15: 4601.44 | F15: 4601.44 | L15: 1084.98 | M15: 0 | N15: 0 | O15: 0 | P15: 0
A16: 9 | B16: 瀝青混凝土面層刨除，厚5cm，刨除機1.2m寬，含瀝青鋪面打毛(未含運費) | C16: M2 | D16: 2588.5 | F16: 2588.5 | L16: 30.45 | M16: 0 | N16: 0 | O16: 0 | P16: 0
A17: 10 | B17: 瀝青混凝土面層刨除，厚10cm，刨除機2.2m寬，未含運費 | C17: M2 | D17: 9177 | F17: 9177 | L17: 28.48 | M17: 0 | N17: 4745 | O17: 0 | P17: 135137.6
A18: 11 | B18: 切割瀝青混凝土或無筋混凝土，5cm≦切割深度＜10cm | C18: M | D18: 162.5 | F18: 162.5 | L18: 65.4 | M18: 0 | N18: 52.1 | O18: 0 | P18: 3407.34
A19: 12 | B19: 清除及掘除，雜草雜木，含垃圾撿除，人工割 | C19: M2 | D19: 5217.7 | F19: 5217.7 | L19: 20.19 | M19: 0 | N19: 3717 | O19: 0 | P19: 75046.23
A20: 13 | B20: 垃圾及廢棄物(以體積計)清運 | C20: M3 | D20: 782.66 | F20: 782.66 | L20: 2286.68 | M20: 0 | N20: 108 | O20: 0 | P20: 246961.44
A21: 14 | B21: 節塊吊放 | C21: 次 | D21: 425 | F21: 425 | L21: 521.15 | M21: 0 | N21: 425 | O21: 0 | P21: 221488.75
A22: 15 | B22: 機械拆除，工地雜項拆除清理，欄杆，含運費 | C22: M | D22: 255.5 | F22: =G22 -> 314.3 | G22: ='數量計算(FOR4變)'!I66 -> 314.3 | H22: =G22-D22 -> 58.8 | I22: =ROUND(H22*L22,2) -> 17032.6 | L22: 289.67 | M22: 0 | N22: 255.5 | O22: 0 | P22: 74010.69
A23: 16 | B23: 土方運送(百齡抽水站) | C23: 趟 | D23: 2204 | F23: 2204 | L23: 3082.11 | M23: 72 | N23: 2107 | O23: 221911.92 | P23: 6494005.8
A24: 17 | B24: 既有路燈拆除繳回 | C24: 盞 | D24: 66 | F24: 66 | L24: 3311.26 | M24: 0 | N24: 65 | O24: 0 | P24: 215231.9
A25: 18 | B25: 座椅拆除繳回 | C25: 座 | D25: 18 | F25: 18 | L25: 1199.93 | M25: 0 | N25: 18 | O25: 0 | P25: 21598.74
A26: 19 | B26: 解說牌拆除 | C26: 座 | D26: 4 | F26: 4 | L26: 2999.84 | M26: 0 | N26: 4 | O26: 0 | P26: 11999.36
A27: 20 | B27: 自行車架拆除 | C27: 座 | D27: 20 | F27: 20 | L27: 2999.84 | M27: 0 | N27: 20 | O27: 0 | P27: 59996.8
A28: 21 | B28: 交通牌誌拆除 | C28: 座 | D28: 15 | F28: 15 | L28: 2999.84 | M28: 0 | N28: 15 | O28: 0 | P28: 44997.6
A29: 22 | B29: 既有水利設施拆除及運送 | C29: 式 | D29: 1 | F29: 1 | L29: 399978.19 | M29: 0 | N29: 1 | O29: 0 | P29: 399978.19 | Q29: (估驗比率約:100%)
A30: 23 | B30: 交通維持，道路管制人員，日間(06-22時)，義交 | C30: 時 | D30: 30800 | F30: 30800 | L30: 280 | M30: 1600 | N30: 21303.5 | O30: 448000 | P30: 5964980
A31: 24 | B31: 表土清除，堆置，及回填費，t=30cm | C31: M2 | D31: 0 | E31: 2150 | F31: 2150 | L31: 70.56 | M31: 0 | N31: 2150 | O31: 0 | P31: 151704
A32: 25 | B32: 餘土分類處理 | C32: 日 | D32: 0 | E32: 111 | F32: 111 | L32: 20000 | M32: 0 | N32: 101 | O32: 0 | P32: 2020000
A33: (二) | B33: 土建景觀工程 | C33: 式 | D33: 1 | L33: 30807124 | M33: 1 | N33: 1 | O33: 140646.04 | P33: 1083872.9
A34: 1 | B34: 構造物回填，回填及夯實(實際) | C34: C.M3 | D34: 1887.64 | F34: =D34 -> 1887.64 | L34: 320.72 | M34: 0 | N34: 0 | O34: 0 | P34: 0
A35: 2 | B35: 構造物回填，回填及夯實，人工夯實 | C35: C.M3 | D35: 402.21 | F35: =D35 -> 402.21 | L35: 346.06 | M35: 0 | N35: 0 | O35: 0 | P35: 0
A36: 3 | B36: 鋼筋，SD280W | C36: KG | D36: 18865.76 | F36: =D36 -> 18865.76 | L36: 36.4 | M36: 0 | N36: 5167.44 | O36: 0 | P36: 188094.82
A37: 4 | B37: 結構用混凝土，預拌，140kgf/cm2 | C37: M3 | D37: 107.91 | F37: =D37 -> 107.91 | L37: 3114.97 | M37: 0 | N37: 4.73 | O37: 0 | P37: 14733.81
A38: 5 | B38: 結構用混凝土，預拌，210kgf/cm2 | C38: M3 | D38: 564.01 | F38: =D38 -> 564.01 | L38: 3320.96 | M38: 0 | N38: 59.94 | O38: 0 | P38: 199058.34
A39: 6 | B39: 普通模板，丙種 | C39: M2 | D39: 1926.87 | F39: =D39 -> 1926.87 | L39: 533.61 | M39: 0 | N39: 374.32 | O39: 0 | P39: 199740.9
A40: 7 | B40: 清水模板，鋼模 | C40: M2 | D40: 301.33 | F40: =D40 -> 301.33 | L40: 1299.82 | M40: 0 | N40: 0 | O40: 0 | P40: 0
...

Sheet 契約
A1: 臺北市政府工務局水利工程處
A2: 詳 細 價 目 表
A4: 工程名稱：磺港溪再造C段護岸及步道整建工程(三合橋至奇岩抽水站)
A5: 施工地點：北投磺港溪 | F5: 工程編號：111 070020302 038 02
A6: 項次 | B6: 項 目 及 說 明 | C6: 單位 | D6: 數量 | E6: 單 價 | F6: 複 價 | G6: 備 註
A7: 壹 | B7: 發包工程費 | C7: 式 | D7: 1 | F7: 257600000
A8: 一 | B8: 工程費 | C8: 式 | D8: 1 | F8: 2.0448708e+08
A9: (一) | B9: 整備工程 | C9: 式 | D9: 1 | F9: 58782954
A10: 1.1.1 | B10: 機械拆除，瀝青混凝土，未含運費 | C10: M3 | D10: 720.24 | E10: 193.11 | F10: 139085.55 | G10: 0222010123 分析表1_x000D_
A11: 1.1.2 | B11: 機械拆除，鋼筋混凝土，未含運費 | C11: M3 | D11: 4813.44 | E11: 1046.16 | F11: 5035628.4 | G11: 0222010E23 分析表2_x000D_
A12: 1.1.3 | B12: 盤踞切割 | C12: M | D12: 1743 | E12: 6199.66 | F12: 10806007 | G12: 0222011101 #磺港路橋(奇岩抽水站旁)1533.9m、希冀橋208.6m
A13: 1.1.4 | B13: 基地及路幅開挖，未含運費，(機械挖，0.7～0.79m3開挖機) | C13: B.M3 | D13: 26370 | E13: 48.28 | F13: 1273143.6 | G13: 02321PWD05AB1 分析表3_x000D_
A14: 1.1.5 | B14: 瀝青混凝土面層刨除，刨除料運費 | C14: M3 | D14: 4726.67 | E14: 599.71 | F14: 2834631.3 | G14: 0296103003 分析表4_x000D_
A15: 1.1.6 | B15: 利用填方，含夯實 | C15: M3 | D15: 13120 | E15: 104.64 | F15: 1372876.8 | G15: 02931BDD101 分析表5_x000D_
A16: 1.1.7 | B16: 餘方遠運處理(台北港) | C16: B.M3 | D16: 13251 | E16: 1027.37 | F16: 13613680 | G16: 023235X46A 分析表6_x000D_ 僅含運費(運距約<20K)(土方管理費檢據核銷)
A17: 1.1.8 | B17: 餘方自行處理(房屋廢方，含水土保持) | C17: M3 | D17: 4601.44 | E17: 1084.98 | F17: 4992470.4 | G17: 0232340063a 分析表7_x000D_
A18: 1.1.9 | B18: 瀝青混凝土面層刨除，厚5cm，刨除機1.2m寬，含瀝青鋪面打毛(未含運費) | C18: M2 | D18: 2588.5 | E18: 30.45 | F18: 78819.83 | G18: 02961403321 分析表8_x000D_ #含瀝青鋪面打毛
A19: 1.1.10 | B19: 瀝青混凝土面層刨除，厚10cm，刨除機2.2m寬，未含運費 | C19: M2 | D19: 9177 | E19: 28.48 | F19: 261360.96 | G19: 0296190432 分析表9_x000D_
A20: 1.1.11 | B20: 切割瀝青混凝土或無筋混凝土，5cm≦切割深度＜10cm | C20: M | D20: 162.5 | E20: 65.4 | F20: 10627.5 | G20: 02220PWD00021 分析表10_x000D_
A21: 1.1.12 | B21: 清除及掘除，雜草雜木，含垃圾撿除，人工割 | C21: M2 | D21: 5217.7 | E21: 20.19 | F21: 105345.36 | G21: 0223109002 分析表11_x000D_
... A32: 1.1.23 | B32: 交通維持，道路管制人員，日間(06-22時)，義交 | C32: 時 | D32: 30800 | E32: 280 | F32: 8624000 | G32: L015566G01001 [人力工項不打折]
A33: (二) | B33: 土建景觀工程 | C33: 式 | D33: 1 | F33: 30807124
A34: 1.2.1 | B34: 構造物回填，回填及夯實(實際) | C34: C.M3 | D34: 1887.64 | E34: 320.72 | F34: 605403.9 | G34: 023174000A 分析表17_x000D_
A35: 1.2.2 | B35: 構造物回填，回填及夯實，人工夯實 | C35: C.M3 | D35: 402.21 | E35: 346.06 | F35: 139188.79 | G35: 0231740#M1 分析表18_x000D_
A36: 1.2.3 | B36: 鋼筋，SD280W | C36: KG | D36: 18865.76 | E36: 36.4 | F36: 686713.66 | G36: 0321040009z 分析表19_x000D_ 本項納入(鋼筋)物價指數調整
A37: 1.2.4 | B37: 結構用混凝土，預拌，140kgf/cm2 | C37: M3 | D37: 107.91 | E37: 3114.97 | F37: 336136.41 | G37: 0331023003 分析表20_x000D_
A38: 1.2.5 | B38: 結構用混凝土，預拌，210kgf/cm2 | C38: M3 | D38: 564.01 | E38: 3320.96 | F38: 1873054.6 | G38: 0331025003 分析表21_x000D_
A39: 1.2.6 | B39: 普通模板，丙種 | C39: M2 | D39: 1926.87 | E39: 533.61 | F39: 1028197.1 | G39: 0311011302z 分析表22_x000D_ U型構，集水井，排水箱涵等。本項納入(普通模板)物價指數調整
A40: 1.2.7 | B40: 清水模板，鋼模 | C40: M2 | D40: 301.33 | E40: 1299.82 | F40: 391674.76 | G40: 03110212A1a 分析表23_x000D_ 本項納入「金屬製品類」物價指數調整
A41: 1.2.8 | B41: 鍍鋅鋼料 | C41: KG | D41: 5991.34 | E41: 60 | F41: 359480.4 | G41: 05500R0009A 分析表24_x000D_ #本項納入「金屬製品類」物價指數調整
A42: 1.2.9 | B42: 金屬材料，鋼料，裁切加工銲製(工廠加工) | C42: KG | D42: 5991.34 | E42: 31.9 | F42: 191123.75 | G42: 050606B009
A43: 1.2.10 | B43: 結構用鋼材，銲接結構用軋鋼料，SM400B鋼構工程及製作、組立工程(含加勁板、續接板、螺絲、螺栓、螺帽等) | C43: KG | D43: 1180.03 | E43: 107.3 | F43: 126617.22 | G43: 0512540009A2 分析表25_x000D_ #本項納入「金屬製品類」物價指數調整
A44: 1.2.11 | B44: 透水磚紙模地坪 | C44: M2 | D44: 3879.21 | E44: 3092.69 | F44: 11997194 | G44: 0279400002 分析表26_x000D_
A45: 1.2.12 | B45: 梯形磚鋪面，149.5x(30,20)x8cmTH | C45: M2 | D45: 462.9 | E45: 3961.37 | F45: 1833718.2 | G45: 0278600342 分析表27_x000D_
... A118: 1.2.85 | B118: 雨水回收槽 | C118: 座 | D118: 2 | E118: 913306.18 | F118: 1826612.4 | G118: 0263121DWA 分析表99_x000D_ #
A119: (三) | B119: 橋梁工程 | C119: 式 | D119: 1 | F119: 40947246
A120: 1.3.1 | B120: 構造物回填，回填及夯實(實際) | C120: C.M3 | D120: 185.59 | E120: 320.72 | F120: 59522.42 | G120: 023174000A 分析表17_x000D_
A121: 1.3.2 | B121: 結構用混凝土，預拌，140kgf/cm2 | C121: M3 | D121: 26.33 | E121: 3114.97 | F121: 82017.16 | G121: 0331023003 分析表20_x000D_
A122: 1.3.3 | B122: 結構用混凝土，預拌，210kgf/cm2 | C122: M3 | D122: 36.86 | E122: 3320.96 | F122: 122410.59 | G122: 0331025003 分析表21_x000D_
A123: 1.3.4 | B123: 結構用混凝土，預拌，280kgf/cm2 | C123: M3 | D123: 654.83 | E123: 3643.53 | F123: 2385892.8 | G123: 0331027003 分析表100_x000D_
...

Sheet 數量計算(勇哥)
A1: 臺北市政府工務局水利工程處
A2: 數量計算書
A3: 工程名稱：磺港溪再造C段護岸及步道整建工程(三合橋至奇岩抽水站)
A4: 施工地點：北投磺港溪 | F4: 工程編號：111 070020302 038 02
A5: 項次 | B5: 項目及說明 | C5: 單位 | D5: 原契約數量 | E5: 變更後數量 | F5: 計算式 | H5: 113/7施作數量 | I5: 合計 | M5: 113/7累計計價數量 | N5: 尚未計價 | O5: 113/8數量=
A6: 壹 | B6: 發包工程費 | C6: 式 | D6: 1
A7: 一 | B7: 工程費 | C7: 式 | D7: 1
A8: (一) | B8: 整備工程 | C8: 式 | D8: 1
A9: 1.1.1 | B9: 機械拆除，瀝青混凝土，未含運費 | C9: M3 | D9: 720.24 | F9: 緣石邊及人孔處(河.LT000~290+RT000~060) | G9: =(290*2*0.15*0.2+12*5*0.15*0.2)+(53*2*0.14*0.2+3*4*0.15*0.2) | H9: =(290*2*0.15*0.2+12*5*0.15*0.2)+(53*2*0.15*0.2+3*4*0.14*0.2) -> 22.716 | I9: =SUM(H9:H13) -> 200.247 | M9: 123.7 | N9: =I9-M9 -> 76.547
F10: 既有磺港橋橋面 | G10: =27.2*10.5*0.25 | H10: =27.2*10.5*0.25 -> 71.4
F11: 既有磺港橋南側 | G11: =11.5*(7.5+4.5)/2*0.23 | H11: =11.5*(7.5+4.5)/2*0.23 -> 15.87
F12: 自行車道AC打除(圖說面積尚未檢核) | G12: (77.5+169.3+170.9+49.4)*0.15 | H12: =(77.5+169.3+170.9+49.4)*0.15 -> 70.065
F13: 抽水站旁 | G13: =10.8*(7.5+9.5)/2*0.22 | H13: =10.8*(7.5+9.5)/2*0.22 -> 20.196
A15: 1.1.2 | B15: 機械拆除，鋼筋混凝土，未含運費 | C15: M3 | D15: 4813.44 | F15: 路側RC護欄(河.LT000~290+RT000~060) | G15: =(1.2*0.5*8*39)+(1.2*0.5*8*7) | H15: =(1.2*0.5*8*39)+(1.2*0.5*8*7) -> 220.8 | I15: =SUM(H15:H34) -> 4091.1705 | M15: 4069.6 | N15: =I15-M15 -> 21.570509
F16: 磺港橋(橋面及護欄+I梁+橫隔樑+帽梁+中墩柱) | G16: ((27.2*10.3*0.3+0.3*1.1*27.2*2)+(13.2*1.25*0.6*7*2)+(6.8*1.25*0.5*7)+(((1.9+0.8)/2*1.2*7.8)+1.9*2.5*1.2)+((1.25*1.25*3.14*3.6))) | H16: =((27.2*10.3*0.3+0.3*1.1*27.2*2)+(13.2*1.25*0.6*7*2)+(6.8*1.25*0.5*7)+(((1.9+0.8)/2*1.2*7.8)+1.9*2.5*1.2)+((1.25*1.25*3.14*3.6))) -> 306.3485
F17: 橋台+基礎+進橋台 | G17: (10.3*1.8*4.2+10.3*1.8*2.8)*2+(10.3*2.8*1.8)*2+((60.65*(3.9+2.2)/2*0.55)+(10.3*3.9*0.6)) | H17: =(10.3*1.8*4.2+10.3*1.8*2.8)*2+(10.3*2.8*1.8)*2+((60.65*(3.9+2.2)/2*0.55)+(10.3*3.9*0.6)) -> 489.22638
F18: 既有橋北側堤牆(含基礎)+既有河道底(含新舊河道銜接段) | G18: ((3.75*(0.3+0.6)/2*63.7)+(5.5*0.85*63.7))+(26.8*7*0.6+18.5*7*0.35) | H18: =((3.75*(0.3+0.6)/2*63.7)+(5.5*0.85*63.7))+(26.8*7*0.6+18.5*7*0.35) -> 563.17625
F19: 人行橋+橋台+基礎+既有河道底+樓梯 | G19: ((19.3*0.52*0.8*4)+(19.3*7.2*0.3)+(6.8*2.2*0.8*2)+(9.5*3*0.8+9.5*1.8*0.3)+(17.8*0.55*2.8*2)) | H19: =((19.3*0.52*0.8*4)+(19.3*7.2*0.3)+(6.8*2.2*0.8*2)+(9.5*3*0.8+9.5*1.8*0.3)+(17.8*0.55*2.8*2)) -> 180.4932
F20: 既有人行道(路.S120~200+河.LT017~280+河.RT005~280含護欄柱) | G20: ((0.9*0.25*80)+(1.25*0.25*263)+(1.15*0.2*263+0.5*0.5*1.05*31)) | H20: =((0.9*0.25*80)+(1.25*0.25*263)+(1.15*0.2*263+0.5*0.5*1.05*31)) -> 168.815
F21: 既有台電(路N.河.LT017~280含手孔) | G21: ((1.1*0.8-(0.04*0.04*3.14*6))*263+(1.15*5)) | H21: =((1.1*0.8-(0.04*0.04*3.14*6))*263+(1.15*5)) -> 229.26213
F22: 既有箱涵+閘門平台 | G22: ((2.1*2.4)-(1.5*1.75))*25.7+(2.1*1.25*0.6) | H22: =((2.1*2.4)-(1.5*1.75))*25.7+(2.1*1.25*0.6) -> 63.6405
F23: 新舊河道銜接段既有堤牆 | G23: ((3.75*(0.3+0.6)/2*35.65)+(5.5*0.85*35.65)) | H23: =((3.75*(0.3+0.6)/2*35.65)+(5.5*0.85*35.65)) -> 226.82312
F24: 河.070處樓梯+既有牆 | G24: ((3.75*(0.3+0.6)/2*6.7)+(2.1*0.6*18.7)+(0.35*1.5*18.7)+(0.35*3.75*3.2)) | H24: =((3.75*(0.3+0.6)/2*6.7)+(2.1*0.6*18.7)+(0.35*1.5*18.7)+(0.35*3.75*3.2)) -> 48.88575
F25: 既有排水溝(含蓋板)(路.N130~420) | G25: (277.6*0.525) | H25: =(277.6*0.525) -> 145.74
F26: 既有管涵+集水井 | G26: (1.1*0.35*196.3)+((0.38*0.38*3.14-0.3*0.3*3.14)*196.3)+2.85*2 | H26: =(1.1*0.35*196.3)+((0.38*0.38*3.14-0.3*0.3*3.14)*196.3)+2.85*2 -> 114.80668
F27: 公園步道及鋪面(圖說面積尚未檢核) | G27: (401.1+1104.5+1276+169.3+767.7+52.1)*0.3 | H27: =(401.1+1104.5+1276+169.3+767.7+52.1)*0.3 -> 1131.21
F28: 自行車道基礎(圖說面積尚未檢核) | G28: (77.5+169.3+170.9+49.4)*0.25 | H28: =(77.5+169.3+170.9+49.4)*0.25 -> 116.775
F29: 綠帶槽緣石+石椅(尚未檢核) | G29: ((112.1+241.1+229.5+0+60.8+0)*0.033)+((3+8+5.7+2.9)*0.5*0.75) | H29: =((112.1+241.1+229.5+0+60.8+0)*0.033)+((3+8+5.7+2.9)*0.5*0.75) -> 28.5855
F30: 河.260~280處既有基礎+路燈基礎 | G30: (0.8*(0.75+0.35)/2*18.2)+(0.8*0.8*1.45*7) | H30: =(0.8*(0.75+0.35)/2*18.2)+(0.8*0.8*1.45*7) -> 14.504
F31: 單孔000~064(清江+2處過路堤牆+抽水井處) | G31: (0.25*1.65*39)+((3.5*(0.3+0.6)/2*5.6)+(2.1*0.6*2.3))+(6.2*5.3*0.35+2.1*2.2*0.6) | H31: =(0.25*1.65*39)+((3.5*(0.3+0.6)/2*5.6)+(2.1*0.6*2.3))+(6.2*5.3*0.35+2.1*2.2*0.6) -> 42.0785
A35: 1.1.3 | B35: 盤踞切割 | C35: M | D35: 1743 | F35: 磺港橋(橋面及護欄+I梁+橫隔樑+帽梁+墩柱) | G35: =(27.2*16+10.5*6)+(1.25*6*12*5)+(2.3*6*7*2)+(3.8*6+5.2*8)+(2.5*3.14*6) | H35: =(27.2*16+10.5*6)+(1.25*6*12*5)+(2.3*6*7*2)+(3.8*6+5.2*8)+(2.5*3.14*6) -> 1252.9 | I35: =SUM(H35:H37) -> 1747.3 | M35: 1741.3 | N35: =I35-M35 -> 6
F36: 人行橋(希冀橋)含下方基礎 | G36: =18*12+8.5*4+(1.1*6*12*3+0.8)+(3*2) | H36: =18*12+8.5*4+(1.1*6*12*3+0.8)+(3*2) -> 494.4
A38: 1.1.4 | B38: 基地及路幅開挖，未含運費，(機械挖，0.7～0.79m3開挖機) | C38: B.M3 | D38: 26370 | E38: 28009.56 | F38: 新設河道斷面計算(尚未檢核) | G38: 新設河道斷面計算 | H38: 26370 | I38: =SUM(H38:H41) -> 28009.56 | M38: 25080 | N38: =I38-M38 -> 2929.56
F39: 磺港橋及希冀橋橋台清障開挖+單孔過路段及清江公園 | G39: ((5*6*6.5*2)+(13*3.5*6.8)+(3.2*8.5*1.6))+((747.2+149.44)) | H39: =((5*6*6.5*2)+(13*3.5*6.8)+(3.2*8.5*1.6))+((747.2+149.44)) -> 1639.56
A42: 1.1.5 | B42: 瀝青混凝土面層刨除，刨除料運費 | C42: M3 | D42: 4726.67 | F42: 既有道路(路.S145~200+路.N140~420) | G42: (7.5*55*0.24)+(9.6*37*0.25)+(7.1*243*0.24) | H42: =(7.5*55*0.24)+(9.6*37*0.25)+(7.1*243*0.24) -> 601.872 | I42: =SUM(H42:H44) -> 601.872 | M42: 569.4 | N42: =I42-M42 -> 32.472
A45: 1.1.6 | B45: 利用填方，含夯實 | C45: M3 | D45: 13120 | F45: 磺港橋及希冀橋基樁區回填 | G45: (16.5*9.2*4.6+21.2*4.7*4.2)+(11.2*3.2*4.6)+(9.5*3.5*2.9) | H45: =(16.5*9.2*4.6+21.2*4.7*4.2)+(11.2*3.2*4.6)+(9.5*3.5*2.9) -> 1378.057 | I45: =SUM(H45:H51) -> 3967.777 | M45: 2172 | N45: =I45-M45 -> 1795.777
F46: 新設LT堤牆(L=52.3M)回填 | G46: (0.8*4.5*52.3)+(1.2*4.5*52.3) | H46: =(0.8*4.5*52.3)+(1.2*4.5*52.3) -> 470.7
F47: 砌石RT植栽槽回填(面積尚未檢核) | G47: 381.5*0.8 | H47: =381.5*0.8 -> 305.2
F48: 單孔箱涵過路段及清江公園 | G48: (0.8*1.9*2*23+3.4*2.7*23)+(0.8*2.1*2*41) | H48: =(0.8*1.9*2*23+3.4*2.7*23)+(0.8*2.1*2*41) -> 418.82
F49: 單孔箱涵064~300
...

Sheet 數量計算(FOR4變)
A1: 臺北市政府工務局水利工程處
A2: 數量計算書
A3: 工程名稱：磺港溪再造C段護岸及步道整建工程(三合橋至奇岩抽水站)
A4: 施工地點：北投磺港溪 | F4: 工程編號：111 070020302 038 02
A5: 項次 | B5: 項目及說明 | C5: 單位 | D5: 原契約數量 | E5: 變更後數量 | F5: 計算式 | H5: 數量小計 | I5: 實作數量合計 | J5: 應追加數量
A6: 壹 | B6: 發包工程費 | C6: 式 | D6: 1
A7: 一 | B7: 工程費 | C7: 式 | D7: 1
A8: (一) | B8: 整備工程 | C8: 式 | D8: 1
A9: 1.1.1 | B9: 機械拆除，瀝青混凝土，未含運費 | C9: M3 | D9: 720.24 | F9: 緣石邊及人孔處(河.LT000~290+RT000~060) | G9: =(290*2*0.15*0.2+12*5*0.15*0.2)+(53*2*0.14*0.2+3*4*0.15*0.2) | H9: =(290*2*0.15*0.2+12*5*0.15*0.2)+(53*2*0.15*0.2+3*4*0.14*0.2) -> 22.716 | I9: =SUM(H9:H13) -> 200.247 | J9: 尚未完成
F10: 既有磺港橋橋面 | G10: =27.2*10.5*0.25 | H10: =27.2*10.5*0.25 -> 71.4
F11: 既有磺港橋南側 | G11: =11.5*(7.5+4.5)/2*0.23 | H11: =11.5*(7.5+4.5)/2*0.23 -> 15.87
F12: 自行車道AC打除(圖說面積尚未檢核) | G12: (77.5+169.3+170.9+49.4)*0.15 | H12: =(77.5+169.3+170.9+49.4)*0.15 -> 70.065
F13: 抽水站旁 | G13: =10.8*(7.5+9.5)/2*0.22 | H13: =10.8*(7.5+9.5)/2*0.22 -> 20.196
A15: 1.1.2 | B15: 機械拆除，鋼筋混凝土，未含運費 | C15: M3 | D15: 4813.44 | F15: 路側RC護欄(河.LT000~290+RT000~060) | G15: =(1.2*0.5*8*39)+(1.2*0.5*8*7) | H15: =(1.2*0.5*8*39)+(1.2*0.5*8*7) -> 220.8 | I15: =SUM(H15:H31) -> 4091.1705 | J15: 尚未完成
F16: 磺港橋(橋面及護欄+I梁+橫隔樑+帽梁+中墩柱) | G16: ((27.2*10.3*0.3+0.3*1.1*27.2*2)+(13.2*1.25*0.6*7*2)+(6.8*1.25*0.5*7)+(((1.9+0.8)/2*1.2*7.8)+1.9*2.5*1.2)+((1.25*1.25*3.14*3.6))) | H16: =((27.2*10.3*0.3+0.3*1.1*27.2*2)+(13.2*1.25*0.6*7*2)+(6.8*1.25*0.5*7)+(((1.9+0.8)/2*1.2*7.8)+1.9*2.5*1.2)+((1.25*1.25*3.14*3.6))) -> 306.3485
F17: 橋台+基礎+進橋台 | G17: (10.3*1.8*4.2+10.3*1.8*2.8)*2+(10.3*2.8*1.8)*2+((60.65*(3.9+2.2)/2*0.55)+(10.3*3.9*0.6)) | H17: =(10.3*1.8*4.2+10.3*1.8*2.8)*2+(10.3*2.8*1.8)*2+((60.65*(3.9+2.2)/2*0.55)+(10.3*3.9*0.6)) -> 489.22638
F18: 既有橋北側堤牆(含基礎)+既有河道底(含新舊河道銜接段) | G18: ((3.75*(0.3+0.6)/2*63.7)+(5.5*0.85*63.7))+(26.8*7*0.6+18.5*7*0.35) | H18: =((3.75*(0.3+0.6)/2*63.7)+(5.5*0.85*63.7))+(26.8*7*0.6+18.5*7*0.35) -> 563.17625
F19: 人行橋+橋台+基礎+既有河道底+樓梯 | G19: ((19.3*0.52*0.8*4)+(19.3*7.2*0.3)+(6.8*2.2*0.8*2)+(9.5*3*0.8+9.5*1.8*0.3)+(17.8*0.55*2.8*2)) | H19: =((19.3*0.52*0.8*4)+(19.3*7.2*0.3)+(6.8*2.2*0.8*2)+(9.5*3*0.8+9.5*1.8*0.3)+(17.8*0.55*2.8*2)) -> 180.4932
F20: 既有人行道(路.S120~200+河.LT017~280+河.RT005~280含護欄柱) | G20: ((0.9*0.25*80)+(1.25*0.25*263)+(1.15*0.2*263+0.5*0.5*1.05*31)) | H20: =((0.9*0.25*80)+(1.25*0.25*263)+(1.15*0.2*263+0.5*0.5*1.05*31)) -> 168.815
F21: 既有台電(路N.河.LT017~280含手孔) | G21: ((1.1*0.8-(0.04*0.04*3.14*6))*263+(1.15*5)) | H21: =((1.1*0.8-(0.04*0.04*3.14*6))*263+(1.15*5)) -> 229.26213
F22: 既有箱涵+閘門平台 | G22: ((2.1*2.4)-(1.5*1.75))*25.7+(2.1*1.25*0.6) | H22: =((2.1*2.4)-(1.5*1.75))*25.7+(2.1*1.25*0.6) -> 63.6405
F23: 新舊河道銜接段既有堤牆 | G23: ((3.75*(0.3+0.6)/2*35.65)+(5.5*0.85*35.65)) | H23: =((3.75*(0.3+0.6)/2*35.65)+(5.5*0.85*35.65)) -> 226.82312
F24: 河.070處樓梯+既有牆 | G24: ((3.75*(0.3+0.6)/2*6.7)+(2.1*0.6*18.7)+(0.35*1.5*18.7)+(0.35*3.75*3.2)) | H24: =((3.75*(0.3+0.6)/2*6.7)+(2.1*0.6*18.7)+(0.35*1.5*18.7)+(0.35*3.75*3.2)) -> 48.88575
F25: 既有排水溝(含蓋板)(路.N130~420) | G25: (277.6*0.525) | H25: =(277.6*0.525) -> 145.74
F26: 既有管涵+集水井 | G26: (1.1*0.35*196.3)+((0.38*0.38*3.14-0.3*0.3*3.14)*196.3)+2.85*2 | H26: =(1.1*0.35*196.3)+((0.38*0.38*3.14-0.3*0.3*3.14)*196.3)+2.85*2 -> 114.80668
F27: 公園步道及鋪面(圖說面積尚未檢核) | G27: (401.1+1104.5+1276+169.3+767.7+52.1)*0.3 | H27: =(401.1+1104.5+1276+169.3+767.7+52.1)*0.3 -> 1131.21
F28: 自行車道基礎(圖說面積尚未檢核) | G28: (77.5+169.3+170.9+49.4)*0.25 | H28: =(77.5+169.3+170.9+49.4)*0.25 -> 116.775
F29: 綠帶槽緣石+石椅(尚未檢核) | G29: ((112.1+241.1+229.5+0+60.8+0)*0.033)+((3+8+5.7+2.9)*0.5*0.75) | H29: =((112.1+241.1+229.5+0+60.8+0)*0.033)+((3+8+5.7+2.9)*0.5*0.75) -> 28.5855
F30: 河.260~280處既有基礎+路燈基礎 | G30: (0.8*(0.75+0.35)/2*18.2)+(0.8*0.8*1.45*7) | H30: =(0.8*(0.75+0.35)/2*18.2)+(0.8*0.8*1.45*7) -> 14.504
F31: 單孔000~064(清江+2處過路堤牆+抽水井處) | G31: (0.25*1.65*39)+((3.5*(0.3+0.6)/2*5.6)+(2.1*0.6*2.3))+(6.2*5.3*0.35+2.1*2.2*0.6) | H31: =(0.25*1.65*39)+((3.5*(0.3+0.6)/2*5.6)+(2.1*0.6*2.3))+(6.2*5.3*0.35+2.1*2.2*0.6) -> 42.0785
A35: 1.1.3 | B35: 盤踞切割 | C35: M | D35: 1743 | F35: 磺港橋(橋面及護欄+I梁+橫隔樑+帽梁+墩柱) | G35: =(27.2*16+10.5*6)+(1.25*6*12*5)+(2.3*6*7*2)+(3.8*6+5.2*8)+(2.5*3.14*6) | H35: =(27.2*16+10.5*6)+(1.25*6*12*5)+(2.3*6*7*2)+(3.8*6+5.2*8)+(2.5*3.14*6) -> 1252.9 | I35: =H35+H36 -> 1747.3 | J35: =I35-D35 -> 4.3 | K35: X
F36: 人行橋(希冀橋)含下方基礎 | G36: =18*12+8.5*4+(1.1*6*12*3+0.8)+(3*2) | H36: =18*12+8.5*4+(1.1*6*12*3+0.8)+(3*2) -> 494.4
A38: 1.1.4 | B38: 基地及路幅開挖，未含運費，(機械挖，0.7～0.79m3開挖機) | C38: B.M3 | D38: 26370 | E38: 28009.56 | F38: 新設河道斷面計算(尚未檢核) | G38: 新設河道斷面計算 | H38: 26370 | I38: =H38+H39 -> 28009.56
F39: 磺港橋及希冀橋橋台清障開挖+單孔過路段及清江公園 | G39: ((5*6*6.5*2)+(13*3.5*6.8)+(3.2*8.5*1.6))+((747.2+149.44)) | H39: =((5*6*6.5*2)+(13*3.5*6.8)+(3.2*8.5*1.6))+((747.2+149.44)) -> 1639.56
A42: 1.1.5 | B42: 瀝青混凝土面層刨除，刨除料運費 | C42: M3 | D42: 4726.67 | F42: 既有道路(路.S145~200+路.N140~420) | G42: (7.5*55*0.24)+(9.6*37*0.25)+(7.1*243*0.24) | H42: =(7.5*55*0.24)+(9.6*37*0.25)+(7.1*243*0.24) -> 601.872 | I42: =H42+H43 -> 601.872 | J42: 尚未完成
A45: 1.1.6 | B45: 利用填方，含夯實 | C45: M3 | D45: 13120 | F45: 磺港橋及希冀橋基樁區回填 | G45: (16.5*9.2*4.6+21.2*4.7*4.2)+(11.2*3.2*4.6)+(9.5*3.5*2.9) | H45: =(16.5*9.2*4.6+21.2*4.7*4.2)+(11.2*3.2*4.6)+(9.5*3.5*2.9) -> 1378.057 | I45: =SUM(H45:H50) -> 6701.747 | J45: 尚未完成
F46: 新設LT堤牆(L=52.3M)回填 | G46: (0.8*4.5*52.3)+(1.2*4.5*52.3) | H46: =(0.8*4.5*52.3)+(1.2*4.5*52.3) -> 470.7
F47: 單孔箱涵過路段及清江公園 | G47: (0.8*1.9*2*23+3.4*2.7*23)+(0.8*2.1*2*41) | H47: =(0.8*1.9*2*23+3.4*2.7*23)+(0.8*2.1*2*41) -> 418.82
F48: 雙孔箱涵右側+左側0K+000-060 | G48: 3091.11+461.7 | H48: =3091.11+461.7 -> 3552.81
F49: 單、雙孔箱涵上方
...

Sheet 4變
C1: 臺北市政府工務局水利工程處
C2: 第4次變更項目對照詳細表
A3: 工程名稱：磺港溪再造C段護岸及步道整建工程(三合橋至奇岩抽水站) | K3: 日期： | L3: 45652
A4: 原契約分為 10 部分 本次變更 4 部分原有 393 項 | J4: 訂約總價 | L4: 257600000
A5: 前經 3 次變更設計，計新增 43 項，減少 3 項，變更 27 項，變更後合計 438 項 | J5: 前次變更後總價(綜簽) | L5: 308240521
A6: 本次變更設計，計新增 項，減少 項，變更 項，變更後合計 項 | J6: 本次變更後總價 | L6: =J9 -> 3.2668348e+08
A7: 項次 | B7: 項目名稱 | C7: 單位 | D7: 原 定 數 量 | E7: 變更後 數 量 | F7: 增 減 數 量 | G7: 契 約 單 價 | H7: 新 增 單 價 | I7: 原 訂 合 價 | J7: 變更後 合價 | K7: 追加 | L7: 追減 | M7: 備註 | O7: 變更依據 | P7: 數量計算式 | Q7: 變更原因
A9: 壹 | B9: 發包工程費 | C9: 式 | G9: =I9 -> 3.0824052e+08 | I9: =I10+I354+I380+I420+I424+I444+I464+I467+I468+I470 -> 3.0824052e+08 | J9: =J10+J354+J380+J420+J424+J444+J464+J467+J468+J470 -> 3.2668348e+08 | K9: =K10+K354+K380+K420+K424+K444+K464+K467+K468+K470 -> 22094340 | L9: =L10+L354+L380+L420+L424+L444+L464+L467+L468+L470 -> -3651377.6 | O9: =K9+L9 -> 18442962
A10: 一 | B10: 工程費 | C10: 式 | G10: =I10 -> 2.3286809e+08 | I10: =I11+I37+I126+I166+I195+I215+I232+I310+I344 -> 2.3286809e+08 | J10: =J11+J37+J126+J166+J195+J215+J232+J310+J344 -> 2.4792176e+08 | K10: =K11+K37+K126+K166+K195+K215+K232+K310+K344 -> 18705054 | L10: =L11+L37+L126+L166+L195+L215+L232+L310+L344 -> -3651377.6
A11: (一) | B11: 整備工程 | C11: 式 | G11: 61233816 | I11: =SUM(I12:I36) -> 61233816 | J11: =SUM(J12:J36) -> 61250848 | K11: =SUM(K12:K36) -> 17032.59 | L11: =SUM(L12:L36) -> 0
A12: 1 | B12: 機械拆除，瀝青混凝土，未含運費 | C12: M3 | D12: 720.24 | E12: =估驗單!F8 -> 720.24 | G12: 193.11 | I12: =ROUND(D12*G12,2) -> 139085.55 | J12: =ROUND(E12*G12,2) -> 139085.55 | K12: =J12-I12 -> 0 | L12: =I12-J12 -> 0
A13: 2 | B13: 機械拆除，鋼筋混凝土，未含運費 | C13: M3 | D13: 4813.44 | E13: =估驗單!F9 -> 4813.44 | G13: 1046.16 | I13: =ROUND(D13*G13,2) -> 5035628.4 | J13: =ROUND(E13*G13,2) -> 5035628.4 | K13: =J13-I13 -> 0 | L13: =I13-J13 -> 0
A14: 3 | B14: 盤踞切割 | C14: M | D14: 1743 | E14: =估驗單!F10 -> 1743 | G14: 6199.66 | I14: =ROUND(D14*G14,2) -> 10806007 | J14: =ROUND(E14*G14,2) -> 10806007 | K14: =J14-I14 -> 0 | L14: =I14-J14 -> 0 | M14: #磺港路橋(奇岩抽水站旁)1533.9m、希冀橋208.6m
A15: 4 | B15: 基地及路幅開挖，未含運費，(機械挖，0.7～0.79m3開挖機) | C15: B.M3 | D15: 28009.56 | E15: =估驗單!F11 -> 28009.56 | G15: 48.28 | I15: =ROUND(D15*G15,2) -> 1352301.6 | J15: =ROUND(E15*G15,2) -> 1352301.6 | K15: =J15-I15 -> 0 | L15: =I15-J15 -> 0 | O15: 112年12月12日 北市工水工字第1126067256號 | P15: 新設磺港橋及希冀橋橋台辦理既有基樁與新設基樁清障開挖+單孔過路段及清江公園 ((5*6*6.5*2)+(13*3.5*6.8)+(3.2*8.5*1.6))+((747.2+149.44)) | Q15: 機關/現場需求 (百齡)
A16: 5 | B16: 瀝青混凝土面層刨除，刨除料運費 | C16: M3 | D16: 4726.67 | E16: =估驗單!F12 -> 4726.67 | G16: 599.71 | I16: =ROUND(D16*G16,2) -> 2834631.3 | J16: =ROUND(E16*G16,2) -> 2834631.3 | K16: =J16-I16 -> 0 | L16: =I16-J16 -> 0
A17: 6 | B17: 利用填方，含夯實 | C17: M3 | D17: 13120 | E17: =估驗單!F13 -> 13120 | G17: 104.64 | I17: =ROUND(D17*G17,2) -> 1372876.8 | J17: =ROUND(E17*G17,2) -> 1372876.8 | K17: =J17-I17 -> 0 | L17: =I17-J17 -> 0
A18: 7 | B18: 餘方遠運處理(台北港) | C18: B.M3 | D18: 13251 | E18: =估驗單!F14 -> 13251 | G18: 1027.37 | I18: =ROUND(D18*G18,2) -> 13613680 | J18: =ROUND(E18*G18,2) -> 13613680 | K18: =J18-I18 -> 0 | L18: =I18-J18 -> 0 | M18: 僅含運費(運距約<20K)(土方管理費檢據核銷)
A19: 8 | B19: 餘方自行處理(房屋廢方，含水土保持) | C19: M3 | D19: 4601.44 | E19: =估驗單!F15 -> 4601.44 | G19: 1084.98 | I19: =ROUND(D19*G19,2) -> 4992470.4 | J19: =ROUND(E19*G19,2) -> 4992470.4 | K19: =J19-I19 -> 0 | L19: =I19-J19 -> 0
A20: 9 | B20: 瀝青混凝土面層刨除，厚5cm，刨除機1.2m寬，含瀝青鋪面打毛(未含運費) | C20: M2 | D20: 2588.5 | E20: =估驗單!F16 -> 2588.5 | G20: 30.45 | I20: =ROUND(D20*G20,2) -> 78819.83 | J20: =ROUND(E20*G20,2) -> 78819.83 | K20: =J20-I20 -> 0 | L20: =I20-J20 -> 0 | M20: #含瀝青鋪面打毛
A21: 10 | B21: 瀝青混凝土面層刨除，厚10cm，刨除機2.2m寬，未含運費 | C21: M2 | D21: 9177 | E21: =估驗單!F17 -> 9177 | G21: 28.48 | I21: =ROUND(D21*G21,2) -> 261360.96 | J21: =ROUND(E21*G21,2) -> 261360.96 | K21: =J21-I21 -> 0 | L21: =I21-J21 -> 0
A22: 11 | B22: 切割瀝青混凝土或無筋混凝土，5cm≦切割深度＜10cm | C22: M | D22: 162.5 | E22: =估驗單!F18 -> 162.5 | G22: 65.4 | I22: =ROUND(D22*G22,2) -> 10627.5 | J22: =ROUND(E22*G22,2) -> 10627.5 | K22: =J22-I22 -> 0 | L22: =I22-J22 -> 0
A23: 12 | B23: 清除及掘除，雜草雜木，含垃圾撿除，人工割 | C23: M2 | D23: 5217.7 | E23: =估驗單!F19 -> 5217.7 | G23: 20.19 | I23: =ROUND(D23*G23,2) -> 105345.36 | J23: =ROUND(E23*G23,2) -> 105345.36 | K23: =J23-I23 -> 0 | L23: =I23-J23 -> 0
A24: 13 | B24: 垃圾及廢棄物(以體積計)清運 | C24: M3 | D24: 782.66 | E24: =估驗單!F20 -> 782.66 | G24: 2286.68 | I24: =ROUND(D24*G24,2) -> 1789693 | J24: =ROUND(E24*G24,2) -> 1789693 | K24: =J24-I24 -> 0 | L24: =I24-J24 -> 0 | M24: #
A25: 14 | B25: 節塊吊放 | C25: 次 | D25: 425 | E25: =估驗單!F21 -> 425 | G25: 521.15 | I25: =ROUND(D25*G25,2) -> 221488.75 | J25: =ROUND(E25*G25,2) -> 221488.75 | K25: =J25-I25 -> 0 | L25: =I25-J25 -> 0 | M25: #磺港路橋、共月橋、三合橋
A26: 15 | B26: 機械拆除，工地雜項拆除清理，欄杆，含運費 | C26: M | D26: 255.5 | E26: =估驗單!F22 -> 314.3 | F26: =E26-D26 -> 58.8 | G26: 289.67 | I26: =ROUND(D26*G26,2) -> 74010.69 | J26: =ROUND(E26*G26,2) -> 91043.28 | K26: =J26-I26 -> 17032.59
A27: 16 | B27: 土方運送(百齡抽水站) | C27: 趟 | D27: 2204 | E27: =估驗單!F23 -> 2204 | G27: 3082.11 | I27: =ROUND(D27*G27,2) -> 6792970.4 | J27: =ROUND(E27*G27,2) -> 6792970.4 | K27: =J27-I27 -> 0 | L27: =I27-J27 -> 0
A28: 17 | B28: 既有路燈拆除繳回 | C28: 盞 | D28: 66 | E28: =估驗單!F24 -> 66 | G28: 3311.26 | I28: =ROUND(D28*G28,2) -> 218543.16 | J28: =ROUND(E28*G28,2) -> 218543.16 | K28: =J28-I28 -> 0 | L28: =I28-J28 -> 0 | M28: #料繳回，含運費。
A29: 18 | B29: 座椅拆除繳回 | C29: 座 | D29: 18 | E29: =估驗單!F25 -> 18 | G29: 1199.93 | I29: =ROUND(D29*G29,2) -> 21598.74 | J29: =ROUND(E29*G29,2) -> 21598.74 | K29: =J29-I29 -> 0 | L29: =I29-J29 -> 0 | M29: #料繳回，含運費。
A30: 19 | B30: 解說牌拆除 | C30: 座 | D30: 4 | E30: =估驗單!F26 -> 4 | G30: 2999.84 | I30: =ROUND(D30*G30,2) -> 11999.36 | J30: =ROUND(E30*G30,2) -> 11999.36 | K30: =J30-I30 -> 0 | L30: =I30-J30 -> 0 | M30: #料繳回，含運費。
A31: 20 | B31: 自行車架拆除 | C31: 座 | D31: 20 | E31: =估驗單!F27 -> 20 | G31: 2999.84 | I31: =ROUND(D31*G31,2) -> 59996.8 | J31: =ROUND(E31*G31,2) -> 59996.8 | K31: =J31-I31 -> 0 | L31: =I31-J31 -> 0 | M31: #料繳回，含運費。
A32: 21 | B32: 交通牌誌拆除 | C32: 座 | D32: 15 | E32: =估驗單!F28 -> 15 | G32: 2999.84 | I32: =ROUND(D32*G32,2) -> 44997.6 | J32: =ROUND(E32*G32,2) -> 44997.6 | K32: =J32-I32 -> 0 | L32: =I32-J32 -> 0 | M32: #料繳回，含運費。
A33: 22 | B33: 既有水利設施拆除及運送 | C33: 式 | D33: 1 | E33: =估驗單!F29 -> 1 | G33: 399978.19 | I33: =ROUND(D33*G33,2) -> 399978.19 | J33: =ROUND(E33*G33,2) -> 399978.19 | K33: =J33-I33 -> 0 | L33: =I33-J33 -> 0 | M33: 水閘門
A34: 23 | B34: 交通維持，道路管制人員，日間(06-22時)，義交 | C34: 時 | D34: 30800 | E34: =估驗單!F30 -> 30800 | F34: =E34-D34 -> 0 | G34: 280 | I34: =ROUND(D34*G34,2) -> 8624000 | J34: =ROUND(E34*G34,2) -> 8624000 | K34: =J34-I34 -> 0 | L34: =I34-J34 -> 0 | M34: [人力工項不打折]
A35: 24 | B35: 表土清除，堆置，及回填費，t=30cm | C35: M2 | D35: 2150 | E35: =估驗單!F31 -> 2150 | F35: =E35-D35 -> 0 | G35: 70.56 | I35: =ROUND(D35*G35,2) -> 151704 | J35: =ROUND(E35*G35,2) -> 151704 | K35: =J35-I35 -> 0 | L35: =I35-J35 -> 0 | M35: 百齡暫置場整地需求
A36: 25 | B36: 餘土分類處理 | C36: 日 | D36: 111 | E36: =估驗單!F32 -> 111 | F36: =E36-D36 -> 0 | G36: 20000 | I36: =ROUND(D36*G36,2) -> 2220000 | J36: =ROUND(E36*G36,2) -> 2220000 | K36: =J36-I36 -> 0 | L36: =I36-J36 -> 0 | M36: 新增工項 02323M00AC | O36: 北市工水工字第1126063128號 第6點 | P36: 數量=餘方遠運處理(台北港)/ 每日約120m3 | Q36: 屬後續擴充5000萬工項 既有磺港路、公園開挖摻雜混合物 | S36: 監造提供數量?
A37: (二) | B37: 土建景觀工程 | C37: 式 | E37: =估驗單!F33 -> 0 | F37: =E37-D37 -> 0 | G37: 30807124 | I37: =SUM(I38:I125) -> 30807124 | J37: =SUM(J38:J125) -> 34151512 | K37: =SUM(K38:K125) -> 5171000 | L37: =SUM(L38:L125) -> -1826612.4
A38: 1 | B38: 構造物回填，回填及夯實(實際) | C38: C.M3 | D38: 1887.64 | E38: =估驗單!F34 -> 1887.64 | F38: =E38-D38 -> 0 | G38: 320.72 | I38: =ROUND(D38*G38,2) -> 605403.9 | J38: =ROUND(E38*G38,2) -> 605403.9 | K38: =J38-I38 -> 0
A39: 2 | B39: 構造物回填，回填及夯實，人工夯實 | C39: C.M3 | D39: 402.21 | E39: =估驗單!F35 -> 402.21 | F39: =E39-D39 -> 0 | G39: 346.06 | I39: =ROUND(D39*G39,2) -> 139188.79 | J39: =ROUND(E39*G39,2) -> 139188.79 | K39: =J39-I39 -> 0
A40: 3 | B40: 鋼筋，SD280W | C40: KG | D40: 18865.76 | E40: =估驗單!F36 -> 18865.76 | F40: =E40-D40 -> 0 | G40: 36.4 | I40: =ROUND(D40*G40,2) -> 686713.66 | J40: =ROUND(E40*G40,2) -> 686713.66 | K40: =J40-I40 -> 0 | M40: 本項納入(鋼筋)物價指數調整
A41: 4 | B41: 結構用混凝土，預拌，140kgf/cm2 | C41: M3 | D41: 107.91 | E41: =估驗單!F37 -> 107.91 | F41: =E41-D41 -> 0 | G41: 3114.97 | I41: =ROUND(D41*G41,2) -> 336136.41 | J41: =ROUND(E41*G41,2) -> 336136.41 | K41: =J41-I41 -> 0
...

Sheet 大宗資材
A1: 臺北市政府工務局水利工程處
A2: 數量計算書
A3: 工程名稱：磺港溪再造C段護岸及步道整建工程(三合橋至奇岩抽水站)
A4: 施工地點：北投磺港溪 | F4: 工程編號：111 070020302 038 02
A5: 項次 | B5: 項目及說明 | C5: 單位 | D5: 原契約數量 | E5: 變更後數量 | F5: 計算式 | H5: 數量小計 | I5: 實作數量合計 | J5: 應追加減數量
A6: 壹 | B6: 發包工程費 | C6: 式 | D6: 1
A7: 一 | B7: 工程費 | C7: 式 | D7: 1
A8: 1.2.3 | B8: 鋼筋，SD280W | C8: KG | D8: 18865.76 | F8: 砌石擋牆A L=35.2 | G8: (1.65*236*2+6*60*2+3.95*236+2.9*236+6*282)*0.994 | H8: =(1.65*236*2+6*60*2+3.95*236+2.9*236+6*282)*0.994 -> 4778.5556 | J8: 尚有其他項目未施做
A9: 1.3.5 | B9: 鋼筋，SD280W | C9: KG | D9: 6240.88 | F9: 希冀橋人行道引道、透空步道混凝土踏階 | J9: 尚未施做
A10: 1.4.7 | B10: 鋼筋，SD280W | C10: KG | D10: 13138 | F10: 低水護岸+護岸二+護岸三 | G10: 鋼筋表 | H10: 16735.408 | I10: 32720.212 | J10: =I10-D10 -> 19582.212
F11: 預力樁柱頭筋 | G11: ((2.8*1.56*8)+(0.55*0.56*13))*58 | H11: 2258.984
F12: 清江公園側擋土牆2處 | G12: 鋼筋表 | H12: 2194.92
A13: 變更 | F13: 保護樹繫粱A+B | G13: (43.6+0.6*8)*4*0.994+(0.3+0.35+0.18*2+0.55)*43.6/0.3*0.994 | H13: 417.79808
A14: 變更 | F14: 保護樹A擋土牆L=35.2 | G14: (1.65*236*2+6*60*2+3.95*236+2.9*236+6*282)*0.994 | H14: 4778.5556
A15: 變更 | F15: 既有堤牆加高 | G15: 堤牆加高計算表 | H15: 599.58
A16: 變更 | F16: 既有堤牆加高(L=18.8M)H=40+漸變19-56cm | G16: (18.8/0.2)*(1.075+0.62)*1.56+(8*18.8*1.56) | H16: 483.1788
A17: 變更 | F17: 植栽槽 | G17: (250/0.5*0.4+1*250)*0.994 | H17: 447.3
A18: 變更 | F18: 橋台下方擋土牆(雙孔箱涵出口端牆) | G18: 鋼筋表 | H18: 2609.568
A19: 變更 | F19: 既有堤牆修復2處(清江公園) | G19: 鋼筋表 | H19: 2194.92
F20: 磺港橋頭2處(與既有銜接) | G20: 尚未施作
A21: 1.5.9 | B21: 鋼筋，SD280W | C21: KG | D21: 137462 | F21: 單孔箱涵 | G21: 鋼筋表 | H21: 75613.2 | I21: 207085.17 | J21: =I21-D21 -> 69623.17
F22: 出流井(含銜接出口) | G22: 鋼筋表 | H22: 262.22
F23: 雙孔箱涵 | G23: 鋼筋表 | H23: 130550.17
F24: 人孔頸 | G24: (1.35*9*2*2*1.56+1.2*8*2*0.994)*4+(1.41+2.59+2.57+1.88)*13*1.56+0.6*3.14*(10+18+17+13)*0.994 | H24: =(1.35*9*2*2*1.56+1.2*8*2*0.994)*4+(1.41+2.59+2.57+1.88)*13*1.56+0.6*3.14*(10+18+17+13)*0.994 -> 659.58557
A25: 1.6.11 | B25: 鋼筋，SD280W | C25: KG | D25: 12810 | F25: 道路側溝 | G25: 計算表 | H25: 41151.39 | I25: 46353.23 | J25: 33543.23
F26: 集水井 | G26: 計算表 | H26: 5201.84
G27: 鋼筋，SD280W追加小計 | I27: =ROUND(SUM(J8:J26),2) -> 122748.61 | J27: =ROUND(I27*36.4,2) -> 4468049.4 | M27: =J27+J40+J58+J73+J81+J92+J106+J122 -> 14615438
A28: 1.3.6 | B28: 鋼筋，SD420W | C28: KG | D28: 102796.95 | F28: 磺港橋橋台(含防震塊) | G28: 7194.35+7703.67+4325.4 | H28: 19223.42 | I28: 56143.838 | J28: 尚有其他項目未施做
F29: 希冀橋橋台(含防震塊) | G29: 2215.51+1346.07 | H29: 3561.58
F30: 橋台下方擋土牆 | G30: (14.6*36+6.75*80+3.65*80+1.75*80+14.6*12)*1.56 | H30: 2609.568
F31: 磺港橋橋面版 | G31: (11.5*142+5*142+9.85*71+8.35*142+6.85*71)*2.25+((8.5+6.4+5)*105+1.6*250+1.3*215+1.6*630+11*53+9.8*104+8.6*53)*1.56 | H31: 19710
F32: 磺港橋進橋版 | G32: 5.25*107*3.05+(12*34+4.8*34+5.25*54+10*9+8.5*18+7*9)*2.25+(5.25*106*3.05)+(12*34+4.8*34+5.25*53+10*9+8.5*18+7*9)*2.25 | H32: 8622
F33: 磺港橋護欄 | G33: (7*108+3.1*252+0.5*252)*0.994 | H33: 1653.2208
F34: 磺港橋伸縮縫 | G34: 7.95*8*3.05+(9.45+6.15)*4*1.56+1.1*191*2.25 | H34: 764.049
A35: 1.4.8 | B35: 鋼筋，SD420W | C35: KG | D35: 15589 | F35: 護岸二+護岸三 | G35: 鋼筋表 | H35: 15565.555 | I35: 23923.675 | J35: 8334.6749
A36: 變更 | F36: 微型樁 | G36: 6*218*6.39 | H36: 8358.12
A37: 變更 | F37: 磺港橋頭2處(與既有銜接) | G37: 尚未施做
A38: 1.5.10 | B38: 鋼筋，SD420W | C38: KG | D38: 116638 | F38: 出流井(含銜接出口) | G38: 鋼筋表 | H38: 5375.786 | I38: 168230.73 | J38: 51592.726
F39: 雙孔箱涵 | G39: 鋼筋表 | H39: 162854.94
G40: 鋼筋，SD420W追加小計 | I40: =ROUND(SUM(J28:J39),2) -> 59927.4 | J40: =ROUND(I40*38.71,2) -> 2319789.6
...

Sheet 變更說明
C1: 臺北市政府工務局水利工程處
C2: 變更項目對照詳細表 | R2: -4483155.4
A3: 工程名稱：磺港溪再造C段護岸及步道整建工程(三合橋至奇岩抽水站) | N3: 日期： | O3: 45621
A4: 原契約分為 10 部分 本次變更 4 部分原有 393 項 | L4: 訂約總價 | O4: 257600000
A5: 前經 2 次變更設計，計新增 9 項，減少 1 項，變更 11 項，變更後合計 402 項 | L5: 前次變更後總價(綜簽)
A6: 本次變更設計，計新增 0 項，減少 0 項，變更 97 項，變更後合計 402 項 | L6: 本次變更後總價
A7: 項次 | B7: 項目名稱 | C7: 單位 | D7: 原 定 數 量 | E7: 2變後 數 量 | F7: 3變後 數 量 | G7: 增 減 數 量 | H7: 契 約 單 價 | I7: 新 增 單 價 | J7: 新 增 單 價 | K7: 原 訂 合 價 | L7: 2變後 合價 | M7: 3變後 合價 | N7: 追加 | O7: 追減 | P7: 備註 | R7: 變更依據 | S7: 數量計算式 | T7: 變更原因
A9: 壹 | B9: 發包工程費 | C9: 式 | D9: 1 | H9: 271134529 | K9: 271134529 | L9: =L10+L351+L362+L402+L406+L425+L445+L448+L449+L451 -> 3.0497528e+08 | M9: =M10+M351+M362+M402+M406+M425+M445+M448+M449+M451 -> 3.2218369e+08 | N9: =N10+N351+N362+N402+N406+N425+N445+N448+N449+N451 -> 18734760 | O9: =O10+O351+O362+O402+O406+O425+O445+O448+O449+O451 -> -1490274.3 | P9: =N9+O9 -> 17244486
A10: 一 | B10: 工程費 | C10: 式 | D10: 1 | H10: 2.1136714e+08 | K10: 2.1136714e+08 | L10: =L11+L37+L123+L163+L192+L212+L229+L307+L341 -> 2.3286809e+08 | M10: =M11+M37+M123+M163+M192+M212+M229+M307+M341 -> 2.4680905e+08 | N10: =N11+N37+N123+N163+N192+N212+N229+N307+N341 -> 15467309 | O10: =O11+O37+O123+O163+O192+O212+O229+O307+O341 -> -1490274.3
A11: (一) | B11: 整備工程 | C11: 式 | D11: 1 | H11: 58934658 | K11: 58934658 | L11: =SUM(L12:L36) -> 61233816 | M11: =SUM(M12:M36) -> 61250848 | N11: =SUM(N12:N36) -> 17032.59 | O11: =SUM(O12:O36) -> 0
A12: 1 | B12: 機械拆除，瀝青混凝土，未含運費 | C12: M3 | D12: 720.24 | E12: 720.24 | F12: =估驗單!F8 -> 720.24 | H12: 193.11 | K12: 139085.55 | L12: =ROUND(E12*H12,2) -> 139085.55 | M12: =ROUND(F12*H12,2) -> 139085.55 | N12: =IF(L12-M12<0+AND(L12<>0),M12-L12," ") -> 0
A13: 2 | B13: 機械拆除，鋼筋混凝土，未含運費 | C13: M3 | D13: 4813.44 | E13: 4813.44 | F13: =估驗單!F9 -> 4813.44 | H13: 1046.16 | K13: 5035628.4 | L13: =ROUND(E13*H13,2) -> 5035628.4 | M13: =ROUND(F13*H13,2) -> 5035628.4 | N13: =IF(L13-M13<0+AND(L13<>0),M13-L13," ") -> 0
A14: 3 | B14: 盤踞切割 | C14: M | D14: 1743 | E14: 1743 | F14: =估驗單!F10 -> 1743 | H14: 6199.66 | K14: 10806007 | L14: =ROUND(E14*H14,2) -> 10806007 | M14: =ROUND(F14*H14,2) -> 10806007 | N14: =IF(L14-M14<0+AND(L14<>0),M14-L14," ") -> 0 | P14: #磺港路橋(奇岩抽水站旁)1533.9m、希冀橋208.6m
A15: 4 | B15: 基地及路幅開挖，未含運費，(機械挖，0.7～0.79m3開挖機) | C15: B.M3 | D15: 26370 | E15: 28009.56 | F15: =估驗單!F11 -> 28009.56 | H15: 48.28 | K15: 1273143.6 | L15: =ROUND(E15*H15,2) -> 1352301.6 | M15: =ROUND(F15*H15,2) -> 1352301.6 | N15: =IF(L15-M15<0+AND(L15<>0),M15-L15," ") -> 0 | R15: 112年12月12日 北市工水工字第1126067256號 | S15: 新設磺港橋及希冀橋橋台辦理既有基樁與新設基樁清障開挖+單孔過路段及清江公園 ((5*6*6.5*2)+(13*3.5*6.8)+(3.2*8.5*1.6))+((747.2+149.44)) | T15: 機關/現場需求 (百齡)
A16: 5 | B16: 瀝青混凝土面層刨除，刨除料運費 | C16: M3 | D16: 4726.67 | E16: 4726.67 | F16: =估驗單!F12 -> 4726.67 | H16: 599.71 | K16: 2834631.3 | L16: =ROUND(E16*H16,2) -> 2834631.3 | M16: =ROUND(F16*H16,2) -> 2834631.3 | N16: =IF(L16-M16<0+AND(L16<>0),M16-L16," ") -> 0
A17: 6 | B17: 利用填方，含夯實 | C17: M3 | D17: 13120 | E17: 13120 | F17: =估驗單!F13 -> 13120 | H17: 104.64 | K17: 1372876.8 | L17: =ROUND(E17*H17,2) -> 1372876.8 | M17: =ROUND(F17*H17,2) -> 1372876.8 | N17: =IF(L17-M17<0+AND(L17<>0),M17-L17," ") -> 0
A18: 7 | B18: 餘方遠運處理(台北港) | C18: B.M3 | D18: 13251 | E18: 13251 | F18: =估驗單!F14 -> 13251 | H18: 1027.37 | K18: 13613680 | L18: =ROUND(E18*H18,2) -> 13613680 | M18: =ROUND(F18*H18,2) -> 13613680 | N18: =IF(L18-M18<0+AND(L18<>0),M18-L18," ") -> 0 | P18: 僅含運費(運距約<20K)(土方管理費檢據核銷)
A19: 8 | B19: 餘方自行處理(房屋廢方，含水土保持) | C19: M3 | D19: 4601.44 | E19: 4601.44 | F19: =估驗單!F15 -> 4601.44 | H19: 1084.98 | K19: 4992470.4 | L19: =ROUND(E19*H19,2) -> 4992470.4 | M19: =ROUND(F19*H19,2) -> 4992470.4 | N19: =IF(L19-M19<0+AND(L19<>0),M19-L19," ") -> 0
A20: 9 | B20: 瀝青混凝土面層刨除，厚5cm，刨除機1.2m寬，含瀝青鋪面打毛(未含運費) | C20: M2 | D20: 2588.5 | E20: 2588.5 | F20: =估驗單!F16 -> 2588.5 | H20: 30.45 | K20: 78819.83 | L20: =ROUND(E20*H20,2) -> 78819.83 | M20: =ROUND(F20*H20,2) -> 78819.83 | N20: =IF(L20-M20<0+AND(L20<>0),M20-L20," ") -> 0 | P20: #含瀝青鋪面打毛
A21: 10 | B21: 瀝青混凝土面層刨除，厚10cm，刨除機2.2m寬，未含運費 | C21: M2 | D21: 9177 | E21: 9177 | F21: =估驗單!F17 -> 9177 | H21: 28.48 | K21: 261360.96 | L21: =ROUND(E21*H21,2) -> 261360.96 | M21: =ROUND(F21*H21,2) -> 261360.96 | N21: =IF(L21-M21<0+AND(L21<>0),M21-L21," ") -> 0
A22: 11 | B22: 切割瀝青混凝土或無筋混凝土，5cm≦切割深度＜10cm | C22: M | D22: 162.5 | E22: 162.5 | F22: =估驗單!F18 -> 162.5 | H22: 65.4 | K22: 10627.5 | L22: =ROUND(E22*H22,2) -> 10627.5 | M22: =ROUND(F22*H22,2) -> 10627.5 | N22: =IF(L22-M22<0+AND(L22<>0),M22-L22," ") -> 0
A23: 12 | B23: 清除及掘除，雜草雜木，含垃圾撿除，人工割 | C23: M2 | D23: 5217.7 | E23: 5217.7 | F23: =估驗單!F19 -> 5217.7 | H23: 20.19 | K23: 105345.36 | L23: =ROUND(E23*H23,2) -> 105345.36 | M23: =ROUND(F23*H23,2) -> 105345.36 | N23: =IF(L23-M23<0+AND(L23<>0),M23-L23," ") -> 0
A24: 13 | B24: 垃圾及廢棄物(以體積計)清運 | C24: M3 | D24: 782.66 | E24: 782.66 | F24: =估驗單!F20 -> 782.66 | H24: 2286.68 | K24: 1789693 | L24: =ROUND(E24*H24,2) -> 1789693 | M24: =ROUND(F24*H24,2) -> 1789693 | N24: =IF(L24-M24<0+AND(L24<>0),M24-L24," ") -> 0 | P24: #
A25: 14 | B25: 節塊吊放 | C25: 次 | D25: 425 | E25: 425 | F25: =估驗單!F21 -> 425 | H25: 521.15 | K25: 221488.75 | L25: =ROUND(E25*H25,2) -> 221488.75 | M25: =ROUND(F25*H25,2) -> 221488.75 | N25: =IF(L25-M25<0+AND(L25<>0),M25-L25," ") -> 0 | P25: #磺港路橋、共月橋、三合橋
A26: 15 | B26: 機械拆除，工地雜項拆除清理，欄杆，含運費 | C26: M | D26: 255.5 | E26: 255.5 | F26: =估驗單!F22 -> 314.3 | G26: =F26-E26 -> 58.8 | H26: 289.67 | K26: 74010.69 | L26: =ROUND(E26*H26,2) -> 74010.69 | M26: =ROUND(F26*H26,2) -> 91043.28 | N26: =IF(L26-M26<0+AND(L26<>0),M26-L26," ") -> 17032.59 | R26: 依實作數量計算
A27: 16 | B27: 土方運送(百齡抽水站) | C27: 趟 | D27: 2204 | E27: 2204 | F27: =估驗單!F23 -> 2204 | H27: 3082.11 | K27: 6792970.4 | L27: =ROUND(E27*H27,2) -> 6792970.4 | M27: =ROUND(F27*H27,2) -> 6792970.4 | N27: =IF(L27-M27<0+AND(L27<>0),M27-L27," ") -> 0
A28: 17 | B28: 既有路燈拆除繳回 | C28: 盞 | D28: 66 | E28: 66 | F28: =估驗單!F24 -> 66 | H28: 3311.26 | K28: 218543.16 | L28: =ROUND(E28*H28,2) -> 218543.16 | M28: =ROUND(F28*H28,2) -> 218543.16 | N28: =IF(L28-M28<0+AND(L28<>0),M28-L28," ") -> 0 | P28: #料繳回，含運費。
A29: 18 | B29: 座椅拆除繳回 | C29: 座 | D29: 18 | E29: 18 | F29: =估驗單!F25 -> 18 | H29: 1199.93 | K29: 21598.74 | L29: =ROUND(E29*H29,2) -> 21598.74 | M29: =ROUND(F29*H29,2) -> 21598.74 | N29: =IF(L29-M29<0+AND(L29<>0),M29-L29," ") -> 0 | P29: #料繳回，含運費。
A30: 19 | B30: 解說牌拆除 | C30: 座 | D30: 4 | E30: 4 | F30: =估驗單!F26 -> 4 | H30: 2999.84 | K30: 11999.36 | L30: =ROUND(E30*H30,2) -> 11999.36 | M30: =ROUND(F30*H30,2) -> 11999.36 | N30: =IF(L30-M30<0+AND(L30<>0),M30-L30," ") -> 0 | P30: #料繳回，含運費。
A31: 20 | B31: 自行車架拆除 | C31: 座 | D31: 20 | E31: 20 | F31: =估驗單!F27 -> 20 | H31: 2999.84 | K31: 59996.8 | L31: =ROUND(E31*H31,2) -> 59996.8 | M31: =ROUND(F31*H31,2) -> 59996.8 | N31: =IF(L31-M31<0+AND(L31<>0),M31-L31," ") -> 0 | P31: #料繳回，含運費。
A32: 21 | B32: 交通牌誌拆除 | C32: 座 | D32: 15 | E32: 15 | F32: =估驗單!F28 -> 15 | H32: 2999.84 | K32: 44997.6 | L32: =ROUND(E32*H32,2) -> 44997.6 | M32: =ROUND(F32*H32,2) -> 44997.6 | N32: =IF(L32-M32<0+AND(L32<>0),M32-L32," ") -> 0 | P32: #料繳回，含運費。
A33: 22 | B33: 既有水利設施拆除及運送 | C33: 式 | D33: 1 | E33: 1 | F33: =估驗單!F29 -> 1 | H33: 399978.19 | K33: 399978.19 | L33: =ROUND(E33*H33,2) -> 399978.19 | M33: =ROUND(F33*H33,2) -> 399978.19 | N33: =IF(L33-M33<0+AND(L33<>0),M33-L33," ") -> 0 | P33: 水閘門
A34: 23 | B34: 交通維持，道路管制人員，日間(06-22時)，義交 | C34: 時 | D34: 30800 | E34: 30800 | F34: =估驗單!F30 -> 30800 | G34: =F34-E34 -> 0 | H34: 280 | K34: 8624000 | L34: =ROUND(E34*H34,2) -> 8624000 | M34: =ROUND(F34*H34,2) -> 8624000 | N34: =IF(L34-M34<0+AND(L34<>0),M34-L34," ") -> 0 | P34: [人力工項不打折]
A35: 24 | B35: 表土清除，堆置，及回填費，t=30cm | C35: M2 | D35: 2150 | E35: 2150 | F35: =估驗單!F31 -> 2150 | G35: =F35-E35 -> 0 | H35: 70.56 | K35: 151704 | L35: =ROUND(E35*H35,2) -> 151704 | M35: =ROUND(F35*H35,2) -> 151704 | N35: =IF(L35-M35<0+AND(L35<>0),M35-L35," ") -> 0 | P35: 百齡暫置場整地需求
A36: 25 | B36: 餘土分類處理 | C36: 日 | D36: 0 | E36: 111 | F36: =估驗單!F32 -> 111 | G36: =F36-E36 -> 0 | H36: 0 | J36: 20000 | K36: 0 | L36: =ROUND(E36*J36,2) -> 2220000 | M36: =ROUND(F36*J36,2) -> 2220000 | N36: =IF(L36-M36<0+AND(L36<>0),M36-L36," ") -> 0 | P36: 新增工項 02323M00AC | R36: 北市工水工字第1126063128號 第6點 | S36: 數量=餘方遠運處理(台北港)/ 每日約120m3 | T36: 屬後續擴充5000萬工項 既有磺港路、公園開挖摻雜混合物 | V36: 監造提供數量?
A37: (二) | B37: 土建景觀工程 | C37: 式 | D37: 1 | F37: =估驗單!F33 -> 0 | G37: =F37-E37 -> 0 | H37: 30807124 | K37: 30807124 | L37: =SUM(L38:L122) -> 30807124 | M37: =SUM(M38:M122) -> 32740380 | N37: =SUM(N38:N122) -> 1933255.4 | O37: =SUM(O38:O122) -> 0
A38: 1 | B38: 構造物回填，回填及夯實(實際) | C38: C.M3 | D38: 1887.64 | E38: 1887.64 | F38: =估驗單!F34 -> 1887.64 | G38: =F38-E38 -> 0 | H38: 320.72 | K38: 605403.9 | L38: =ROUND(E38*H38,2) -> 605403.9 | M38: =ROUND(F38*H38,2) -> 605403.9 | N38: =IF(L38-M38<0+AND(L38<>0),M38-L38," ") -> 0
A39: 2 | B39: 構造物回填，回填及夯實，人工夯實 | C39: C.M3 | D39: 402.21 | E39: 402.21 | F39: =估驗單!F35 -> 402.21 | G39: =F39-E39 -> 0 | H39: 346.06 | K39: 139188.79 | L39: =ROUND(E39*H39,2) -> 139188.79 | M39: =ROUND(F39*H39,2) -> 139188.79 | N39: =IF(L39-M39<0+AND(L39<>0),M39-L39," ") -> 0
A40: 3 | B40: 鋼筋，SD280W | C40: KG | D40: 18865.76 | E40: 18865.76 | F40: =估驗單!F36 -> 18865.76 | G40: =F40-E40 -> 0 | H40: 36.4 | K40: 686713.66 | L40: =ROUND(E40*H40,2) -> 686713.66 | M40: =ROUND(F40*H40,2) -> 686713.66 | N40: =IF(L40-M40<0+AND(L40<>0),M40-L40," ") -> 0 | P40: 本項納入(鋼筋)物價指數調整
A41: 4 | B41: 結構用混凝土，預拌，140kgf/cm2 | C41: M3 | D41: 107.91 | E41: 107.91 | F41: =估驗單!F37 -> 107.91 | G41: =F41-E41 -> 0 | H41: 3114.97 | K41: 336136.41 | L41: =ROUND(E41*H41,2) -> 336136.41 | M41: =ROUND(F41*H41,2) -> 336136.41 | N41: =IF(L41-M41<0+AND(L41<>0),M41-L41," ") -> 0
...

Sheet 水溝集水井
A1: U溝 | C1: U+矩溝= | D1: =E20+Q6 -> 731.4 | H1: 清水丙模 | I1: 普通丙模 | M1: 矩型溝 | T1: 清水丙模 | U1: 普通丙模
A2: 編號 | B2: 均深 | C2: 起點深 | D2: 終點深 | E2: 長度 | F2: 鋼筋(溝) | G2: 鋼筋(蓋) | H2: 模板(內) | I2: 模板(外) | J2: 免拆模 | K2: 混凝土 | M2: 編號 | N2: 均深 | O2: 起點深 | P2: 終點深 | Q2: 長度 | R2: 鋼筋(溝) | S2: 鋼筋(蓋) | T2: 模板(內) | U2: 模板(外) | V2: 免拆模 | W2: 混凝土
A3: U15 | B3: =ROUND((C3+D3)/2,2) -> 0.5 | C3: 0.5 | D3: 0.5 | E3: 43 | F3: =ROUND(((B3*2+0.7)*(1/0.15)*1.56+((B3*2+0.7)/0.15+1)*1*0.994)*E3,2) -> 1287.39 | G3: =ROUND((4.33/0.13*1.6+4.33*10+2*1.85*2*2+0.7*2*4*2+0.4*13*2)*0.994*E3/5,2) -> 1136.87 | H3: =ROUND((B3*1.1*2)*E3,2) -> 47.3 | I3: =ROUND((B3+0.2)*2*E3,2) -> 60.2 | J3: =(0.4+0.2)*E3 -> 25.8 | K3: =ROUND((B3*0.2*2+(0.4+0.2*2)*0.2*2+0.8*0.15)*E3-(E3/5*0.53*0.45*0.15),2) -> 27.21 | M3: L23 | N3: =ROUND((O3+P3)/2,2) -> 0.36 | O3: 0.3 | P3: 0.41 | Q3: 52.7 | R3: =ROUND(((N3*2+0.7)*(1/0.15)*1.56+((N3*2+0.7)/0.15+1)*1*0.994)*Q3,2) -> 1326.56 | S3: =ROUND((4.33/0.13*1.6+4.33*10+2*1.85*2*2+0.7*2*4*2+0.4*13*2)*0.994*Q3/5,2) -> 1393.33 | T3: =ROUND(N3*2*Q3,2) -> 37.94 | U3: =ROUND((N3+0.2)*2*Q3,2) -> 59.02 | V3: =(0.4+0.2)*Q3 -> 31.62 | W3: =ROUND((N3*0.2*2+(0.4+0.2*2)*0.2*2+0.8*0.15)*Q3-(E3/5*0.53*0.45*0.15),2) -> 30.47
A4: U16 | B4: =ROUND((C4+D4)/2,2) -> 0.53 | C4: 0.5 | D4: 0.55 | E4: 9.4 | F4: =ROUND(((B4*2+0.7)*(1/0.15)*1.56+((B4*2+0.7)/0.15+1)*1*0.994)*E4,2) -> 291.03 | G4: =ROUND((4.33/0.13*1.6+4.33*10+2*1.85*2*2+0.7*2*4*2+0.4*13*2)*0.994*E4/5,2) -> 248.53 | H4: =ROUND((B4*1.1*2)*E4,2) -> 10.96 | I4: =ROUND((B4+0.2)*2*E4,2) -> 13.72 | J4: =(0.4+0.2)*E4 -> 5.64 | K4: =ROUND((B4*0.2*2+(0.4+0.2*2)*0.2*2+0.8*0.15)*E4-(E4/5*0.53*0.45*0.15),2) -> 6.06 | M4: L26 | N4: =ROUND((O4+P4)/2,2) -> 0.41 | O4: 0.3 | P4: 0.52 | Q4: 48.3 | R4: =ROUND(((N4*2+0.7)*(1/0.15)*1.56+((N4*2+0.7)/0.15+1)*1*0.994)*Q4,2) -> 1298.04 | S4: =ROUND((4.33/0.13*1.6+4.33*10+2*1.85*2*2+0.7*2*4*2+0.4*13*2)*0.994*Q4/5,2) -> 1277 | T4: =ROUND(N4*2*Q4,2) -> 39.61 | U4: =ROUND((N4+0.2)*2*Q4,2) -> 58.93 | V4: =(0.4+0.2)*Q4 -> 28.98 | W4: =ROUND((N4*0.2*2+(0.4+0.2*2)*0.2*2+0.8*0.15)*Q4-(E4/5*0.53*0.45*0.15),2) -> 29.11
A5: U17 | B5: =ROUND((C5+D5)/2,2) -> 0.45 | C5: 0.4 | D5: 0.5 | E5: 42 | F5: =ROUND(((B5*2+0.7)*(1/0.15)*1.56+((B5*2+0.7)/0.15+1)*1*0.994)*E5,2) -> 1185.94 | G5: =ROUND((4.33/0.13*1.6+4.33*10+2*1.85*2*2+0.7*2*4*2+0.4*13*2)*0.994*E5/5,2) -> 1110.43 | H5: =ROUND((B5*1.1*2)*E5,2) -> 41.58 | I5: =ROUND((B5+0.2)*2*E5,2) -> 54.6 | J5: =(0.4+0.2)*E5 -> 25.2 | K5: =ROUND((B5*0.2*2+(0.4+0.2*2)*0.2*2+0.8*0.15)*E5-(E5/5*0.53*0.45*0.15),2) -> 25.74 | M5: L27 | N5: =ROUND((O5+P5)/2,2) -> 0.4 | O5: 0.4 | P5: 0.4 | Q5: 21.2 | R5: =ROUND(((N5*2+0.7)*(1/0.15)*1.56+((N5*2+0.7)/0.15+1)*1*0.994)*Q5,2) -> 562.52 | S5: =ROUND((4.33/0.13*1.6+4.33*10+2*1.85*2*2+0.7*2*4*2+0.4*13*2)*0.994*Q5/5,2) -> 560.5 | T5: =ROUND(N5*2*Q5,2) -> 16.96 | U5: =ROUND((N5+0.2)*2*Q5,2) -> 25.44 | V5: =(0.4+0.2)*Q5 -> 12.72 | W5: =ROUND((N5*0.2*2+(0.4+0.2*2)*0.2*2+0.8*0.15)*Q5-(E5/5*0.53*0.45*0.15),2) -> 12.42
A6: U18 | B6: =ROUND((C6+D6)/2,2) -> 0.43 | C6: 0.35 | D6: 0.5 | E6: 43.6 | F6: =ROUND(((B6*2+0.7)*(1/0.15)*1.56+((B6*2+0.7)/0.15+1)*1*0.994)*E6,2) -> 1201.42 | G6: =ROUND((4.33/0.13*1.6+4.33*10+2*1.85*2*2+0.7*2*4*2+0.4*13*2)*0.994*E6/5,2) -> 1152.73 | H6: =ROUND((B6*1.1*2)*E6,2) -> 41.25 | I6: =ROUND((B6+0.2)*2*E6,2) -> 54.94 | J6: =(0.4+0.2)*E6 -> 26.16 | K6: =ROUND((B6*0.2*2+(0.4+0.2*2)*0.2*2+0.8*0.15)*E6-(E6/5*0.53*0.45*0.15),2) -> 26.37 | M6: 合計 | Q6: =SUM(Q3:Q5) -> 122.2 | R6: =SUM(R3:R5) -> 3187.12 | S6: =SUM(S3:S5) -> 3230.83 | T6: =SUM(T3:T5) -> 94.51 | U6: =SUM(U3:U5) -> 143.39 | V6: =SUM(V3:V5) -> 73.32 | W6: =SUM(W3:W5) -> 72
A7: U19 | B7: =ROUND((C7+D7)/2,2) -> 0.6 | C7: 0.5 | D7: 0.7 | E7: 20.1 | F7: =ROUND(((B7*2+0.7)*(1/0.15)*1.56+((B7*2+0.7)/0.15+1)*1*0.994)*E7,2) -> 670.23 | G7: =ROUND((4.33/0.13*1.6+4.33*10+2*1.85*2*2+0.7*2*4*2+0.4*13*2)*0.994*E7/5,2) -> 531.42 | H7: =ROUND((B7*1.1*2)*E7,2) -> 26.53 | I7: =ROUND((B7+0.2)*2*E7,2) -> 32.16 | J7: =(0.4+0.2)*E7 -> 12.06 | K7: =ROUND((B7*0.2*2+(0.4+0.2*2)*0.2*2+0.8*0.15)*E7-(E7/5*0.53*0.45*0.15),2) -> 13.52
A8: U20 | B8: =ROUND((C8+D8)/2,2) -> 0.6 | C8: 0.5 | D8: 0.7 | E8: 9.1 | F8: =ROUND(((B8*2+0.7)*(1/0.15)*1.56+((B8*2+0.7)/0.15+1)*1*0.994)*E8,2) -> 303.44 | G8: =ROUND((4.33/0.13*1.6+4.33*10+2*1.85*2*2+0.7*2*4*2+0.4*13*2)*0.994*E8/5,2) -> 240.59 | H8: =ROUND((B8*1.1*2)*E8,2) -> 12.01 | I8: =ROUND((B8+0.2)*2*E8,2) -> 14.56 | J8: =(0.4+0.2)*E8 -> 5.46 | K8: =ROUND((B8*0.2*2+(0.4+0.2*2)*0.2*2+0.8*0.15)*E8-(E8/5*0.53*0.45*0.15),2) -> 6.12
A9: U21 | B9: =ROUND((C9+D9)/2,2) -> 0.8 | C9: 0.7 | D9: 0.9 | E9: 77.7 | F9: =ROUND(((B9*2+0.7)*(1/0.15)*1.56+((B9*2+0.7)/0.15+1)*1*0.994)*E9,2) -> 3120.07 | G9: =ROUND((4.33/0.13*1.6+4.33*10+2*1.85*2*2+0.7*2*4*2+0.4*13*2)*0.994*E9/5,2) -> 2054.3 | H9: =ROUND((B9*1.1*2)*E9,2) -> 136.75 | I9: =ROUND((B9+0.2)*2*E9,2) -> 155.4 | J9: =(0.4+0.2)*E9 -> 46.62 | K9: =ROUND((B9*0.2*2+(0.4+0.2*2)*0.2*2+0.8*0.15)*E9-(E9/5*0.53*0.45*0.15),2) -> 58.5
A10: U22 | B10: =ROUND((C10+D10)/2,2) -> 0.5 | C10: 0.5 | D10: 0.5 | E10: 67.4 | F10: =ROUND(((B10*2+0.7)*(1/0.15)*1.56+((B10*2+0.7)/0.15+1)*1*0.994)*E10,2) -> 2017.91 | G10: =ROUND((4.33/0.13*1.6+4.33*10+2*1.85*2*2+0.7*2*4*2+0.4*13*2)*0.994*E10/5,2) -> 1781.98 | H10: =ROUND((B10*1.1*2)*E10,2) -> 74.14 | I10: =ROUND((B10+0.2)*2*E10,2) -> 94.36 | J10: =(0.4+0.2)*E10 -> 40.44 | K10: =ROUND((B10*0.2*2+(0.4+0.2*2)*0.2*2+0.8*0.15)*E10-(E10/5*0.53*0.45*0.15),2) -> 42.65 | Q10: 清水丙模 | R10: 普通丙模
A11: U24 | B11: =ROUND((C11+D11)/2,2) -> 0.73 | C11: 0.7 | D11: 0.75 | E11: 13.8 | F11: =ROUND(((B11*2+0.7)*(1/0.15)*1.56+((B11*2+0.7)/0.15+1)*1*0.994)*E11,2) -> 521.25 | G11: =ROUND((4.33/0.13*1.6+4.33*10+2*1.85*2*2+0.7*2*4*2+0.4*13*2)*0.994*E11/5,2) -> 364.86 | H11: =ROUND((B11*1.1*2)*E11,2) -> 22.16 | I11: =ROUND((B11+0.2)*2*E11,2) -> 25.67 | J11: =(0.4+0.2)*E11 -> 8.28 | K11: =ROUND((B11*0.2*2+(0.4+0.2*2)*0.2*2+0.8*0.15)*E11-(E11/5*0.53*0.45*0.15),2) -> 10 | N11: 長度 | O11: 鋼筋(溝) | P11: 鋼筋(蓋) | Q11: 模板(內) | R11: 模板(外) | S11: 免拆模 | T11: 混凝土
A12: U25 | B12: =ROUND((C12+D12)/2,2) -> 0.63 | C12: 0.5 | D12: 0.75 | E12: 49.3 | F12: =ROUND(((B12*2+0.7)*(1/0.15)*1.56+((B12*2+0.7)/0.15+1)*1*0.994)*E12,2) -> 1694.26 | G12: =ROUND((4.33/0.13*1.6+4.33*10+2*1.85*2*2+0.7*2*4*2+0.4*13*2)*0.994*E12/5,2) -> 1303.44 | H12: =ROUND((B12*1.1*2)*E12,2) -> 68.33 | I12: =ROUND((B12+0.2)*2*E12,2) -> 81.84 | J12: =(0.4+0.2)*E12 -> 29.58 | K12: =ROUND((B12*0.2*2+(0.4+0.2*2)*0.2*2+0.8*0.15)*E12-(E12/5*0.53*0.45*0.15),2) -> 33.76 | M12: U+矩溝= | N12: =E20+Q6 -> 731.4 | O12: =F20+R6 -> 22279.3 | P12: =G20+S6 -> 19337.39 | Q12: =H20+T6 -> 819.75 | R12: =I20+U6 -> 1046.38 | S12: =J20+V6 -> 438.84 | T12: =K20+W6 -> 467.51
A13: U28 | B13: =ROUND((C13+D13)/2,2) -> 0.5 | C13: 0.5 | D13: 0.5 | E13: 24.2 | F13: =ROUND(((B13*2+0.7)*(1/0.15)*1.56+((B13*2+0.7)/0.15+1)*1*0.994)*E13,2) -> 724.53 | G13: =ROUND((4.33/0.13*1.6+4.33*10+2*1.85*2*2+0.7*2*4*2+0.4*13*2)*0.994*E13/5,2) -> 639.82 | H13: =ROUND((B13*1.1*2)*E13,2) -> 26.62 | I13: =ROUND((B13+0.2)*2*E13,2) -> 33.88 | J13: =(0.4+0.2)*E13 -> 14.52 | K13: =ROUND((B13*0.2*2+(0.4+0.2*2)*0.2*2+0.8*0.15)*E13-(E13/5*0.53*0.45*0.15),2) -> 15.31 | M13: 鋼筋合計 | O13: =O12+P12 -> 41616.69
A14: U29 | B14: =ROUND((C14+D14)/2,2) -> 0.5 | C14: 0.5 | D14: 0.5 | E14: 23.9 | F14: =ROUND(((B14*2+0.7)*(1/0.15)*1.56+((B14*2+0.7)/0.15+1)*1*0.994)*E14,2) -> 715.55 | G14: =ROUND((4.33/0.13*1.6+4.33*10+2*1.85*2*2+0.7*2*4*2+0.4*13*2)*0.994*E14/5,2) -> 631.89 | H14: =ROUND((B14*1.1*2)*E14,2) -> 26.29 | I14: =ROUND((B14+0.2)*2*E14,2) -> 33.46 | J14: =(0.4+0.2)*E14 -> 14.34 | K14: =ROUND((B14*0.2*2+(0.4+0.2*2)*0.2*2+0.8*0.15)*E14-(E14/5*0.53*0.45*0.15),2) -> 15.12
A15: U30 | B15: =ROUND((C15+D15)/2,2) -> 0.45 | C15: 0.4 | D15: 0.5 | E15: 49.8 | F15: =ROUND(((B15*2+0.7)*(1/0.15)*1.56+((B15*2+0.7)/0.15+1)*1*0.994)*E15,2) -> 1406.19 | G15: =ROUND((4.33/0.13*1.6+4.33*10+2*1.85*2*2+0.7*2*4*2+0.4*13*2)*0.994*E15/5,2) -> 1316.66 | H15: =ROUND((B15*1.1*2)*E15,2) -> 49.3 | I15: =ROUND((B15+0.2)*2*E15,2) -> 64.74 | J15: =(0.4+0.2)*E15 -> 29.88 | K15: =ROUND((B15*0.2*2+(0.4+0.2*2)*0.2*2+0.8*0.15)*E15-(E15/5*0.53*0.45*0.15),2) -> 30.52 | N15: #5 | O15: #4
A16: U31 | B16: =ROUND((C16+D16)/2,2) -> 0.4 | C16: 0.4 | D16: 0.4 | E16: 26.4 | F16: =ROUND(((B16*2+0.7)*(1/0.15)*1.56+((B16*2+0.7)/0.15+1)*1*0.994)*E16,2) -> 700.5 | G16: =ROUND((4.33/0.13*1.6+4.33*10+2*1.85*2*2+0.7*2*4*2+0.4*13*2)*0.994*E16/5,2) -> 697.99 | H16: =ROUND((B16*1.1*2)*E16,2) -> 23.23 | I16: =ROUND((B16+0.2)*2*E16,2) -> 31.68 | J16: =(0.4+0.2)*E16 -> 15.84 | K16: =ROUND((B16*0.2*2+(0.4+0.2*2)*0.2*2+0.8*0.15)*E16-(E16/5*0.53*0.45*0.15),2) -> 15.65 | N16: =ROUND((B3*2+0.7)*(1/0.15)*E3*1.56,2) -> 760.24 | O16: =((B3*2+0.7)/0.15+1)*1*0.994*E3 -> 527.15133 | Q16: 南 | R16: =E3+E4+E8+E10+E13+E14+E15+E18+E19 -> 314.9 | S16: =E13+E14+E15 -> 97.9
A17: U32 | B17: =ROUND((C17+D17)/2,2) -> 0.45 | C17: 0.5 | D17: 0.4 | E17: 21.4 | F17: =ROUND(((B17*2+0.7)*(1/0.15)*1.56+((B17*2+0.7)/0.15+1)*1*0.994)*E17,2) -> 604.26 | G17: =ROUND((4.33/0.13*1.6+4.33*10+2*1.85*2*2+0.7*2*4*2+0.4*13*2)*0.994*E17/5,2) -> 565.79 | H17: =ROUND((B17*1.1*2)*E17,2) -> 21.19 | I17: =ROUND((B17+0.2)*2*E17,2) -> 27.82 | J17: =(0.4+0.2)*E17 -> 12.84 | K17: =ROUND((B17*0.2*2+(0.4+0.2*2)*0.2*2+0.8*0.15)*E17-(E17/5*0.53*0.45*0.15),2) -> 13.11 | N17: =ROUND((B4*2+0.7)*(1/0.15)*E4*1.56,2) -> 172.06 | O17: =((B4*2+0.7)/0.15+1)*1*0.994*E4 -> 118.97517 | Q17: 北 | R17: =E20-R16 -> 294.3
A18: U33 | B18: =ROUND((C18+D18)/2,2) -> 0.55 | C18: 0.6 | D18: 0.5 | E18: 29.6 | F18: =ROUND(((B18*2+0.7)*(1/0.15)*1.56+((B18*2+0.7)/0.15+1)*1*0.994)*E18,2) -> 936.6 | G18: =ROUND((4.33/0.13*1.6+4.33*10+2*1.85*2*2+0.7*2*4*2+0.4*13*2)*0.994*E18/5,2) -> 782.59 | H18: =ROUND((B18*1.1*2)*E18,2) -> 35.82 | I18: =ROUND((B18+0.2)*2*E18,2) -> 44.4 | J18: =(0.4+0.2)*E18 -> 17.76 | K18: =ROUND((B18*0.2*2+(0.4+0.2*2)*0.2*2+0.8*0.15)*E18-(E18/5*0.53*0.45*0.15),2) -> 19.32 | N18: =ROUND((B5*2+0.7)*(1/0.15)*E5*1.56,2) -> 698.88 | O18: =((B5*2+0.7)/0.15+1)*1*0.994*E5 -> 487.06
A19: U34 | B19: =ROUND((C19+D19)/2,2) -> 0.48 | C19: 0.55 | D19: 0.4 | E19: 58.5 | F19: =ROUND(((B19*2+0.7)*(1/0.15)*1.56+((B19*2+0.7)/0.15+1)*1*0.994)*E19,2) -> 1711.61 | G19: =ROUND((4.33/0.13*1.6+4.33*10+2*1.85*2*2+0.7*2*4*2+0.4*13*2)*0.994*E19/5,2) -> 1546.67 | H19: =ROUND((B19*1.1*2)*E19,2) -> 61.78 | I19: =ROUND((B19+0.2)*2*E19,2) -> 79.56 | J19: =(0.4+0.2)*E19 -> 35.1 | K19: =ROUND((B19*0.2*2+(0.4+0.2*2)*0.2*2+0.8*0.15)*E19-(E19/5*0.53*0.45*0.15),2) -> 36.55 | N19: =ROUND((B6*2+0.7)*(1/0.15)*E6*1.56,2) -> 707.37 | O19: =((B6*2+0.7)/0.15+1)*1*0.994*E6 -> 494.05776
A20: 合計 | E20: =SUM(E3:E19) -> 609.2 | F20: =SUM(F3:F19) -> 19092.18 | G20: =SUM(G3:G19) -> 16106.56 | H20: =SUM(H3:H19) -> 725.24 | I20: =SUM(I3:I19) -> 902.99 | J20: =SUM(J3:J19) -> 365.52 | K20: =SUM(K3:K19) -> 395.51 | N20: =ROUND((B7*2+0.7)*(1/0.15)*E7*1.56,2) -> 397.18 | O20: =((B7*2+0.7)/0.15+1)*1*0.994*E7 -> 273.0518
N21: =ROUND((B8*2+0.7)*(1/0.15)*E8*1.56,2) -> 179.82 | O21: =((B8*2+0.7)/0.15+1)*1*0.994*E8 -> 123.62047
H22: 清水丙模 | I22: 普通丙模 | N22: =ROUND((B9*2+0.7)*(1/0.15)*E9*1.56,2) -> 1858.58 | O22: =((B9*2+0.7)/0.15+1)*1*0.994*E9 -> 1261.4854
B23: 集水井 | C23: 長 | D23: 寬 | E23: 高 | F23: 備註 | G23: 鋼筋 | H23: 模板(內) | I23: 模板(外) | J23: 免拆模 | K23: 混凝土 | N23: =ROUND((B10*2+0.7)*(1/0.15)*E10*1.56,2) -> 1191.63 | O23: =((B10*2+0.7)/0.15+1)*1*0.994*E10 -> 826.27907
A24: 1 | B24: S21 | C24: 0.7 | D24: 0.5 | E24: 0.65 | G24: =ROUND(((E24*2+0.8)*7+(E24*2+1)*6)*1.56+((E24/0.15*1*4)+(0.4*(1+0.8)/0.15)+(3*(0.8*2+1*2)*2))*0.994,2) -> 87.93 | H24: =(C24+D24)*E24*2-0.4*0.6*2 -> 1.08 | I24: =(C24+0.2*2+D24+0.2*2)*2*(E24+0.2+0.2)-(0.8*1)*2 -> 2.6 | J24: 0 | K24: =ROUND(C24*0.2*2*E24+0.1*0.2*2*E24+0.9*1.1*0.15*2-(0.53*0.65*0.15),2) -> 0.45 | N24: =ROUND((B11*2+0.7)*(1/0.15)*E11*1.56,2) -> 310 | O24: =((B11*2+0.7)/0.15+1)*1*0.994*E11 -> 211.24488
A25: 2 | B25: S22 | C25: 0.7 | D25: 0.5 | E25: 0.65 | G25: =ROUND(((E25*2+0.8)*7+(E25*2+1)*6)*1.56+((E25/0.15*1*4)+(0.4*(1+0.8)/0.15)+(3*(0.8*2+1*2)*2))*0.994,2) -> 87.93 | H25: =(C25+D25)*E25*2-0.4*0.6*2 -> 1.08 | I25: =(C25+0.2*2+D25+0.2*2)*2*(E25+0.2+0.2)-(0.8*1)*2 -> 2.6 | K25: =ROUND(C25*0.2*2*E25+0.1*0.2*2*E25+0.9*1.1*0.15*2-(0.53*0.65*0.15),2) -> 0.45 | N25: =ROUND((B12*2+0.7)*(1/0.15)*E12*1.56,2) -> 1004.93 | O25: =((B12*2+0.7)/0.15+1)*1*0.994*E12 -> 689.32575
A26: 3 | B26: S23 | C26: 0.7 | D26: 0.5 | E26: 0.65 | G26: =ROUND(((E26*2+0.8)*7+(E26*2+1)*6)*1.56+((E26/0.15*1*4)+(0.4*(1+0.8)/0.15)+(3*(0.8*2+1*2)*2))*0.994,2) -> 87.93 | H26: =(C26+D26)*E26*2-0.4*0.6*2 -> 1.08 | I26: =(C26+0.2*2+D26+0.2*2)*2*(E26+0.2+0.2)-(0.8*1)*2 -> 2.6 | K26: =ROUND(C26*0.2*2*E26+0.1*0.2*2*E26+0.9*1.1*0.15*2-(0.53*0.65*0.15),2) -> 0.45 | N26: =ROUND((B13*2+0.7)*(1/0.15)*E13*1.56,2) -> 427.86 | O26: =((B13*2+0.7)/0.15+1)*1*0.994*E13 -> 296.67587
A27: 4 | B27: S24 | C27: 0.7 | D27: 0.5 | E27: 0.65 | G27: =ROUND(((E27*2+0.8)*7+(E27*2+1)*6)*1.56+((E27/0.15*1*4)+(0.4*(1+0.8)/0.15)+(3*(0.8*2+1*2)*2))*0.994,2) -> 87.93 | H27: =(C27+D27)*E27*2-0.4*0.6*2 -> 1.08 | I27: =(C27+0.2*2+D27+0.2*2)*2*(E27+0.2+0.2)-(0.8*1)*2 -> 2.6 | K27: =ROUND(C27*0.2*2*E27+0.1*0.2*2*E27+0.9*1.1*0.15*2-(0.53*0.65*0.15),2) -> 0.45 | N27: =ROUND((B14*2+0.7)*(1/0.15)*E14*1.56,2) -> 422.55 | O27: =((B14*2+0.7)/0.15+1)*1*0.994*E14 -> 292.99807
A28: 5 | B28: S24-1 | C28: 0.7 | D28: 0.5 | E28: 1.8 | G28: =ROUND(((E28*2+0.8)*7+(E28*2+1)*6)*1.56+((E28/0.15*1*4)+(0.4*(1+0.8)/0.15)+(3*(0.8*2+1*2)*2))*0.994,2) -> 165.06 | H28: =(C28+D28)*E28*2-0.4*0.6*2 -> 3.84 | I28: =(C28+0.2*2+D28+0.2*2)*2*(E28+0.2+0.2)-(0.8*1)*2 -> 7.2 | K28: =ROUND(C28*0.2*2*E28+0.1*0.2*2*E28+0.9*1.1*0.15*2-(0.53*0.65*0.15),2) -> 0.82 | N28: =ROUND((B15*2+0.7)*(1/0.15)*E15*1.56,2) -> 828.67 | O28: =((B15*2+0.7)/0.15+1)*1*0.994*E15 -> 577.514
A29: 6 | B29: S25 | C29: 0.7 | D29: 0.5 | E29: 0.8 | G29: =ROUND(((E29*2+0.8)*7+(E29*2+1)*6)*1.56+((E29/0.15*1*4)+(0.4*(1+0.8)/0.15)+(3*(0.8*2+1*2)*2))*0.994,2) -> 97.99 | H29: =(C29+D29)*E29*2-0.4*0.6*2 -> 1.44 | I29: =(C29+0.2*2+D29+0.2*2)*2*(E29+0.2+0.2)-(0.8*1)*2 -> 3.2 | K29: =ROUND(C29*0.2*2*E29+0.1*0.2*2*E29+0.9*1.1*0.15*2-(0.53*0.65*0.15),2) -> 0.5 | N29: =ROUND((B16*2+0.7)*(1/0.15)*E16*1.56,2) -> 411.84 | O29: =((B16*2+0.7)/0.15+1)*1*0.994*E16 -> 288.6576
A30: 7 | B30: S26 | C30: 0.7 | D30: 0.5 | E30: 0.65 | G30: =ROUND(((E30*2+0.8)*7+(E30*2+1)*6)*1.56+((E30/0.15*1*4)+(0.4*(1+0.8)/0.15)+(3*(0.8*2+1*2)*2))*0.994,2) -> 87.93 | H30: =(C30+D30)*E30*2-0.4*0.6*2 -> 1.08 | I30: =(C30+0.2*2+D30+0.2*2)*2*(E30+0.2+0.2)-(0.8*1)*2 -> 2.6 | K30: =ROUND(C30*0.2*2*E30+0.1*0.2*2*E30+0.9*1.1*0.15*2-(0.53*0.65*0.15),2) -> 0.45 | N30: =ROUND((B17*2+0.7)*(1/0.15)*E17*1.56,2) -> 356.1 | O30: =((B17*2+0.7)/0.15+1)*1*0.994*E17 -> 248.16867
A31: 8 | B31: S27 | C31: 0.7 | D31: 0.5 | E31: 0.65 | G31: =ROUND(((E31*2+0.8)*7+(E31*2+1)*6)*1.56+((E31/0.15*1*4)+(0.4*(1+0.8)/0.15)+(3*(0.8*2+1*2)*2))*0.994,2) -> 87.93 | H31: =(C31+D31)*E31*2-0.4*0.6*2 -> 1.08 | I31: =(C31+0.2*2+D31+0.2*2)*2*(E31+0.2+0.2)-(0.8*1)*2 -> 2.6 | K31: =ROUND(C31*0.2*2*E31+0.1*0.2*2*E31+0.9*1.1*0.15*2-(0.53*0.65*0.15),2) -> 0.45 | N31: =ROUND((B18*2+0.7)*(1/0.15)*E18*1.56,2) -> 554.11 | O31: =((B18*2+0.7)/0.15+1)*1*0.994*E18 -> 382.4912
A32: 9 | B32: S28 | C32: 0.7 | D32: 0.5 | E32: 0.65 | G32: =ROUND(((E32*2+0.8)*7+(E32*2+1)*6)*1.56+((E32/0.15*1*4)+(0.4*(1+0.8)/0.15)+(3*(0.8*2+1*2)*2))*0.994,2) -> 87.93 | H32: =(C32+D32)*E32*2-0.4*0.6*2 -> 1.08 | I32: =(C32+0.2*2+D32+0.2*2)*2*(E32+0.2+0.2)-(0.8*1)*2 -> 2.6 | K32: =ROUND(C32*0.2*2*E32+0.1*0.2*2*E32+0.9*1.1*0.15*2-(0.53*0.65*0.15),2) -> 0.45 | N32: =ROUND((B19*2+0.7)*(1/0.15)*E19*1.56,2) -> 1009.94 | O32: =((B19*2+0.7)/0.15+1)*1*0.994*E19 -> 701.6646
A33: 10 | B33: S29 | C33: 0.7 | D33: 0.5 | E33: 0.55 | F33: 0.41 | G33: =ROUND(((E33*2+0.8)*7+(E33*2+1)*6)*1.56+((E33/0.15*1*4)+(0.4*(1+0.8)/0.15)+(3*(0.8*2+1*2)*2))*0.994,2) -> 81.22 | H33: =(C33+D33)*E33*2-0.4*0.6*2 -> 0.84 | I33: =(C33+0.2*2+D33+0.2*2)*2*(E33+0.2+0.2)-(0.8*1)*2 -> 2.2 | K33: =ROUND(C33*0.2*2*E33+0.1*0.2*2*E33+0.9*1.1*0.15*2-(0.53*0.65*0.15),2) -> 0.42
A34: 11 | B34: S29-1 | C34: 0.7 | D34: 0.5 | E34: 0.67 | F34: 0.51 | G34: =ROUND(((E34*2+0.8)*7+(E34*2+1)*6)*1.56+((E34/0.15*1*4)+(0.4*(1+0.8)/0.15)+(3*(0.8*2+1*2)*2))*0.994,2) -> 89.27 | H34: =(C34+D34)*E34*2-0.4*0.6*2 -> 1.128 | I34: =(C34+0.2*2+D34+0.2*2)*2*(E34+0.2+0.2)-(0.8*1)*2 -> 2.68 | K34: =ROUND(C34*0.2*2*E34+0.1*0.2*2*E34+0.9*1.1*0.15*2-(0.53*0.65*0.15),2) -> 0.46 | N34: =ROUND((N3*2+0.7)*(1/0.15)*Q3*1.56,2) -> 778.27 | O34: =((N3*2+0.7)/0.15+1)*1*0.994*Q3 -> 548.28377
A35: 12 | B35: S29-2 | C35: 0.7 | D35: 0.5 | E35: 0.7 | G35: =ROUND(((E35*2+0.8)*7+(E35*2+1)*6)*1.56+((E35/0.15*1*4)+(0.4*(1+0.8)/0.15)+(3*(0.8*2+1*2)*2))*0.994,2) -> 91.28 | H35: =(C35+D35)*E35*2-0.4*0.6*2 -> 1.2 | I35: =(C35+0.2*2+D35+0.2*2)*2*(E35+0.2+0.2)-(0.8*1)*2 -> 2.8 | K35: =ROUND(C35*0.2*2*E35+0.1*0.2*2*E35+0.9*1.1*0.15*2-(0.53*0.65*0.15),2) -> 0.47 | N35: =ROUND((N4*2+0.7)*(1/0.15)*Q4*1.56,2) -> 763.53 | O35: =((N4*2+0.7)/0.15+1)*1*0.994*Q4 -> 534.51356
A36: 13 | B36: S30 | C36: 0.7 | D36: 0.5 | E36: 0.65 | G36: =ROUND(((E36*2+0.8)*7+(E36*2+1)*6)*1.56+((E36/0.15*1*4)+(0.4*(1+0.8)/0.15)+(3*(0.8*2+1*2)*2))*0.994,2) -> 87.93 | H36: =(C36+D36)*E36*2-0.4*0.6*2 -> 1.08 | I36: =(C36+0.2*2+D36+0.2*2)*2*(E36+0.2+0.2)-(0.8*1)*2 -> 2.6 | K36: =ROUND(C36*0.2*2*E36+0.1*0.2*2*E36+0.9*1.1*0.15*2-(0.53*0.65*0.15),2) -> 0.45 | N36: =ROUND((N5*2+0.7)*(1/0.15)*Q5*1.56,2) -> 330.72 | O36: =((N5*2+0.7)/0.15+1)*1*0.994*Q5 -> 231.8008
A37: 14 | B37: S31 | C37: 0.7 | D37: 0.5 | E37: 1.15 | F37: 0.8 | G37: =ROUND(((E37*2+0.8)*7+(E37*2+1)*6)*1.56+((E37/0.15*1*4)+(0.4*(1+0.8)/0.15)+(3*(0.8*2+1*2)*2))*0.994,2) -> 121.46 | H37: =(C37+D37)*E37*2-0.4*0.6*2 -> 2.28 | I37: =(C37+0.2*2+D37+0.2*2)*2*(E37+0.2+0.2)-(0.8*1)*2 -> 4.6 | K37: =ROUND(C37*0.2*2*E37+0.1*0.2*2*E37+0.9*1.1*0.15*2-(0.53*0.65*0.15),2) -> 0.61 | M37: 水溝小計 | N37: =SUM(N16:N36) -> 13164.28 | O37: =SUM(O16:O36)+G20+S6 -> 28452.41
